('2015-04-18 10:35:25.278570', 'Traceback (most recent call last):\n  File "/river/fd/fd_worker/fd_channel.py", line 235, in create_channel\n    handle.connect()\n  File "/usr/lib/python3.4/http/client.py", line 1197, in connect\n    self.timeout, self.source_address)\n  File "/usr/lib/python3.4/socket.py", line 509, in create_connection\n    raise err\n  File "/usr/lib/python3.4/socket.py", line 500, in create_connection\n    sock.connect(sa)\nTimeoutError: [Errno 110] Connection timed out\n')
('2015-04-18 10:35:31.291762', 'Traceback (most recent call last):\n  File "/river/fd/fd_worker/fd_channel.py", line 235, in create_channel\n    handle.connect()\n  File "/usr/lib/python3.4/http/client.py", line 1197, in connect\n    self.timeout, self.source_address)\n  File "/usr/lib/python3.4/socket.py", line 509, in create_connection\n    raise err\n  File "/usr/lib/python3.4/socket.py", line 500, in create_connection\n    sock.connect(sa)\nTimeoutError: [Errno 110] Connection timed out\n')
('2015-04-18 11:29:31.541805', 'Traceback (most recent call last):\n  File "/river/fd/fd_worker/fd_channel.py", line 235, in create_channel\n    handle.connect()\n  File "/usr/lib/python3.4/http/client.py", line 1205, in connect\n    server_hostname=server_hostname)\n  File "/usr/lib/python3.4/ssl.py", line 364, in wrap_socket\n    _context=self)\n  File "/usr/lib/python3.4/ssl.py", line 578, in __init__\n    self.do_handshake()\n  File "/usr/lib/python3.4/ssl.py", line 805, in do_handshake\n    self._sslobj.do_handshake()\nConnectionResetError: [Errno 104] Connection reset by peer\n')
('2015-04-18 11:29:32.508469', 'Traceback (most recent call last):\n  File "/river/fd/fd_worker/fd_channel.py", line 235, in create_channel\n    handle.connect()\n  File "/usr/lib/python3.4/http/client.py", line 1205, in connect\n    server_hostname=server_hostname)\n  File "/usr/lib/python3.4/ssl.py", line 364, in wrap_socket\n    _context=self)\n  File "/usr/lib/python3.4/ssl.py", line 578, in __init__\n    self.do_handshake()\n  File "/usr/lib/python3.4/ssl.py", line 805, in do_handshake\n    self._sslobj.do_handshake()\nConnectionResetError: [Errno 104] Connection reset by peer\n')
('2015-04-18 11:29:33.038078', 'Traceback (most recent call last):\n  File "/river/fd/fd_worker/fd_channel.py", line 235, in create_channel\n    handle.connect()\n  File "/usr/lib/python3.4/http/client.py", line 1205, in connect\n    server_hostname=server_hostname)\n  File "/usr/lib/python3.4/ssl.py", line 364, in wrap_socket\n    _context=self)\n  File "/usr/lib/python3.4/ssl.py", line 578, in __init__\n    self.do_handshake()\n  File "/usr/lib/python3.4/ssl.py", line 805, in do_handshake\n    self._sslobj.do_handshake()\nConnectionResetError: [Errno 104] Connection reset by peer\n')
('2015-04-18 11:29:33.209127', 'Traceback (most recent call last):\n  File "/river/fd/fd_worker/fd_channel.py", line 235, in create_channel\n    handle.connect()\n  File "/usr/lib/python3.4/http/client.py", line 1205, in connect\n    server_hostname=server_hostname)\n  File "/usr/lib/python3.4/ssl.py", line 364, in wrap_socket\n    _context=self)\n  File "/usr/lib/python3.4/ssl.py", line 578, in __init__\n    self.do_handshake()\n  File "/usr/lib/python3.4/ssl.py", line 805, in do_handshake\n    self._sslobj.do_handshake()\nConnectionResetError: [Errno 104] Connection reset by peer\n')
('2015-04-18 11:29:36.137521', 'Traceback (most recent call last):\n  File "/river/fd/fd_worker/fd_channel.py", line 235, in create_channel\n    handle.connect()\n  File "/usr/lib/python3.4/http/client.py", line 1205, in connect\n    server_hostname=server_hostname)\n  File "/usr/lib/python3.4/ssl.py", line 364, in wrap_socket\n    _context=self)\n  File "/usr/lib/python3.4/ssl.py", line 578, in __init__\n    self.do_handshake()\n  File "/usr/lib/python3.4/ssl.py", line 805, in do_handshake\n    self._sslobj.do_handshake()\nConnectionResetError: [Errno 104] Connection reset by peer\n')
('2015-04-18 11:29:37.517188', 'Traceback (most recent call last):\n  File "/river/fd/fd_worker/fd_channel.py", line 235, in create_channel\n    handle.connect()\n  File "/usr/lib/python3.4/http/client.py", line 1205, in connect\n    server_hostname=server_hostname)\n  File "/usr/lib/python3.4/ssl.py", line 364, in wrap_socket\n    _context=self)\n  File "/usr/lib/python3.4/ssl.py", line 578, in __init__\n    self.do_handshake()\n  File "/usr/lib/python3.4/ssl.py", line 805, in do_handshake\n    self._sslobj.do_handshake()\nConnectionResetError: [Errno 104] Connection reset by peer\n')
('2015-04-18 11:29:41.321386', 'Traceback (most recent call last):\n  File "/river/fd/fd_worker/fd_channel.py", line 235, in create_channel\n    handle.connect()\n  File "/usr/lib/python3.4/http/client.py", line 1205, in connect\n    server_hostname=server_hostname)\n  File "/usr/lib/python3.4/ssl.py", line 364, in wrap_socket\n    _context=self)\n  File "/usr/lib/python3.4/ssl.py", line 578, in __init__\n    self.do_handshake()\n  File "/usr/lib/python3.4/ssl.py", line 805, in do_handshake\n    self._sslobj.do_handshake()\nConnectionResetError: [Errno 104] Connection reset by peer\n')
('2015-04-18 11:29:42.820437', 'Traceback (most recent call last):\n  File "/river/fd/fd_worker/fd_channel.py", line 235, in create_channel\n    handle.connect()\n  File "/usr/lib/python3.4/http/client.py", line 1205, in connect\n    server_hostname=server_hostname)\n  File "/usr/lib/python3.4/ssl.py", line 364, in wrap_socket\n    _context=self)\n  File "/usr/lib/python3.4/ssl.py", line 578, in __init__\n    self.do_handshake()\n  File "/usr/lib/python3.4/ssl.py", line 805, in do_handshake\n    self._sslobj.do_handshake()\nConnectionResetError: [Errno 104] Connection reset by peer\n')
('2015-04-18 11:29:50.588435', 'Traceback (most recent call last):\n  File "/river/fd/fd_worker/fd_channel.py", line 235, in create_channel\n    handle.connect()\n  File "/usr/lib/python3.4/http/client.py", line 1205, in connect\n    server_hostname=server_hostname)\n  File "/usr/lib/python3.4/ssl.py", line 364, in wrap_socket\n    _context=self)\n  File "/usr/lib/python3.4/ssl.py", line 578, in __init__\n    self.do_handshake()\n  File "/usr/lib/python3.4/ssl.py", line 805, in do_handshake\n    self._sslobj.do_handshake()\nConnectionResetError: [Errno 104] Connection reset by peer\n')
('2015-04-18 11:29:55.508934', 'Traceback (most recent call last):\n  File "/river/fd/fd_worker/fd_channel.py", line 235, in create_channel\n    handle.connect()\n  File "/usr/lib/python3.4/http/client.py", line 1205, in connect\n    server_hostname=server_hostname)\n  File "/usr/lib/python3.4/ssl.py", line 364, in wrap_socket\n    _context=self)\n  File "/usr/lib/python3.4/ssl.py", line 578, in __init__\n    self.do_handshake()\n  File "/usr/lib/python3.4/ssl.py", line 805, in do_handshake\n    self._sslobj.do_handshake()\nConnectionResetError: [Errno 104] Connection reset by peer\n')
('2015-04-18 11:29:58.509548', 'Traceback (most recent call last):\n  File "/river/fd/fd_worker/fd_channel.py", line 235, in create_channel\n    handle.connect()\n  File "/usr/lib/python3.4/http/client.py", line 1205, in connect\n    server_hostname=server_hostname)\n  File "/usr/lib/python3.4/ssl.py", line 364, in wrap_socket\n    _context=self)\n  File "/usr/lib/python3.4/ssl.py", line 578, in __init__\n    self.do_handshake()\n  File "/usr/lib/python3.4/ssl.py", line 805, in do_handshake\n    self._sslobj.do_handshake()\nConnectionResetError: [Errno 104] Connection reset by peer\n')
('2015-04-18 11:30:13.660961', 'Traceback (most recent call last):\n  File "/river/fd/fd_worker/fd_channel.py", line 235, in create_channel\n    handle.connect()\n  File "/usr/lib/python3.4/http/client.py", line 1205, in connect\n    server_hostname=server_hostname)\n  File "/usr/lib/python3.4/ssl.py", line 364, in wrap_socket\n    _context=self)\n  File "/usr/lib/python3.4/ssl.py", line 578, in __init__\n    self.do_handshake()\n  File "/usr/lib/python3.4/ssl.py", line 805, in do_handshake\n    self._sslobj.do_handshake()\nConnectionResetError: [Errno 104] Connection reset by peer\n')
('2015-04-18 11:30:19.227413', 'Traceback (most recent call last):\n  File "/river/fd/fd_worker/fd_channel.py", line 235, in create_channel\n    handle.connect()\n  File "/usr/lib/python3.4/http/client.py", line 1197, in connect\n    self.timeout, self.source_address)\n  File "/usr/lib/python3.4/socket.py", line 509, in create_connection\n    raise err\n  File "/usr/lib/python3.4/socket.py", line 500, in create_connection\n    sock.connect(sa)\nTimeoutError: [Errno 110] Connection timed out\n')
('2015-04-18 11:30:24.284481', 'Traceback (most recent call last):\n  File "/river/fd/fd_worker/fd_channel.py", line 235, in create_channel\n    handle.connect()\n  File "/usr/lib/python3.4/http/client.py", line 1205, in connect\n    server_hostname=server_hostname)\n  File "/usr/lib/python3.4/ssl.py", line 364, in wrap_socket\n    _context=self)\n  File "/usr/lib/python3.4/ssl.py", line 578, in __init__\n    self.do_handshake()\n  File "/usr/lib/python3.4/ssl.py", line 805, in do_handshake\n    self._sslobj.do_handshake()\nConnectionResetError: [Errno 104] Connection reset by peer\n')
('2015-04-18 11:30:25.243590', 'Traceback (most recent call last):\n  File "/river/fd/fd_worker/fd_channel.py", line 235, in create_channel\n    handle.connect()\n  File "/usr/lib/python3.4/http/client.py", line 1197, in connect\n    self.timeout, self.source_address)\n  File "/usr/lib/python3.4/socket.py", line 509, in create_connection\n    raise err\n  File "/usr/lib/python3.4/socket.py", line 500, in create_connection\n    sock.connect(sa)\nTimeoutError: [Errno 110] Connection timed out\n')
('2015-04-18 11:30:35.739566', 'Traceback (most recent call last):\n  File "/river/fd/fd_worker/fd_channel.py", line 235, in create_channel\n    handle.connect()\n  File "/usr/lib/python3.4/http/client.py", line 1197, in connect\n    self.timeout, self.source_address)\n  File "/usr/lib/python3.4/socket.py", line 509, in create_connection\n    raise err\n  File "/usr/lib/python3.4/socket.py", line 500, in create_connection\n    sock.connect(sa)\nTimeoutError: [Errno 110] Connection timed out\n')
('2015-04-18 11:30:50.715570', 'Traceback (most recent call last):\n  File "/river/fd/fd_worker/fd_channel.py", line 235, in create_channel\n    handle.connect()\n  File "/usr/lib/python3.4/http/client.py", line 1197, in connect\n    self.timeout, self.source_address)\n  File "/usr/lib/python3.4/socket.py", line 509, in create_connection\n    raise err\n  File "/usr/lib/python3.4/socket.py", line 500, in create_connection\n    sock.connect(sa)\nTimeoutError: [Errno 110] Connection timed out\n')
('2015-04-18 11:30:55.195402', 'Traceback (most recent call last):\n  File "/river/fd/fd_worker/fd_channel.py", line 235, in create_channel\n    handle.connect()\n  File "/usr/lib/python3.4/http/client.py", line 1197, in connect\n    self.timeout, self.source_address)\n  File "/usr/lib/python3.4/socket.py", line 509, in create_connection\n    raise err\n  File "/usr/lib/python3.4/socket.py", line 500, in create_connection\n    sock.connect(sa)\nTimeoutError: [Errno 110] Connection timed out\n')
('2015-04-18 11:30:56.731654', 'Traceback (most recent call last):\n  File "/river/fd/fd_worker/fd_channel.py", line 235, in create_channel\n    handle.connect()\n  File "/usr/lib/python3.4/http/client.py", line 1197, in connect\n    self.timeout, self.source_address)\n  File "/usr/lib/python3.4/socket.py", line 509, in create_connection\n    raise err\n  File "/usr/lib/python3.4/socket.py", line 500, in create_connection\n    sock.connect(sa)\nTimeoutError: [Errno 110] Connection timed out\n')
('2015-04-18 11:30:56.732525', 'Traceback (most recent call last):\n  File "/river/fd/fd_worker/fd_channel.py", line 235, in create_channel\n    handle.connect()\n  File "/usr/lib/python3.4/http/client.py", line 1197, in connect\n    self.timeout, self.source_address)\n  File "/usr/lib/python3.4/socket.py", line 509, in create_connection\n    raise err\n  File "/usr/lib/python3.4/socket.py", line 500, in create_connection\n    sock.connect(sa)\nTimeoutError: [Errno 110] Connection timed out\n')
('2015-04-18 11:30:59.803559', 'Traceback (most recent call last):\n  File "/river/fd/fd_worker/fd_channel.py", line 235, in create_channel\n    handle.connect()\n  File "/usr/lib/python3.4/http/client.py", line 1197, in connect\n    self.timeout, self.source_address)\n  File "/usr/lib/python3.4/socket.py", line 509, in create_connection\n    raise err\n  File "/usr/lib/python3.4/socket.py", line 500, in create_connection\n    sock.connect(sa)\nTimeoutError: [Errno 110] Connection timed out\n')
('2015-04-18 11:31:01.339584', 'Traceback (most recent call last):\n  File "/river/fd/fd_worker/fd_channel.py", line 235, in create_channel\n    handle.connect()\n  File "/usr/lib/python3.4/http/client.py", line 1197, in connect\n    self.timeout, self.source_address)\n  File "/usr/lib/python3.4/socket.py", line 509, in create_connection\n    raise err\n  File "/usr/lib/python3.4/socket.py", line 500, in create_connection\n    sock.connect(sa)\nTimeoutError: [Errno 110] Connection timed out\n')
