('2015-02-07 10:33:46.617727', 'Traceback (most recent call last):\n  File "/river/fd/fd_worker/fd_channel.py", line 204, in create_channel\n    handle.connect()\n  File "/usr/lib/python3.4/http/client.py", line 1205, in connect\n    server_hostname=server_hostname)\n  File "/usr/lib/python3.4/ssl.py", line 364, in wrap_socket\n    _context=self)\n  File "/usr/lib/python3.4/ssl.py", line 578, in __init__\n    self.do_handshake()\n  File "/usr/lib/python3.4/ssl.py", line 805, in do_handshake\n    self._sslobj.do_handshake()\nConnectionResetError: [Errno 104] Connection reset by peer\n')
('2015-02-07 10:33:46.618165', 'Traceback (most recent call last):\n  File "/river/fd/fd_worker/fd_channel.py", line 204, in create_channel\n    handle.connect()\n  File "/usr/lib/python3.4/http/client.py", line 1205, in connect\n    server_hostname=server_hostname)\n  File "/usr/lib/python3.4/ssl.py", line 364, in wrap_socket\n    _context=self)\n  File "/usr/lib/python3.4/ssl.py", line 578, in __init__\n    self.do_handshake()\n  File "/usr/lib/python3.4/ssl.py", line 805, in do_handshake\n    self._sslobj.do_handshake()\nConnectionResetError: [Errno 104] Connection reset by peer\n')
('2015-02-07 10:33:46.774211', 'Traceback (most recent call last):\n  File "/river/fd/fd_worker/fd_channel.py", line 204, in create_channel\n    handle.connect()\n  File "/usr/lib/python3.4/http/client.py", line 1205, in connect\n    server_hostname=server_hostname)\n  File "/usr/lib/python3.4/ssl.py", line 364, in wrap_socket\n    _context=self)\n  File "/usr/lib/python3.4/ssl.py", line 578, in __init__\n    self.do_handshake()\n  File "/usr/lib/python3.4/ssl.py", line 805, in do_handshake\n    self._sslobj.do_handshake()\nConnectionResetError: [Errno 104] Connection reset by peer\n')
('2015-02-07 10:33:47.593865', 'Traceback (most recent call last):\n  File "/river/fd/fd_worker/fd_channel.py", line 204, in create_channel\n    handle.connect()\n  File "/usr/lib/python3.4/http/client.py", line 1205, in connect\n    server_hostname=server_hostname)\n  File "/usr/lib/python3.4/ssl.py", line 364, in wrap_socket\n    _context=self)\n  File "/usr/lib/python3.4/ssl.py", line 578, in __init__\n    self.do_handshake()\n  File "/usr/lib/python3.4/ssl.py", line 805, in do_handshake\n    self._sslobj.do_handshake()\nConnectionResetError: [Errno 104] Connection reset by peer\n')
('2015-02-07 10:33:48.545758', 'Traceback (most recent call last):\n  File "/river/fd/fd_worker/fd_channel.py", line 204, in create_channel\n    handle.connect()\n  File "/usr/lib/python3.4/http/client.py", line 1205, in connect\n    server_hostname=server_hostname)\n  File "/usr/lib/python3.4/ssl.py", line 364, in wrap_socket\n    _context=self)\n  File "/usr/lib/python3.4/ssl.py", line 578, in __init__\n    self.do_handshake()\n  File "/usr/lib/python3.4/ssl.py", line 805, in do_handshake\n    self._sslobj.do_handshake()\nConnectionResetError: [Errno 104] Connection reset by peer\n')
('2015-02-07 10:33:50.186206', 'Traceback (most recent call last):\n  File "/river/fd/fd_worker/fd_channel.py", line 204, in create_channel\n    handle.connect()\n  File "/usr/lib/python3.4/http/client.py", line 1205, in connect\n    server_hostname=server_hostname)\n  File "/usr/lib/python3.4/ssl.py", line 364, in wrap_socket\n    _context=self)\n  File "/usr/lib/python3.4/ssl.py", line 578, in __init__\n    self.do_handshake()\n  File "/usr/lib/python3.4/ssl.py", line 805, in do_handshake\n    self._sslobj.do_handshake()\nConnectionResetError: [Errno 104] Connection reset by peer\n')
('2015-02-07 10:33:51.033515', 'Traceback (most recent call last):\n  File "/river/fd/fd_worker/fd_channel.py", line 204, in create_channel\n    handle.connect()\n  File "/usr/lib/python3.4/http/client.py", line 1205, in connect\n    server_hostname=server_hostname)\n  File "/usr/lib/python3.4/ssl.py", line 364, in wrap_socket\n    _context=self)\n  File "/usr/lib/python3.4/ssl.py", line 578, in __init__\n    self.do_handshake()\n  File "/usr/lib/python3.4/ssl.py", line 805, in do_handshake\n    self._sslobj.do_handshake()\nConnectionResetError: [Errno 104] Connection reset by peer\n')
('2015-02-07 10:33:51.690121', 'Traceback (most recent call last):\n  File "/river/fd/fd_worker/fd_channel.py", line 204, in create_channel\n    handle.connect()\n  File "/usr/lib/python3.4/http/client.py", line 1205, in connect\n    server_hostname=server_hostname)\n  File "/usr/lib/python3.4/ssl.py", line 364, in wrap_socket\n    _context=self)\n  File "/usr/lib/python3.4/ssl.py", line 578, in __init__\n    self.do_handshake()\n  File "/usr/lib/python3.4/ssl.py", line 805, in do_handshake\n    self._sslobj.do_handshake()\nConnectionResetError: [Errno 104] Connection reset by peer\n')
('2015-02-07 10:33:55.561439', 'Traceback (most recent call last):\n  File "/river/fd/fd_worker/fd_channel.py", line 204, in create_channel\n    handle.connect()\n  File "/usr/lib/python3.4/http/client.py", line 1205, in connect\n    server_hostname=server_hostname)\n  File "/usr/lib/python3.4/ssl.py", line 364, in wrap_socket\n    _context=self)\n  File "/usr/lib/python3.4/ssl.py", line 578, in __init__\n    self.do_handshake()\n  File "/usr/lib/python3.4/ssl.py", line 805, in do_handshake\n    self._sslobj.do_handshake()\nConnectionResetError: [Errno 104] Connection reset by peer\n')
('2015-02-07 10:34:54.200176', 'Traceback (most recent call last):\n  File "/river/fd/fd_worker/fd_channel.py", line 144, in pyget\n    ack  = handle.getresponse()\n  File "/usr/lib/python3.4/http/client.py", line 1147, in getresponse\n    response.begin()\n  File "/usr/lib/python3.4/http/client.py", line 351, in begin\n    version, status, reason = self._read_status()\n  File "/usr/lib/python3.4/http/client.py", line 313, in _read_status\n    line = str(self.fp.readline(_MAXLINE + 1), "iso-8859-1")\n  File "/usr/lib/python3.4/socket.py", line 371, in readinto\n    return self._sock.recv_into(b)\n  File "/usr/lib/python3.4/ssl.py", line 746, in recv_into\n    return self.read(nbytes, buffer)\n  File "/usr/lib/python3.4/ssl.py", line 618, in read\n    v = self._sslobj.read(len, buffer)\nConnectionResetError: [Errno 104] Connection reset by peer\n')
('2015-02-07 10:34:54.217615', 'Traceback (most recent call last):\n  File "/river/fd/fd_worker/fd_channel.py", line 144, in pyget\n    ack  = handle.getresponse()\n  File "/usr/lib/python3.4/http/client.py", line 1147, in getresponse\n    response.begin()\n  File "/usr/lib/python3.4/http/client.py", line 351, in begin\n    version, status, reason = self._read_status()\n  File "/usr/lib/python3.4/http/client.py", line 313, in _read_status\n    line = str(self.fp.readline(_MAXLINE + 1), "iso-8859-1")\n  File "/usr/lib/python3.4/socket.py", line 371, in readinto\n    return self._sock.recv_into(b)\n  File "/usr/lib/python3.4/ssl.py", line 746, in recv_into\n    return self.read(nbytes, buffer)\n  File "/usr/lib/python3.4/ssl.py", line 618, in read\n    v = self._sslobj.read(len, buffer)\nConnectionResetError: [Errno 104] Connection reset by peer\n')
('2015-02-07 10:34:58.249586', 'Traceback (most recent call last):\n  File "/river/fd/fd_worker/fd_channel.py", line 204, in create_channel\n    handle.connect()\n  File "/usr/lib/python3.4/http/client.py", line 1205, in connect\n    server_hostname=server_hostname)\n  File "/usr/lib/python3.4/ssl.py", line 364, in wrap_socket\n    _context=self)\n  File "/usr/lib/python3.4/ssl.py", line 578, in __init__\n    self.do_handshake()\n  File "/usr/lib/python3.4/ssl.py", line 805, in do_handshake\n    self._sslobj.do_handshake()\nConnectionResetError: [Errno 104] Connection reset by peer\n')
('2015-02-07 10:34:59.849602', 'Traceback (most recent call last):\n  File "/river/fd/fd_worker/fd_channel.py", line 204, in create_channel\n    handle.connect()\n  File "/usr/lib/python3.4/http/client.py", line 1205, in connect\n    server_hostname=server_hostname)\n  File "/usr/lib/python3.4/ssl.py", line 364, in wrap_socket\n    _context=self)\n  File "/usr/lib/python3.4/ssl.py", line 578, in __init__\n    self.do_handshake()\n  File "/usr/lib/python3.4/ssl.py", line 805, in do_handshake\n    self._sslobj.do_handshake()\nConnectionResetError: [Errno 104] Connection reset by peer\n')
('2015-02-07 10:35:23.720619', 'Traceback (most recent call last):\n  File "/river/fd/fd_worker/fd_channel.py", line 204, in create_channel\n    handle.connect()\n  File "/usr/lib/python3.4/http/client.py", line 1197, in connect\n    self.timeout, self.source_address)\n  File "/usr/lib/python3.4/socket.py", line 509, in create_connection\n    raise err\n  File "/usr/lib/python3.4/socket.py", line 500, in create_connection\n    sock.connect(sa)\nTimeoutError: [Errno 110] Connection timed out\n')
('2015-02-07 10:35:29.736639', 'Traceback (most recent call last):\n  File "/river/fd/fd_worker/fd_channel.py", line 204, in create_channel\n    handle.connect()\n  File "/usr/lib/python3.4/http/client.py", line 1197, in connect\n    self.timeout, self.source_address)\n  File "/usr/lib/python3.4/socket.py", line 509, in create_connection\n    raise err\n  File "/usr/lib/python3.4/socket.py", line 500, in create_connection\n    sock.connect(sa)\nTimeoutError: [Errno 110] Connection timed out\n')
('2015-02-07 10:35:57.769319', 'Traceback (most recent call last):\n  File "/river/fd/fd_worker/fd_channel.py", line 144, in pyget\n    ack  = handle.getresponse()\n  File "/usr/lib/python3.4/http/client.py", line 1147, in getresponse\n    response.begin()\n  File "/usr/lib/python3.4/http/client.py", line 351, in begin\n    version, status, reason = self._read_status()\n  File "/usr/lib/python3.4/http/client.py", line 313, in _read_status\n    line = str(self.fp.readline(_MAXLINE + 1), "iso-8859-1")\n  File "/usr/lib/python3.4/socket.py", line 371, in readinto\n    return self._sock.recv_into(b)\n  File "/usr/lib/python3.4/ssl.py", line 746, in recv_into\n    return self.read(nbytes, buffer)\n  File "/usr/lib/python3.4/ssl.py", line 618, in read\n    v = self._sslobj.read(len, buffer)\nConnectionResetError: [Errno 104] Connection reset by peer\n')
('2015-02-07 10:35:59.049293', 'Traceback (most recent call last):\n  File "/river/fd/fd_worker/fd_channel.py", line 144, in pyget\n    ack  = handle.getresponse()\n  File "/usr/lib/python3.4/http/client.py", line 1147, in getresponse\n    response.begin()\n  File "/usr/lib/python3.4/http/client.py", line 351, in begin\n    version, status, reason = self._read_status()\n  File "/usr/lib/python3.4/http/client.py", line 313, in _read_status\n    line = str(self.fp.readline(_MAXLINE + 1), "iso-8859-1")\n  File "/usr/lib/python3.4/socket.py", line 371, in readinto\n    return self._sock.recv_into(b)\n  File "/usr/lib/python3.4/ssl.py", line 746, in recv_into\n    return self.read(nbytes, buffer)\n  File "/usr/lib/python3.4/ssl.py", line 618, in read\n    v = self._sslobj.read(len, buffer)\nConnectionResetError: [Errno 104] Connection reset by peer\n')
('2015-02-07 10:36:04.168290', 'Traceback (most recent call last):\n  File "/river/fd/fd_worker/fd_channel.py", line 204, in create_channel\n    handle.connect()\n  File "/usr/lib/python3.4/http/client.py", line 1197, in connect\n    self.timeout, self.source_address)\n  File "/usr/lib/python3.4/socket.py", line 509, in create_connection\n    raise err\n  File "/usr/lib/python3.4/socket.py", line 500, in create_connection\n    sock.connect(sa)\nTimeoutError: [Errno 110] Connection timed out\n')
('2015-02-07 10:36:16.200557', 'Traceback (most recent call last):\n  File "/river/fd/fd_worker/fd_channel.py", line 204, in create_channel\n    handle.connect()\n  File "/usr/lib/python3.4/http/client.py", line 1197, in connect\n    self.timeout, self.source_address)\n  File "/usr/lib/python3.4/socket.py", line 509, in create_connection\n    raise err\n  File "/usr/lib/python3.4/socket.py", line 500, in create_connection\n    sock.connect(sa)\nTimeoutError: [Errno 110] Connection timed out\n')
('2015-02-07 10:36:17.736376', 'Traceback (most recent call last):\n  File "/river/fd/fd_worker/fd_channel.py", line 204, in create_channel\n    handle.connect()\n  File "/usr/lib/python3.4/http/client.py", line 1197, in connect\n    self.timeout, self.source_address)\n  File "/usr/lib/python3.4/socket.py", line 509, in create_connection\n    raise err\n  File "/usr/lib/python3.4/socket.py", line 500, in create_connection\n    sock.connect(sa)\nTimeoutError: [Errno 110] Connection timed out\n')
('2015-02-07 10:36:17.736828', 'Traceback (most recent call last):\n  File "/river/fd/fd_worker/fd_channel.py", line 204, in create_channel\n    handle.connect()\n  File "/usr/lib/python3.4/http/client.py", line 1197, in connect\n    self.timeout, self.source_address)\n  File "/usr/lib/python3.4/socket.py", line 509, in create_connection\n    raise err\n  File "/usr/lib/python3.4/socket.py", line 500, in create_connection\n    sock.connect(sa)\nTimeoutError: [Errno 110] Connection timed out\n')
('2015-02-07 10:36:19.272626', 'Traceback (most recent call last):\n  File "/river/fd/fd_worker/fd_channel.py", line 204, in create_channel\n    handle.connect()\n  File "/usr/lib/python3.4/http/client.py", line 1197, in connect\n    self.timeout, self.source_address)\n  File "/usr/lib/python3.4/socket.py", line 509, in create_connection\n    raise err\n  File "/usr/lib/python3.4/socket.py", line 500, in create_connection\n    sock.connect(sa)\nTimeoutError: [Errno 110] Connection timed out\n')
('2015-02-07 10:36:19.273457', 'Traceback (most recent call last):\n  File "/river/fd/fd_worker/fd_channel.py", line 204, in create_channel\n    handle.connect()\n  File "/usr/lib/python3.4/http/client.py", line 1197, in connect\n    self.timeout, self.source_address)\n  File "/usr/lib/python3.4/socket.py", line 509, in create_connection\n    raise err\n  File "/usr/lib/python3.4/socket.py", line 500, in create_connection\n    sock.connect(sa)\nTimeoutError: [Errno 110] Connection timed out\n')
('2015-02-07 10:36:22.216374', 'Traceback (most recent call last):\n  File "/river/fd/fd_worker/fd_channel.py", line 204, in create_channel\n    handle.connect()\n  File "/usr/lib/python3.4/http/client.py", line 1197, in connect\n    self.timeout, self.source_address)\n  File "/usr/lib/python3.4/socket.py", line 509, in create_connection\n    raise err\n  File "/usr/lib/python3.4/socket.py", line 500, in create_connection\n    sock.connect(sa)\nTimeoutError: [Errno 110] Connection timed out\n')
('2015-02-07 10:36:22.216854', 'Traceback (most recent call last):\n  File "/river/fd/fd_worker/fd_channel.py", line 204, in create_channel\n    handle.connect()\n  File "/usr/lib/python3.4/http/client.py", line 1197, in connect\n    self.timeout, self.source_address)\n  File "/usr/lib/python3.4/socket.py", line 509, in create_connection\n    raise err\n  File "/usr/lib/python3.4/socket.py", line 500, in create_connection\n    sock.connect(sa)\nTimeoutError: [Errno 110] Connection timed out\n')
('2015-02-07 10:36:23.752353', 'Traceback (most recent call last):\n  File "/river/fd/fd_worker/fd_channel.py", line 204, in create_channel\n    handle.connect()\n  File "/usr/lib/python3.4/http/client.py", line 1197, in connect\n    self.timeout, self.source_address)\n  File "/usr/lib/python3.4/socket.py", line 509, in create_connection\n    raise err\n  File "/usr/lib/python3.4/socket.py", line 500, in create_connection\n    sock.connect(sa)\nTimeoutError: [Errno 110] Connection timed out\n')
('2015-02-07 10:36:23.752797', 'Traceback (most recent call last):\n  File "/river/fd/fd_worker/fd_channel.py", line 204, in create_channel\n    handle.connect()\n  File "/usr/lib/python3.4/http/client.py", line 1197, in connect\n    self.timeout, self.source_address)\n  File "/usr/lib/python3.4/socket.py", line 509, in create_connection\n    raise err\n  File "/usr/lib/python3.4/socket.py", line 500, in create_connection\n    sock.connect(sa)\nTimeoutError: [Errno 110] Connection timed out\n')
('2015-02-07 10:36:25.288337', 'Traceback (most recent call last):\n  File "/river/fd/fd_worker/fd_channel.py", line 204, in create_channel\n    handle.connect()\n  File "/usr/lib/python3.4/http/client.py", line 1197, in connect\n    self.timeout, self.source_address)\n  File "/usr/lib/python3.4/socket.py", line 509, in create_connection\n    raise err\n  File "/usr/lib/python3.4/socket.py", line 500, in create_connection\n    sock.connect(sa)\nTimeoutError: [Errno 110] Connection timed out\n')
('2015-02-07 10:36:25.289266', 'Traceback (most recent call last):\n  File "/river/fd/fd_worker/fd_channel.py", line 204, in create_channel\n    handle.connect()\n  File "/usr/lib/python3.4/http/client.py", line 1197, in connect\n    self.timeout, self.source_address)\n  File "/usr/lib/python3.4/socket.py", line 509, in create_connection\n    raise err\n  File "/usr/lib/python3.4/socket.py", line 500, in create_connection\n    sock.connect(sa)\nTimeoutError: [Errno 110] Connection timed out\n')
('2015-02-07 10:36:26.696567', 'Traceback (most recent call last):\n  File "/river/fd/fd_worker/fd_channel.py", line 204, in create_channel\n    handle.connect()\n  File "/usr/lib/python3.4/http/client.py", line 1197, in connect\n    self.timeout, self.source_address)\n  File "/usr/lib/python3.4/socket.py", line 509, in create_connection\n    raise err\n  File "/usr/lib/python3.4/socket.py", line 500, in create_connection\n    sock.connect(sa)\nTimeoutError: [Errno 110] Connection timed out\n')
('2015-02-07 10:36:28.232601', 'Traceback (most recent call last):\n  File "/river/fd/fd_worker/fd_channel.py", line 204, in create_channel\n    handle.connect()\n  File "/usr/lib/python3.4/http/client.py", line 1197, in connect\n    self.timeout, self.source_address)\n  File "/usr/lib/python3.4/socket.py", line 509, in create_connection\n    raise err\n  File "/usr/lib/python3.4/socket.py", line 500, in create_connection\n    sock.connect(sa)\nTimeoutError: [Errno 110] Connection timed out\n')
('2015-02-07 10:36:41.800451', 'Traceback (most recent call last):\n  File "/river/fd/fd_worker/fd_channel.py", line 204, in create_channel\n    handle.connect()\n  File "/usr/lib/python3.4/http/client.py", line 1197, in connect\n    self.timeout, self.source_address)\n  File "/usr/lib/python3.4/socket.py", line 509, in create_connection\n    raise err\n  File "/usr/lib/python3.4/socket.py", line 500, in create_connection\n    sock.connect(sa)\nTimeoutError: [Errno 110] Connection timed out\n')
('2015-02-07 10:36:47.688534', 'Traceback (most recent call last):\n  File "/river/fd/fd_worker/fd_channel.py", line 204, in create_channel\n    handle.connect()\n  File "/usr/lib/python3.4/http/client.py", line 1197, in connect\n    self.timeout, self.source_address)\n  File "/usr/lib/python3.4/socket.py", line 509, in create_connection\n    raise err\n  File "/usr/lib/python3.4/socket.py", line 500, in create_connection\n    sock.connect(sa)\nTimeoutError: [Errno 110] Connection timed out\n')
('2015-02-07 10:36:49.224360', 'Traceback (most recent call last):\n  File "/river/fd/fd_worker/fd_channel.py", line 204, in create_channel\n    handle.connect()\n  File "/usr/lib/python3.4/http/client.py", line 1197, in connect\n    self.timeout, self.source_address)\n  File "/usr/lib/python3.4/socket.py", line 509, in create_connection\n    raise err\n  File "/usr/lib/python3.4/socket.py", line 500, in create_connection\n    sock.connect(sa)\nTimeoutError: [Errno 110] Connection timed out\n')
('2015-02-07 10:36:50.760590', 'Traceback (most recent call last):\n  File "/river/fd/fd_worker/fd_channel.py", line 204, in create_channel\n    handle.connect()\n  File "/usr/lib/python3.4/http/client.py", line 1197, in connect\n    self.timeout, self.source_address)\n  File "/usr/lib/python3.4/socket.py", line 509, in create_connection\n    raise err\n  File "/usr/lib/python3.4/socket.py", line 500, in create_connection\n    sock.connect(sa)\nTimeoutError: [Errno 110] Connection timed out\n')
('2015-02-07 10:36:52.296425', 'Traceback (most recent call last):\n  File "/river/fd/fd_worker/fd_channel.py", line 204, in create_channel\n    handle.connect()\n  File "/usr/lib/python3.4/http/client.py", line 1197, in connect\n    self.timeout, self.source_address)\n  File "/usr/lib/python3.4/socket.py", line 509, in create_connection\n    raise err\n  File "/usr/lib/python3.4/socket.py", line 500, in create_connection\n    sock.connect(sa)\nTimeoutError: [Errno 110] Connection timed out\n')
('2015-02-07 10:37:01.256311', 'Traceback (most recent call last):\n  File "/river/fd/fd_worker/fd_channel.py", line 204, in create_channel\n    handle.connect()\n  File "/usr/lib/python3.4/http/client.py", line 1197, in connect\n    self.timeout, self.source_address)\n  File "/usr/lib/python3.4/socket.py", line 509, in create_connection\n    raise err\n  File "/usr/lib/python3.4/socket.py", line 500, in create_connection\n    sock.connect(sa)\nTimeoutError: [Errno 110] Connection timed out\n')
('2015-02-07 10:37:12.136477', 'Traceback (most recent call last):\n  File "/river/fd/fd_worker/fd_channel.py", line 144, in pyget\n    ack  = handle.getresponse()\n  File "/usr/lib/python3.4/http/client.py", line 1147, in getresponse\n    response.begin()\n  File "/usr/lib/python3.4/http/client.py", line 351, in begin\n    version, status, reason = self._read_status()\n  File "/usr/lib/python3.4/http/client.py", line 321, in _read_status\n    raise BadStatusLine(line)\nhttp.client.BadStatusLine: \'\'\n')
('2015-02-07 10:37:13.288331', 'Traceback (most recent call last):\n  File "/river/fd/fd_worker/fd_channel.py", line 204, in create_channel\n    handle.connect()\n  File "/usr/lib/python3.4/http/client.py", line 1197, in connect\n    self.timeout, self.source_address)\n  File "/usr/lib/python3.4/socket.py", line 509, in create_connection\n    raise err\n  File "/usr/lib/python3.4/socket.py", line 500, in create_connection\n    sock.connect(sa)\nTimeoutError: [Errno 110] Connection timed out\n')
('2015-02-07 10:37:14.824366', 'Traceback (most recent call last):\n  File "/river/fd/fd_worker/fd_channel.py", line 204, in create_channel\n    handle.connect()\n  File "/usr/lib/python3.4/http/client.py", line 1197, in connect\n    self.timeout, self.source_address)\n  File "/usr/lib/python3.4/socket.py", line 509, in create_connection\n    raise err\n  File "/usr/lib/python3.4/socket.py", line 500, in create_connection\n    sock.connect(sa)\nTimeoutError: [Errno 110] Connection timed out\n')
('2015-02-07 10:37:16.232358', 'Traceback (most recent call last):\n  File "/river/fd/fd_worker/fd_channel.py", line 204, in create_channel\n    handle.connect()\n  File "/usr/lib/python3.4/http/client.py", line 1197, in connect\n    self.timeout, self.source_address)\n  File "/usr/lib/python3.4/socket.py", line 509, in create_connection\n    raise err\n  File "/usr/lib/python3.4/socket.py", line 500, in create_connection\n    sock.connect(sa)\nTimeoutError: [Errno 110] Connection timed out\n')
('2015-02-07 10:37:16.232680', 'Traceback (most recent call last):\n  File "/river/fd/fd_worker/fd_channel.py", line 204, in create_channel\n    handle.connect()\n  File "/usr/lib/python3.4/http/client.py", line 1197, in connect\n    self.timeout, self.source_address)\n  File "/usr/lib/python3.4/socket.py", line 509, in create_connection\n    raise err\n  File "/usr/lib/python3.4/socket.py", line 500, in create_connection\n    sock.connect(sa)\nTimeoutError: [Errno 110] Connection timed out\n')
('2015-02-07 10:37:17.768651', 'Traceback (most recent call last):\n  File "/river/fd/fd_worker/fd_channel.py", line 204, in create_channel\n    handle.connect()\n  File "/usr/lib/python3.4/http/client.py", line 1197, in connect\n    self.timeout, self.source_address)\n  File "/usr/lib/python3.4/socket.py", line 509, in create_connection\n    raise err\n  File "/usr/lib/python3.4/socket.py", line 500, in create_connection\n    sock.connect(sa)\nTimeoutError: [Errno 110] Connection timed out\n')
('2015-02-07 10:37:17.769233', 'Traceback (most recent call last):\n  File "/river/fd/fd_worker/fd_channel.py", line 204, in create_channel\n    handle.connect()\n  File "/usr/lib/python3.4/http/client.py", line 1197, in connect\n    self.timeout, self.source_address)\n  File "/usr/lib/python3.4/socket.py", line 509, in create_connection\n    raise err\n  File "/usr/lib/python3.4/socket.py", line 500, in create_connection\n    sock.connect(sa)\nTimeoutError: [Errno 110] Connection timed out\n')
('2015-02-07 10:37:19.176335', 'Traceback (most recent call last):\n  File "/river/fd/fd_worker/fd_channel.py", line 204, in create_channel\n    handle.connect()\n  File "/usr/lib/python3.4/http/client.py", line 1197, in connect\n    self.timeout, self.source_address)\n  File "/usr/lib/python3.4/socket.py", line 509, in create_connection\n    raise err\n  File "/usr/lib/python3.4/socket.py", line 500, in create_connection\n    sock.connect(sa)\nTimeoutError: [Errno 110] Connection timed out\n')
('2015-02-07 10:37:20.712661', 'Traceback (most recent call last):\n  File "/river/fd/fd_worker/fd_channel.py", line 204, in create_channel\n    handle.connect()\n  File "/usr/lib/python3.4/http/client.py", line 1197, in connect\n    self.timeout, self.source_address)\n  File "/usr/lib/python3.4/socket.py", line 509, in create_connection\n    raise err\n  File "/usr/lib/python3.4/socket.py", line 500, in create_connection\n    sock.connect(sa)\nTimeoutError: [Errno 110] Connection timed out\n')
('2015-02-07 10:37:23.784959', 'Traceback (most recent call last):\n  File "/river/fd/fd_worker/fd_channel.py", line 204, in create_channel\n    handle.connect()\n  File "/usr/lib/python3.4/http/client.py", line 1197, in connect\n    self.timeout, self.source_address)\n  File "/usr/lib/python3.4/socket.py", line 509, in create_connection\n    raise err\n  File "/usr/lib/python3.4/socket.py", line 500, in create_connection\n    sock.connect(sa)\nTimeoutError: [Errno 110] Connection timed out\n')
('2015-02-07 10:37:25.320408', 'Traceback (most recent call last):\n  File "/river/fd/fd_worker/fd_channel.py", line 204, in create_channel\n    handle.connect()\n  File "/usr/lib/python3.4/http/client.py", line 1197, in connect\n    self.timeout, self.source_address)\n  File "/usr/lib/python3.4/socket.py", line 509, in create_connection\n    raise err\n  File "/usr/lib/python3.4/socket.py", line 500, in create_connection\n    sock.connect(sa)\nTimeoutError: [Errno 110] Connection timed out\n')
('2015-02-07 10:37:26.728395', 'Traceback (most recent call last):\n  File "/river/fd/fd_worker/fd_channel.py", line 204, in create_channel\n    handle.connect()\n  File "/usr/lib/python3.4/http/client.py", line 1197, in connect\n    self.timeout, self.source_address)\n  File "/usr/lib/python3.4/socket.py", line 509, in create_connection\n    raise err\n  File "/usr/lib/python3.4/socket.py", line 500, in create_connection\n    sock.connect(sa)\nTimeoutError: [Errno 110] Connection timed out\n')
('2015-02-07 10:37:28.264366', 'Traceback (most recent call last):\n  File "/river/fd/fd_worker/fd_channel.py", line 204, in create_channel\n    handle.connect()\n  File "/usr/lib/python3.4/http/client.py", line 1197, in connect\n    self.timeout, self.source_address)\n  File "/usr/lib/python3.4/socket.py", line 509, in create_connection\n    raise err\n  File "/usr/lib/python3.4/socket.py", line 500, in create_connection\n    sock.connect(sa)\nTimeoutError: [Errno 110] Connection timed out\n')
('2015-02-07 10:37:28.765913', 'Traceback (most recent call last):\n  File "/river/fd/fd_worker/fd_channel.py", line 144, in pyget\n    ack  = handle.getresponse()\n  File "/usr/lib/python3.4/http/client.py", line 1147, in getresponse\n    response.begin()\n  File "/usr/lib/python3.4/http/client.py", line 351, in begin\n    version, status, reason = self._read_status()\n  File "/usr/lib/python3.4/http/client.py", line 321, in _read_status\n    raise BadStatusLine(line)\nhttp.client.BadStatusLine: \'\'\n')
('2015-02-07 10:37:44.776447', 'Traceback (most recent call last):\n  File "/river/fd/fd_worker/fd_channel.py", line 204, in create_channel\n    handle.connect()\n  File "/usr/lib/python3.4/http/client.py", line 1197, in connect\n    self.timeout, self.source_address)\n  File "/usr/lib/python3.4/socket.py", line 509, in create_connection\n    raise err\n  File "/usr/lib/python3.4/socket.py", line 500, in create_connection\n    sock.connect(sa)\nTimeoutError: [Errno 110] Connection timed out\n')
('2015-02-07 10:37:46.312332', 'Traceback (most recent call last):\n  File "/river/fd/fd_worker/fd_channel.py", line 204, in create_channel\n    handle.connect()\n  File "/usr/lib/python3.4/http/client.py", line 1197, in connect\n    self.timeout, self.source_address)\n  File "/usr/lib/python3.4/socket.py", line 509, in create_connection\n    raise err\n  File "/usr/lib/python3.4/socket.py", line 500, in create_connection\n    sock.connect(sa)\nTimeoutError: [Errno 110] Connection timed out\n')
('2015-02-07 10:37:46.312881', 'Traceback (most recent call last):\n  File "/river/fd/fd_worker/fd_channel.py", line 204, in create_channel\n    handle.connect()\n  File "/usr/lib/python3.4/http/client.py", line 1197, in connect\n    self.timeout, self.source_address)\n  File "/usr/lib/python3.4/socket.py", line 509, in create_connection\n    raise err\n  File "/usr/lib/python3.4/socket.py", line 500, in create_connection\n    sock.connect(sa)\nTimeoutError: [Errno 110] Connection timed out\n')
('2015-02-07 10:37:47.720368', 'Traceback (most recent call last):\n  File "/river/fd/fd_worker/fd_channel.py", line 204, in create_channel\n    handle.connect()\n  File "/usr/lib/python3.4/http/client.py", line 1197, in connect\n    self.timeout, self.source_address)\n  File "/usr/lib/python3.4/socket.py", line 509, in create_connection\n    raise err\n  File "/usr/lib/python3.4/socket.py", line 500, in create_connection\n    sock.connect(sa)\nTimeoutError: [Errno 110] Connection timed out\n')
('2015-02-07 10:37:47.720836', 'Traceback (most recent call last):\n  File "/river/fd/fd_worker/fd_channel.py", line 204, in create_channel\n    handle.connect()\n  File "/usr/lib/python3.4/http/client.py", line 1197, in connect\n    self.timeout, self.source_address)\n  File "/usr/lib/python3.4/socket.py", line 509, in create_connection\n    raise err\n  File "/usr/lib/python3.4/socket.py", line 500, in create_connection\n    sock.connect(sa)\nTimeoutError: [Errno 110] Connection timed out\n')
('2015-02-07 10:37:49.256277', 'Traceback (most recent call last):\n  File "/river/fd/fd_worker/fd_channel.py", line 204, in create_channel\n    handle.connect()\n  File "/usr/lib/python3.4/http/client.py", line 1197, in connect\n    self.timeout, self.source_address)\n  File "/usr/lib/python3.4/socket.py", line 509, in create_connection\n    raise err\n  File "/usr/lib/python3.4/socket.py", line 500, in create_connection\n    sock.connect(sa)\nTimeoutError: [Errno 110] Connection timed out\n')
('2015-02-07 10:37:50.792715', 'Traceback (most recent call last):\n  File "/river/fd/fd_worker/fd_channel.py", line 204, in create_channel\n    handle.connect()\n  File "/usr/lib/python3.4/http/client.py", line 1197, in connect\n    self.timeout, self.source_address)\n  File "/usr/lib/python3.4/socket.py", line 509, in create_connection\n    raise err\n  File "/usr/lib/python3.4/socket.py", line 500, in create_connection\n    sock.connect(sa)\nTimeoutError: [Errno 110] Connection timed out\n')
('2015-02-07 10:37:52.200272', 'Traceback (most recent call last):\n  File "/river/fd/fd_worker/fd_channel.py", line 204, in create_channel\n    handle.connect()\n  File "/usr/lib/python3.4/http/client.py", line 1197, in connect\n    self.timeout, self.source_address)\n  File "/usr/lib/python3.4/socket.py", line 509, in create_connection\n    raise err\n  File "/usr/lib/python3.4/socket.py", line 500, in create_connection\n    sock.connect(sa)\nTimeoutError: [Errno 110] Connection timed out\n')
('2015-02-07 10:37:53.736633', 'Traceback (most recent call last):\n  File "/river/fd/fd_worker/fd_channel.py", line 204, in create_channel\n    handle.connect()\n  File "/usr/lib/python3.4/http/client.py", line 1197, in connect\n    self.timeout, self.source_address)\n  File "/usr/lib/python3.4/socket.py", line 509, in create_connection\n    raise err\n  File "/usr/lib/python3.4/socket.py", line 500, in create_connection\n    sock.connect(sa)\nTimeoutError: [Errno 110] Connection timed out\n')
('2015-02-07 10:38:01.161095', 'Traceback (most recent call last):\n  File "/river/fd/fd_worker/fd_channel.py", line 144, in pyget\n    ack  = handle.getresponse()\n  File "/usr/lib/python3.4/http/client.py", line 1147, in getresponse\n    response.begin()\n  File "/usr/lib/python3.4/http/client.py", line 351, in begin\n    version, status, reason = self._read_status()\n  File "/usr/lib/python3.4/http/client.py", line 313, in _read_status\n    line = str(self.fp.readline(_MAXLINE + 1), "iso-8859-1")\n  File "/usr/lib/python3.4/socket.py", line 371, in readinto\n    return self._sock.recv_into(b)\n  File "/usr/lib/python3.4/ssl.py", line 746, in recv_into\n    return self.read(nbytes, buffer)\n  File "/usr/lib/python3.4/ssl.py", line 618, in read\n    v = self._sslobj.read(len, buffer)\nConnectionResetError: [Errno 104] Connection reset by peer\n')
('2015-02-07 10:38:01.161689', 'Traceback (most recent call last):\n  File "/river/fd/fd_worker/fd_channel.py", line 144, in pyget\n    ack  = handle.getresponse()\n  File "/usr/lib/python3.4/http/client.py", line 1147, in getresponse\n    response.begin()\n  File "/usr/lib/python3.4/http/client.py", line 351, in begin\n    version, status, reason = self._read_status()\n  File "/usr/lib/python3.4/http/client.py", line 313, in _read_status\n    line = str(self.fp.readline(_MAXLINE + 1), "iso-8859-1")\n  File "/usr/lib/python3.4/socket.py", line 371, in readinto\n    return self._sock.recv_into(b)\n  File "/usr/lib/python3.4/ssl.py", line 746, in recv_into\n    return self.read(nbytes, buffer)\n  File "/usr/lib/python3.4/ssl.py", line 618, in read\n    v = self._sslobj.read(len, buffer)\nConnectionResetError: [Errno 104] Connection reset by peer\n')
('2015-02-07 10:38:01.288254', 'Traceback (most recent call last):\n  File "/river/fd/fd_worker/fd_channel.py", line 204, in create_channel\n    handle.connect()\n  File "/usr/lib/python3.4/http/client.py", line 1197, in connect\n    self.timeout, self.source_address)\n  File "/usr/lib/python3.4/socket.py", line 509, in create_connection\n    raise err\n  File "/usr/lib/python3.4/socket.py", line 500, in create_connection\n    sock.connect(sa)\nTimeoutError: [Errno 110] Connection timed out\n')
('2015-02-07 10:38:15.497948', 'Traceback (most recent call last):\n  File "/river/fd/fd_worker/fd_channel.py", line 144, in pyget\n    ack  = handle.getresponse()\n  File "/usr/lib/python3.4/http/client.py", line 1147, in getresponse\n    response.begin()\n  File "/usr/lib/python3.4/http/client.py", line 351, in begin\n    version, status, reason = self._read_status()\n  File "/usr/lib/python3.4/http/client.py", line 313, in _read_status\n    line = str(self.fp.readline(_MAXLINE + 1), "iso-8859-1")\n  File "/usr/lib/python3.4/socket.py", line 371, in readinto\n    return self._sock.recv_into(b)\n  File "/usr/lib/python3.4/ssl.py", line 746, in recv_into\n    return self.read(nbytes, buffer)\n  File "/usr/lib/python3.4/ssl.py", line 618, in read\n    v = self._sslobj.read(len, buffer)\nConnectionResetError: [Errno 104] Connection reset by peer\n')
('2015-02-07 10:38:17.545193', 'Traceback (most recent call last):\n  File "/river/fd/fd_worker/fd_channel.py", line 144, in pyget\n    ack  = handle.getresponse()\n  File "/usr/lib/python3.4/http/client.py", line 1147, in getresponse\n    response.begin()\n  File "/usr/lib/python3.4/http/client.py", line 351, in begin\n    version, status, reason = self._read_status()\n  File "/usr/lib/python3.4/http/client.py", line 313, in _read_status\n    line = str(self.fp.readline(_MAXLINE + 1), "iso-8859-1")\n  File "/usr/lib/python3.4/socket.py", line 371, in readinto\n    return self._sock.recv_into(b)\n  File "/usr/lib/python3.4/ssl.py", line 746, in recv_into\n    return self.read(nbytes, buffer)\n  File "/usr/lib/python3.4/ssl.py", line 618, in read\n    v = self._sslobj.read(len, buffer)\nConnectionResetError: [Errno 104] Connection reset by peer\n')
('2015-02-07 10:38:20.744320', 'Traceback (most recent call last):\n  File "/river/fd/fd_worker/fd_channel.py", line 204, in create_channel\n    handle.connect()\n  File "/usr/lib/python3.4/http/client.py", line 1197, in connect\n    self.timeout, self.source_address)\n  File "/usr/lib/python3.4/socket.py", line 509, in create_connection\n    raise err\n  File "/usr/lib/python3.4/socket.py", line 500, in create_connection\n    sock.connect(sa)\nTimeoutError: [Errno 110] Connection timed out\n')
('2015-02-07 10:38:22.280293', 'Traceback (most recent call last):\n  File "/river/fd/fd_worker/fd_channel.py", line 204, in create_channel\n    handle.connect()\n  File "/usr/lib/python3.4/http/client.py", line 1197, in connect\n    self.timeout, self.source_address)\n  File "/usr/lib/python3.4/socket.py", line 509, in create_connection\n    raise err\n  File "/usr/lib/python3.4/socket.py", line 500, in create_connection\n    sock.connect(sa)\nTimeoutError: [Errno 110] Connection timed out\n')
('2015-02-07 10:38:23.688382', 'Traceback (most recent call last):\n  File "/river/fd/fd_worker/fd_channel.py", line 204, in create_channel\n    handle.connect()\n  File "/usr/lib/python3.4/http/client.py", line 1197, in connect\n    self.timeout, self.source_address)\n  File "/usr/lib/python3.4/socket.py", line 509, in create_connection\n    raise err\n  File "/usr/lib/python3.4/socket.py", line 500, in create_connection\n    sock.connect(sa)\nTimeoutError: [Errno 110] Connection timed out\n')
('2015-02-07 10:38:25.224563', 'Traceback (most recent call last):\n  File "/river/fd/fd_worker/fd_channel.py", line 204, in create_channel\n    handle.connect()\n  File "/usr/lib/python3.4/http/client.py", line 1197, in connect\n    self.timeout, self.source_address)\n  File "/usr/lib/python3.4/socket.py", line 509, in create_connection\n    raise err\n  File "/usr/lib/python3.4/socket.py", line 500, in create_connection\n    sock.connect(sa)\nTimeoutError: [Errno 110] Connection timed out\n')
('2015-02-07 10:38:25.225399', 'Traceback (most recent call last):\n  File "/river/fd/fd_worker/fd_channel.py", line 204, in create_channel\n    handle.connect()\n  File "/usr/lib/python3.4/http/client.py", line 1197, in connect\n    self.timeout, self.source_address)\n  File "/usr/lib/python3.4/socket.py", line 509, in create_connection\n    raise err\n  File "/usr/lib/python3.4/socket.py", line 500, in create_connection\n    sock.connect(sa)\nTimeoutError: [Errno 110] Connection timed out\n')
('2015-02-07 10:38:26.760382', 'Traceback (most recent call last):\n  File "/river/fd/fd_worker/fd_channel.py", line 204, in create_channel\n    handle.connect()\n  File "/usr/lib/python3.4/http/client.py", line 1197, in connect\n    self.timeout, self.source_address)\n  File "/usr/lib/python3.4/socket.py", line 509, in create_connection\n    raise err\n  File "/usr/lib/python3.4/socket.py", line 500, in create_connection\n    sock.connect(sa)\nTimeoutError: [Errno 110] Connection timed out\n')
('2015-02-07 10:38:26.760863', 'Traceback (most recent call last):\n  File "/river/fd/fd_worker/fd_channel.py", line 204, in create_channel\n    handle.connect()\n  File "/usr/lib/python3.4/http/client.py", line 1197, in connect\n    self.timeout, self.source_address)\n  File "/usr/lib/python3.4/socket.py", line 509, in create_connection\n    raise err\n  File "/usr/lib/python3.4/socket.py", line 500, in create_connection\n    sock.connect(sa)\nTimeoutError: [Errno 110] Connection timed out\n')
('2015-02-07 10:38:28.296377', 'Traceback (most recent call last):\n  File "/river/fd/fd_worker/fd_channel.py", line 204, in create_channel\n    handle.connect()\n  File "/usr/lib/python3.4/http/client.py", line 1197, in connect\n    self.timeout, self.source_address)\n  File "/usr/lib/python3.4/socket.py", line 509, in create_connection\n    raise err\n  File "/usr/lib/python3.4/socket.py", line 500, in create_connection\n    sock.connect(sa)\nTimeoutError: [Errno 110] Connection timed out\n')
('2015-02-07 10:38:34.184578', 'Traceback (most recent call last):\n  File "/river/fd/fd_worker/fd_channel.py", line 204, in create_channel\n    handle.connect()\n  File "/usr/lib/python3.4/http/client.py", line 1197, in connect\n    self.timeout, self.source_address)\n  File "/usr/lib/python3.4/socket.py", line 509, in create_connection\n    raise err\n  File "/usr/lib/python3.4/socket.py", line 500, in create_connection\n    sock.connect(sa)\nTimeoutError: [Errno 110] Connection timed out\n')
('2015-02-07 10:38:35.720569', 'Traceback (most recent call last):\n  File "/river/fd/fd_worker/fd_channel.py", line 204, in create_channel\n    handle.connect()\n  File "/usr/lib/python3.4/http/client.py", line 1197, in connect\n    self.timeout, self.source_address)\n  File "/usr/lib/python3.4/socket.py", line 509, in create_connection\n    raise err\n  File "/usr/lib/python3.4/socket.py", line 500, in create_connection\n    sock.connect(sa)\nTimeoutError: [Errno 110] Connection timed out\n')
('2015-02-07 10:38:49.288446', 'Traceback (most recent call last):\n  File "/river/fd/fd_worker/fd_channel.py", line 204, in create_channel\n    handle.connect()\n  File "/usr/lib/python3.4/http/client.py", line 1197, in connect\n    self.timeout, self.source_address)\n  File "/usr/lib/python3.4/socket.py", line 509, in create_connection\n    raise err\n  File "/usr/lib/python3.4/socket.py", line 500, in create_connection\n    sock.connect(sa)\nTimeoutError: [Errno 110] Connection timed out\n')
('2015-02-07 10:39:07.495791', 'Traceback (most recent call last):\n  File "/river/fd/fd_worker/fd_channel.py", line 144, in pyget\n    ack  = handle.getresponse()\n  File "/usr/lib/python3.4/http/client.py", line 1147, in getresponse\n    response.begin()\n  File "/usr/lib/python3.4/http/client.py", line 351, in begin\n    version, status, reason = self._read_status()\n  File "/usr/lib/python3.4/http/client.py", line 321, in _read_status\n    raise BadStatusLine(line)\nhttp.client.BadStatusLine: \'\'\n')
('2015-02-07 10:39:27.177223', 'Traceback (most recent call last):\n  File "/river/fd/fd_worker/fd_channel.py", line 144, in pyget\n    ack  = handle.getresponse()\n  File "/usr/lib/python3.4/http/client.py", line 1147, in getresponse\n    response.begin()\n  File "/usr/lib/python3.4/http/client.py", line 351, in begin\n    version, status, reason = self._read_status()\n  File "/usr/lib/python3.4/http/client.py", line 313, in _read_status\n    line = str(self.fp.readline(_MAXLINE + 1), "iso-8859-1")\n  File "/usr/lib/python3.4/socket.py", line 371, in readinto\n    return self._sock.recv_into(b)\n  File "/usr/lib/python3.4/ssl.py", line 746, in recv_into\n    return self.read(nbytes, buffer)\n  File "/usr/lib/python3.4/ssl.py", line 618, in read\n    v = self._sslobj.read(len, buffer)\nConnectionResetError: [Errno 104] Connection reset by peer\n')
('2015-02-07 10:39:31.273103', 'Traceback (most recent call last):\n  File "/river/fd/fd_worker/fd_channel.py", line 144, in pyget\n    ack  = handle.getresponse()\n  File "/usr/lib/python3.4/http/client.py", line 1147, in getresponse\n    response.begin()\n  File "/usr/lib/python3.4/http/client.py", line 351, in begin\n    version, status, reason = self._read_status()\n  File "/usr/lib/python3.4/http/client.py", line 313, in _read_status\n    line = str(self.fp.readline(_MAXLINE + 1), "iso-8859-1")\n  File "/usr/lib/python3.4/socket.py", line 371, in readinto\n    return self._sock.recv_into(b)\n  File "/usr/lib/python3.4/ssl.py", line 746, in recv_into\n    return self.read(nbytes, buffer)\n  File "/usr/lib/python3.4/ssl.py", line 618, in read\n    v = self._sslobj.read(len, buffer)\nConnectionResetError: [Errno 104] Connection reset by peer\n')
('2015-02-07 10:39:40.490094', 'Traceback (most recent call last):\n  File "/river/fd/fd_worker/fd_channel.py", line 144, in pyget\n    ack  = handle.getresponse()\n  File "/usr/lib/python3.4/http/client.py", line 1147, in getresponse\n    response.begin()\n  File "/usr/lib/python3.4/http/client.py", line 351, in begin\n    version, status, reason = self._read_status()\n  File "/usr/lib/python3.4/http/client.py", line 313, in _read_status\n    line = str(self.fp.readline(_MAXLINE + 1), "iso-8859-1")\n  File "/usr/lib/python3.4/socket.py", line 371, in readinto\n    return self._sock.recv_into(b)\n  File "/usr/lib/python3.4/ssl.py", line 746, in recv_into\n    return self.read(nbytes, buffer)\n  File "/usr/lib/python3.4/ssl.py", line 618, in read\n    v = self._sslobj.read(len, buffer)\nConnectionResetError: [Errno 104] Connection reset by peer\n')
('2015-02-07 10:39:42.537986', 'Traceback (most recent call last):\n  File "/river/fd/fd_worker/fd_channel.py", line 144, in pyget\n    ack  = handle.getresponse()\n  File "/usr/lib/python3.4/http/client.py", line 1147, in getresponse\n    response.begin()\n  File "/usr/lib/python3.4/http/client.py", line 351, in begin\n    version, status, reason = self._read_status()\n  File "/usr/lib/python3.4/http/client.py", line 313, in _read_status\n    line = str(self.fp.readline(_MAXLINE + 1), "iso-8859-1")\n  File "/usr/lib/python3.4/socket.py", line 371, in readinto\n    return self._sock.recv_into(b)\n  File "/usr/lib/python3.4/ssl.py", line 746, in recv_into\n    return self.read(nbytes, buffer)\n  File "/usr/lib/python3.4/ssl.py", line 618, in read\n    v = self._sslobj.read(len, buffer)\nConnectionResetError: [Errno 104] Connection reset by peer\n')
('2015-02-07 11:29:19.222670', 'Traceback (most recent call last):\n  File "/river/fd/fd_worker/fd_channel.py", line 204, in create_channel\n    handle.connect()\n  File "/usr/lib/python3.4/http/client.py", line 1205, in connect\n    server_hostname=server_hostname)\n  File "/usr/lib/python3.4/ssl.py", line 364, in wrap_socket\n    _context=self)\n  File "/usr/lib/python3.4/ssl.py", line 578, in __init__\n    self.do_handshake()\n  File "/usr/lib/python3.4/ssl.py", line 805, in do_handshake\n    self._sslobj.do_handshake()\nConnectionResetError: [Errno 104] Connection reset by peer\n')
('2015-02-07 11:29:19.434115', 'Traceback (most recent call last):\n  File "/river/fd/fd_worker/fd_channel.py", line 204, in create_channel\n    handle.connect()\n  File "/usr/lib/python3.4/http/client.py", line 1205, in connect\n    server_hostname=server_hostname)\n  File "/usr/lib/python3.4/ssl.py", line 364, in wrap_socket\n    _context=self)\n  File "/usr/lib/python3.4/ssl.py", line 578, in __init__\n    self.do_handshake()\n  File "/usr/lib/python3.4/ssl.py", line 805, in do_handshake\n    self._sslobj.do_handshake()\nConnectionResetError: [Errno 104] Connection reset by peer\n')
('2015-02-07 11:29:20.118369', 'Traceback (most recent call last):\n  File "/river/fd/fd_worker/fd_channel.py", line 204, in create_channel\n    handle.connect()\n  File "/usr/lib/python3.4/http/client.py", line 1205, in connect\n    server_hostname=server_hostname)\n  File "/usr/lib/python3.4/ssl.py", line 364, in wrap_socket\n    _context=self)\n  File "/usr/lib/python3.4/ssl.py", line 578, in __init__\n    self.do_handshake()\n  File "/usr/lib/python3.4/ssl.py", line 805, in do_handshake\n    self._sslobj.do_handshake()\nConnectionResetError: [Errno 104] Connection reset by peer\n')
('2015-02-07 11:29:21.115218', 'Traceback (most recent call last):\n  File "/river/fd/fd_worker/fd_channel.py", line 204, in create_channel\n    handle.connect()\n  File "/usr/lib/python3.4/http/client.py", line 1205, in connect\n    server_hostname=server_hostname)\n  File "/usr/lib/python3.4/ssl.py", line 364, in wrap_socket\n    _context=self)\n  File "/usr/lib/python3.4/ssl.py", line 578, in __init__\n    self.do_handshake()\n  File "/usr/lib/python3.4/ssl.py", line 805, in do_handshake\n    self._sslobj.do_handshake()\nConnectionResetError: [Errno 104] Connection reset by peer\n')
('2015-02-07 11:29:21.125793', 'Traceback (most recent call last):\n  File "/river/fd/fd_worker/fd_channel.py", line 204, in create_channel\n    handle.connect()\n  File "/usr/lib/python3.4/http/client.py", line 1205, in connect\n    server_hostname=server_hostname)\n  File "/usr/lib/python3.4/ssl.py", line 364, in wrap_socket\n    _context=self)\n  File "/usr/lib/python3.4/ssl.py", line 578, in __init__\n    self.do_handshake()\n  File "/usr/lib/python3.4/ssl.py", line 805, in do_handshake\n    self._sslobj.do_handshake()\nConnectionResetError: [Errno 104] Connection reset by peer\n')
('2015-02-07 11:29:23.322576', 'Traceback (most recent call last):\n  File "/river/fd/fd_worker/fd_channel.py", line 204, in create_channel\n    handle.connect()\n  File "/usr/lib/python3.4/http/client.py", line 1205, in connect\n    server_hostname=server_hostname)\n  File "/usr/lib/python3.4/ssl.py", line 364, in wrap_socket\n    _context=self)\n  File "/usr/lib/python3.4/ssl.py", line 578, in __init__\n    self.do_handshake()\n  File "/usr/lib/python3.4/ssl.py", line 805, in do_handshake\n    self._sslobj.do_handshake()\nConnectionResetError: [Errno 104] Connection reset by peer\n')
('2015-02-07 11:29:24.214110', 'Traceback (most recent call last):\n  File "/river/fd/fd_worker/fd_channel.py", line 204, in create_channel\n    handle.connect()\n  File "/usr/lib/python3.4/http/client.py", line 1205, in connect\n    server_hostname=server_hostname)\n  File "/usr/lib/python3.4/ssl.py", line 364, in wrap_socket\n    _context=self)\n  File "/usr/lib/python3.4/ssl.py", line 578, in __init__\n    self.do_handshake()\n  File "/usr/lib/python3.4/ssl.py", line 805, in do_handshake\n    self._sslobj.do_handshake()\nConnectionResetError: [Errno 104] Connection reset by peer\n')
('2015-02-07 11:29:25.222521', 'Traceback (most recent call last):\n  File "/river/fd/fd_worker/fd_channel.py", line 204, in create_channel\n    handle.connect()\n  File "/usr/lib/python3.4/http/client.py", line 1205, in connect\n    server_hostname=server_hostname)\n  File "/usr/lib/python3.4/ssl.py", line 364, in wrap_socket\n    _context=self)\n  File "/usr/lib/python3.4/ssl.py", line 578, in __init__\n    self.do_handshake()\n  File "/usr/lib/python3.4/ssl.py", line 805, in do_handshake\n    self._sslobj.do_handshake()\nConnectionResetError: [Errno 104] Connection reset by peer\n')
('2015-02-07 11:29:25.615004', 'Traceback (most recent call last):\n  File "/river/fd/fd_worker/fd_channel.py", line 204, in create_channel\n    handle.connect()\n  File "/usr/lib/python3.4/http/client.py", line 1205, in connect\n    server_hostname=server_hostname)\n  File "/usr/lib/python3.4/ssl.py", line 364, in wrap_socket\n    _context=self)\n  File "/usr/lib/python3.4/ssl.py", line 578, in __init__\n    self.do_handshake()\n  File "/usr/lib/python3.4/ssl.py", line 805, in do_handshake\n    self._sslobj.do_handshake()\nConnectionResetError: [Errno 104] Connection reset by peer\n')
('2015-02-07 11:29:30.210369', 'Traceback (most recent call last):\n  File "/river/fd/fd_worker/fd_channel.py", line 204, in create_channel\n    handle.connect()\n  File "/usr/lib/python3.4/http/client.py", line 1205, in connect\n    server_hostname=server_hostname)\n  File "/usr/lib/python3.4/ssl.py", line 364, in wrap_socket\n    _context=self)\n  File "/usr/lib/python3.4/ssl.py", line 578, in __init__\n    self.do_handshake()\n  File "/usr/lib/python3.4/ssl.py", line 805, in do_handshake\n    self._sslobj.do_handshake()\nConnectionResetError: [Errno 104] Connection reset by peer\n')
('2015-02-07 11:29:31.222105', 'Traceback (most recent call last):\n  File "/river/fd/fd_worker/fd_channel.py", line 204, in create_channel\n    handle.connect()\n  File "/usr/lib/python3.4/http/client.py", line 1205, in connect\n    server_hostname=server_hostname)\n  File "/usr/lib/python3.4/ssl.py", line 364, in wrap_socket\n    _context=self)\n  File "/usr/lib/python3.4/ssl.py", line 578, in __init__\n    self.do_handshake()\n  File "/usr/lib/python3.4/ssl.py", line 805, in do_handshake\n    self._sslobj.do_handshake()\nConnectionResetError: [Errno 104] Connection reset by peer\n')
('2015-02-07 11:29:33.131035', 'Traceback (most recent call last):\n  File "/river/fd/fd_worker/fd_channel.py", line 204, in create_channel\n    handle.connect()\n  File "/usr/lib/python3.4/http/client.py", line 1205, in connect\n    server_hostname=server_hostname)\n  File "/usr/lib/python3.4/ssl.py", line 364, in wrap_socket\n    _context=self)\n  File "/usr/lib/python3.4/ssl.py", line 578, in __init__\n    self.do_handshake()\n  File "/usr/lib/python3.4/ssl.py", line 805, in do_handshake\n    self._sslobj.do_handshake()\nConnectionResetError: [Errno 104] Connection reset by peer\n')
('2015-02-07 11:29:33.414560', 'Traceback (most recent call last):\n  File "/river/fd/fd_worker/fd_channel.py", line 204, in create_channel\n    handle.connect()\n  File "/usr/lib/python3.4/http/client.py", line 1205, in connect\n    server_hostname=server_hostname)\n  File "/usr/lib/python3.4/ssl.py", line 364, in wrap_socket\n    _context=self)\n  File "/usr/lib/python3.4/ssl.py", line 578, in __init__\n    self.do_handshake()\n  File "/usr/lib/python3.4/ssl.py", line 805, in do_handshake\n    self._sslobj.do_handshake()\nConnectionResetError: [Errno 104] Connection reset by peer\n')
('2015-02-07 11:29:37.222323', 'Traceback (most recent call last):\n  File "/river/fd/fd_worker/fd_channel.py", line 204, in create_channel\n    handle.connect()\n  File "/usr/lib/python3.4/http/client.py", line 1205, in connect\n    server_hostname=server_hostname)\n  File "/usr/lib/python3.4/ssl.py", line 364, in wrap_socket\n    _context=self)\n  File "/usr/lib/python3.4/ssl.py", line 578, in __init__\n    self.do_handshake()\n  File "/usr/lib/python3.4/ssl.py", line 805, in do_handshake\n    self._sslobj.do_handshake()\nConnectionResetError: [Errno 104] Connection reset by peer\n')
('2015-02-07 11:29:38.493312', 'Traceback (most recent call last):\n  File "/river/fd/fd_worker/fd_channel.py", line 204, in create_channel\n    handle.connect()\n  File "/usr/lib/python3.4/http/client.py", line 1205, in connect\n    server_hostname=server_hostname)\n  File "/usr/lib/python3.4/ssl.py", line 364, in wrap_socket\n    _context=self)\n  File "/usr/lib/python3.4/ssl.py", line 578, in __init__\n    self.do_handshake()\n  File "/usr/lib/python3.4/ssl.py", line 805, in do_handshake\n    self._sslobj.do_handshake()\nConnectionResetError: [Errno 104] Connection reset by peer\n')
('2015-02-07 11:29:39.401478', 'Traceback (most recent call last):\n  File "/river/fd/fd_worker/fd_channel.py", line 204, in create_channel\n    handle.connect()\n  File "/usr/lib/python3.4/http/client.py", line 1205, in connect\n    server_hostname=server_hostname)\n  File "/usr/lib/python3.4/ssl.py", line 364, in wrap_socket\n    _context=self)\n  File "/usr/lib/python3.4/ssl.py", line 578, in __init__\n    self.do_handshake()\n  File "/usr/lib/python3.4/ssl.py", line 805, in do_handshake\n    self._sslobj.do_handshake()\nConnectionResetError: [Errno 104] Connection reset by peer\n')
('2015-02-07 11:29:42.294217', 'Traceback (most recent call last):\n  File "/river/fd/fd_worker/fd_channel.py", line 204, in create_channel\n    handle.connect()\n  File "/usr/lib/python3.4/http/client.py", line 1205, in connect\n    server_hostname=server_hostname)\n  File "/usr/lib/python3.4/ssl.py", line 364, in wrap_socket\n    _context=self)\n  File "/usr/lib/python3.4/ssl.py", line 578, in __init__\n    self.do_handshake()\n  File "/usr/lib/python3.4/ssl.py", line 805, in do_handshake\n    self._sslobj.do_handshake()\nConnectionResetError: [Errno 104] Connection reset by peer\n')
('2015-02-07 11:29:43.221937', 'Traceback (most recent call last):\n  File "/river/fd/fd_worker/fd_channel.py", line 204, in create_channel\n    handle.connect()\n  File "/usr/lib/python3.4/http/client.py", line 1205, in connect\n    server_hostname=server_hostname)\n  File "/usr/lib/python3.4/ssl.py", line 364, in wrap_socket\n    _context=self)\n  File "/usr/lib/python3.4/ssl.py", line 578, in __init__\n    self.do_handshake()\n  File "/usr/lib/python3.4/ssl.py", line 805, in do_handshake\n    self._sslobj.do_handshake()\nConnectionResetError: [Errno 104] Connection reset by peer\n')
('2015-02-07 11:29:45.134369', 'Traceback (most recent call last):\n  File "/river/fd/fd_worker/fd_channel.py", line 204, in create_channel\n    handle.connect()\n  File "/usr/lib/python3.4/http/client.py", line 1205, in connect\n    server_hostname=server_hostname)\n  File "/usr/lib/python3.4/ssl.py", line 364, in wrap_socket\n    _context=self)\n  File "/usr/lib/python3.4/ssl.py", line 578, in __init__\n    self.do_handshake()\n  File "/usr/lib/python3.4/ssl.py", line 805, in do_handshake\n    self._sslobj.do_handshake()\nConnectionResetError: [Errno 104] Connection reset by peer\n')
('2015-02-07 11:29:45.274484', 'Traceback (most recent call last):\n  File "/river/fd/fd_worker/fd_channel.py", line 204, in create_channel\n    handle.connect()\n  File "/usr/lib/python3.4/http/client.py", line 1205, in connect\n    server_hostname=server_hostname)\n  File "/usr/lib/python3.4/ssl.py", line 364, in wrap_socket\n    _context=self)\n  File "/usr/lib/python3.4/ssl.py", line 578, in __init__\n    self.do_handshake()\n  File "/usr/lib/python3.4/ssl.py", line 805, in do_handshake\n    self._sslobj.do_handshake()\nConnectionResetError: [Errno 104] Connection reset by peer\n')
('2015-02-07 11:29:57.333869', 'Traceback (most recent call last):\n  File "/river/fd/fd_worker/fd_channel.py", line 204, in create_channel\n    handle.connect()\n  File "/usr/lib/python3.4/http/client.py", line 1205, in connect\n    server_hostname=server_hostname)\n  File "/usr/lib/python3.4/ssl.py", line 364, in wrap_socket\n    _context=self)\n  File "/usr/lib/python3.4/ssl.py", line 578, in __init__\n    self.do_handshake()\n  File "/usr/lib/python3.4/ssl.py", line 805, in do_handshake\n    self._sslobj.do_handshake()\nConnectionResetError: [Errno 104] Connection reset by peer\n')
('2015-02-07 11:30:00.189066', 'Traceback (most recent call last):\n  File "/river/fd/fd_worker/fd_channel.py", line 204, in create_channel\n    handle.connect()\n  File "/usr/lib/python3.4/http/client.py", line 1205, in connect\n    server_hostname=server_hostname)\n  File "/usr/lib/python3.4/ssl.py", line 364, in wrap_socket\n    _context=self)\n  File "/usr/lib/python3.4/ssl.py", line 578, in __init__\n    self.do_handshake()\n  File "/usr/lib/python3.4/ssl.py", line 805, in do_handshake\n    self._sslobj.do_handshake()\nConnectionResetError: [Errno 104] Connection reset by peer\n')
('2015-02-07 11:30:03.645621', 'Traceback (most recent call last):\n  File "/river/fd/fd_worker/fd_channel.py", line 204, in create_channel\n    handle.connect()\n  File "/usr/lib/python3.4/http/client.py", line 1205, in connect\n    server_hostname=server_hostname)\n  File "/usr/lib/python3.4/ssl.py", line 364, in wrap_socket\n    _context=self)\n  File "/usr/lib/python3.4/ssl.py", line 578, in __init__\n    self.do_handshake()\n  File "/usr/lib/python3.4/ssl.py", line 805, in do_handshake\n    self._sslobj.do_handshake()\nConnectionResetError: [Errno 104] Connection reset by peer\n')
('2015-02-07 11:30:04.232380', 'Traceback (most recent call last):\n  File "/river/fd/fd_worker/fd_channel.py", line 204, in create_channel\n    handle.connect()\n  File "/usr/lib/python3.4/http/client.py", line 1197, in connect\n    self.timeout, self.source_address)\n  File "/usr/lib/python3.4/socket.py", line 509, in create_connection\n    raise err\n  File "/usr/lib/python3.4/socket.py", line 500, in create_connection\n    sock.connect(sa)\nTimeoutError: [Errno 110] Connection timed out\n')
('2015-02-07 11:30:05.768653', 'Traceback (most recent call last):\n  File "/river/fd/fd_worker/fd_channel.py", line 204, in create_channel\n    handle.connect()\n  File "/usr/lib/python3.4/http/client.py", line 1197, in connect\n    self.timeout, self.source_address)\n  File "/usr/lib/python3.4/socket.py", line 509, in create_connection\n    raise err\n  File "/usr/lib/python3.4/socket.py", line 500, in create_connection\n    sock.connect(sa)\nTimeoutError: [Errno 110] Connection timed out\n')
('2015-02-07 11:30:13.320533', 'Traceback (most recent call last):\n  File "/river/fd/fd_worker/fd_channel.py", line 204, in create_channel\n    handle.connect()\n  File "/usr/lib/python3.4/http/client.py", line 1197, in connect\n    self.timeout, self.source_address)\n  File "/usr/lib/python3.4/socket.py", line 509, in create_connection\n    raise err\n  File "/usr/lib/python3.4/socket.py", line 500, in create_connection\n    sock.connect(sa)\nTimeoutError: [Errno 110] Connection timed out\n')
('2015-02-07 11:30:19.595799', 'Traceback (most recent call last):\n  File "/river/fd/fd_worker/fd_channel.py", line 204, in create_channel\n    handle.connect()\n  File "/usr/lib/python3.4/http/client.py", line 1205, in connect\n    server_hostname=server_hostname)\n  File "/usr/lib/python3.4/ssl.py", line 364, in wrap_socket\n    _context=self)\n  File "/usr/lib/python3.4/ssl.py", line 578, in __init__\n    self.do_handshake()\n  File "/usr/lib/python3.4/ssl.py", line 805, in do_handshake\n    self._sslobj.do_handshake()\nConnectionResetError: [Errno 104] Connection reset by peer\n')
('2015-02-07 11:30:29.704594', 'Traceback (most recent call last):\n  File "/river/fd/fd_worker/fd_channel.py", line 204, in create_channel\n    handle.connect()\n  File "/usr/lib/python3.4/http/client.py", line 1197, in connect\n    self.timeout, self.source_address)\n  File "/usr/lib/python3.4/socket.py", line 509, in create_connection\n    raise err\n  File "/usr/lib/python3.4/socket.py", line 500, in create_connection\n    sock.connect(sa)\nTimeoutError: [Errno 110] Connection timed out\n')
('2015-02-07 11:30:29.897607', 'Traceback (most recent call last):\n  File "/river/fd/fd_worker/fd_channel.py", line 204, in create_channel\n    handle.connect()\n  File "/usr/lib/python3.4/http/client.py", line 1205, in connect\n    server_hostname=server_hostname)\n  File "/usr/lib/python3.4/ssl.py", line 364, in wrap_socket\n    _context=self)\n  File "/usr/lib/python3.4/ssl.py", line 578, in __init__\n    self.do_handshake()\n  File "/usr/lib/python3.4/ssl.py", line 805, in do_handshake\n    self._sslobj.do_handshake()\nConnectionResetError: [Errno 104] Connection reset by peer\n')
('2015-02-07 11:30:31.240360', 'Traceback (most recent call last):\n  File "/river/fd/fd_worker/fd_channel.py", line 204, in create_channel\n    handle.connect()\n  File "/usr/lib/python3.4/http/client.py", line 1197, in connect\n    self.timeout, self.source_address)\n  File "/usr/lib/python3.4/socket.py", line 509, in create_connection\n    raise err\n  File "/usr/lib/python3.4/socket.py", line 500, in create_connection\n    sock.connect(sa)\nTimeoutError: [Errno 110] Connection timed out\n')
('2015-02-07 11:30:32.776653', 'Traceback (most recent call last):\n  File "/river/fd/fd_worker/fd_channel.py", line 204, in create_channel\n    handle.connect()\n  File "/usr/lib/python3.4/http/client.py", line 1197, in connect\n    self.timeout, self.source_address)\n  File "/usr/lib/python3.4/socket.py", line 509, in create_connection\n    raise err\n  File "/usr/lib/python3.4/socket.py", line 500, in create_connection\n    sock.connect(sa)\nTimeoutError: [Errno 110] Connection timed out\n')
('2015-02-07 11:30:38.792827', 'Traceback (most recent call last):\n  File "/river/fd/fd_worker/fd_channel.py", line 204, in create_channel\n    handle.connect()\n  File "/usr/lib/python3.4/http/client.py", line 1197, in connect\n    self.timeout, self.source_address)\n  File "/usr/lib/python3.4/socket.py", line 509, in create_connection\n    raise err\n  File "/usr/lib/python3.4/socket.py", line 500, in create_connection\n    sock.connect(sa)\nTimeoutError: [Errno 110] Connection timed out\n')
('2015-02-07 11:30:40.200429', 'Traceback (most recent call last):\n  File "/river/fd/fd_worker/fd_channel.py", line 204, in create_channel\n    handle.connect()\n  File "/usr/lib/python3.4/http/client.py", line 1197, in connect\n    self.timeout, self.source_address)\n  File "/usr/lib/python3.4/socket.py", line 509, in create_connection\n    raise err\n  File "/usr/lib/python3.4/socket.py", line 500, in create_connection\n    sock.connect(sa)\nTimeoutError: [Errno 110] Connection timed out\n')
('2015-02-07 11:30:52.232636', 'Traceback (most recent call last):\n  File "/river/fd/fd_worker/fd_channel.py", line 204, in create_channel\n    handle.connect()\n  File "/usr/lib/python3.4/http/client.py", line 1197, in connect\n    self.timeout, self.source_address)\n  File "/usr/lib/python3.4/socket.py", line 509, in create_connection\n    raise err\n  File "/usr/lib/python3.4/socket.py", line 500, in create_connection\n    sock.connect(sa)\nTimeoutError: [Errno 110] Connection timed out\n')
('2015-02-07 11:30:56.712351', 'Traceback (most recent call last):\n  File "/river/fd/fd_worker/fd_channel.py", line 204, in create_channel\n    handle.connect()\n  File "/usr/lib/python3.4/http/client.py", line 1197, in connect\n    self.timeout, self.source_address)\n  File "/usr/lib/python3.4/socket.py", line 509, in create_connection\n    raise err\n  File "/usr/lib/python3.4/socket.py", line 500, in create_connection\n    sock.connect(sa)\nTimeoutError: [Errno 110] Connection timed out\n')
('2015-02-07 11:30:58.248369', 'Traceback (most recent call last):\n  File "/river/fd/fd_worker/fd_channel.py", line 204, in create_channel\n    handle.connect()\n  File "/usr/lib/python3.4/http/client.py", line 1197, in connect\n    self.timeout, self.source_address)\n  File "/usr/lib/python3.4/socket.py", line 509, in create_connection\n    raise err\n  File "/usr/lib/python3.4/socket.py", line 500, in create_connection\n    sock.connect(sa)\nTimeoutError: [Errno 110] Connection timed out\n')
('2015-02-07 11:30:58.248849', 'Traceback (most recent call last):\n  File "/river/fd/fd_worker/fd_channel.py", line 204, in create_channel\n    handle.connect()\n  File "/usr/lib/python3.4/http/client.py", line 1197, in connect\n    self.timeout, self.source_address)\n  File "/usr/lib/python3.4/socket.py", line 509, in create_connection\n    raise err\n  File "/usr/lib/python3.4/socket.py", line 500, in create_connection\n    sock.connect(sa)\nTimeoutError: [Errno 110] Connection timed out\n')
