('2015-03-21 10:33:29.888773', 'Traceback (most recent call last):\n  File "/river/fd/fd_worker/fd_channel.py", line 204, in create_channel\n    handle.connect()\n  File "/usr/lib/python3.4/http/client.py", line 1205, in connect\n    server_hostname=server_hostname)\n  File "/usr/lib/python3.4/ssl.py", line 364, in wrap_socket\n    _context=self)\n  File "/usr/lib/python3.4/ssl.py", line 578, in __init__\n    self.do_handshake()\n  File "/usr/lib/python3.4/ssl.py", line 805, in do_handshake\n    self._sslobj.do_handshake()\nConnectionResetError: [Errno 104] Connection reset by peer\n')
('2015-03-21 10:33:45.180252', 'Traceback (most recent call last):\n  File "/river/fd/fd_worker/fd_channel.py", line 204, in create_channel\n    handle.connect()\n  File "/usr/lib/python3.4/http/client.py", line 1205, in connect\n    server_hostname=server_hostname)\n  File "/usr/lib/python3.4/ssl.py", line 364, in wrap_socket\n    _context=self)\n  File "/usr/lib/python3.4/ssl.py", line 578, in __init__\n    self.do_handshake()\n  File "/usr/lib/python3.4/ssl.py", line 805, in do_handshake\n    self._sslobj.do_handshake()\nConnectionResetError: [Errno 104] Connection reset by peer\n')
('2015-03-21 10:33:45.348096', 'Traceback (most recent call last):\n  File "/river/fd/fd_worker/fd_channel.py", line 204, in create_channel\n    handle.connect()\n  File "/usr/lib/python3.4/http/client.py", line 1205, in connect\n    server_hostname=server_hostname)\n  File "/usr/lib/python3.4/ssl.py", line 364, in wrap_socket\n    _context=self)\n  File "/usr/lib/python3.4/ssl.py", line 578, in __init__\n    self.do_handshake()\n  File "/usr/lib/python3.4/ssl.py", line 805, in do_handshake\n    self._sslobj.do_handshake()\nConnectionResetError: [Errno 104] Connection reset by peer\n')
('2015-03-21 10:33:45.684435', 'Traceback (most recent call last):\n  File "/river/fd/fd_worker/fd_channel.py", line 204, in create_channel\n    handle.connect()\n  File "/usr/lib/python3.4/http/client.py", line 1205, in connect\n    server_hostname=server_hostname)\n  File "/usr/lib/python3.4/ssl.py", line 364, in wrap_socket\n    _context=self)\n  File "/usr/lib/python3.4/ssl.py", line 578, in __init__\n    self.do_handshake()\n  File "/usr/lib/python3.4/ssl.py", line 805, in do_handshake\n    self._sslobj.do_handshake()\nConnectionResetError: [Errno 104] Connection reset by peer\n')
('2015-03-21 10:33:46.044595', 'Traceback (most recent call last):\n  File "/river/fd/fd_worker/fd_channel.py", line 204, in create_channel\n    handle.connect()\n  File "/usr/lib/python3.4/http/client.py", line 1205, in connect\n    server_hostname=server_hostname)\n  File "/usr/lib/python3.4/ssl.py", line 364, in wrap_socket\n    _context=self)\n  File "/usr/lib/python3.4/ssl.py", line 578, in __init__\n    self.do_handshake()\n  File "/usr/lib/python3.4/ssl.py", line 805, in do_handshake\n    self._sslobj.do_handshake()\nConnectionResetError: [Errno 104] Connection reset by peer\n')
('2015-03-21 10:33:46.364734', 'Traceback (most recent call last):\n  File "/river/fd/fd_worker/fd_channel.py", line 204, in create_channel\n    handle.connect()\n  File "/usr/lib/python3.4/http/client.py", line 1205, in connect\n    server_hostname=server_hostname)\n  File "/usr/lib/python3.4/ssl.py", line 364, in wrap_socket\n    _context=self)\n  File "/usr/lib/python3.4/ssl.py", line 578, in __init__\n    self.do_handshake()\n  File "/usr/lib/python3.4/ssl.py", line 805, in do_handshake\n    self._sslobj.do_handshake()\nConnectionResetError: [Errno 104] Connection reset by peer\n')
('2015-03-21 10:33:47.180736', 'Traceback (most recent call last):\n  File "/river/fd/fd_worker/fd_channel.py", line 204, in create_channel\n    handle.connect()\n  File "/usr/lib/python3.4/http/client.py", line 1205, in connect\n    server_hostname=server_hostname)\n  File "/usr/lib/python3.4/ssl.py", line 364, in wrap_socket\n    _context=self)\n  File "/usr/lib/python3.4/ssl.py", line 578, in __init__\n    self.do_handshake()\n  File "/usr/lib/python3.4/ssl.py", line 805, in do_handshake\n    self._sslobj.do_handshake()\nConnectionResetError: [Errno 104] Connection reset by peer\n')
('2015-03-21 10:33:47.852036', 'Traceback (most recent call last):\n  File "/river/fd/fd_worker/fd_channel.py", line 204, in create_channel\n    handle.connect()\n  File "/usr/lib/python3.4/http/client.py", line 1205, in connect\n    server_hostname=server_hostname)\n  File "/usr/lib/python3.4/ssl.py", line 364, in wrap_socket\n    _context=self)\n  File "/usr/lib/python3.4/ssl.py", line 578, in __init__\n    self.do_handshake()\n  File "/usr/lib/python3.4/ssl.py", line 805, in do_handshake\n    self._sslobj.do_handshake()\nConnectionResetError: [Errno 104] Connection reset by peer\n')
('2015-03-21 10:33:49.356547', 'Traceback (most recent call last):\n  File "/river/fd/fd_worker/fd_channel.py", line 204, in create_channel\n    handle.connect()\n  File "/usr/lib/python3.4/http/client.py", line 1205, in connect\n    server_hostname=server_hostname)\n  File "/usr/lib/python3.4/ssl.py", line 364, in wrap_socket\n    _context=self)\n  File "/usr/lib/python3.4/ssl.py", line 578, in __init__\n    self.do_handshake()\n  File "/usr/lib/python3.4/ssl.py", line 805, in do_handshake\n    self._sslobj.do_handshake()\nConnectionResetError: [Errno 104] Connection reset by peer\n')
('2015-03-21 10:33:50.862795', 'Traceback (most recent call last):\n  File "/river/fd/fd_worker/fd_channel.py", line 204, in create_channel\n    handle.connect()\n  File "/usr/lib/python3.4/http/client.py", line 1205, in connect\n    server_hostname=server_hostname)\n  File "/usr/lib/python3.4/ssl.py", line 364, in wrap_socket\n    _context=self)\n  File "/usr/lib/python3.4/ssl.py", line 578, in __init__\n    self.do_handshake()\n  File "/usr/lib/python3.4/ssl.py", line 805, in do_handshake\n    self._sslobj.do_handshake()\nConnectionResetError: [Errno 104] Connection reset by peer\n')
('2015-03-21 10:33:55.548420', 'Traceback (most recent call last):\n  File "/river/fd/fd_worker/fd_channel.py", line 204, in create_channel\n    handle.connect()\n  File "/usr/lib/python3.4/http/client.py", line 1205, in connect\n    server_hostname=server_hostname)\n  File "/usr/lib/python3.4/ssl.py", line 364, in wrap_socket\n    _context=self)\n  File "/usr/lib/python3.4/ssl.py", line 578, in __init__\n    self.do_handshake()\n  File "/usr/lib/python3.4/ssl.py", line 805, in do_handshake\n    self._sslobj.do_handshake()\nConnectionResetError: [Errno 104] Connection reset by peer\n')
('2015-03-21 10:34:11.388023', 'Traceback (most recent call last):\n  File "/river/fd/fd_worker/fd_channel.py", line 204, in create_channel\n    handle.connect()\n  File "/usr/lib/python3.4/http/client.py", line 1205, in connect\n    server_hostname=server_hostname)\n  File "/usr/lib/python3.4/ssl.py", line 364, in wrap_socket\n    _context=self)\n  File "/usr/lib/python3.4/ssl.py", line 578, in __init__\n    self.do_handshake()\n  File "/usr/lib/python3.4/ssl.py", line 805, in do_handshake\n    self._sslobj.do_handshake()\nConnectionResetError: [Errno 104] Connection reset by peer\n')
('2015-03-21 10:34:58.548581', 'Traceback (most recent call last):\n  File "/river/fd/fd_worker/fd_channel.py", line 204, in create_channel\n    handle.connect()\n  File "/usr/lib/python3.4/http/client.py", line 1205, in connect\n    server_hostname=server_hostname)\n  File "/usr/lib/python3.4/ssl.py", line 364, in wrap_socket\n    _context=self)\n  File "/usr/lib/python3.4/ssl.py", line 578, in __init__\n    self.do_handshake()\n  File "/usr/lib/python3.4/ssl.py", line 805, in do_handshake\n    self._sslobj.do_handshake()\nConnectionResetError: [Errno 104] Connection reset by peer\n')
('2015-03-21 10:34:58.849007', 'Traceback (most recent call last):\n  File "/river/fd/fd_worker/fd_channel.py", line 204, in create_channel\n    handle.connect()\n  File "/usr/lib/python3.4/http/client.py", line 1205, in connect\n    server_hostname=server_hostname)\n  File "/usr/lib/python3.4/ssl.py", line 364, in wrap_socket\n    _context=self)\n  File "/usr/lib/python3.4/ssl.py", line 578, in __init__\n    self.do_handshake()\n  File "/usr/lib/python3.4/ssl.py", line 805, in do_handshake\n    self._sslobj.do_handshake()\nConnectionResetError: [Errno 104] Connection reset by peer\n')
('2015-03-21 10:34:59.582519', 'Traceback (most recent call last):\n  File "/river/fd/fd_worker/fd_channel.py", line 204, in create_channel\n    handle.connect()\n  File "/usr/lib/python3.4/http/client.py", line 1205, in connect\n    server_hostname=server_hostname)\n  File "/usr/lib/python3.4/ssl.py", line 364, in wrap_socket\n    _context=self)\n  File "/usr/lib/python3.4/ssl.py", line 578, in __init__\n    self.do_handshake()\n  File "/usr/lib/python3.4/ssl.py", line 805, in do_handshake\n    self._sslobj.do_handshake()\nConnectionResetError: [Errno 104] Connection reset by peer\n')
('2015-03-21 10:35:01.181001', 'Traceback (most recent call last):\n  File "/river/fd/fd_worker/fd_channel.py", line 204, in create_channel\n    handle.connect()\n  File "/usr/lib/python3.4/http/client.py", line 1205, in connect\n    server_hostname=server_hostname)\n  File "/usr/lib/python3.4/ssl.py", line 364, in wrap_socket\n    _context=self)\n  File "/usr/lib/python3.4/ssl.py", line 578, in __init__\n    self.do_handshake()\n  File "/usr/lib/python3.4/ssl.py", line 805, in do_handshake\n    self._sslobj.do_handshake()\nConnectionResetError: [Errno 104] Connection reset by peer\n')
('2015-03-21 10:35:01.356657', 'Traceback (most recent call last):\n  File "/river/fd/fd_worker/fd_channel.py", line 204, in create_channel\n    handle.connect()\n  File "/usr/lib/python3.4/http/client.py", line 1205, in connect\n    server_hostname=server_hostname)\n  File "/usr/lib/python3.4/ssl.py", line 364, in wrap_socket\n    _context=self)\n  File "/usr/lib/python3.4/ssl.py", line 578, in __init__\n    self.do_handshake()\n  File "/usr/lib/python3.4/ssl.py", line 805, in do_handshake\n    self._sslobj.do_handshake()\nConnectionResetError: [Errno 104] Connection reset by peer\n')
('2015-03-21 10:35:03.043392', 'Traceback (most recent call last):\n  File "/river/fd/fd_worker/fd_channel.py", line 144, in pyget\n    ack  = handle.getresponse()\n  File "/usr/lib/python3.4/http/client.py", line 1147, in getresponse\n    response.begin()\n  File "/usr/lib/python3.4/http/client.py", line 351, in begin\n    version, status, reason = self._read_status()\n  File "/usr/lib/python3.4/http/client.py", line 313, in _read_status\n    line = str(self.fp.readline(_MAXLINE + 1), "iso-8859-1")\n  File "/usr/lib/python3.4/socket.py", line 371, in readinto\n    return self._sock.recv_into(b)\n  File "/usr/lib/python3.4/ssl.py", line 746, in recv_into\n    return self.read(nbytes, buffer)\n  File "/usr/lib/python3.4/ssl.py", line 618, in read\n    v = self._sslobj.read(len, buffer)\nConnectionResetError: [Errno 104] Connection reset by peer\n')
('2015-03-21 10:35:03.548682', 'Traceback (most recent call last):\n  File "/river/fd/fd_worker/fd_channel.py", line 144, in pyget\n    ack  = handle.getresponse()\n  File "/usr/lib/python3.4/http/client.py", line 1147, in getresponse\n    response.begin()\n  File "/usr/lib/python3.4/http/client.py", line 351, in begin\n    version, status, reason = self._read_status()\n  File "/usr/lib/python3.4/http/client.py", line 313, in _read_status\n    line = str(self.fp.readline(_MAXLINE + 1), "iso-8859-1")\n  File "/usr/lib/python3.4/socket.py", line 371, in readinto\n    return self._sock.recv_into(b)\n  File "/usr/lib/python3.4/ssl.py", line 746, in recv_into\n    return self.read(nbytes, buffer)\n  File "/usr/lib/python3.4/ssl.py", line 618, in read\n    v = self._sslobj.read(len, buffer)\nConnectionResetError: [Errno 104] Connection reset by peer\n')
('2015-03-21 10:35:04.061845', 'Traceback (most recent call last):\n  File "/river/fd/fd_worker/fd_channel.py", line 204, in create_channel\n    handle.connect()\n  File "/usr/lib/python3.4/http/client.py", line 1205, in connect\n    server_hostname=server_hostname)\n  File "/usr/lib/python3.4/ssl.py", line 364, in wrap_socket\n    _context=self)\n  File "/usr/lib/python3.4/ssl.py", line 578, in __init__\n    self.do_handshake()\n  File "/usr/lib/python3.4/ssl.py", line 805, in do_handshake\n    self._sslobj.do_handshake()\nConnectionResetError: [Errno 104] Connection reset by peer\n')
('2015-03-21 10:35:04.190142', 'Traceback (most recent call last):\n  File "/river/fd/fd_worker/fd_channel.py", line 204, in create_channel\n    handle.connect()\n  File "/usr/lib/python3.4/http/client.py", line 1205, in connect\n    server_hostname=server_hostname)\n  File "/usr/lib/python3.4/ssl.py", line 364, in wrap_socket\n    _context=self)\n  File "/usr/lib/python3.4/ssl.py", line 578, in __init__\n    self.do_handshake()\n  File "/usr/lib/python3.4/ssl.py", line 805, in do_handshake\n    self._sslobj.do_handshake()\nConnectionResetError: [Errno 104] Connection reset by peer\n')
('2015-03-21 10:35:05.532440', 'Traceback (most recent call last):\n  File "/river/fd/fd_worker/fd_channel.py", line 144, in pyget\n    ack  = handle.getresponse()\n  File "/usr/lib/python3.4/http/client.py", line 1147, in getresponse\n    response.begin()\n  File "/usr/lib/python3.4/http/client.py", line 351, in begin\n    version, status, reason = self._read_status()\n  File "/usr/lib/python3.4/http/client.py", line 313, in _read_status\n    line = str(self.fp.readline(_MAXLINE + 1), "iso-8859-1")\n  File "/usr/lib/python3.4/socket.py", line 371, in readinto\n    return self._sock.recv_into(b)\n  File "/usr/lib/python3.4/ssl.py", line 746, in recv_into\n    return self.read(nbytes, buffer)\n  File "/usr/lib/python3.4/ssl.py", line 618, in read\n    v = self._sslobj.read(len, buffer)\nConnectionResetError: [Errno 104] Connection reset by peer\n')
('2015-03-21 10:35:08.700150', 'Traceback (most recent call last):\n  File "/river/fd/fd_worker/fd_channel.py", line 204, in create_channel\n    handle.connect()\n  File "/usr/lib/python3.4/http/client.py", line 1205, in connect\n    server_hostname=server_hostname)\n  File "/usr/lib/python3.4/ssl.py", line 364, in wrap_socket\n    _context=self)\n  File "/usr/lib/python3.4/ssl.py", line 578, in __init__\n    self.do_handshake()\n  File "/usr/lib/python3.4/ssl.py", line 805, in do_handshake\n    self._sslobj.do_handshake()\nConnectionResetError: [Errno 104] Connection reset by peer\n')
('2015-03-21 10:35:09.083903', 'Traceback (most recent call last):\n  File "/river/fd/fd_worker/fd_channel.py", line 204, in create_channel\n    handle.connect()\n  File "/usr/lib/python3.4/http/client.py", line 1205, in connect\n    server_hostname=server_hostname)\n  File "/usr/lib/python3.4/ssl.py", line 364, in wrap_socket\n    _context=self)\n  File "/usr/lib/python3.4/ssl.py", line 578, in __init__\n    self.do_handshake()\n  File "/usr/lib/python3.4/ssl.py", line 805, in do_handshake\n    self._sslobj.do_handshake()\nConnectionResetError: [Errno 104] Connection reset by peer\n')
('2015-03-21 10:35:20.636211', 'Traceback (most recent call last):\n  File "/river/fd/fd_worker/fd_channel.py", line 204, in create_channel\n    handle.connect()\n  File "/usr/lib/python3.4/http/client.py", line 1205, in connect\n    server_hostname=server_hostname)\n  File "/usr/lib/python3.4/ssl.py", line 364, in wrap_socket\n    _context=self)\n  File "/usr/lib/python3.4/ssl.py", line 578, in __init__\n    self.do_handshake()\n  File "/usr/lib/python3.4/ssl.py", line 805, in do_handshake\n    self._sslobj.do_handshake()\nConnectionResetError: [Errno 104] Connection reset by peer\n')
('2015-03-21 10:35:25.172684', 'Traceback (most recent call last):\n  File "/river/fd/fd_worker/fd_channel.py", line 204, in create_channel\n    handle.connect()\n  File "/usr/lib/python3.4/http/client.py", line 1197, in connect\n    self.timeout, self.source_address)\n  File "/usr/lib/python3.4/socket.py", line 509, in create_connection\n    raise err\n  File "/usr/lib/python3.4/socket.py", line 500, in create_connection\n    sock.connect(sa)\nTimeoutError: [Errno 110] Connection timed out\n')
('2015-03-21 10:35:25.556250', 'Traceback (most recent call last):\n  File "/river/fd/fd_worker/fd_channel.py", line 144, in pyget\n    ack  = handle.getresponse()\n  File "/usr/lib/python3.4/http/client.py", line 1147, in getresponse\n    response.begin()\n  File "/usr/lib/python3.4/http/client.py", line 351, in begin\n    version, status, reason = self._read_status()\n  File "/usr/lib/python3.4/http/client.py", line 313, in _read_status\n    line = str(self.fp.readline(_MAXLINE + 1), "iso-8859-1")\n  File "/usr/lib/python3.4/socket.py", line 371, in readinto\n    return self._sock.recv_into(b)\n  File "/usr/lib/python3.4/ssl.py", line 746, in recv_into\n    return self.read(nbytes, buffer)\n  File "/usr/lib/python3.4/ssl.py", line 618, in read\n    v = self._sslobj.read(len, buffer)\nConnectionResetError: [Errno 104] Connection reset by peer\n')
('2015-03-21 10:35:26.708743', 'Traceback (most recent call last):\n  File "/river/fd/fd_worker/fd_channel.py", line 204, in create_channel\n    handle.connect()\n  File "/usr/lib/python3.4/http/client.py", line 1197, in connect\n    self.timeout, self.source_address)\n  File "/usr/lib/python3.4/socket.py", line 509, in create_connection\n    raise err\n  File "/usr/lib/python3.4/socket.py", line 500, in create_connection\n    sock.connect(sa)\nTimeoutError: [Errno 110] Connection timed out\n')
('2015-03-21 10:35:27.256144', 'Traceback (most recent call last):\n  File "/river/fd/fd_worker/fd_channel.py", line 144, in pyget\n    ack  = handle.getresponse()\n  File "/usr/lib/python3.4/http/client.py", line 1147, in getresponse\n    response.begin()\n  File "/usr/lib/python3.4/http/client.py", line 351, in begin\n    version, status, reason = self._read_status()\n  File "/usr/lib/python3.4/http/client.py", line 313, in _read_status\n    line = str(self.fp.readline(_MAXLINE + 1), "iso-8859-1")\n  File "/usr/lib/python3.4/socket.py", line 371, in readinto\n    return self._sock.recv_into(b)\n  File "/usr/lib/python3.4/ssl.py", line 746, in recv_into\n    return self.read(nbytes, buffer)\n  File "/usr/lib/python3.4/ssl.py", line 618, in read\n    v = self._sslobj.read(len, buffer)\nConnectionResetError: [Errno 104] Connection reset by peer\n')
('2015-03-21 10:35:54.364052', 'Traceback (most recent call last):\n  File "/river/fd/fd_worker/fd_channel.py", line 144, in pyget\n    ack  = handle.getresponse()\n  File "/usr/lib/python3.4/http/client.py", line 1147, in getresponse\n    response.begin()\n  File "/usr/lib/python3.4/http/client.py", line 351, in begin\n    version, status, reason = self._read_status()\n  File "/usr/lib/python3.4/http/client.py", line 313, in _read_status\n    line = str(self.fp.readline(_MAXLINE + 1), "iso-8859-1")\n  File "/usr/lib/python3.4/socket.py", line 371, in readinto\n    return self._sock.recv_into(b)\n  File "/usr/lib/python3.4/ssl.py", line 746, in recv_into\n    return self.read(nbytes, buffer)\n  File "/usr/lib/python3.4/ssl.py", line 618, in read\n    v = self._sslobj.read(len, buffer)\nConnectionResetError: [Errno 104] Connection reset by peer\n')
('2015-03-21 10:35:56.541569', 'Traceback (most recent call last):\n  File "/river/fd/fd_worker/fd_channel.py", line 144, in pyget\n    ack  = handle.getresponse()\n  File "/usr/lib/python3.4/http/client.py", line 1147, in getresponse\n    response.begin()\n  File "/usr/lib/python3.4/http/client.py", line 351, in begin\n    version, status, reason = self._read_status()\n  File "/usr/lib/python3.4/http/client.py", line 313, in _read_status\n    line = str(self.fp.readline(_MAXLINE + 1), "iso-8859-1")\n  File "/usr/lib/python3.4/socket.py", line 371, in readinto\n    return self._sock.recv_into(b)\n  File "/usr/lib/python3.4/ssl.py", line 746, in recv_into\n    return self.read(nbytes, buffer)\n  File "/usr/lib/python3.4/ssl.py", line 618, in read\n    v = self._sslobj.read(len, buffer)\nConnectionResetError: [Errno 104] Connection reset by peer\n')
('2015-03-21 10:36:11.764660', 'Traceback (most recent call last):\n  File "/river/fd/fd_worker/fd_channel.py", line 204, in create_channel\n    handle.connect()\n  File "/usr/lib/python3.4/http/client.py", line 1197, in connect\n    self.timeout, self.source_address)\n  File "/usr/lib/python3.4/socket.py", line 509, in create_connection\n    raise err\n  File "/usr/lib/python3.4/socket.py", line 500, in create_connection\n    sock.connect(sa)\nTimeoutError: [Errno 110] Connection timed out\n')
('2015-03-21 10:36:13.300770', 'Traceback (most recent call last):\n  File "/river/fd/fd_worker/fd_channel.py", line 204, in create_channel\n    handle.connect()\n  File "/usr/lib/python3.4/http/client.py", line 1197, in connect\n    self.timeout, self.source_address)\n  File "/usr/lib/python3.4/socket.py", line 509, in create_connection\n    raise err\n  File "/usr/lib/python3.4/socket.py", line 500, in create_connection\n    sock.connect(sa)\nTimeoutError: [Errno 110] Connection timed out\n')
('2015-03-21 10:36:14.836692', 'Traceback (most recent call last):\n  File "/river/fd/fd_worker/fd_channel.py", line 204, in create_channel\n    handle.connect()\n  File "/usr/lib/python3.4/http/client.py", line 1197, in connect\n    self.timeout, self.source_address)\n  File "/usr/lib/python3.4/socket.py", line 509, in create_connection\n    raise err\n  File "/usr/lib/python3.4/socket.py", line 500, in create_connection\n    sock.connect(sa)\nTimeoutError: [Errno 110] Connection timed out\n')
('2015-03-21 10:36:38.772665', 'Traceback (most recent call last):\n  File "/river/fd/fd_worker/fd_channel.py", line 204, in create_channel\n    handle.connect()\n  File "/usr/lib/python3.4/http/client.py", line 1197, in connect\n    self.timeout, self.source_address)\n  File "/usr/lib/python3.4/socket.py", line 509, in create_connection\n    raise err\n  File "/usr/lib/python3.4/socket.py", line 500, in create_connection\n    sock.connect(sa)\nTimeoutError: [Errno 110] Connection timed out\n')
('2015-03-21 10:36:46.324650', 'Traceback (most recent call last):\n  File "/river/fd/fd_worker/fd_channel.py", line 204, in create_channel\n    handle.connect()\n  File "/usr/lib/python3.4/http/client.py", line 1197, in connect\n    self.timeout, self.source_address)\n  File "/usr/lib/python3.4/socket.py", line 509, in create_connection\n    raise err\n  File "/usr/lib/python3.4/socket.py", line 500, in create_connection\n    sock.connect(sa)\nTimeoutError: [Errno 110] Connection timed out\n')
('2015-03-21 10:36:47.732663', 'Traceback (most recent call last):\n  File "/river/fd/fd_worker/fd_channel.py", line 204, in create_channel\n    handle.connect()\n  File "/usr/lib/python3.4/http/client.py", line 1197, in connect\n    self.timeout, self.source_address)\n  File "/usr/lib/python3.4/socket.py", line 509, in create_connection\n    raise err\n  File "/usr/lib/python3.4/socket.py", line 500, in create_connection\n    sock.connect(sa)\nTimeoutError: [Errno 110] Connection timed out\n')
('2015-03-21 10:37:02.708676', 'Traceback (most recent call last):\n  File "/river/fd/fd_worker/fd_channel.py", line 204, in create_channel\n    handle.connect()\n  File "/usr/lib/python3.4/http/client.py", line 1197, in connect\n    self.timeout, self.source_address)\n  File "/usr/lib/python3.4/socket.py", line 509, in create_connection\n    raise err\n  File "/usr/lib/python3.4/socket.py", line 500, in create_connection\n    sock.connect(sa)\nTimeoutError: [Errno 110] Connection timed out\n')
('2015-03-21 10:37:04.244572', 'Traceback (most recent call last):\n  File "/river/fd/fd_worker/fd_channel.py", line 204, in create_channel\n    handle.connect()\n  File "/usr/lib/python3.4/http/client.py", line 1197, in connect\n    self.timeout, self.source_address)\n  File "/usr/lib/python3.4/socket.py", line 509, in create_connection\n    raise err\n  File "/usr/lib/python3.4/socket.py", line 500, in create_connection\n    sock.connect(sa)\nTimeoutError: [Errno 110] Connection timed out\n')
('2015-03-21 10:37:05.780678', 'Traceback (most recent call last):\n  File "/river/fd/fd_worker/fd_channel.py", line 204, in create_channel\n    handle.connect()\n  File "/usr/lib/python3.4/http/client.py", line 1197, in connect\n    self.timeout, self.source_address)\n  File "/usr/lib/python3.4/socket.py", line 509, in create_connection\n    raise err\n  File "/usr/lib/python3.4/socket.py", line 500, in create_connection\n    sock.connect(sa)\nTimeoutError: [Errno 110] Connection timed out\n')
('2015-03-21 10:37:07.316750', 'Traceback (most recent call last):\n  File "/river/fd/fd_worker/fd_channel.py", line 204, in create_channel\n    handle.connect()\n  File "/usr/lib/python3.4/http/client.py", line 1197, in connect\n    self.timeout, self.source_address)\n  File "/usr/lib/python3.4/socket.py", line 509, in create_connection\n    raise err\n  File "/usr/lib/python3.4/socket.py", line 500, in create_connection\n    sock.connect(sa)\nTimeoutError: [Errno 110] Connection timed out\n')
('2015-03-21 10:37:08.724671', 'Traceback (most recent call last):\n  File "/river/fd/fd_worker/fd_channel.py", line 204, in create_channel\n    handle.connect()\n  File "/usr/lib/python3.4/http/client.py", line 1197, in connect\n    self.timeout, self.source_address)\n  File "/usr/lib/python3.4/socket.py", line 509, in create_connection\n    raise err\n  File "/usr/lib/python3.4/socket.py", line 500, in create_connection\n    sock.connect(sa)\nTimeoutError: [Errno 110] Connection timed out\n')
('2015-03-21 10:37:10.260655', 'Traceback (most recent call last):\n  File "/river/fd/fd_worker/fd_channel.py", line 204, in create_channel\n    handle.connect()\n  File "/usr/lib/python3.4/http/client.py", line 1197, in connect\n    self.timeout, self.source_address)\n  File "/usr/lib/python3.4/socket.py", line 509, in create_connection\n    raise err\n  File "/usr/lib/python3.4/socket.py", line 500, in create_connection\n    sock.connect(sa)\nTimeoutError: [Errno 110] Connection timed out\n')
('2015-03-21 10:37:11.668532', 'Traceback (most recent call last):\n  File "/river/fd/fd_worker/fd_channel.py", line 204, in create_channel\n    handle.connect()\n  File "/usr/lib/python3.4/http/client.py", line 1197, in connect\n    self.timeout, self.source_address)\n  File "/usr/lib/python3.4/socket.py", line 509, in create_connection\n    raise err\n  File "/usr/lib/python3.4/socket.py", line 500, in create_connection\n    sock.connect(sa)\nTimeoutError: [Errno 110] Connection timed out\n')
('2015-03-21 10:37:13.204681', 'Traceback (most recent call last):\n  File "/river/fd/fd_worker/fd_channel.py", line 204, in create_channel\n    handle.connect()\n  File "/usr/lib/python3.4/http/client.py", line 1197, in connect\n    self.timeout, self.source_address)\n  File "/usr/lib/python3.4/socket.py", line 509, in create_connection\n    raise err\n  File "/usr/lib/python3.4/socket.py", line 500, in create_connection\n    sock.connect(sa)\nTimeoutError: [Errno 110] Connection timed out\n')
('2015-03-21 10:37:16.276611', 'Traceback (most recent call last):\n  File "/river/fd/fd_worker/fd_channel.py", line 204, in create_channel\n    handle.connect()\n  File "/usr/lib/python3.4/http/client.py", line 1197, in connect\n    self.timeout, self.source_address)\n  File "/usr/lib/python3.4/socket.py", line 509, in create_connection\n    raise err\n  File "/usr/lib/python3.4/socket.py", line 500, in create_connection\n    sock.connect(sa)\nTimeoutError: [Errno 110] Connection timed out\n')
('2015-03-21 10:37:17.812604', 'Traceback (most recent call last):\n  File "/river/fd/fd_worker/fd_channel.py", line 204, in create_channel\n    handle.connect()\n  File "/usr/lib/python3.4/http/client.py", line 1197, in connect\n    self.timeout, self.source_address)\n  File "/usr/lib/python3.4/socket.py", line 509, in create_connection\n    raise err\n  File "/usr/lib/python3.4/socket.py", line 500, in create_connection\n    sock.connect(sa)\nTimeoutError: [Errno 110] Connection timed out\n')
('2015-03-21 10:37:19.220589', 'Traceback (most recent call last):\n  File "/river/fd/fd_worker/fd_channel.py", line 204, in create_channel\n    handle.connect()\n  File "/usr/lib/python3.4/http/client.py", line 1197, in connect\n    self.timeout, self.source_address)\n  File "/usr/lib/python3.4/socket.py", line 509, in create_connection\n    raise err\n  File "/usr/lib/python3.4/socket.py", line 500, in create_connection\n    sock.connect(sa)\nTimeoutError: [Errno 110] Connection timed out\n')
('2015-03-21 10:37:35.732563', 'Traceback (most recent call last):\n  File "/river/fd/fd_worker/fd_channel.py", line 204, in create_channel\n    handle.connect()\n  File "/usr/lib/python3.4/http/client.py", line 1197, in connect\n    self.timeout, self.source_address)\n  File "/usr/lib/python3.4/socket.py", line 509, in create_connection\n    raise err\n  File "/usr/lib/python3.4/socket.py", line 500, in create_connection\n    sock.connect(sa)\nTimeoutError: [Errno 110] Connection timed out\n')
('2015-03-21 10:37:37.268713', 'Traceback (most recent call last):\n  File "/river/fd/fd_worker/fd_channel.py", line 204, in create_channel\n    handle.connect()\n  File "/usr/lib/python3.4/http/client.py", line 1197, in connect\n    self.timeout, self.source_address)\n  File "/usr/lib/python3.4/socket.py", line 509, in create_connection\n    raise err\n  File "/usr/lib/python3.4/socket.py", line 500, in create_connection\n    sock.connect(sa)\nTimeoutError: [Errno 110] Connection timed out\n')
('2015-03-21 10:37:38.804682', 'Traceback (most recent call last):\n  File "/river/fd/fd_worker/fd_channel.py", line 204, in create_channel\n    handle.connect()\n  File "/usr/lib/python3.4/http/client.py", line 1197, in connect\n    self.timeout, self.source_address)\n  File "/usr/lib/python3.4/socket.py", line 509, in create_connection\n    raise err\n  File "/usr/lib/python3.4/socket.py", line 500, in create_connection\n    sock.connect(sa)\nTimeoutError: [Errno 110] Connection timed out\n')
('2015-03-21 10:37:40.212699', 'Traceback (most recent call last):\n  File "/river/fd/fd_worker/fd_channel.py", line 204, in create_channel\n    handle.connect()\n  File "/usr/lib/python3.4/http/client.py", line 1197, in connect\n    self.timeout, self.source_address)\n  File "/usr/lib/python3.4/socket.py", line 509, in create_connection\n    raise err\n  File "/usr/lib/python3.4/socket.py", line 500, in create_connection\n    sock.connect(sa)\nTimeoutError: [Errno 110] Connection timed out\n')
('2015-03-21 10:37:41.115906', 'Traceback (most recent call last):\n  File "/river/fd/fd_worker/fd_channel.py", line 144, in pyget\n    ack  = handle.getresponse()\n  File "/usr/lib/python3.4/http/client.py", line 1147, in getresponse\n    response.begin()\n  File "/usr/lib/python3.4/http/client.py", line 351, in begin\n    version, status, reason = self._read_status()\n  File "/usr/lib/python3.4/http/client.py", line 313, in _read_status\n    line = str(self.fp.readline(_MAXLINE + 1), "iso-8859-1")\n  File "/usr/lib/python3.4/socket.py", line 371, in readinto\n    return self._sock.recv_into(b)\n  File "/usr/lib/python3.4/ssl.py", line 746, in recv_into\n    return self.read(nbytes, buffer)\n  File "/usr/lib/python3.4/ssl.py", line 618, in read\n    v = self._sslobj.read(len, buffer)\nConnectionResetError: [Errno 104] Connection reset by peer\n')
('2015-03-21 10:37:41.748641', 'Traceback (most recent call last):\n  File "/river/fd/fd_worker/fd_channel.py", line 204, in create_channel\n    handle.connect()\n  File "/usr/lib/python3.4/http/client.py", line 1197, in connect\n    self.timeout, self.source_address)\n  File "/usr/lib/python3.4/socket.py", line 509, in create_connection\n    raise err\n  File "/usr/lib/python3.4/socket.py", line 500, in create_connection\n    sock.connect(sa)\nTimeoutError: [Errno 110] Connection timed out\n')
('2015-03-21 10:38:05.071266', 'Traceback (most recent call last):\n  File "/river/fd/fd_worker/fd_channel.py", line 144, in pyget\n    ack  = handle.getresponse()\n  File "/usr/lib/python3.4/http/client.py", line 1147, in getresponse\n    response.begin()\n  File "/usr/lib/python3.4/http/client.py", line 351, in begin\n    version, status, reason = self._read_status()\n  File "/usr/lib/python3.4/http/client.py", line 321, in _read_status\n    raise BadStatusLine(line)\nhttp.client.BadStatusLine: \'\'\n')
('2015-03-21 10:38:05.577043', 'Traceback (most recent call last):\n  File "/river/fd/fd_worker/fd_channel.py", line 144, in pyget\n    ack  = handle.getresponse()\n  File "/usr/lib/python3.4/http/client.py", line 1147, in getresponse\n    response.begin()\n  File "/usr/lib/python3.4/http/client.py", line 351, in begin\n    version, status, reason = self._read_status()\n  File "/usr/lib/python3.4/http/client.py", line 321, in _read_status\n    raise BadStatusLine(line)\nhttp.client.BadStatusLine: \'\'\n')
('2015-03-21 10:38:06.459958', 'Traceback (most recent call last):\n  File "/river/fd/fd_worker/fd_channel.py", line 144, in pyget\n    ack  = handle.getresponse()\n  File "/usr/lib/python3.4/http/client.py", line 1147, in getresponse\n    response.begin()\n  File "/usr/lib/python3.4/http/client.py", line 351, in begin\n    version, status, reason = self._read_status()\n  File "/usr/lib/python3.4/http/client.py", line 313, in _read_status\n    line = str(self.fp.readline(_MAXLINE + 1), "iso-8859-1")\n  File "/usr/lib/python3.4/socket.py", line 371, in readinto\n    return self._sock.recv_into(b)\n  File "/usr/lib/python3.4/ssl.py", line 746, in recv_into\n    return self.read(nbytes, buffer)\n  File "/usr/lib/python3.4/ssl.py", line 618, in read\n    v = self._sslobj.read(len, buffer)\nConnectionResetError: [Errno 104] Connection reset by peer\n')
('2015-03-21 10:38:07.220549', 'Traceback (most recent call last):\n  File "/river/fd/fd_worker/fd_channel.py", line 204, in create_channel\n    handle.connect()\n  File "/usr/lib/python3.4/http/client.py", line 1197, in connect\n    self.timeout, self.source_address)\n  File "/usr/lib/python3.4/socket.py", line 509, in create_connection\n    raise err\n  File "/usr/lib/python3.4/socket.py", line 500, in create_connection\n    sock.connect(sa)\nTimeoutError: [Errno 110] Connection timed out\n')
('2015-03-21 10:38:08.756670', 'Traceback (most recent call last):\n  File "/river/fd/fd_worker/fd_channel.py", line 204, in create_channel\n    handle.connect()\n  File "/usr/lib/python3.4/http/client.py", line 1197, in connect\n    self.timeout, self.source_address)\n  File "/usr/lib/python3.4/socket.py", line 509, in create_connection\n    raise err\n  File "/usr/lib/python3.4/socket.py", line 500, in create_connection\n    sock.connect(sa)\nTimeoutError: [Errno 110] Connection timed out\n')
('2015-03-21 10:38:10.292770', 'Traceback (most recent call last):\n  File "/river/fd/fd_worker/fd_channel.py", line 204, in create_channel\n    handle.connect()\n  File "/usr/lib/python3.4/http/client.py", line 1197, in connect\n    self.timeout, self.source_address)\n  File "/usr/lib/python3.4/socket.py", line 509, in create_connection\n    raise err\n  File "/usr/lib/python3.4/socket.py", line 500, in create_connection\n    sock.connect(sa)\nTimeoutError: [Errno 110] Connection timed out\n')
('2015-03-21 10:38:10.293433', 'Traceback (most recent call last):\n  File "/river/fd/fd_worker/fd_channel.py", line 204, in create_channel\n    handle.connect()\n  File "/usr/lib/python3.4/http/client.py", line 1197, in connect\n    self.timeout, self.source_address)\n  File "/usr/lib/python3.4/socket.py", line 509, in create_connection\n    raise err\n  File "/usr/lib/python3.4/socket.py", line 500, in create_connection\n    sock.connect(sa)\nTimeoutError: [Errno 110] Connection timed out\n')
('2015-03-21 10:38:11.828562', 'Traceback (most recent call last):\n  File "/river/fd/fd_worker/fd_channel.py", line 204, in create_channel\n    handle.connect()\n  File "/usr/lib/python3.4/http/client.py", line 1197, in connect\n    self.timeout, self.source_address)\n  File "/usr/lib/python3.4/socket.py", line 509, in create_connection\n    raise err\n  File "/usr/lib/python3.4/socket.py", line 500, in create_connection\n    sock.connect(sa)\nTimeoutError: [Errno 110] Connection timed out\n')
('2015-03-21 10:38:11.828953', 'Traceback (most recent call last):\n  File "/river/fd/fd_worker/fd_channel.py", line 204, in create_channel\n    handle.connect()\n  File "/usr/lib/python3.4/http/client.py", line 1197, in connect\n    self.timeout, self.source_address)\n  File "/usr/lib/python3.4/socket.py", line 509, in create_connection\n    raise err\n  File "/usr/lib/python3.4/socket.py", line 500, in create_connection\n    sock.connect(sa)\nTimeoutError: [Errno 110] Connection timed out\n')
('2015-03-21 10:38:13.236673', 'Traceback (most recent call last):\n  File "/river/fd/fd_worker/fd_channel.py", line 204, in create_channel\n    handle.connect()\n  File "/usr/lib/python3.4/http/client.py", line 1197, in connect\n    self.timeout, self.source_address)\n  File "/usr/lib/python3.4/socket.py", line 509, in create_connection\n    raise err\n  File "/usr/lib/python3.4/socket.py", line 500, in create_connection\n    sock.connect(sa)\nTimeoutError: [Errno 110] Connection timed out\n')
('2015-03-21 10:38:13.237116', 'Traceback (most recent call last):\n  File "/river/fd/fd_worker/fd_channel.py", line 204, in create_channel\n    handle.connect()\n  File "/usr/lib/python3.4/http/client.py", line 1197, in connect\n    self.timeout, self.source_address)\n  File "/usr/lib/python3.4/socket.py", line 509, in create_connection\n    raise err\n  File "/usr/lib/python3.4/socket.py", line 500, in create_connection\n    sock.connect(sa)\nTimeoutError: [Errno 110] Connection timed out\n')
('2015-03-21 10:38:14.772623', 'Traceback (most recent call last):\n  File "/river/fd/fd_worker/fd_channel.py", line 204, in create_channel\n    handle.connect()\n  File "/usr/lib/python3.4/http/client.py", line 1197, in connect\n    self.timeout, self.source_address)\n  File "/usr/lib/python3.4/socket.py", line 509, in create_connection\n    raise err\n  File "/usr/lib/python3.4/socket.py", line 500, in create_connection\n    sock.connect(sa)\nTimeoutError: [Errno 110] Connection timed out\n')
('2015-03-21 10:38:14.772954', 'Traceback (most recent call last):\n  File "/river/fd/fd_worker/fd_channel.py", line 204, in create_channel\n    handle.connect()\n  File "/usr/lib/python3.4/http/client.py", line 1197, in connect\n    self.timeout, self.source_address)\n  File "/usr/lib/python3.4/socket.py", line 509, in create_connection\n    raise err\n  File "/usr/lib/python3.4/socket.py", line 500, in create_connection\n    sock.connect(sa)\nTimeoutError: [Errno 110] Connection timed out\n')
('2015-03-21 10:38:16.180760', 'Traceback (most recent call last):\n  File "/river/fd/fd_worker/fd_channel.py", line 204, in create_channel\n    handle.connect()\n  File "/usr/lib/python3.4/http/client.py", line 1197, in connect\n    self.timeout, self.source_address)\n  File "/usr/lib/python3.4/socket.py", line 509, in create_connection\n    raise err\n  File "/usr/lib/python3.4/socket.py", line 500, in create_connection\n    sock.connect(sa)\nTimeoutError: [Errno 110] Connection timed out\n')
('2015-03-21 10:38:17.716575', 'Traceback (most recent call last):\n  File "/river/fd/fd_worker/fd_channel.py", line 204, in create_channel\n    handle.connect()\n  File "/usr/lib/python3.4/http/client.py", line 1197, in connect\n    self.timeout, self.source_address)\n  File "/usr/lib/python3.4/socket.py", line 509, in create_connection\n    raise err\n  File "/usr/lib/python3.4/socket.py", line 500, in create_connection\n    sock.connect(sa)\nTimeoutError: [Errno 110] Connection timed out\n')
('2015-03-21 10:38:19.252561', 'Traceback (most recent call last):\n  File "/river/fd/fd_worker/fd_channel.py", line 204, in create_channel\n    handle.connect()\n  File "/usr/lib/python3.4/http/client.py", line 1197, in connect\n    self.timeout, self.source_address)\n  File "/usr/lib/python3.4/socket.py", line 509, in create_connection\n    raise err\n  File "/usr/lib/python3.4/socket.py", line 500, in create_connection\n    sock.connect(sa)\nTimeoutError: [Errno 110] Connection timed out\n')
('2015-03-21 10:38:22.324557', 'Traceback (most recent call last):\n  File "/river/fd/fd_worker/fd_channel.py", line 204, in create_channel\n    handle.connect()\n  File "/usr/lib/python3.4/http/client.py", line 1197, in connect\n    self.timeout, self.source_address)\n  File "/usr/lib/python3.4/socket.py", line 509, in create_connection\n    raise err\n  File "/usr/lib/python3.4/socket.py", line 500, in create_connection\n    sock.connect(sa)\nTimeoutError: [Errno 110] Connection timed out\n')
('2015-03-21 10:38:22.325113', 'Traceback (most recent call last):\n  File "/river/fd/fd_worker/fd_channel.py", line 204, in create_channel\n    handle.connect()\n  File "/usr/lib/python3.4/http/client.py", line 1197, in connect\n    self.timeout, self.source_address)\n  File "/usr/lib/python3.4/socket.py", line 509, in create_connection\n    raise err\n  File "/usr/lib/python3.4/socket.py", line 500, in create_connection\n    sock.connect(sa)\nTimeoutError: [Errno 110] Connection timed out\n')
('2015-03-21 10:38:23.732579', 'Traceback (most recent call last):\n  File "/river/fd/fd_worker/fd_channel.py", line 204, in create_channel\n    handle.connect()\n  File "/usr/lib/python3.4/http/client.py", line 1197, in connect\n    self.timeout, self.source_address)\n  File "/usr/lib/python3.4/socket.py", line 509, in create_connection\n    raise err\n  File "/usr/lib/python3.4/socket.py", line 500, in create_connection\n    sock.connect(sa)\nTimeoutError: [Errno 110] Connection timed out\n')
('2015-03-21 10:38:25.268639', 'Traceback (most recent call last):\n  File "/river/fd/fd_worker/fd_channel.py", line 204, in create_channel\n    handle.connect()\n  File "/usr/lib/python3.4/http/client.py", line 1197, in connect\n    self.timeout, self.source_address)\n  File "/usr/lib/python3.4/socket.py", line 509, in create_connection\n    raise err\n  File "/usr/lib/python3.4/socket.py", line 500, in create_connection\n    sock.connect(sa)\nTimeoutError: [Errno 110] Connection timed out\n')
('2015-03-21 10:38:26.676665', 'Traceback (most recent call last):\n  File "/river/fd/fd_worker/fd_channel.py", line 204, in create_channel\n    handle.connect()\n  File "/usr/lib/python3.4/http/client.py", line 1197, in connect\n    self.timeout, self.source_address)\n  File "/usr/lib/python3.4/socket.py", line 509, in create_connection\n    raise err\n  File "/usr/lib/python3.4/socket.py", line 500, in create_connection\n    sock.connect(sa)\nTimeoutError: [Errno 110] Connection timed out\n')
('2015-03-21 10:38:28.212665', 'Traceback (most recent call last):\n  File "/river/fd/fd_worker/fd_channel.py", line 204, in create_channel\n    handle.connect()\n  File "/usr/lib/python3.4/http/client.py", line 1197, in connect\n    self.timeout, self.source_address)\n  File "/usr/lib/python3.4/socket.py", line 509, in create_connection\n    raise err\n  File "/usr/lib/python3.4/socket.py", line 500, in create_connection\n    sock.connect(sa)\nTimeoutError: [Errno 110] Connection timed out\n')
('2015-03-21 10:38:31.284608', 'Traceback (most recent call last):\n  File "/river/fd/fd_worker/fd_channel.py", line 204, in create_channel\n    handle.connect()\n  File "/usr/lib/python3.4/http/client.py", line 1197, in connect\n    self.timeout, self.source_address)\n  File "/usr/lib/python3.4/socket.py", line 509, in create_connection\n    raise err\n  File "/usr/lib/python3.4/socket.py", line 500, in create_connection\n    sock.connect(sa)\nTimeoutError: [Errno 110] Connection timed out\n')
('2015-03-21 10:38:32.820635', 'Traceback (most recent call last):\n  File "/river/fd/fd_worker/fd_channel.py", line 204, in create_channel\n    handle.connect()\n  File "/usr/lib/python3.4/http/client.py", line 1197, in connect\n    self.timeout, self.source_address)\n  File "/usr/lib/python3.4/socket.py", line 509, in create_connection\n    raise err\n  File "/usr/lib/python3.4/socket.py", line 500, in create_connection\n    sock.connect(sa)\nTimeoutError: [Errno 110] Connection timed out\n')
('2015-03-21 10:38:34.228640', 'Traceback (most recent call last):\n  File "/river/fd/fd_worker/fd_channel.py", line 204, in create_channel\n    handle.connect()\n  File "/usr/lib/python3.4/http/client.py", line 1197, in connect\n    self.timeout, self.source_address)\n  File "/usr/lib/python3.4/socket.py", line 509, in create_connection\n    raise err\n  File "/usr/lib/python3.4/socket.py", line 500, in create_connection\n    sock.connect(sa)\nTimeoutError: [Errno 110] Connection timed out\n')
('2015-03-21 10:38:35.388394', 'Traceback (most recent call last):\n  File "/river/fd/fd_worker/fd_channel.py", line 144, in pyget\n    ack  = handle.getresponse()\n  File "/usr/lib/python3.4/http/client.py", line 1147, in getresponse\n    response.begin()\n  File "/usr/lib/python3.4/http/client.py", line 351, in begin\n    version, status, reason = self._read_status()\n  File "/usr/lib/python3.4/http/client.py", line 313, in _read_status\n    line = str(self.fp.readline(_MAXLINE + 1), "iso-8859-1")\n  File "/usr/lib/python3.4/socket.py", line 371, in readinto\n    return self._sock.recv_into(b)\n  File "/usr/lib/python3.4/ssl.py", line 746, in recv_into\n    return self.read(nbytes, buffer)\n  File "/usr/lib/python3.4/ssl.py", line 618, in read\n    v = self._sslobj.read(len, buffer)\nConnectionResetError: [Errno 104] Connection reset by peer\n')
('2015-03-21 10:38:43.316632', 'Traceback (most recent call last):\n  File "/river/fd/fd_worker/fd_channel.py", line 204, in create_channel\n    handle.connect()\n  File "/usr/lib/python3.4/http/client.py", line 1197, in connect\n    self.timeout, self.source_address)\n  File "/usr/lib/python3.4/socket.py", line 509, in create_connection\n    raise err\n  File "/usr/lib/python3.4/socket.py", line 500, in create_connection\n    sock.connect(sa)\nTimeoutError: [Errno 110] Connection timed out\n')
('2015-03-21 10:38:44.443606', 'Traceback (most recent call last):\n  File "/river/fd/fd_worker/fd_channel.py", line 144, in pyget\n    ack  = handle.getresponse()\n  File "/usr/lib/python3.4/http/client.py", line 1147, in getresponse\n    response.begin()\n  File "/usr/lib/python3.4/http/client.py", line 351, in begin\n    version, status, reason = self._read_status()\n  File "/usr/lib/python3.4/http/client.py", line 321, in _read_status\n    raise BadStatusLine(line)\nhttp.client.BadStatusLine: \'\'\n')
('2015-03-21 10:38:44.724619', 'Traceback (most recent call last):\n  File "/river/fd/fd_worker/fd_channel.py", line 204, in create_channel\n    handle.connect()\n  File "/usr/lib/python3.4/http/client.py", line 1197, in connect\n    self.timeout, self.source_address)\n  File "/usr/lib/python3.4/socket.py", line 509, in create_connection\n    raise err\n  File "/usr/lib/python3.4/socket.py", line 500, in create_connection\n    sock.connect(sa)\nTimeoutError: [Errno 110] Connection timed out\n')
('2015-03-21 10:38:46.260576', 'Traceback (most recent call last):\n  File "/river/fd/fd_worker/fd_channel.py", line 204, in create_channel\n    handle.connect()\n  File "/usr/lib/python3.4/http/client.py", line 1197, in connect\n    self.timeout, self.source_address)\n  File "/usr/lib/python3.4/socket.py", line 509, in create_connection\n    raise err\n  File "/usr/lib/python3.4/socket.py", line 500, in create_connection\n    sock.connect(sa)\nTimeoutError: [Errno 110] Connection timed out\n')
('2015-03-21 10:38:47.668619', 'Traceback (most recent call last):\n  File "/river/fd/fd_worker/fd_channel.py", line 204, in create_channel\n    handle.connect()\n  File "/usr/lib/python3.4/http/client.py", line 1197, in connect\n    self.timeout, self.source_address)\n  File "/usr/lib/python3.4/socket.py", line 509, in create_connection\n    raise err\n  File "/usr/lib/python3.4/socket.py", line 500, in create_connection\n    sock.connect(sa)\nTimeoutError: [Errno 110] Connection timed out\n')
('2015-03-21 10:38:49.204610', 'Traceback (most recent call last):\n  File "/river/fd/fd_worker/fd_channel.py", line 204, in create_channel\n    handle.connect()\n  File "/usr/lib/python3.4/http/client.py", line 1197, in connect\n    self.timeout, self.source_address)\n  File "/usr/lib/python3.4/socket.py", line 509, in create_connection\n    raise err\n  File "/usr/lib/python3.4/socket.py", line 500, in create_connection\n    sock.connect(sa)\nTimeoutError: [Errno 110] Connection timed out\n')
('2015-03-21 10:38:50.740660', 'Traceback (most recent call last):\n  File "/river/fd/fd_worker/fd_channel.py", line 204, in create_channel\n    handle.connect()\n  File "/usr/lib/python3.4/http/client.py", line 1197, in connect\n    self.timeout, self.source_address)\n  File "/usr/lib/python3.4/socket.py", line 509, in create_connection\n    raise err\n  File "/usr/lib/python3.4/socket.py", line 500, in create_connection\n    sock.connect(sa)\nTimeoutError: [Errno 110] Connection timed out\n')
('2015-03-21 10:38:58.292726', 'Traceback (most recent call last):\n  File "/river/fd/fd_worker/fd_channel.py", line 204, in create_channel\n    handle.connect()\n  File "/usr/lib/python3.4/http/client.py", line 1197, in connect\n    self.timeout, self.source_address)\n  File "/usr/lib/python3.4/socket.py", line 509, in create_connection\n    raise err\n  File "/usr/lib/python3.4/socket.py", line 500, in create_connection\n    sock.connect(sa)\nTimeoutError: [Errno 110] Connection timed out\n')
('2015-03-21 10:38:59.700630', 'Traceback (most recent call last):\n  File "/river/fd/fd_worker/fd_channel.py", line 204, in create_channel\n    handle.connect()\n  File "/usr/lib/python3.4/http/client.py", line 1197, in connect\n    self.timeout, self.source_address)\n  File "/usr/lib/python3.4/socket.py", line 509, in create_connection\n    raise err\n  File "/usr/lib/python3.4/socket.py", line 500, in create_connection\n    sock.connect(sa)\nTimeoutError: [Errno 110] Connection timed out\n')
('2015-03-21 10:39:02.772631', 'Traceback (most recent call last):\n  File "/river/fd/fd_worker/fd_channel.py", line 204, in create_channel\n    handle.connect()\n  File "/usr/lib/python3.4/http/client.py", line 1197, in connect\n    self.timeout, self.source_address)\n  File "/usr/lib/python3.4/socket.py", line 509, in create_connection\n    raise err\n  File "/usr/lib/python3.4/socket.py", line 500, in create_connection\n    sock.connect(sa)\nTimeoutError: [Errno 110] Connection timed out\n')
('2015-03-21 10:39:04.308567', 'Traceback (most recent call last):\n  File "/river/fd/fd_worker/fd_channel.py", line 204, in create_channel\n    handle.connect()\n  File "/usr/lib/python3.4/http/client.py", line 1197, in connect\n    self.timeout, self.source_address)\n  File "/usr/lib/python3.4/socket.py", line 509, in create_connection\n    raise err\n  File "/usr/lib/python3.4/socket.py", line 500, in create_connection\n    sock.connect(sa)\nTimeoutError: [Errno 110] Connection timed out\n')
('2015-03-21 10:39:05.716630', 'Traceback (most recent call last):\n  File "/river/fd/fd_worker/fd_channel.py", line 204, in create_channel\n    handle.connect()\n  File "/usr/lib/python3.4/http/client.py", line 1197, in connect\n    self.timeout, self.source_address)\n  File "/usr/lib/python3.4/socket.py", line 509, in create_connection\n    raise err\n  File "/usr/lib/python3.4/socket.py", line 500, in create_connection\n    sock.connect(sa)\nTimeoutError: [Errno 110] Connection timed out\n')
('2015-03-21 10:39:07.252650', 'Traceback (most recent call last):\n  File "/river/fd/fd_worker/fd_channel.py", line 204, in create_channel\n    handle.connect()\n  File "/usr/lib/python3.4/http/client.py", line 1197, in connect\n    self.timeout, self.source_address)\n  File "/usr/lib/python3.4/socket.py", line 509, in create_connection\n    raise err\n  File "/usr/lib/python3.4/socket.py", line 500, in create_connection\n    sock.connect(sa)\nTimeoutError: [Errno 110] Connection timed out\n')
('2015-03-21 10:39:08.788723', 'Traceback (most recent call last):\n  File "/river/fd/fd_worker/fd_channel.py", line 204, in create_channel\n    handle.connect()\n  File "/usr/lib/python3.4/http/client.py", line 1197, in connect\n    self.timeout, self.source_address)\n  File "/usr/lib/python3.4/socket.py", line 509, in create_connection\n    raise err\n  File "/usr/lib/python3.4/socket.py", line 500, in create_connection\n    sock.connect(sa)\nTimeoutError: [Errno 110] Connection timed out\n')
('2015-03-21 10:39:10.196640', 'Traceback (most recent call last):\n  File "/river/fd/fd_worker/fd_channel.py", line 204, in create_channel\n    handle.connect()\n  File "/usr/lib/python3.4/http/client.py", line 1197, in connect\n    self.timeout, self.source_address)\n  File "/usr/lib/python3.4/socket.py", line 509, in create_connection\n    raise err\n  File "/usr/lib/python3.4/socket.py", line 500, in create_connection\n    sock.connect(sa)\nTimeoutError: [Errno 110] Connection timed out\n')
('2015-03-21 10:39:11.732570', 'Traceback (most recent call last):\n  File "/river/fd/fd_worker/fd_channel.py", line 204, in create_channel\n    handle.connect()\n  File "/usr/lib/python3.4/http/client.py", line 1197, in connect\n    self.timeout, self.source_address)\n  File "/usr/lib/python3.4/socket.py", line 509, in create_connection\n    raise err\n  File "/usr/lib/python3.4/socket.py", line 500, in create_connection\n    sock.connect(sa)\nTimeoutError: [Errno 110] Connection timed out\n')
('2015-03-21 10:39:16.212695', 'Traceback (most recent call last):\n  File "/river/fd/fd_worker/fd_channel.py", line 204, in create_channel\n    handle.connect()\n  File "/usr/lib/python3.4/http/client.py", line 1197, in connect\n    self.timeout, self.source_address)\n  File "/usr/lib/python3.4/socket.py", line 509, in create_connection\n    raise err\n  File "/usr/lib/python3.4/socket.py", line 500, in create_connection\n    sock.connect(sa)\nTimeoutError: [Errno 110] Connection timed out\n')
('2015-03-21 10:39:17.748632', 'Traceback (most recent call last):\n  File "/river/fd/fd_worker/fd_channel.py", line 204, in create_channel\n    handle.connect()\n  File "/usr/lib/python3.4/http/client.py", line 1197, in connect\n    self.timeout, self.source_address)\n  File "/usr/lib/python3.4/socket.py", line 509, in create_connection\n    raise err\n  File "/usr/lib/python3.4/socket.py", line 500, in create_connection\n    sock.connect(sa)\nTimeoutError: [Errno 110] Connection timed out\n')
('2015-03-21 10:39:19.284605', 'Traceback (most recent call last):\n  File "/river/fd/fd_worker/fd_channel.py", line 204, in create_channel\n    handle.connect()\n  File "/usr/lib/python3.4/http/client.py", line 1197, in connect\n    self.timeout, self.source_address)\n  File "/usr/lib/python3.4/socket.py", line 509, in create_connection\n    raise err\n  File "/usr/lib/python3.4/socket.py", line 500, in create_connection\n    sock.connect(sa)\nTimeoutError: [Errno 110] Connection timed out\n')
('2015-03-21 10:39:20.692623', 'Traceback (most recent call last):\n  File "/river/fd/fd_worker/fd_channel.py", line 204, in create_channel\n    handle.connect()\n  File "/usr/lib/python3.4/http/client.py", line 1197, in connect\n    self.timeout, self.source_address)\n  File "/usr/lib/python3.4/socket.py", line 509, in create_connection\n    raise err\n  File "/usr/lib/python3.4/socket.py", line 500, in create_connection\n    sock.connect(sa)\nTimeoutError: [Errno 110] Connection timed out\n')
('2015-03-21 10:39:20.693001', 'Traceback (most recent call last):\n  File "/river/fd/fd_worker/fd_channel.py", line 204, in create_channel\n    handle.connect()\n  File "/usr/lib/python3.4/http/client.py", line 1197, in connect\n    self.timeout, self.source_address)\n  File "/usr/lib/python3.4/socket.py", line 509, in create_connection\n    raise err\n  File "/usr/lib/python3.4/socket.py", line 500, in create_connection\n    sock.connect(sa)\nTimeoutError: [Errno 110] Connection timed out\n')
('2015-03-21 10:39:22.228755', 'Traceback (most recent call last):\n  File "/river/fd/fd_worker/fd_channel.py", line 204, in create_channel\n    handle.connect()\n  File "/usr/lib/python3.4/http/client.py", line 1197, in connect\n    self.timeout, self.source_address)\n  File "/usr/lib/python3.4/socket.py", line 509, in create_connection\n    raise err\n  File "/usr/lib/python3.4/socket.py", line 500, in create_connection\n    sock.connect(sa)\nTimeoutError: [Errno 110] Connection timed out\n')
('2015-03-21 10:39:22.229261', 'Traceback (most recent call last):\n  File "/river/fd/fd_worker/fd_channel.py", line 204, in create_channel\n    handle.connect()\n  File "/usr/lib/python3.4/http/client.py", line 1197, in connect\n    self.timeout, self.source_address)\n  File "/usr/lib/python3.4/socket.py", line 509, in create_connection\n    raise err\n  File "/usr/lib/python3.4/socket.py", line 500, in create_connection\n    sock.connect(sa)\nTimeoutError: [Errno 110] Connection timed out\n')
('2015-03-21 10:39:23.764625', 'Traceback (most recent call last):\n  File "/river/fd/fd_worker/fd_channel.py", line 204, in create_channel\n    handle.connect()\n  File "/usr/lib/python3.4/http/client.py", line 1197, in connect\n    self.timeout, self.source_address)\n  File "/usr/lib/python3.4/socket.py", line 509, in create_connection\n    raise err\n  File "/usr/lib/python3.4/socket.py", line 500, in create_connection\n    sock.connect(sa)\nTimeoutError: [Errno 110] Connection timed out\n')
('2015-03-21 10:39:23.765014', 'Traceback (most recent call last):\n  File "/river/fd/fd_worker/fd_channel.py", line 204, in create_channel\n    handle.connect()\n  File "/usr/lib/python3.4/http/client.py", line 1197, in connect\n    self.timeout, self.source_address)\n  File "/usr/lib/python3.4/socket.py", line 509, in create_connection\n    raise err\n  File "/usr/lib/python3.4/socket.py", line 500, in create_connection\n    sock.connect(sa)\nTimeoutError: [Errno 110] Connection timed out\n')
('2015-03-21 10:39:25.300728', 'Traceback (most recent call last):\n  File "/river/fd/fd_worker/fd_channel.py", line 204, in create_channel\n    handle.connect()\n  File "/usr/lib/python3.4/http/client.py", line 1197, in connect\n    self.timeout, self.source_address)\n  File "/usr/lib/python3.4/socket.py", line 509, in create_connection\n    raise err\n  File "/usr/lib/python3.4/socket.py", line 500, in create_connection\n    sock.connect(sa)\nTimeoutError: [Errno 110] Connection timed out\n')
('2015-03-21 10:39:25.301229', 'Traceback (most recent call last):\n  File "/river/fd/fd_worker/fd_channel.py", line 204, in create_channel\n    handle.connect()\n  File "/usr/lib/python3.4/http/client.py", line 1197, in connect\n    self.timeout, self.source_address)\n  File "/usr/lib/python3.4/socket.py", line 509, in create_connection\n    raise err\n  File "/usr/lib/python3.4/socket.py", line 500, in create_connection\n    sock.connect(sa)\nTimeoutError: [Errno 110] Connection timed out\n')
('2015-03-21 10:39:26.836767', 'Traceback (most recent call last):\n  File "/river/fd/fd_worker/fd_channel.py", line 204, in create_channel\n    handle.connect()\n  File "/usr/lib/python3.4/http/client.py", line 1197, in connect\n    self.timeout, self.source_address)\n  File "/usr/lib/python3.4/socket.py", line 509, in create_connection\n    raise err\n  File "/usr/lib/python3.4/socket.py", line 500, in create_connection\n    sock.connect(sa)\nTimeoutError: [Errno 110] Connection timed out\n')
('2015-03-21 10:39:26.837272', 'Traceback (most recent call last):\n  File "/river/fd/fd_worker/fd_channel.py", line 204, in create_channel\n    handle.connect()\n  File "/usr/lib/python3.4/http/client.py", line 1197, in connect\n    self.timeout, self.source_address)\n  File "/usr/lib/python3.4/socket.py", line 509, in create_connection\n    raise err\n  File "/usr/lib/python3.4/socket.py", line 500, in create_connection\n    sock.connect(sa)\nTimeoutError: [Errno 110] Connection timed out\n')
('2015-03-21 10:39:28.244624', 'Traceback (most recent call last):\n  File "/river/fd/fd_worker/fd_channel.py", line 204, in create_channel\n    handle.connect()\n  File "/usr/lib/python3.4/http/client.py", line 1197, in connect\n    self.timeout, self.source_address)\n  File "/usr/lib/python3.4/socket.py", line 509, in create_connection\n    raise err\n  File "/usr/lib/python3.4/socket.py", line 500, in create_connection\n    sock.connect(sa)\nTimeoutError: [Errno 110] Connection timed out\n')
('2015-03-21 10:39:28.245216', 'Traceback (most recent call last):\n  File "/river/fd/fd_worker/fd_channel.py", line 204, in create_channel\n    handle.connect()\n  File "/usr/lib/python3.4/http/client.py", line 1197, in connect\n    self.timeout, self.source_address)\n  File "/usr/lib/python3.4/socket.py", line 509, in create_connection\n    raise err\n  File "/usr/lib/python3.4/socket.py", line 500, in create_connection\n    sock.connect(sa)\nTimeoutError: [Errno 110] Connection timed out\n')
('2015-03-21 10:39:29.780598', 'Traceback (most recent call last):\n  File "/river/fd/fd_worker/fd_channel.py", line 204, in create_channel\n    handle.connect()\n  File "/usr/lib/python3.4/http/client.py", line 1197, in connect\n    self.timeout, self.source_address)\n  File "/usr/lib/python3.4/socket.py", line 509, in create_connection\n    raise err\n  File "/usr/lib/python3.4/socket.py", line 500, in create_connection\n    sock.connect(sa)\nTimeoutError: [Errno 110] Connection timed out\n')
('2015-03-21 10:39:31.188603', 'Traceback (most recent call last):\n  File "/river/fd/fd_worker/fd_channel.py", line 204, in create_channel\n    handle.connect()\n  File "/usr/lib/python3.4/http/client.py", line 1197, in connect\n    self.timeout, self.source_address)\n  File "/usr/lib/python3.4/socket.py", line 509, in create_connection\n    raise err\n  File "/usr/lib/python3.4/socket.py", line 500, in create_connection\n    sock.connect(sa)\nTimeoutError: [Errno 110] Connection timed out\n')
('2015-03-21 10:39:32.724614', 'Traceback (most recent call last):\n  File "/river/fd/fd_worker/fd_channel.py", line 204, in create_channel\n    handle.connect()\n  File "/usr/lib/python3.4/http/client.py", line 1197, in connect\n    self.timeout, self.source_address)\n  File "/usr/lib/python3.4/socket.py", line 509, in create_connection\n    raise err\n  File "/usr/lib/python3.4/socket.py", line 500, in create_connection\n    sock.connect(sa)\nTimeoutError: [Errno 110] Connection timed out\n')
('2015-03-21 10:39:34.260720', 'Traceback (most recent call last):\n  File "/river/fd/fd_worker/fd_channel.py", line 204, in create_channel\n    handle.connect()\n  File "/usr/lib/python3.4/http/client.py", line 1197, in connect\n    self.timeout, self.source_address)\n  File "/usr/lib/python3.4/socket.py", line 509, in create_connection\n    raise err\n  File "/usr/lib/python3.4/socket.py", line 500, in create_connection\n    sock.connect(sa)\nTimeoutError: [Errno 110] Connection timed out\n')
('2015-03-21 10:39:35.796669', 'Traceback (most recent call last):\n  File "/river/fd/fd_worker/fd_channel.py", line 204, in create_channel\n    handle.connect()\n  File "/usr/lib/python3.4/http/client.py", line 1197, in connect\n    self.timeout, self.source_address)\n  File "/usr/lib/python3.4/socket.py", line 509, in create_connection\n    raise err\n  File "/usr/lib/python3.4/socket.py", line 500, in create_connection\n    sock.connect(sa)\nTimeoutError: [Errno 110] Connection timed out\n')
('2015-03-21 10:39:37.332820', 'Traceback (most recent call last):\n  File "/river/fd/fd_worker/fd_channel.py", line 204, in create_channel\n    handle.connect()\n  File "/usr/lib/python3.4/http/client.py", line 1197, in connect\n    self.timeout, self.source_address)\n  File "/usr/lib/python3.4/socket.py", line 509, in create_connection\n    raise err\n  File "/usr/lib/python3.4/socket.py", line 500, in create_connection\n    sock.connect(sa)\nTimeoutError: [Errno 110] Connection timed out\n')
('2015-03-21 10:39:38.740688', 'Traceback (most recent call last):\n  File "/river/fd/fd_worker/fd_channel.py", line 204, in create_channel\n    handle.connect()\n  File "/usr/lib/python3.4/http/client.py", line 1197, in connect\n    self.timeout, self.source_address)\n  File "/usr/lib/python3.4/socket.py", line 509, in create_connection\n    raise err\n  File "/usr/lib/python3.4/socket.py", line 500, in create_connection\n    sock.connect(sa)\nTimeoutError: [Errno 110] Connection timed out\n')
('2015-03-21 10:39:40.276730', 'Traceback (most recent call last):\n  File "/river/fd/fd_worker/fd_channel.py", line 204, in create_channel\n    handle.connect()\n  File "/usr/lib/python3.4/http/client.py", line 1197, in connect\n    self.timeout, self.source_address)\n  File "/usr/lib/python3.4/socket.py", line 509, in create_connection\n    raise err\n  File "/usr/lib/python3.4/socket.py", line 500, in create_connection\n    sock.connect(sa)\nTimeoutError: [Errno 110] Connection timed out\n')
('2015-03-21 10:39:41.684659', 'Traceback (most recent call last):\n  File "/river/fd/fd_worker/fd_channel.py", line 204, in create_channel\n    handle.connect()\n  File "/usr/lib/python3.4/http/client.py", line 1197, in connect\n    self.timeout, self.source_address)\n  File "/usr/lib/python3.4/socket.py", line 509, in create_connection\n    raise err\n  File "/usr/lib/python3.4/socket.py", line 500, in create_connection\n    sock.connect(sa)\nTimeoutError: [Errno 110] Connection timed out\n')
('2015-03-21 10:39:43.995588', 'Traceback (most recent call last):\n  File "/river/fd/fd_worker/fd_channel.py", line 144, in pyget\n    ack  = handle.getresponse()\n  File "/usr/lib/python3.4/http/client.py", line 1147, in getresponse\n    response.begin()\n  File "/usr/lib/python3.4/http/client.py", line 351, in begin\n    version, status, reason = self._read_status()\n  File "/usr/lib/python3.4/http/client.py", line 313, in _read_status\n    line = str(self.fp.readline(_MAXLINE + 1), "iso-8859-1")\n  File "/usr/lib/python3.4/socket.py", line 371, in readinto\n    return self._sock.recv_into(b)\n  File "/usr/lib/python3.4/ssl.py", line 746, in recv_into\n    return self.read(nbytes, buffer)\n  File "/usr/lib/python3.4/ssl.py", line 618, in read\n    v = self._sslobj.read(len, buffer)\nConnectionResetError: [Errno 104] Connection reset by peer\n')
('2015-03-21 10:39:46.044067', 'Traceback (most recent call last):\n  File "/river/fd/fd_worker/fd_channel.py", line 144, in pyget\n    ack  = handle.getresponse()\n  File "/usr/lib/python3.4/http/client.py", line 1147, in getresponse\n    response.begin()\n  File "/usr/lib/python3.4/http/client.py", line 351, in begin\n    version, status, reason = self._read_status()\n  File "/usr/lib/python3.4/http/client.py", line 313, in _read_status\n    line = str(self.fp.readline(_MAXLINE + 1), "iso-8859-1")\n  File "/usr/lib/python3.4/socket.py", line 371, in readinto\n    return self._sock.recv_into(b)\n  File "/usr/lib/python3.4/ssl.py", line 746, in recv_into\n    return self.read(nbytes, buffer)\n  File "/usr/lib/python3.4/ssl.py", line 618, in read\n    v = self._sslobj.read(len, buffer)\nConnectionResetError: [Errno 104] Connection reset by peer\n')
('2015-03-21 10:39:46.045345', 'Traceback (most recent call last):\n  File "/river/fd/fd_worker/fd_channel.py", line 144, in pyget\n    ack  = handle.getresponse()\n  File "/usr/lib/python3.4/http/client.py", line 1147, in getresponse\n    response.begin()\n  File "/usr/lib/python3.4/http/client.py", line 351, in begin\n    version, status, reason = self._read_status()\n  File "/usr/lib/python3.4/http/client.py", line 313, in _read_status\n    line = str(self.fp.readline(_MAXLINE + 1), "iso-8859-1")\n  File "/usr/lib/python3.4/socket.py", line 371, in readinto\n    return self._sock.recv_into(b)\n  File "/usr/lib/python3.4/ssl.py", line 746, in recv_into\n    return self.read(nbytes, buffer)\n  File "/usr/lib/python3.4/ssl.py", line 618, in read\n    v = self._sslobj.read(len, buffer)\nConnectionResetError: [Errno 104] Connection reset by peer\n')
('2015-03-21 10:39:46.047384', 'Traceback (most recent call last):\n  File "/river/fd/fd_worker/fd_channel.py", line 144, in pyget\n    ack  = handle.getresponse()\n  File "/usr/lib/python3.4/http/client.py", line 1147, in getresponse\n    response.begin()\n  File "/usr/lib/python3.4/http/client.py", line 351, in begin\n    version, status, reason = self._read_status()\n  File "/usr/lib/python3.4/http/client.py", line 313, in _read_status\n    line = str(self.fp.readline(_MAXLINE + 1), "iso-8859-1")\n  File "/usr/lib/python3.4/socket.py", line 371, in readinto\n    return self._sock.recv_into(b)\n  File "/usr/lib/python3.4/ssl.py", line 746, in recv_into\n    return self.read(nbytes, buffer)\n  File "/usr/lib/python3.4/ssl.py", line 618, in read\n    v = self._sslobj.read(len, buffer)\nConnectionResetError: [Errno 104] Connection reset by peer\n')
('2015-03-21 10:39:48.596361', 'Traceback (most recent call last):\n  File "/river/fd/fd_worker/fd_channel.py", line 144, in pyget\n    ack  = handle.getresponse()\n  File "/usr/lib/python3.4/http/client.py", line 1147, in getresponse\n    response.begin()\n  File "/usr/lib/python3.4/http/client.py", line 351, in begin\n    version, status, reason = self._read_status()\n  File "/usr/lib/python3.4/http/client.py", line 321, in _read_status\n    raise BadStatusLine(line)\nhttp.client.BadStatusLine: \'\'\n')
('2015-03-21 10:39:49.616386', 'Traceback (most recent call last):\n  File "/river/fd/fd_worker/fd_channel.py", line 144, in pyget\n    ack  = handle.getresponse()\n  File "/usr/lib/python3.4/http/client.py", line 1147, in getresponse\n    response.begin()\n  File "/usr/lib/python3.4/http/client.py", line 351, in begin\n    version, status, reason = self._read_status()\n  File "/usr/lib/python3.4/http/client.py", line 321, in _read_status\n    raise BadStatusLine(line)\nhttp.client.BadStatusLine: \'\'\n')
('2015-03-21 10:39:49.910801', 'Traceback (most recent call last):\n  File "/river/fd/fd_worker/fd_channel.py", line 144, in pyget\n    ack  = handle.getresponse()\n  File "/usr/lib/python3.4/http/client.py", line 1147, in getresponse\n    response.begin()\n  File "/usr/lib/python3.4/http/client.py", line 351, in begin\n    version, status, reason = self._read_status()\n  File "/usr/lib/python3.4/http/client.py", line 321, in _read_status\n    raise BadStatusLine(line)\nhttp.client.BadStatusLine: \'\'\n')
('2015-03-21 10:39:50.772600', 'Traceback (most recent call last):\n  File "/river/fd/fd_worker/fd_channel.py", line 204, in create_channel\n    handle.connect()\n  File "/usr/lib/python3.4/http/client.py", line 1197, in connect\n    self.timeout, self.source_address)\n  File "/usr/lib/python3.4/socket.py", line 509, in create_connection\n    raise err\n  File "/usr/lib/python3.4/socket.py", line 500, in create_connection\n    sock.connect(sa)\nTimeoutError: [Errno 110] Connection timed out\n')
('2015-03-21 10:39:50.772994', 'Traceback (most recent call last):\n  File "/river/fd/fd_worker/fd_channel.py", line 204, in create_channel\n    handle.connect()\n  File "/usr/lib/python3.4/http/client.py", line 1197, in connect\n    self.timeout, self.source_address)\n  File "/usr/lib/python3.4/socket.py", line 509, in create_connection\n    raise err\n  File "/usr/lib/python3.4/socket.py", line 500, in create_connection\n    sock.connect(sa)\nTimeoutError: [Errno 110] Connection timed out\n')
('2015-03-21 10:39:52.180609', 'Traceback (most recent call last):\n  File "/river/fd/fd_worker/fd_channel.py", line 204, in create_channel\n    handle.connect()\n  File "/usr/lib/python3.4/http/client.py", line 1197, in connect\n    self.timeout, self.source_address)\n  File "/usr/lib/python3.4/socket.py", line 509, in create_connection\n    raise err\n  File "/usr/lib/python3.4/socket.py", line 500, in create_connection\n    sock.connect(sa)\nTimeoutError: [Errno 110] Connection timed out\n')
('2015-03-21 10:39:52.181021', 'Traceback (most recent call last):\n  File "/river/fd/fd_worker/fd_channel.py", line 204, in create_channel\n    handle.connect()\n  File "/usr/lib/python3.4/http/client.py", line 1197, in connect\n    self.timeout, self.source_address)\n  File "/usr/lib/python3.4/socket.py", line 509, in create_connection\n    raise err\n  File "/usr/lib/python3.4/socket.py", line 500, in create_connection\n    sock.connect(sa)\nTimeoutError: [Errno 110] Connection timed out\n')
('2015-03-21 10:39:53.716739', 'Traceback (most recent call last):\n  File "/river/fd/fd_worker/fd_channel.py", line 204, in create_channel\n    handle.connect()\n  File "/usr/lib/python3.4/http/client.py", line 1197, in connect\n    self.timeout, self.source_address)\n  File "/usr/lib/python3.4/socket.py", line 509, in create_connection\n    raise err\n  File "/usr/lib/python3.4/socket.py", line 500, in create_connection\n    sock.connect(sa)\nTimeoutError: [Errno 110] Connection timed out\n')
('2015-03-21 10:39:53.717263', 'Traceback (most recent call last):\n  File "/river/fd/fd_worker/fd_channel.py", line 204, in create_channel\n    handle.connect()\n  File "/usr/lib/python3.4/http/client.py", line 1197, in connect\n    self.timeout, self.source_address)\n  File "/usr/lib/python3.4/socket.py", line 509, in create_connection\n    raise err\n  File "/usr/lib/python3.4/socket.py", line 500, in create_connection\n    sock.connect(sa)\nTimeoutError: [Errno 110] Connection timed out\n')
('2015-03-21 10:39:55.252634', 'Traceback (most recent call last):\n  File "/river/fd/fd_worker/fd_channel.py", line 204, in create_channel\n    handle.connect()\n  File "/usr/lib/python3.4/http/client.py", line 1197, in connect\n    self.timeout, self.source_address)\n  File "/usr/lib/python3.4/socket.py", line 509, in create_connection\n    raise err\n  File "/usr/lib/python3.4/socket.py", line 500, in create_connection\n    sock.connect(sa)\nTimeoutError: [Errno 110] Connection timed out\n')
('2015-03-21 10:39:55.253019', 'Traceback (most recent call last):\n  File "/river/fd/fd_worker/fd_channel.py", line 204, in create_channel\n    handle.connect()\n  File "/usr/lib/python3.4/http/client.py", line 1197, in connect\n    self.timeout, self.source_address)\n  File "/usr/lib/python3.4/socket.py", line 509, in create_connection\n    raise err\n  File "/usr/lib/python3.4/socket.py", line 500, in create_connection\n    sock.connect(sa)\nTimeoutError: [Errno 110] Connection timed out\n')
('2015-03-21 10:39:56.788773', 'Traceback (most recent call last):\n  File "/river/fd/fd_worker/fd_channel.py", line 204, in create_channel\n    handle.connect()\n  File "/usr/lib/python3.4/http/client.py", line 1197, in connect\n    self.timeout, self.source_address)\n  File "/usr/lib/python3.4/socket.py", line 509, in create_connection\n    raise err\n  File "/usr/lib/python3.4/socket.py", line 500, in create_connection\n    sock.connect(sa)\nTimeoutError: [Errno 110] Connection timed out\n')
('2015-03-21 10:39:56.789278', 'Traceback (most recent call last):\n  File "/river/fd/fd_worker/fd_channel.py", line 204, in create_channel\n    handle.connect()\n  File "/usr/lib/python3.4/http/client.py", line 1197, in connect\n    self.timeout, self.source_address)\n  File "/usr/lib/python3.4/socket.py", line 509, in create_connection\n    raise err\n  File "/usr/lib/python3.4/socket.py", line 500, in create_connection\n    sock.connect(sa)\nTimeoutError: [Errno 110] Connection timed out\n')
('2015-03-21 10:39:58.324621', 'Traceback (most recent call last):\n  File "/river/fd/fd_worker/fd_channel.py", line 204, in create_channel\n    handle.connect()\n  File "/usr/lib/python3.4/http/client.py", line 1197, in connect\n    self.timeout, self.source_address)\n  File "/usr/lib/python3.4/socket.py", line 509, in create_connection\n    raise err\n  File "/usr/lib/python3.4/socket.py", line 500, in create_connection\n    sock.connect(sa)\nTimeoutError: [Errno 110] Connection timed out\n')
('2015-03-21 10:39:59.732689', 'Traceback (most recent call last):\n  File "/river/fd/fd_worker/fd_channel.py", line 204, in create_channel\n    handle.connect()\n  File "/usr/lib/python3.4/http/client.py", line 1197, in connect\n    self.timeout, self.source_address)\n  File "/usr/lib/python3.4/socket.py", line 509, in create_connection\n    raise err\n  File "/usr/lib/python3.4/socket.py", line 500, in create_connection\n    sock.connect(sa)\nTimeoutError: [Errno 110] Connection timed out\n')
('2015-03-21 10:40:00.893063', 'Traceback (most recent call last):\n  File "/river/fd/fd_worker/fd_channel.py", line 144, in pyget\n    ack  = handle.getresponse()\n  File "/usr/lib/python3.4/http/client.py", line 1147, in getresponse\n    response.begin()\n  File "/usr/lib/python3.4/http/client.py", line 351, in begin\n    version, status, reason = self._read_status()\n  File "/usr/lib/python3.4/http/client.py", line 313, in _read_status\n    line = str(self.fp.readline(_MAXLINE + 1), "iso-8859-1")\n  File "/usr/lib/python3.4/socket.py", line 371, in readinto\n    return self._sock.recv_into(b)\n  File "/usr/lib/python3.4/ssl.py", line 746, in recv_into\n    return self.read(nbytes, buffer)\n  File "/usr/lib/python3.4/ssl.py", line 618, in read\n    v = self._sslobj.read(len, buffer)\nConnectionResetError: [Errno 104] Connection reset by peer\n')
('2015-03-21 10:40:02.427879', 'Traceback (most recent call last):\n  File "/river/fd/fd_worker/fd_channel.py", line 144, in pyget\n    ack  = handle.getresponse()\n  File "/usr/lib/python3.4/http/client.py", line 1147, in getresponse\n    response.begin()\n  File "/usr/lib/python3.4/http/client.py", line 351, in begin\n    version, status, reason = self._read_status()\n  File "/usr/lib/python3.4/http/client.py", line 313, in _read_status\n    line = str(self.fp.readline(_MAXLINE + 1), "iso-8859-1")\n  File "/usr/lib/python3.4/socket.py", line 371, in readinto\n    return self._sock.recv_into(b)\n  File "/usr/lib/python3.4/ssl.py", line 746, in recv_into\n    return self.read(nbytes, buffer)\n  File "/usr/lib/python3.4/ssl.py", line 618, in read\n    v = self._sslobj.read(len, buffer)\nConnectionResetError: [Errno 104] Connection reset by peer\n')
('2015-03-21 10:40:04.475857', 'Traceback (most recent call last):\n  File "/river/fd/fd_worker/fd_channel.py", line 144, in pyget\n    ack  = handle.getresponse()\n  File "/usr/lib/python3.4/http/client.py", line 1147, in getresponse\n    response.begin()\n  File "/usr/lib/python3.4/http/client.py", line 351, in begin\n    version, status, reason = self._read_status()\n  File "/usr/lib/python3.4/http/client.py", line 313, in _read_status\n    line = str(self.fp.readline(_MAXLINE + 1), "iso-8859-1")\n  File "/usr/lib/python3.4/socket.py", line 371, in readinto\n    return self._sock.recv_into(b)\n  File "/usr/lib/python3.4/ssl.py", line 746, in recv_into\n    return self.read(nbytes, buffer)\n  File "/usr/lib/python3.4/ssl.py", line 618, in read\n    v = self._sslobj.read(len, buffer)\nConnectionResetError: [Errno 104] Connection reset by peer\n')
('2015-03-21 10:40:04.477081', 'Traceback (most recent call last):\n  File "/river/fd/fd_worker/fd_channel.py", line 144, in pyget\n    ack  = handle.getresponse()\n  File "/usr/lib/python3.4/http/client.py", line 1147, in getresponse\n    response.begin()\n  File "/usr/lib/python3.4/http/client.py", line 351, in begin\n    version, status, reason = self._read_status()\n  File "/usr/lib/python3.4/http/client.py", line 313, in _read_status\n    line = str(self.fp.readline(_MAXLINE + 1), "iso-8859-1")\n  File "/usr/lib/python3.4/socket.py", line 371, in readinto\n    return self._sock.recv_into(b)\n  File "/usr/lib/python3.4/ssl.py", line 746, in recv_into\n    return self.read(nbytes, buffer)\n  File "/usr/lib/python3.4/ssl.py", line 618, in read\n    v = self._sslobj.read(len, buffer)\nConnectionResetError: [Errno 104] Connection reset by peer\n')
('2015-03-21 10:40:05.499582', 'Traceback (most recent call last):\n  File "/river/fd/fd_worker/fd_channel.py", line 144, in pyget\n    ack  = handle.getresponse()\n  File "/usr/lib/python3.4/http/client.py", line 1147, in getresponse\n    response.begin()\n  File "/usr/lib/python3.4/http/client.py", line 351, in begin\n    version, status, reason = self._read_status()\n  File "/usr/lib/python3.4/http/client.py", line 313, in _read_status\n    line = str(self.fp.readline(_MAXLINE + 1), "iso-8859-1")\n  File "/usr/lib/python3.4/socket.py", line 371, in readinto\n    return self._sock.recv_into(b)\n  File "/usr/lib/python3.4/ssl.py", line 746, in recv_into\n    return self.read(nbytes, buffer)\n  File "/usr/lib/python3.4/ssl.py", line 618, in read\n    v = self._sslobj.read(len, buffer)\nConnectionResetError: [Errno 104] Connection reset by peer\n')
('2015-03-21 10:40:05.500152', 'Traceback (most recent call last):\n  File "/river/fd/fd_worker/fd_channel.py", line 144, in pyget\n    ack  = handle.getresponse()\n  File "/usr/lib/python3.4/http/client.py", line 1147, in getresponse\n    response.begin()\n  File "/usr/lib/python3.4/http/client.py", line 351, in begin\n    version, status, reason = self._read_status()\n  File "/usr/lib/python3.4/http/client.py", line 313, in _read_status\n    line = str(self.fp.readline(_MAXLINE + 1), "iso-8859-1")\n  File "/usr/lib/python3.4/socket.py", line 371, in readinto\n    return self._sock.recv_into(b)\n  File "/usr/lib/python3.4/ssl.py", line 746, in recv_into\n    return self.read(nbytes, buffer)\n  File "/usr/lib/python3.4/ssl.py", line 618, in read\n    v = self._sslobj.read(len, buffer)\nConnectionResetError: [Errno 104] Connection reset by peer\n')
('2015-03-21 10:40:05.748722', 'Traceback (most recent call last):\n  File "/river/fd/fd_worker/fd_channel.py", line 204, in create_channel\n    handle.connect()\n  File "/usr/lib/python3.4/http/client.py", line 1197, in connect\n    self.timeout, self.source_address)\n  File "/usr/lib/python3.4/socket.py", line 509, in create_connection\n    raise err\n  File "/usr/lib/python3.4/socket.py", line 500, in create_connection\n    sock.connect(sa)\nTimeoutError: [Errno 110] Connection timed out\n')
('2015-03-21 10:40:17.787897', 'Traceback (most recent call last):\n  File "/river/fd/fd_worker/fd_channel.py", line 144, in pyget\n    ack  = handle.getresponse()\n  File "/usr/lib/python3.4/http/client.py", line 1147, in getresponse\n    response.begin()\n  File "/usr/lib/python3.4/http/client.py", line 351, in begin\n    version, status, reason = self._read_status()\n  File "/usr/lib/python3.4/http/client.py", line 313, in _read_status\n    line = str(self.fp.readline(_MAXLINE + 1), "iso-8859-1")\n  File "/usr/lib/python3.4/socket.py", line 371, in readinto\n    return self._sock.recv_into(b)\n  File "/usr/lib/python3.4/ssl.py", line 746, in recv_into\n    return self.read(nbytes, buffer)\n  File "/usr/lib/python3.4/ssl.py", line 618, in read\n    v = self._sslobj.read(len, buffer)\nConnectionResetError: [Errno 104] Connection reset by peer\n')
('2015-03-21 10:40:19.836043', 'Traceback (most recent call last):\n  File "/river/fd/fd_worker/fd_channel.py", line 144, in pyget\n    ack  = handle.getresponse()\n  File "/usr/lib/python3.4/http/client.py", line 1147, in getresponse\n    response.begin()\n  File "/usr/lib/python3.4/http/client.py", line 351, in begin\n    version, status, reason = self._read_status()\n  File "/usr/lib/python3.4/http/client.py", line 313, in _read_status\n    line = str(self.fp.readline(_MAXLINE + 1), "iso-8859-1")\n  File "/usr/lib/python3.4/socket.py", line 371, in readinto\n    return self._sock.recv_into(b)\n  File "/usr/lib/python3.4/ssl.py", line 746, in recv_into\n    return self.read(nbytes, buffer)\n  File "/usr/lib/python3.4/ssl.py", line 618, in read\n    v = self._sslobj.read(len, buffer)\nConnectionResetError: [Errno 104] Connection reset by peer\n')
('2015-03-21 10:40:22.260720', 'Traceback (most recent call last):\n  File "/river/fd/fd_worker/fd_channel.py", line 204, in create_channel\n    handle.connect()\n  File "/usr/lib/python3.4/http/client.py", line 1197, in connect\n    self.timeout, self.source_address)\n  File "/usr/lib/python3.4/socket.py", line 509, in create_connection\n    raise err\n  File "/usr/lib/python3.4/socket.py", line 500, in create_connection\n    sock.connect(sa)\nTimeoutError: [Errno 110] Connection timed out\n')
('2015-03-21 10:40:26.740592', 'Traceback (most recent call last):\n  File "/river/fd/fd_worker/fd_channel.py", line 204, in create_channel\n    handle.connect()\n  File "/usr/lib/python3.4/http/client.py", line 1197, in connect\n    self.timeout, self.source_address)\n  File "/usr/lib/python3.4/socket.py", line 509, in create_connection\n    raise err\n  File "/usr/lib/python3.4/socket.py", line 500, in create_connection\n    sock.connect(sa)\nTimeoutError: [Errno 110] Connection timed out\n')
('2015-03-21 10:40:29.812610', 'Traceback (most recent call last):\n  File "/river/fd/fd_worker/fd_channel.py", line 204, in create_channel\n    handle.connect()\n  File "/usr/lib/python3.4/http/client.py", line 1197, in connect\n    self.timeout, self.source_address)\n  File "/usr/lib/python3.4/socket.py", line 509, in create_connection\n    raise err\n  File "/usr/lib/python3.4/socket.py", line 500, in create_connection\n    sock.connect(sa)\nTimeoutError: [Errno 110] Connection timed out\n')
('2015-03-21 10:40:31.220523', 'Traceback (most recent call last):\n  File "/river/fd/fd_worker/fd_channel.py", line 204, in create_channel\n    handle.connect()\n  File "/usr/lib/python3.4/http/client.py", line 1197, in connect\n    self.timeout, self.source_address)\n  File "/usr/lib/python3.4/socket.py", line 509, in create_connection\n    raise err\n  File "/usr/lib/python3.4/socket.py", line 500, in create_connection\n    sock.connect(sa)\nTimeoutError: [Errno 110] Connection timed out\n')
('2015-03-21 10:40:38.772525', 'Traceback (most recent call last):\n  File "/river/fd/fd_worker/fd_channel.py", line 204, in create_channel\n    handle.connect()\n  File "/usr/lib/python3.4/http/client.py", line 1197, in connect\n    self.timeout, self.source_address)\n  File "/usr/lib/python3.4/socket.py", line 509, in create_connection\n    raise err\n  File "/usr/lib/python3.4/socket.py", line 500, in create_connection\n    sock.connect(sa)\nTimeoutError: [Errno 110] Connection timed out\n')
('2015-03-21 10:40:40.308686', 'Traceback (most recent call last):\n  File "/river/fd/fd_worker/fd_channel.py", line 204, in create_channel\n    handle.connect()\n  File "/usr/lib/python3.4/http/client.py", line 1197, in connect\n    self.timeout, self.source_address)\n  File "/usr/lib/python3.4/socket.py", line 509, in create_connection\n    raise err\n  File "/usr/lib/python3.4/socket.py", line 500, in create_connection\n    sock.connect(sa)\nTimeoutError: [Errno 110] Connection timed out\n')
('2015-03-21 10:40:41.716577', 'Traceback (most recent call last):\n  File "/river/fd/fd_worker/fd_channel.py", line 204, in create_channel\n    handle.connect()\n  File "/usr/lib/python3.4/http/client.py", line 1197, in connect\n    self.timeout, self.source_address)\n  File "/usr/lib/python3.4/socket.py", line 509, in create_connection\n    raise err\n  File "/usr/lib/python3.4/socket.py", line 500, in create_connection\n    sock.connect(sa)\nTimeoutError: [Errno 110] Connection timed out\n')
('2015-03-21 10:40:58.748449', 'Traceback (most recent call last):\n  File "/river/fd/fd_worker/fd_channel.py", line 144, in pyget\n    ack  = handle.getresponse()\n  File "/usr/lib/python3.4/http/client.py", line 1147, in getresponse\n    response.begin()\n  File "/usr/lib/python3.4/http/client.py", line 351, in begin\n    version, status, reason = self._read_status()\n  File "/usr/lib/python3.4/http/client.py", line 313, in _read_status\n    line = str(self.fp.readline(_MAXLINE + 1), "iso-8859-1")\n  File "/usr/lib/python3.4/socket.py", line 371, in readinto\n    return self._sock.recv_into(b)\n  File "/usr/lib/python3.4/ssl.py", line 746, in recv_into\n    return self.read(nbytes, buffer)\n  File "/usr/lib/python3.4/ssl.py", line 618, in read\n    v = self._sslobj.read(len, buffer)\nConnectionResetError: [Errno 104] Connection reset by peer\n')
('2015-03-21 10:41:31.004344', 'Traceback (most recent call last):\n  File "/river/fd/fd_worker/fd_channel.py", line 144, in pyget\n    ack  = handle.getresponse()\n  File "/usr/lib/python3.4/http/client.py", line 1147, in getresponse\n    response.begin()\n  File "/usr/lib/python3.4/http/client.py", line 351, in begin\n    version, status, reason = self._read_status()\n  File "/usr/lib/python3.4/http/client.py", line 313, in _read_status\n    line = str(self.fp.readline(_MAXLINE + 1), "iso-8859-1")\n  File "/usr/lib/python3.4/socket.py", line 371, in readinto\n    return self._sock.recv_into(b)\n  File "/usr/lib/python3.4/ssl.py", line 746, in recv_into\n    return self.read(nbytes, buffer)\n  File "/usr/lib/python3.4/ssl.py", line 618, in read\n    v = self._sslobj.read(len, buffer)\nConnectionResetError: [Errno 104] Connection reset by peer\n')
('2015-03-21 10:41:32.539598', 'Traceback (most recent call last):\n  File "/river/fd/fd_worker/fd_channel.py", line 144, in pyget\n    ack  = handle.getresponse()\n  File "/usr/lib/python3.4/http/client.py", line 1147, in getresponse\n    response.begin()\n  File "/usr/lib/python3.4/http/client.py", line 351, in begin\n    version, status, reason = self._read_status()\n  File "/usr/lib/python3.4/http/client.py", line 313, in _read_status\n    line = str(self.fp.readline(_MAXLINE + 1), "iso-8859-1")\n  File "/usr/lib/python3.4/socket.py", line 371, in readinto\n    return self._sock.recv_into(b)\n  File "/usr/lib/python3.4/ssl.py", line 746, in recv_into\n    return self.read(nbytes, buffer)\n  File "/usr/lib/python3.4/ssl.py", line 618, in read\n    v = self._sslobj.read(len, buffer)\nConnectionResetError: [Errno 104] Connection reset by peer\n')
('2015-03-21 10:41:36.123924', 'Traceback (most recent call last):\n  File "/river/fd/fd_worker/fd_channel.py", line 144, in pyget\n    ack  = handle.getresponse()\n  File "/usr/lib/python3.4/http/client.py", line 1147, in getresponse\n    response.begin()\n  File "/usr/lib/python3.4/http/client.py", line 351, in begin\n    version, status, reason = self._read_status()\n  File "/usr/lib/python3.4/http/client.py", line 313, in _read_status\n    line = str(self.fp.readline(_MAXLINE + 1), "iso-8859-1")\n  File "/usr/lib/python3.4/socket.py", line 371, in readinto\n    return self._sock.recv_into(b)\n  File "/usr/lib/python3.4/ssl.py", line 746, in recv_into\n    return self.read(nbytes, buffer)\n  File "/usr/lib/python3.4/ssl.py", line 618, in read\n    v = self._sslobj.read(len, buffer)\nConnectionResetError: [Errno 104] Connection reset by peer\n')
('2015-03-21 10:41:36.124559', 'Traceback (most recent call last):\n  File "/river/fd/fd_worker/fd_channel.py", line 144, in pyget\n    ack  = handle.getresponse()\n  File "/usr/lib/python3.4/http/client.py", line 1147, in getresponse\n    response.begin()\n  File "/usr/lib/python3.4/http/client.py", line 351, in begin\n    version, status, reason = self._read_status()\n  File "/usr/lib/python3.4/http/client.py", line 313, in _read_status\n    line = str(self.fp.readline(_MAXLINE + 1), "iso-8859-1")\n  File "/usr/lib/python3.4/socket.py", line 371, in readinto\n    return self._sock.recv_into(b)\n  File "/usr/lib/python3.4/ssl.py", line 746, in recv_into\n    return self.read(nbytes, buffer)\n  File "/usr/lib/python3.4/ssl.py", line 618, in read\n    v = self._sslobj.read(len, buffer)\nConnectionResetError: [Errno 104] Connection reset by peer\n')
('2015-03-21 10:41:36.125263', 'Traceback (most recent call last):\n  File "/river/fd/fd_worker/fd_channel.py", line 144, in pyget\n    ack  = handle.getresponse()\n  File "/usr/lib/python3.4/http/client.py", line 1147, in getresponse\n    response.begin()\n  File "/usr/lib/python3.4/http/client.py", line 351, in begin\n    version, status, reason = self._read_status()\n  File "/usr/lib/python3.4/http/client.py", line 313, in _read_status\n    line = str(self.fp.readline(_MAXLINE + 1), "iso-8859-1")\n  File "/usr/lib/python3.4/socket.py", line 371, in readinto\n    return self._sock.recv_into(b)\n  File "/usr/lib/python3.4/ssl.py", line 746, in recv_into\n    return self.read(nbytes, buffer)\n  File "/usr/lib/python3.4/ssl.py", line 618, in read\n    v = self._sslobj.read(len, buffer)\nConnectionResetError: [Errno 104] Connection reset by peer\n')
('2015-03-21 11:29:24.656311', 'Traceback (most recent call last):\n  File "/river/fd/fd_worker/fd_channel.py", line 204, in create_channel\n    handle.connect()\n  File "/usr/lib/python3.4/http/client.py", line 1205, in connect\n    server_hostname=server_hostname)\n  File "/usr/lib/python3.4/ssl.py", line 364, in wrap_socket\n    _context=self)\n  File "/usr/lib/python3.4/ssl.py", line 578, in __init__\n    self.do_handshake()\n  File "/usr/lib/python3.4/ssl.py", line 805, in do_handshake\n    self._sslobj.do_handshake()\nConnectionResetError: [Errno 104] Connection reset by peer\n')
('2015-03-21 11:29:27.140367', 'Traceback (most recent call last):\n  File "/river/fd/fd_worker/fd_channel.py", line 204, in create_channel\n    handle.connect()\n  File "/usr/lib/python3.4/http/client.py", line 1205, in connect\n    server_hostname=server_hostname)\n  File "/usr/lib/python3.4/ssl.py", line 364, in wrap_socket\n    _context=self)\n  File "/usr/lib/python3.4/ssl.py", line 578, in __init__\n    self.do_handshake()\n  File "/usr/lib/python3.4/ssl.py", line 805, in do_handshake\n    self._sslobj.do_handshake()\nConnectionResetError: [Errno 104] Connection reset by peer\n')
('2015-03-21 11:29:28.636398', 'Traceback (most recent call last):\n  File "/river/fd/fd_worker/fd_channel.py", line 204, in create_channel\n    handle.connect()\n  File "/usr/lib/python3.4/http/client.py", line 1205, in connect\n    server_hostname=server_hostname)\n  File "/usr/lib/python3.4/ssl.py", line 364, in wrap_socket\n    _context=self)\n  File "/usr/lib/python3.4/ssl.py", line 578, in __init__\n    self.do_handshake()\n  File "/usr/lib/python3.4/ssl.py", line 805, in do_handshake\n    self._sslobj.do_handshake()\nConnectionResetError: [Errno 104] Connection reset by peer\n')
('2015-03-21 11:29:30.256339', 'Traceback (most recent call last):\n  File "/river/fd/fd_worker/fd_channel.py", line 204, in create_channel\n    handle.connect()\n  File "/usr/lib/python3.4/http/client.py", line 1205, in connect\n    server_hostname=server_hostname)\n  File "/usr/lib/python3.4/ssl.py", line 364, in wrap_socket\n    _context=self)\n  File "/usr/lib/python3.4/ssl.py", line 578, in __init__\n    self.do_handshake()\n  File "/usr/lib/python3.4/ssl.py", line 805, in do_handshake\n    self._sslobj.do_handshake()\nConnectionResetError: [Errno 104] Connection reset by peer\n')
('2015-03-21 11:29:30.676670', 'Traceback (most recent call last):\n  File "/river/fd/fd_worker/fd_channel.py", line 204, in create_channel\n    handle.connect()\n  File "/usr/lib/python3.4/http/client.py", line 1205, in connect\n    server_hostname=server_hostname)\n  File "/usr/lib/python3.4/ssl.py", line 364, in wrap_socket\n    _context=self)\n  File "/usr/lib/python3.4/ssl.py", line 578, in __init__\n    self.do_handshake()\n  File "/usr/lib/python3.4/ssl.py", line 805, in do_handshake\n    self._sslobj.do_handshake()\nConnectionResetError: [Errno 104] Connection reset by peer\n')
('2015-03-21 11:29:33.348178', 'Traceback (most recent call last):\n  File "/river/fd/fd_worker/fd_channel.py", line 204, in create_channel\n    handle.connect()\n  File "/usr/lib/python3.4/http/client.py", line 1205, in connect\n    server_hostname=server_hostname)\n  File "/usr/lib/python3.4/ssl.py", line 364, in wrap_socket\n    _context=self)\n  File "/usr/lib/python3.4/ssl.py", line 578, in __init__\n    self.do_handshake()\n  File "/usr/lib/python3.4/ssl.py", line 805, in do_handshake\n    self._sslobj.do_handshake()\nConnectionResetError: [Errno 104] Connection reset by peer\n')
('2015-03-21 11:29:33.848593', 'Traceback (most recent call last):\n  File "/river/fd/fd_worker/fd_channel.py", line 204, in create_channel\n    handle.connect()\n  File "/usr/lib/python3.4/http/client.py", line 1205, in connect\n    server_hostname=server_hostname)\n  File "/usr/lib/python3.4/ssl.py", line 364, in wrap_socket\n    _context=self)\n  File "/usr/lib/python3.4/ssl.py", line 578, in __init__\n    self.do_handshake()\n  File "/usr/lib/python3.4/ssl.py", line 805, in do_handshake\n    self._sslobj.do_handshake()\nConnectionResetError: [Errno 104] Connection reset by peer\n')
('2015-03-21 11:29:36.848412', 'Traceback (most recent call last):\n  File "/river/fd/fd_worker/fd_channel.py", line 204, in create_channel\n    handle.connect()\n  File "/usr/lib/python3.4/http/client.py", line 1205, in connect\n    server_hostname=server_hostname)\n  File "/usr/lib/python3.4/ssl.py", line 364, in wrap_socket\n    _context=self)\n  File "/usr/lib/python3.4/ssl.py", line 578, in __init__\n    self.do_handshake()\n  File "/usr/lib/python3.4/ssl.py", line 805, in do_handshake\n    self._sslobj.do_handshake()\nConnectionResetError: [Errno 104] Connection reset by peer\n')
('2015-03-21 11:29:37.356190', 'Traceback (most recent call last):\n  File "/river/fd/fd_worker/fd_channel.py", line 204, in create_channel\n    handle.connect()\n  File "/usr/lib/python3.4/http/client.py", line 1205, in connect\n    server_hostname=server_hostname)\n  File "/usr/lib/python3.4/ssl.py", line 364, in wrap_socket\n    _context=self)\n  File "/usr/lib/python3.4/ssl.py", line 578, in __init__\n    self.do_handshake()\n  File "/usr/lib/python3.4/ssl.py", line 805, in do_handshake\n    self._sslobj.do_handshake()\nConnectionResetError: [Errno 104] Connection reset by peer\n')
('2015-03-21 11:29:41.780756', 'Traceback (most recent call last):\n  File "/river/fd/fd_worker/fd_channel.py", line 204, in create_channel\n    handle.connect()\n  File "/usr/lib/python3.4/http/client.py", line 1205, in connect\n    server_hostname=server_hostname)\n  File "/usr/lib/python3.4/ssl.py", line 364, in wrap_socket\n    _context=self)\n  File "/usr/lib/python3.4/ssl.py", line 578, in __init__\n    self.do_handshake()\n  File "/usr/lib/python3.4/ssl.py", line 805, in do_handshake\n    self._sslobj.do_handshake()\nConnectionResetError: [Errno 104] Connection reset by peer\n')
('2015-03-21 11:29:45.850068', 'Traceback (most recent call last):\n  File "/river/fd/fd_worker/fd_channel.py", line 204, in create_channel\n    handle.connect()\n  File "/usr/lib/python3.4/http/client.py", line 1205, in connect\n    server_hostname=server_hostname)\n  File "/usr/lib/python3.4/ssl.py", line 364, in wrap_socket\n    _context=self)\n  File "/usr/lib/python3.4/ssl.py", line 578, in __init__\n    self.do_handshake()\n  File "/usr/lib/python3.4/ssl.py", line 805, in do_handshake\n    self._sslobj.do_handshake()\nConnectionResetError: [Errno 104] Connection reset by peer\n')
('2015-03-21 11:29:47.148924', 'Traceback (most recent call last):\n  File "/river/fd/fd_worker/fd_channel.py", line 204, in create_channel\n    handle.connect()\n  File "/usr/lib/python3.4/http/client.py", line 1205, in connect\n    server_hostname=server_hostname)\n  File "/usr/lib/python3.4/ssl.py", line 364, in wrap_socket\n    _context=self)\n  File "/usr/lib/python3.4/ssl.py", line 578, in __init__\n    self.do_handshake()\n  File "/usr/lib/python3.4/ssl.py", line 805, in do_handshake\n    self._sslobj.do_handshake()\nConnectionResetError: [Errno 104] Connection reset by peer\n')
('2015-03-21 11:29:53.348720', 'Traceback (most recent call last):\n  File "/river/fd/fd_worker/fd_channel.py", line 204, in create_channel\n    handle.connect()\n  File "/usr/lib/python3.4/http/client.py", line 1205, in connect\n    server_hostname=server_hostname)\n  File "/usr/lib/python3.4/ssl.py", line 364, in wrap_socket\n    _context=self)\n  File "/usr/lib/python3.4/ssl.py", line 578, in __init__\n    self.do_handshake()\n  File "/usr/lib/python3.4/ssl.py", line 805, in do_handshake\n    self._sslobj.do_handshake()\nConnectionResetError: [Errno 104] Connection reset by peer\n')
('2015-03-21 11:29:54.640148', 'Traceback (most recent call last):\n  File "/river/fd/fd_worker/fd_channel.py", line 204, in create_channel\n    handle.connect()\n  File "/usr/lib/python3.4/http/client.py", line 1205, in connect\n    server_hostname=server_hostname)\n  File "/usr/lib/python3.4/ssl.py", line 364, in wrap_socket\n    _context=self)\n  File "/usr/lib/python3.4/ssl.py", line 578, in __init__\n    self.do_handshake()\n  File "/usr/lib/python3.4/ssl.py", line 805, in do_handshake\n    self._sslobj.do_handshake()\nConnectionResetError: [Errno 104] Connection reset by peer\n')
('2015-03-21 11:30:00.850553', 'Traceback (most recent call last):\n  File "/river/fd/fd_worker/fd_channel.py", line 204, in create_channel\n    handle.connect()\n  File "/usr/lib/python3.4/http/client.py", line 1205, in connect\n    server_hostname=server_hostname)\n  File "/usr/lib/python3.4/ssl.py", line 364, in wrap_socket\n    _context=self)\n  File "/usr/lib/python3.4/ssl.py", line 578, in __init__\n    self.do_handshake()\n  File "/usr/lib/python3.4/ssl.py", line 805, in do_handshake\n    self._sslobj.do_handshake()\nConnectionResetError: [Errno 104] Connection reset by peer\n')
('2015-03-21 11:30:10.292643', 'Traceback (most recent call last):\n  File "/river/fd/fd_worker/fd_channel.py", line 204, in create_channel\n    handle.connect()\n  File "/usr/lib/python3.4/http/client.py", line 1197, in connect\n    self.timeout, self.source_address)\n  File "/usr/lib/python3.4/socket.py", line 509, in create_connection\n    raise err\n  File "/usr/lib/python3.4/socket.py", line 500, in create_connection\n    sock.connect(sa)\nTimeoutError: [Errno 110] Connection timed out\n')
('2015-03-21 11:30:16.541689', 'Traceback (most recent call last):\n  File "/river/fd/fd_worker/fd_channel.py", line 204, in create_channel\n    handle.connect()\n  File "/usr/lib/python3.4/http/client.py", line 1205, in connect\n    server_hostname=server_hostname)\n  File "/usr/lib/python3.4/ssl.py", line 364, in wrap_socket\n    _context=self)\n  File "/usr/lib/python3.4/ssl.py", line 578, in __init__\n    self.do_handshake()\n  File "/usr/lib/python3.4/ssl.py", line 805, in do_handshake\n    self._sslobj.do_handshake()\nConnectionResetError: [Errno 104] Connection reset by peer\n')
('2015-03-21 11:30:17.086488', 'Traceback (most recent call last):\n  File "/river/fd/fd_worker/fd_channel.py", line 204, in create_channel\n    handle.connect()\n  File "/usr/lib/python3.4/http/client.py", line 1205, in connect\n    server_hostname=server_hostname)\n  File "/usr/lib/python3.4/ssl.py", line 364, in wrap_socket\n    _context=self)\n  File "/usr/lib/python3.4/ssl.py", line 578, in __init__\n    self.do_handshake()\n  File "/usr/lib/python3.4/ssl.py", line 805, in do_handshake\n    self._sslobj.do_handshake()\nConnectionResetError: [Errno 104] Connection reset by peer\n')
('2015-03-21 11:30:21.501729', 'Traceback (most recent call last):\n  File "/river/fd/fd_worker/fd_channel.py", line 204, in create_channel\n    handle.connect()\n  File "/usr/lib/python3.4/http/client.py", line 1205, in connect\n    server_hostname=server_hostname)\n  File "/usr/lib/python3.4/ssl.py", line 364, in wrap_socket\n    _context=self)\n  File "/usr/lib/python3.4/ssl.py", line 578, in __init__\n    self.do_handshake()\n  File "/usr/lib/python3.4/ssl.py", line 805, in do_handshake\n    self._sslobj.do_handshake()\nConnectionResetError: [Errno 104] Connection reset by peer\n')
('2015-03-21 11:30:35.764635', 'Traceback (most recent call last):\n  File "/river/fd/fd_worker/fd_channel.py", line 204, in create_channel\n    handle.connect()\n  File "/usr/lib/python3.4/http/client.py", line 1197, in connect\n    self.timeout, self.source_address)\n  File "/usr/lib/python3.4/socket.py", line 509, in create_connection\n    raise err\n  File "/usr/lib/python3.4/socket.py", line 500, in create_connection\n    sock.connect(sa)\nTimeoutError: [Errno 110] Connection timed out\n')
('2015-03-21 11:30:38.836637', 'Traceback (most recent call last):\n  File "/river/fd/fd_worker/fd_channel.py", line 204, in create_channel\n    handle.connect()\n  File "/usr/lib/python3.4/http/client.py", line 1197, in connect\n    self.timeout, self.source_address)\n  File "/usr/lib/python3.4/socket.py", line 509, in create_connection\n    raise err\n  File "/usr/lib/python3.4/socket.py", line 500, in create_connection\n    sock.connect(sa)\nTimeoutError: [Errno 110] Connection timed out\n')
('2015-03-21 11:30:51.196021', 'Traceback (most recent call last):\n  File "/river/fd/fd_worker/fd_channel.py", line 204, in create_channel\n    handle.connect()\n  File "/usr/lib/python3.4/http/client.py", line 1205, in connect\n    server_hostname=server_hostname)\n  File "/usr/lib/python3.4/ssl.py", line 364, in wrap_socket\n    _context=self)\n  File "/usr/lib/python3.4/ssl.py", line 578, in __init__\n    self.do_handshake()\n  File "/usr/lib/python3.4/ssl.py", line 805, in do_handshake\n    self._sslobj.do_handshake()\nConnectionResetError: [Errno 104] Connection reset by peer\n')
('2015-03-21 11:30:51.197074', 'Traceback (most recent call last):\n  File "/river/fd/fd_worker/fd_channel.py", line 204, in create_channel\n    handle.connect()\n  File "/usr/lib/python3.4/http/client.py", line 1205, in connect\n    server_hostname=server_hostname)\n  File "/usr/lib/python3.4/ssl.py", line 364, in wrap_socket\n    _context=self)\n  File "/usr/lib/python3.4/ssl.py", line 578, in __init__\n    self.do_handshake()\n  File "/usr/lib/python3.4/ssl.py", line 805, in do_handshake\n    self._sslobj.do_handshake()\nConnectionResetError: [Errno 104] Connection reset by peer\n')
