('2015-03-21 10:33:27.388504', 'Traceback (most recent call last):\n  File "/river/fd/fd_worker/fd_channel.py", line 204, in create_channel\n    handle.connect()\n  File "/usr/lib/python3.4/http/client.py", line 1205, in connect\n    server_hostname=server_hostname)\n  File "/usr/lib/python3.4/ssl.py", line 364, in wrap_socket\n    _context=self)\n  File "/usr/lib/python3.4/ssl.py", line 578, in __init__\n    self.do_handshake()\n  File "/usr/lib/python3.4/ssl.py", line 805, in do_handshake\n    self._sslobj.do_handshake()\nConnectionResetError: [Errno 104] Connection reset by peer\n')
('2015-03-21 10:33:27.683046', 'Traceback (most recent call last):\n  File "/river/fd/fd_worker/fd_channel.py", line 204, in create_channel\n    handle.connect()\n  File "/usr/lib/python3.4/http/client.py", line 1205, in connect\n    server_hostname=server_hostname)\n  File "/usr/lib/python3.4/ssl.py", line 364, in wrap_socket\n    _context=self)\n  File "/usr/lib/python3.4/ssl.py", line 578, in __init__\n    self.do_handshake()\n  File "/usr/lib/python3.4/ssl.py", line 805, in do_handshake\n    self._sslobj.do_handshake()\nConnectionResetError: [Errno 104] Connection reset by peer\n')
('2015-03-21 10:33:28.522962', 'Traceback (most recent call last):\n  File "/river/fd/fd_worker/fd_channel.py", line 204, in create_channel\n    handle.connect()\n  File "/usr/lib/python3.4/http/client.py", line 1205, in connect\n    server_hostname=server_hostname)\n  File "/usr/lib/python3.4/ssl.py", line 364, in wrap_socket\n    _context=self)\n  File "/usr/lib/python3.4/ssl.py", line 578, in __init__\n    self.do_handshake()\n  File "/usr/lib/python3.4/ssl.py", line 805, in do_handshake\n    self._sslobj.do_handshake()\nConnectionResetError: [Errno 104] Connection reset by peer\n')
('2015-03-21 10:33:28.530420', 'Traceback (most recent call last):\n  File "/river/fd/fd_worker/fd_channel.py", line 204, in create_channel\n    handle.connect()\n  File "/usr/lib/python3.4/http/client.py", line 1205, in connect\n    server_hostname=server_hostname)\n  File "/usr/lib/python3.4/ssl.py", line 364, in wrap_socket\n    _context=self)\n  File "/usr/lib/python3.4/ssl.py", line 578, in __init__\n    self.do_handshake()\n  File "/usr/lib/python3.4/ssl.py", line 805, in do_handshake\n    self._sslobj.do_handshake()\nConnectionResetError: [Errno 104] Connection reset by peer\n')
('2015-03-21 10:33:31.347386', 'Traceback (most recent call last):\n  File "/river/fd/fd_worker/fd_channel.py", line 204, in create_channel\n    handle.connect()\n  File "/usr/lib/python3.4/http/client.py", line 1205, in connect\n    server_hostname=server_hostname)\n  File "/usr/lib/python3.4/ssl.py", line 364, in wrap_socket\n    _context=self)\n  File "/usr/lib/python3.4/ssl.py", line 578, in __init__\n    self.do_handshake()\n  File "/usr/lib/python3.4/ssl.py", line 805, in do_handshake\n    self._sslobj.do_handshake()\nConnectionResetError: [Errno 104] Connection reset by peer\n')
('2015-03-21 10:33:32.851239', 'Traceback (most recent call last):\n  File "/river/fd/fd_worker/fd_channel.py", line 204, in create_channel\n    handle.connect()\n  File "/usr/lib/python3.4/http/client.py", line 1205, in connect\n    server_hostname=server_hostname)\n  File "/usr/lib/python3.4/ssl.py", line 364, in wrap_socket\n    _context=self)\n  File "/usr/lib/python3.4/ssl.py", line 578, in __init__\n    self.do_handshake()\n  File "/usr/lib/python3.4/ssl.py", line 805, in do_handshake\n    self._sslobj.do_handshake()\nConnectionResetError: [Errno 104] Connection reset by peer\n')
('2015-03-21 10:34:40.847335', 'Traceback (most recent call last):\n  File "/river/fd/fd_worker/fd_channel.py", line 204, in create_channel\n    handle.connect()\n  File "/usr/lib/python3.4/http/client.py", line 1205, in connect\n    server_hostname=server_hostname)\n  File "/usr/lib/python3.4/ssl.py", line 364, in wrap_socket\n    _context=self)\n  File "/usr/lib/python3.4/ssl.py", line 578, in __init__\n    self.do_handshake()\n  File "/usr/lib/python3.4/ssl.py", line 805, in do_handshake\n    self._sslobj.do_handshake()\nConnectionResetError: [Errno 104] Connection reset by peer\n')
('2015-03-21 10:34:41.539248', 'Traceback (most recent call last):\n  File "/river/fd/fd_worker/fd_channel.py", line 204, in create_channel\n    handle.connect()\n  File "/usr/lib/python3.4/http/client.py", line 1205, in connect\n    server_hostname=server_hostname)\n  File "/usr/lib/python3.4/ssl.py", line 364, in wrap_socket\n    _context=self)\n  File "/usr/lib/python3.4/ssl.py", line 578, in __init__\n    self.do_handshake()\n  File "/usr/lib/python3.4/ssl.py", line 805, in do_handshake\n    self._sslobj.do_handshake()\nConnectionResetError: [Errno 104] Connection reset by peer\n')
('2015-03-21 10:34:41.554618', 'Traceback (most recent call last):\n  File "/river/fd/fd_worker/fd_channel.py", line 204, in create_channel\n    handle.connect()\n  File "/usr/lib/python3.4/http/client.py", line 1205, in connect\n    server_hostname=server_hostname)\n  File "/usr/lib/python3.4/ssl.py", line 364, in wrap_socket\n    _context=self)\n  File "/usr/lib/python3.4/ssl.py", line 578, in __init__\n    self.do_handshake()\n  File "/usr/lib/python3.4/ssl.py", line 805, in do_handshake\n    self._sslobj.do_handshake()\nConnectionResetError: [Errno 104] Connection reset by peer\n')
('2015-03-21 10:34:42.018882', 'Traceback (most recent call last):\n  File "/river/fd/fd_worker/fd_channel.py", line 204, in create_channel\n    handle.connect()\n  File "/usr/lib/python3.4/http/client.py", line 1205, in connect\n    server_hostname=server_hostname)\n  File "/usr/lib/python3.4/ssl.py", line 364, in wrap_socket\n    _context=self)\n  File "/usr/lib/python3.4/ssl.py", line 578, in __init__\n    self.do_handshake()\n  File "/usr/lib/python3.4/ssl.py", line 805, in do_handshake\n    self._sslobj.do_handshake()\nConnectionResetError: [Errno 104] Connection reset by peer\n')
('2015-03-21 10:34:43.018925', 'Traceback (most recent call last):\n  File "/river/fd/fd_worker/fd_channel.py", line 204, in create_channel\n    handle.connect()\n  File "/usr/lib/python3.4/http/client.py", line 1205, in connect\n    server_hostname=server_hostname)\n  File "/usr/lib/python3.4/ssl.py", line 364, in wrap_socket\n    _context=self)\n  File "/usr/lib/python3.4/ssl.py", line 578, in __init__\n    self.do_handshake()\n  File "/usr/lib/python3.4/ssl.py", line 805, in do_handshake\n    self._sslobj.do_handshake()\nConnectionResetError: [Errno 104] Connection reset by peer\n')
('2015-03-21 10:34:43.026656', 'Traceback (most recent call last):\n  File "/river/fd/fd_worker/fd_channel.py", line 204, in create_channel\n    handle.connect()\n  File "/usr/lib/python3.4/http/client.py", line 1205, in connect\n    server_hostname=server_hostname)\n  File "/usr/lib/python3.4/ssl.py", line 364, in wrap_socket\n    _context=self)\n  File "/usr/lib/python3.4/ssl.py", line 578, in __init__\n    self.do_handshake()\n  File "/usr/lib/python3.4/ssl.py", line 805, in do_handshake\n    self._sslobj.do_handshake()\nConnectionResetError: [Errno 104] Connection reset by peer\n')
('2015-03-21 10:34:43.058935', 'Traceback (most recent call last):\n  File "/river/fd/fd_worker/fd_channel.py", line 204, in create_channel\n    handle.connect()\n  File "/usr/lib/python3.4/http/client.py", line 1205, in connect\n    server_hostname=server_hostname)\n  File "/usr/lib/python3.4/ssl.py", line 364, in wrap_socket\n    _context=self)\n  File "/usr/lib/python3.4/ssl.py", line 578, in __init__\n    self.do_handshake()\n  File "/usr/lib/python3.4/ssl.py", line 805, in do_handshake\n    self._sslobj.do_handshake()\nConnectionResetError: [Errno 104] Connection reset by peer\n')
('2015-03-21 10:34:43.187084', 'Traceback (most recent call last):\n  File "/river/fd/fd_worker/fd_channel.py", line 204, in create_channel\n    handle.connect()\n  File "/usr/lib/python3.4/http/client.py", line 1205, in connect\n    server_hostname=server_hostname)\n  File "/usr/lib/python3.4/ssl.py", line 364, in wrap_socket\n    _context=self)\n  File "/usr/lib/python3.4/ssl.py", line 578, in __init__\n    self.do_handshake()\n  File "/usr/lib/python3.4/ssl.py", line 805, in do_handshake\n    self._sslobj.do_handshake()\nConnectionResetError: [Errno 104] Connection reset by peer\n')
('2015-03-21 10:34:44.851619', 'Traceback (most recent call last):\n  File "/river/fd/fd_worker/fd_channel.py", line 204, in create_channel\n    handle.connect()\n  File "/usr/lib/python3.4/http/client.py", line 1205, in connect\n    server_hostname=server_hostname)\n  File "/usr/lib/python3.4/ssl.py", line 364, in wrap_socket\n    _context=self)\n  File "/usr/lib/python3.4/ssl.py", line 578, in __init__\n    self.do_handshake()\n  File "/usr/lib/python3.4/ssl.py", line 805, in do_handshake\n    self._sslobj.do_handshake()\nConnectionResetError: [Errno 104] Connection reset by peer\n')
('2015-03-21 10:34:46.066531', 'Traceback (most recent call last):\n  File "/river/fd/fd_worker/fd_channel.py", line 204, in create_channel\n    handle.connect()\n  File "/usr/lib/python3.4/http/client.py", line 1205, in connect\n    server_hostname=server_hostname)\n  File "/usr/lib/python3.4/ssl.py", line 364, in wrap_socket\n    _context=self)\n  File "/usr/lib/python3.4/ssl.py", line 578, in __init__\n    self.do_handshake()\n  File "/usr/lib/python3.4/ssl.py", line 805, in do_handshake\n    self._sslobj.do_handshake()\nConnectionResetError: [Errno 104] Connection reset by peer\n')
('2015-03-21 10:34:46.195161', 'Traceback (most recent call last):\n  File "/river/fd/fd_worker/fd_channel.py", line 204, in create_channel\n    handle.connect()\n  File "/usr/lib/python3.4/http/client.py", line 1205, in connect\n    server_hostname=server_hostname)\n  File "/usr/lib/python3.4/ssl.py", line 364, in wrap_socket\n    _context=self)\n  File "/usr/lib/python3.4/ssl.py", line 578, in __init__\n    self.do_handshake()\n  File "/usr/lib/python3.4/ssl.py", line 805, in do_handshake\n    self._sslobj.do_handshake()\nConnectionResetError: [Errno 104] Connection reset by peer\n')
('2015-03-21 10:34:47.698995', 'Traceback (most recent call last):\n  File "/river/fd/fd_worker/fd_channel.py", line 204, in create_channel\n    handle.connect()\n  File "/usr/lib/python3.4/http/client.py", line 1205, in connect\n    server_hostname=server_hostname)\n  File "/usr/lib/python3.4/ssl.py", line 364, in wrap_socket\n    _context=self)\n  File "/usr/lib/python3.4/ssl.py", line 578, in __init__\n    self.do_handshake()\n  File "/usr/lib/python3.4/ssl.py", line 805, in do_handshake\n    self._sslobj.do_handshake()\nConnectionResetError: [Errno 104] Connection reset by peer\n')
('2015-03-21 10:34:48.051349', 'Traceback (most recent call last):\n  File "/river/fd/fd_worker/fd_channel.py", line 204, in create_channel\n    handle.connect()\n  File "/usr/lib/python3.4/http/client.py", line 1205, in connect\n    server_hostname=server_hostname)\n  File "/usr/lib/python3.4/ssl.py", line 364, in wrap_socket\n    _context=self)\n  File "/usr/lib/python3.4/ssl.py", line 578, in __init__\n    self.do_handshake()\n  File "/usr/lib/python3.4/ssl.py", line 805, in do_handshake\n    self._sslobj.do_handshake()\nConnectionResetError: [Errno 104] Connection reset by peer\n')
('2015-03-21 10:34:48.082576', 'Traceback (most recent call last):\n  File "/river/fd/fd_worker/fd_channel.py", line 204, in create_channel\n    handle.connect()\n  File "/usr/lib/python3.4/http/client.py", line 1205, in connect\n    server_hostname=server_hostname)\n  File "/usr/lib/python3.4/ssl.py", line 364, in wrap_socket\n    _context=self)\n  File "/usr/lib/python3.4/ssl.py", line 578, in __init__\n    self.do_handshake()\n  File "/usr/lib/python3.4/ssl.py", line 805, in do_handshake\n    self._sslobj.do_handshake()\nConnectionResetError: [Errno 104] Connection reset by peer\n')
('2015-03-21 10:34:49.203289', 'Traceback (most recent call last):\n  File "/river/fd/fd_worker/fd_channel.py", line 204, in create_channel\n    handle.connect()\n  File "/usr/lib/python3.4/http/client.py", line 1205, in connect\n    server_hostname=server_hostname)\n  File "/usr/lib/python3.4/ssl.py", line 364, in wrap_socket\n    _context=self)\n  File "/usr/lib/python3.4/ssl.py", line 578, in __init__\n    self.do_handshake()\n  File "/usr/lib/python3.4/ssl.py", line 805, in do_handshake\n    self._sslobj.do_handshake()\nConnectionResetError: [Errno 104] Connection reset by peer\n')
('2015-03-21 10:34:53.683071', 'Traceback (most recent call last):\n  File "/river/fd/fd_worker/fd_channel.py", line 204, in create_channel\n    handle.connect()\n  File "/usr/lib/python3.4/http/client.py", line 1205, in connect\n    server_hostname=server_hostname)\n  File "/usr/lib/python3.4/ssl.py", line 364, in wrap_socket\n    _context=self)\n  File "/usr/lib/python3.4/ssl.py", line 578, in __init__\n    self.do_handshake()\n  File "/usr/lib/python3.4/ssl.py", line 805, in do_handshake\n    self._sslobj.do_handshake()\nConnectionResetError: [Errno 104] Connection reset by peer\n')
('2015-03-21 10:35:02.642932', 'Traceback (most recent call last):\n  File "/river/fd/fd_worker/fd_channel.py", line 204, in create_channel\n    handle.connect()\n  File "/usr/lib/python3.4/http/client.py", line 1205, in connect\n    server_hostname=server_hostname)\n  File "/usr/lib/python3.4/ssl.py", line 364, in wrap_socket\n    _context=self)\n  File "/usr/lib/python3.4/ssl.py", line 578, in __init__\n    self.do_handshake()\n  File "/usr/lib/python3.4/ssl.py", line 805, in do_handshake\n    self._sslobj.do_handshake()\nConnectionResetError: [Errno 104] Connection reset by peer\n')
('2015-03-21 10:35:23.758650', 'Traceback (most recent call last):\n  File "/river/fd/fd_worker/fd_channel.py", line 204, in create_channel\n    handle.connect()\n  File "/usr/lib/python3.4/http/client.py", line 1197, in connect\n    self.timeout, self.source_address)\n  File "/usr/lib/python3.4/socket.py", line 509, in create_connection\n    raise err\n  File "/usr/lib/python3.4/socket.py", line 500, in create_connection\n    sock.connect(sa)\nTimeoutError: [Errno 110] Connection timed out\n')
('2015-03-21 10:35:37.323505', 'Traceback (most recent call last):\n  File "/river/fd/fd_worker/fd_channel.py", line 204, in create_channel\n    handle.connect()\n  File "/usr/lib/python3.4/http/client.py", line 1197, in connect\n    self.timeout, self.source_address)\n  File "/usr/lib/python3.4/socket.py", line 509, in create_connection\n    raise err\n  File "/usr/lib/python3.4/socket.py", line 500, in create_connection\n    sock.connect(sa)\nTimeoutError: [Errno 110] Connection timed out\n')
('2015-03-21 10:35:56.779556', 'Traceback (most recent call last):\n  File "/river/fd/fd_worker/fd_channel.py", line 204, in create_channel\n    handle.connect()\n  File "/usr/lib/python3.4/http/client.py", line 1197, in connect\n    self.timeout, self.source_address)\n  File "/usr/lib/python3.4/socket.py", line 509, in create_connection\n    raise err\n  File "/usr/lib/python3.4/socket.py", line 500, in create_connection\n    sock.connect(sa)\nTimeoutError: [Errno 110] Connection timed out\n')
('2015-03-21 10:35:58.315476', 'Traceback (most recent call last):\n  File "/river/fd/fd_worker/fd_channel.py", line 204, in create_channel\n    handle.connect()\n  File "/usr/lib/python3.4/http/client.py", line 1197, in connect\n    self.timeout, self.source_address)\n  File "/usr/lib/python3.4/socket.py", line 509, in create_connection\n    raise err\n  File "/usr/lib/python3.4/socket.py", line 500, in create_connection\n    sock.connect(sa)\nTimeoutError: [Errno 110] Connection timed out\n')
('2015-03-21 10:36:19.307488', 'Traceback (most recent call last):\n  File "/river/fd/fd_worker/fd_channel.py", line 204, in create_channel\n    handle.connect()\n  File "/usr/lib/python3.4/http/client.py", line 1197, in connect\n    self.timeout, self.source_address)\n  File "/usr/lib/python3.4/socket.py", line 509, in create_connection\n    raise err\n  File "/usr/lib/python3.4/socket.py", line 500, in create_connection\n    sock.connect(sa)\nTimeoutError: [Errno 110] Connection timed out\n')
('2015-03-21 10:36:20.715499', 'Traceback (most recent call last):\n  File "/river/fd/fd_worker/fd_channel.py", line 204, in create_channel\n    handle.connect()\n  File "/usr/lib/python3.4/http/client.py", line 1197, in connect\n    self.timeout, self.source_address)\n  File "/usr/lib/python3.4/socket.py", line 509, in create_connection\n    raise err\n  File "/usr/lib/python3.4/socket.py", line 500, in create_connection\n    sock.connect(sa)\nTimeoutError: [Errno 110] Connection timed out\n')
('2015-03-21 10:36:35.691480', 'Traceback (most recent call last):\n  File "/river/fd/fd_worker/fd_channel.py", line 204, in create_channel\n    handle.connect()\n  File "/usr/lib/python3.4/http/client.py", line 1197, in connect\n    self.timeout, self.source_address)\n  File "/usr/lib/python3.4/socket.py", line 509, in create_connection\n    raise err\n  File "/usr/lib/python3.4/socket.py", line 500, in create_connection\n    sock.connect(sa)\nTimeoutError: [Errno 110] Connection timed out\n')
('2015-03-21 10:36:37.227484', 'Traceback (most recent call last):\n  File "/river/fd/fd_worker/fd_channel.py", line 204, in create_channel\n    handle.connect()\n  File "/usr/lib/python3.4/http/client.py", line 1197, in connect\n    self.timeout, self.source_address)\n  File "/usr/lib/python3.4/socket.py", line 509, in create_connection\n    raise err\n  File "/usr/lib/python3.4/socket.py", line 500, in create_connection\n    sock.connect(sa)\nTimeoutError: [Errno 110] Connection timed out\n')
('2015-03-21 10:36:58.219485', 'Traceback (most recent call last):\n  File "/river/fd/fd_worker/fd_channel.py", line 204, in create_channel\n    handle.connect()\n  File "/usr/lib/python3.4/http/client.py", line 1197, in connect\n    self.timeout, self.source_address)\n  File "/usr/lib/python3.4/socket.py", line 509, in create_connection\n    raise err\n  File "/usr/lib/python3.4/socket.py", line 500, in create_connection\n    sock.connect(sa)\nTimeoutError: [Errno 110] Connection timed out\n')
('2015-03-21 10:37:00.914550', 'Traceback (most recent call last):\n  File "/river/fd/fd_worker/fd_channel.py", line 144, in pyget\n    ack  = handle.getresponse()\n  File "/usr/lib/python3.4/http/client.py", line 1147, in getresponse\n    response.begin()\n  File "/usr/lib/python3.4/http/client.py", line 351, in begin\n    version, status, reason = self._read_status()\n  File "/usr/lib/python3.4/http/client.py", line 313, in _read_status\n    line = str(self.fp.readline(_MAXLINE + 1), "iso-8859-1")\n  File "/usr/lib/python3.4/socket.py", line 371, in readinto\n    return self._sock.recv_into(b)\n  File "/usr/lib/python3.4/ssl.py", line 746, in recv_into\n    return self.read(nbytes, buffer)\n  File "/usr/lib/python3.4/ssl.py", line 618, in read\n    v = self._sslobj.read(len, buffer)\nConnectionResetError: [Errno 104] Connection reset by peer\n')
('2015-03-21 10:37:04.235490', 'Traceback (most recent call last):\n  File "/river/fd/fd_worker/fd_channel.py", line 204, in create_channel\n    handle.connect()\n  File "/usr/lib/python3.4/http/client.py", line 1197, in connect\n    self.timeout, self.source_address)\n  File "/usr/lib/python3.4/socket.py", line 509, in create_connection\n    raise err\n  File "/usr/lib/python3.4/socket.py", line 500, in create_connection\n    sock.connect(sa)\nTimeoutError: [Errno 110] Connection timed out\n')
('2015-03-21 10:37:05.771483', 'Traceback (most recent call last):\n  File "/river/fd/fd_worker/fd_channel.py", line 204, in create_channel\n    handle.connect()\n  File "/usr/lib/python3.4/http/client.py", line 1197, in connect\n    self.timeout, self.source_address)\n  File "/usr/lib/python3.4/socket.py", line 509, in create_connection\n    raise err\n  File "/usr/lib/python3.4/socket.py", line 500, in create_connection\n    sock.connect(sa)\nTimeoutError: [Errno 110] Connection timed out\n')
('2015-03-21 10:37:07.179512', 'Traceback (most recent call last):\n  File "/river/fd/fd_worker/fd_channel.py", line 204, in create_channel\n    handle.connect()\n  File "/usr/lib/python3.4/http/client.py", line 1197, in connect\n    self.timeout, self.source_address)\n  File "/usr/lib/python3.4/socket.py", line 509, in create_connection\n    raise err\n  File "/usr/lib/python3.4/socket.py", line 500, in create_connection\n    sock.connect(sa)\nTimeoutError: [Errno 110] Connection timed out\n')
('2015-03-21 10:37:11.787589', 'Traceback (most recent call last):\n  File "/river/fd/fd_worker/fd_channel.py", line 204, in create_channel\n    handle.connect()\n  File "/usr/lib/python3.4/http/client.py", line 1197, in connect\n    self.timeout, self.source_address)\n  File "/usr/lib/python3.4/socket.py", line 509, in create_connection\n    raise err\n  File "/usr/lib/python3.4/socket.py", line 500, in create_connection\n    sock.connect(sa)\nTimeoutError: [Errno 110] Connection timed out\n')
('2015-03-21 10:37:20.747559', 'Traceback (most recent call last):\n  File "/river/fd/fd_worker/fd_channel.py", line 204, in create_channel\n    handle.connect()\n  File "/usr/lib/python3.4/http/client.py", line 1197, in connect\n    self.timeout, self.source_address)\n  File "/usr/lib/python3.4/socket.py", line 509, in create_connection\n    raise err\n  File "/usr/lib/python3.4/socket.py", line 500, in create_connection\n    sock.connect(sa)\nTimeoutError: [Errno 110] Connection timed out\n')
('2015-03-21 10:37:22.283453', 'Traceback (most recent call last):\n  File "/river/fd/fd_worker/fd_channel.py", line 204, in create_channel\n    handle.connect()\n  File "/usr/lib/python3.4/http/client.py", line 1197, in connect\n    self.timeout, self.source_address)\n  File "/usr/lib/python3.4/socket.py", line 509, in create_connection\n    raise err\n  File "/usr/lib/python3.4/socket.py", line 500, in create_connection\n    sock.connect(sa)\nTimeoutError: [Errno 110] Connection timed out\n')
('2015-03-21 10:37:34.315477', 'Traceback (most recent call last):\n  File "/river/fd/fd_worker/fd_channel.py", line 204, in create_channel\n    handle.connect()\n  File "/usr/lib/python3.4/http/client.py", line 1197, in connect\n    self.timeout, self.source_address)\n  File "/usr/lib/python3.4/socket.py", line 509, in create_connection\n    raise err\n  File "/usr/lib/python3.4/socket.py", line 500, in create_connection\n    sock.connect(sa)\nTimeoutError: [Errno 110] Connection timed out\n')
('2015-03-21 10:37:34.315691', 'Traceback (most recent call last):\n  File "/river/fd/fd_worker/fd_channel.py", line 204, in create_channel\n    handle.connect()\n  File "/usr/lib/python3.4/http/client.py", line 1197, in connect\n    self.timeout, self.source_address)\n  File "/usr/lib/python3.4/socket.py", line 509, in create_connection\n    raise err\n  File "/usr/lib/python3.4/socket.py", line 500, in create_connection\n    sock.connect(sa)\nTimeoutError: [Errno 110] Connection timed out\n')
('2015-03-21 10:37:35.091083', 'Traceback (most recent call last):\n  File "/river/fd/fd_worker/fd_channel.py", line 144, in pyget\n    ack  = handle.getresponse()\n  File "/usr/lib/python3.4/http/client.py", line 1147, in getresponse\n    response.begin()\n  File "/usr/lib/python3.4/http/client.py", line 351, in begin\n    version, status, reason = self._read_status()\n  File "/usr/lib/python3.4/http/client.py", line 313, in _read_status\n    line = str(self.fp.readline(_MAXLINE + 1), "iso-8859-1")\n  File "/usr/lib/python3.4/socket.py", line 371, in readinto\n    return self._sock.recv_into(b)\n  File "/usr/lib/python3.4/ssl.py", line 746, in recv_into\n    return self.read(nbytes, buffer)\n  File "/usr/lib/python3.4/ssl.py", line 618, in read\n    v = self._sslobj.read(len, buffer)\nConnectionResetError: [Errno 104] Connection reset by peer\n')
('2015-03-21 10:37:35.092041', 'Traceback (most recent call last):\n  File "/river/fd/fd_worker/fd_channel.py", line 144, in pyget\n    ack  = handle.getresponse()\n  File "/usr/lib/python3.4/http/client.py", line 1147, in getresponse\n    response.begin()\n  File "/usr/lib/python3.4/http/client.py", line 351, in begin\n    version, status, reason = self._read_status()\n  File "/usr/lib/python3.4/http/client.py", line 313, in _read_status\n    line = str(self.fp.readline(_MAXLINE + 1), "iso-8859-1")\n  File "/usr/lib/python3.4/socket.py", line 371, in readinto\n    return self._sock.recv_into(b)\n  File "/usr/lib/python3.4/ssl.py", line 746, in recv_into\n    return self.read(nbytes, buffer)\n  File "/usr/lib/python3.4/ssl.py", line 618, in read\n    v = self._sslobj.read(len, buffer)\nConnectionResetError: [Errno 104] Connection reset by peer\n')
('2015-03-21 10:37:35.092456', 'Traceback (most recent call last):\n  File "/river/fd/fd_worker/fd_channel.py", line 144, in pyget\n    ack  = handle.getresponse()\n  File "/usr/lib/python3.4/http/client.py", line 1147, in getresponse\n    response.begin()\n  File "/usr/lib/python3.4/http/client.py", line 351, in begin\n    version, status, reason = self._read_status()\n  File "/usr/lib/python3.4/http/client.py", line 313, in _read_status\n    line = str(self.fp.readline(_MAXLINE + 1), "iso-8859-1")\n  File "/usr/lib/python3.4/socket.py", line 371, in readinto\n    return self._sock.recv_into(b)\n  File "/usr/lib/python3.4/ssl.py", line 746, in recv_into\n    return self.read(nbytes, buffer)\n  File "/usr/lib/python3.4/ssl.py", line 618, in read\n    v = self._sslobj.read(len, buffer)\nConnectionResetError: [Errno 104] Connection reset by peer\n')
('2015-03-21 10:37:35.723496', 'Traceback (most recent call last):\n  File "/river/fd/fd_worker/fd_channel.py", line 204, in create_channel\n    handle.connect()\n  File "/usr/lib/python3.4/http/client.py", line 1197, in connect\n    self.timeout, self.source_address)\n  File "/usr/lib/python3.4/socket.py", line 509, in create_connection\n    raise err\n  File "/usr/lib/python3.4/socket.py", line 500, in create_connection\n    sock.connect(sa)\nTimeoutError: [Errno 110] Connection timed out\n')
('2015-03-21 10:37:35.723742', 'Traceback (most recent call last):\n  File "/river/fd/fd_worker/fd_channel.py", line 204, in create_channel\n    handle.connect()\n  File "/usr/lib/python3.4/http/client.py", line 1197, in connect\n    self.timeout, self.source_address)\n  File "/usr/lib/python3.4/socket.py", line 509, in create_connection\n    raise err\n  File "/usr/lib/python3.4/socket.py", line 500, in create_connection\n    sock.connect(sa)\nTimeoutError: [Errno 110] Connection timed out\n')
('2015-03-21 10:37:37.259510', 'Traceback (most recent call last):\n  File "/river/fd/fd_worker/fd_channel.py", line 204, in create_channel\n    handle.connect()\n  File "/usr/lib/python3.4/http/client.py", line 1197, in connect\n    self.timeout, self.source_address)\n  File "/usr/lib/python3.4/socket.py", line 509, in create_connection\n    raise err\n  File "/usr/lib/python3.4/socket.py", line 500, in create_connection\n    sock.connect(sa)\nTimeoutError: [Errno 110] Connection timed out\n')
('2015-03-21 10:37:40.203483', 'Traceback (most recent call last):\n  File "/river/fd/fd_worker/fd_channel.py", line 204, in create_channel\n    handle.connect()\n  File "/usr/lib/python3.4/http/client.py", line 1197, in connect\n    self.timeout, self.source_address)\n  File "/usr/lib/python3.4/socket.py", line 509, in create_connection\n    raise err\n  File "/usr/lib/python3.4/socket.py", line 500, in create_connection\n    sock.connect(sa)\nTimeoutError: [Errno 110] Connection timed out\n')
('2015-03-21 10:37:46.354880', 'Traceback (most recent call last):\n  File "/river/fd/fd_worker/fd_channel.py", line 144, in pyget\n    ack  = handle.getresponse()\n  File "/usr/lib/python3.4/http/client.py", line 1147, in getresponse\n    response.begin()\n  File "/usr/lib/python3.4/http/client.py", line 351, in begin\n    version, status, reason = self._read_status()\n  File "/usr/lib/python3.4/http/client.py", line 313, in _read_status\n    line = str(self.fp.readline(_MAXLINE + 1), "iso-8859-1")\n  File "/usr/lib/python3.4/socket.py", line 371, in readinto\n    return self._sock.recv_into(b)\n  File "/usr/lib/python3.4/ssl.py", line 746, in recv_into\n    return self.read(nbytes, buffer)\n  File "/usr/lib/python3.4/ssl.py", line 618, in read\n    v = self._sslobj.read(len, buffer)\nConnectionResetError: [Errno 104] Connection reset by peer\n')
('2015-03-21 10:37:55.307482', 'Traceback (most recent call last):\n  File "/river/fd/fd_worker/fd_channel.py", line 204, in create_channel\n    handle.connect()\n  File "/usr/lib/python3.4/http/client.py", line 1197, in connect\n    self.timeout, self.source_address)\n  File "/usr/lib/python3.4/socket.py", line 509, in create_connection\n    raise err\n  File "/usr/lib/python3.4/socket.py", line 500, in create_connection\n    sock.connect(sa)\nTimeoutError: [Errno 110] Connection timed out\n')
('2015-03-21 10:37:56.715475', 'Traceback (most recent call last):\n  File "/river/fd/fd_worker/fd_channel.py", line 204, in create_channel\n    handle.connect()\n  File "/usr/lib/python3.4/http/client.py", line 1197, in connect\n    self.timeout, self.source_address)\n  File "/usr/lib/python3.4/socket.py", line 509, in create_connection\n    raise err\n  File "/usr/lib/python3.4/socket.py", line 500, in create_connection\n    sock.connect(sa)\nTimeoutError: [Errno 110] Connection timed out\n')
('2015-03-21 10:37:58.251490', 'Traceback (most recent call last):\n  File "/river/fd/fd_worker/fd_channel.py", line 204, in create_channel\n    handle.connect()\n  File "/usr/lib/python3.4/http/client.py", line 1197, in connect\n    self.timeout, self.source_address)\n  File "/usr/lib/python3.4/socket.py", line 509, in create_connection\n    raise err\n  File "/usr/lib/python3.4/socket.py", line 500, in create_connection\n    sock.connect(sa)\nTimeoutError: [Errno 110] Connection timed out\n')
('2015-03-21 10:37:59.787453', 'Traceback (most recent call last):\n  File "/river/fd/fd_worker/fd_channel.py", line 204, in create_channel\n    handle.connect()\n  File "/usr/lib/python3.4/http/client.py", line 1197, in connect\n    self.timeout, self.source_address)\n  File "/usr/lib/python3.4/socket.py", line 509, in create_connection\n    raise err\n  File "/usr/lib/python3.4/socket.py", line 500, in create_connection\n    sock.connect(sa)\nTimeoutError: [Errno 110] Connection timed out\n')
('2015-03-21 10:38:01.195457', 'Traceback (most recent call last):\n  File "/river/fd/fd_worker/fd_channel.py", line 204, in create_channel\n    handle.connect()\n  File "/usr/lib/python3.4/http/client.py", line 1197, in connect\n    self.timeout, self.source_address)\n  File "/usr/lib/python3.4/socket.py", line 509, in create_connection\n    raise err\n  File "/usr/lib/python3.4/socket.py", line 500, in create_connection\n    sock.connect(sa)\nTimeoutError: [Errno 110] Connection timed out\n')
('2015-03-21 10:38:05.803569', 'Traceback (most recent call last):\n  File "/river/fd/fd_worker/fd_channel.py", line 204, in create_channel\n    handle.connect()\n  File "/usr/lib/python3.4/http/client.py", line 1197, in connect\n    self.timeout, self.source_address)\n  File "/usr/lib/python3.4/socket.py", line 509, in create_connection\n    raise err\n  File "/usr/lib/python3.4/socket.py", line 500, in create_connection\n    sock.connect(sa)\nTimeoutError: [Errno 110] Connection timed out\n')
('2015-03-21 10:38:07.211875', 'Traceback (most recent call last):\n  File "/river/fd/fd_worker/fd_channel.py", line 204, in create_channel\n    handle.connect()\n  File "/usr/lib/python3.4/http/client.py", line 1197, in connect\n    self.timeout, self.source_address)\n  File "/usr/lib/python3.4/socket.py", line 509, in create_connection\n    raise err\n  File "/usr/lib/python3.4/socket.py", line 500, in create_connection\n    sock.connect(sa)\nTimeoutError: [Errno 110] Connection timed out\n')
('2015-03-21 10:38:08.747505', 'Traceback (most recent call last):\n  File "/river/fd/fd_worker/fd_channel.py", line 204, in create_channel\n    handle.connect()\n  File "/usr/lib/python3.4/http/client.py", line 1197, in connect\n    self.timeout, self.source_address)\n  File "/usr/lib/python3.4/socket.py", line 509, in create_connection\n    raise err\n  File "/usr/lib/python3.4/socket.py", line 500, in create_connection\n    sock.connect(sa)\nTimeoutError: [Errno 110] Connection timed out\n')
('2015-03-21 10:38:08.747913', 'Traceback (most recent call last):\n  File "/river/fd/fd_worker/fd_channel.py", line 204, in create_channel\n    handle.connect()\n  File "/usr/lib/python3.4/http/client.py", line 1197, in connect\n    self.timeout, self.source_address)\n  File "/usr/lib/python3.4/socket.py", line 509, in create_connection\n    raise err\n  File "/usr/lib/python3.4/socket.py", line 500, in create_connection\n    sock.connect(sa)\nTimeoutError: [Errno 110] Connection timed out\n')
('2015-03-21 10:38:10.283552', 'Traceback (most recent call last):\n  File "/river/fd/fd_worker/fd_channel.py", line 204, in create_channel\n    handle.connect()\n  File "/usr/lib/python3.4/http/client.py", line 1197, in connect\n    self.timeout, self.source_address)\n  File "/usr/lib/python3.4/socket.py", line 509, in create_connection\n    raise err\n  File "/usr/lib/python3.4/socket.py", line 500, in create_connection\n    sock.connect(sa)\nTimeoutError: [Errno 110] Connection timed out\n')
('2015-03-21 10:38:10.284001', 'Traceback (most recent call last):\n  File "/river/fd/fd_worker/fd_channel.py", line 204, in create_channel\n    handle.connect()\n  File "/usr/lib/python3.4/http/client.py", line 1197, in connect\n    self.timeout, self.source_address)\n  File "/usr/lib/python3.4/socket.py", line 509, in create_connection\n    raise err\n  File "/usr/lib/python3.4/socket.py", line 500, in create_connection\n    sock.connect(sa)\nTimeoutError: [Errno 110] Connection timed out\n')
('2015-03-21 10:38:11.691613', 'Traceback (most recent call last):\n  File "/river/fd/fd_worker/fd_channel.py", line 204, in create_channel\n    handle.connect()\n  File "/usr/lib/python3.4/http/client.py", line 1197, in connect\n    self.timeout, self.source_address)\n  File "/usr/lib/python3.4/socket.py", line 509, in create_connection\n    raise err\n  File "/usr/lib/python3.4/socket.py", line 500, in create_connection\n    sock.connect(sa)\nTimeoutError: [Errno 110] Connection timed out\n')
('2015-03-21 10:38:13.227582', 'Traceback (most recent call last):\n  File "/river/fd/fd_worker/fd_channel.py", line 204, in create_channel\n    handle.connect()\n  File "/usr/lib/python3.4/http/client.py", line 1197, in connect\n    self.timeout, self.source_address)\n  File "/usr/lib/python3.4/socket.py", line 509, in create_connection\n    raise err\n  File "/usr/lib/python3.4/socket.py", line 500, in create_connection\n    sock.connect(sa)\nTimeoutError: [Errno 110] Connection timed out\n')
('2015-03-21 10:38:13.228075', 'Traceback (most recent call last):\n  File "/river/fd/fd_worker/fd_channel.py", line 204, in create_channel\n    handle.connect()\n  File "/usr/lib/python3.4/http/client.py", line 1197, in connect\n    self.timeout, self.source_address)\n  File "/usr/lib/python3.4/socket.py", line 509, in create_connection\n    raise err\n  File "/usr/lib/python3.4/socket.py", line 500, in create_connection\n    sock.connect(sa)\nTimeoutError: [Errno 110] Connection timed out\n')
('2015-03-21 10:38:14.763590', 'Traceback (most recent call last):\n  File "/river/fd/fd_worker/fd_channel.py", line 204, in create_channel\n    handle.connect()\n  File "/usr/lib/python3.4/http/client.py", line 1197, in connect\n    self.timeout, self.source_address)\n  File "/usr/lib/python3.4/socket.py", line 509, in create_connection\n    raise err\n  File "/usr/lib/python3.4/socket.py", line 500, in create_connection\n    sock.connect(sa)\nTimeoutError: [Errno 110] Connection timed out\n')
('2015-03-21 10:38:19.243588', 'Traceback (most recent call last):\n  File "/river/fd/fd_worker/fd_channel.py", line 204, in create_channel\n    handle.connect()\n  File "/usr/lib/python3.4/http/client.py", line 1197, in connect\n    self.timeout, self.source_address)\n  File "/usr/lib/python3.4/socket.py", line 509, in create_connection\n    raise err\n  File "/usr/lib/python3.4/socket.py", line 500, in create_connection\n    sock.connect(sa)\nTimeoutError: [Errno 110] Connection timed out\n')
('2015-03-21 10:38:20.779541', 'Traceback (most recent call last):\n  File "/river/fd/fd_worker/fd_channel.py", line 204, in create_channel\n    handle.connect()\n  File "/usr/lib/python3.4/http/client.py", line 1197, in connect\n    self.timeout, self.source_address)\n  File "/usr/lib/python3.4/socket.py", line 509, in create_connection\n    raise err\n  File "/usr/lib/python3.4/socket.py", line 500, in create_connection\n    sock.connect(sa)\nTimeoutError: [Errno 110] Connection timed out\n')
('2015-03-21 10:38:22.187587', 'Traceback (most recent call last):\n  File "/river/fd/fd_worker/fd_channel.py", line 204, in create_channel\n    handle.connect()\n  File "/usr/lib/python3.4/http/client.py", line 1197, in connect\n    self.timeout, self.source_address)\n  File "/usr/lib/python3.4/socket.py", line 509, in create_connection\n    raise err\n  File "/usr/lib/python3.4/socket.py", line 500, in create_connection\n    sock.connect(sa)\nTimeoutError: [Errno 110] Connection timed out\n')
('2015-03-21 10:38:37.291478', 'Traceback (most recent call last):\n  File "/river/fd/fd_worker/fd_channel.py", line 204, in create_channel\n    handle.connect()\n  File "/usr/lib/python3.4/http/client.py", line 1197, in connect\n    self.timeout, self.source_address)\n  File "/usr/lib/python3.4/socket.py", line 509, in create_connection\n    raise err\n  File "/usr/lib/python3.4/socket.py", line 500, in create_connection\n    sock.connect(sa)\nTimeoutError: [Errno 110] Connection timed out\n')
('2015-03-21 10:38:38.827476', 'Traceback (most recent call last):\n  File "/river/fd/fd_worker/fd_channel.py", line 204, in create_channel\n    handle.connect()\n  File "/usr/lib/python3.4/http/client.py", line 1197, in connect\n    self.timeout, self.source_address)\n  File "/usr/lib/python3.4/socket.py", line 509, in create_connection\n    raise err\n  File "/usr/lib/python3.4/socket.py", line 500, in create_connection\n    sock.connect(sa)\nTimeoutError: [Errno 110] Connection timed out\n')
('2015-03-21 10:38:40.235469', 'Traceback (most recent call last):\n  File "/river/fd/fd_worker/fd_channel.py", line 204, in create_channel\n    handle.connect()\n  File "/usr/lib/python3.4/http/client.py", line 1197, in connect\n    self.timeout, self.source_address)\n  File "/usr/lib/python3.4/socket.py", line 509, in create_connection\n    raise err\n  File "/usr/lib/python3.4/socket.py", line 500, in create_connection\n    sock.connect(sa)\nTimeoutError: [Errno 110] Connection timed out\n')
('2015-03-21 10:38:41.771492', 'Traceback (most recent call last):\n  File "/river/fd/fd_worker/fd_channel.py", line 204, in create_channel\n    handle.connect()\n  File "/usr/lib/python3.4/http/client.py", line 1197, in connect\n    self.timeout, self.source_address)\n  File "/usr/lib/python3.4/socket.py", line 509, in create_connection\n    raise err\n  File "/usr/lib/python3.4/socket.py", line 500, in create_connection\n    sock.connect(sa)\nTimeoutError: [Errno 110] Connection timed out\n')
('2015-03-21 10:38:42.768022', 'Traceback (most recent call last):\n  File "/river/fd/fd_worker/fd_channel.py", line 144, in pyget\n    ack  = handle.getresponse()\n  File "/usr/lib/python3.4/http/client.py", line 1147, in getresponse\n    response.begin()\n  File "/usr/lib/python3.4/http/client.py", line 351, in begin\n    version, status, reason = self._read_status()\n  File "/usr/lib/python3.4/http/client.py", line 321, in _read_status\n    raise BadStatusLine(line)\nhttp.client.BadStatusLine: \'\'\n')
('2015-03-21 10:38:43.179540', 'Traceback (most recent call last):\n  File "/river/fd/fd_worker/fd_channel.py", line 204, in create_channel\n    handle.connect()\n  File "/usr/lib/python3.4/http/client.py", line 1197, in connect\n    self.timeout, self.source_address)\n  File "/usr/lib/python3.4/socket.py", line 509, in create_connection\n    raise err\n  File "/usr/lib/python3.4/socket.py", line 500, in create_connection\n    sock.connect(sa)\nTimeoutError: [Errno 110] Connection timed out\n')
('2015-03-21 10:38:44.715577', 'Traceback (most recent call last):\n  File "/river/fd/fd_worker/fd_channel.py", line 204, in create_channel\n    handle.connect()\n  File "/usr/lib/python3.4/http/client.py", line 1197, in connect\n    self.timeout, self.source_address)\n  File "/usr/lib/python3.4/socket.py", line 509, in create_connection\n    raise err\n  File "/usr/lib/python3.4/socket.py", line 500, in create_connection\n    sock.connect(sa)\nTimeoutError: [Errno 110] Connection timed out\n')
('2015-03-21 10:38:45.056977', 'Traceback (most recent call last):\n  File "/river/fd/fd_worker/fd_channel.py", line 144, in pyget\n    ack  = handle.getresponse()\n  File "/usr/lib/python3.4/http/client.py", line 1147, in getresponse\n    response.begin()\n  File "/usr/lib/python3.4/http/client.py", line 351, in begin\n    version, status, reason = self._read_status()\n  File "/usr/lib/python3.4/http/client.py", line 321, in _read_status\n    raise BadStatusLine(line)\nhttp.client.BadStatusLine: \'\'\n')
('2015-03-21 10:38:46.251543', 'Traceback (most recent call last):\n  File "/river/fd/fd_worker/fd_channel.py", line 204, in create_channel\n    handle.connect()\n  File "/usr/lib/python3.4/http/client.py", line 1197, in connect\n    self.timeout, self.source_address)\n  File "/usr/lib/python3.4/socket.py", line 509, in create_connection\n    raise err\n  File "/usr/lib/python3.4/socket.py", line 500, in create_connection\n    sock.connect(sa)\nTimeoutError: [Errno 110] Connection timed out\n')
('2015-03-21 10:38:49.586934', 'Traceback (most recent call last):\n  File "/river/fd/fd_worker/fd_channel.py", line 144, in pyget\n    ack  = handle.getresponse()\n  File "/usr/lib/python3.4/http/client.py", line 1147, in getresponse\n    response.begin()\n  File "/usr/lib/python3.4/http/client.py", line 351, in begin\n    version, status, reason = self._read_status()\n  File "/usr/lib/python3.4/http/client.py", line 313, in _read_status\n    line = str(self.fp.readline(_MAXLINE + 1), "iso-8859-1")\n  File "/usr/lib/python3.4/socket.py", line 371, in readinto\n    return self._sock.recv_into(b)\n  File "/usr/lib/python3.4/ssl.py", line 746, in recv_into\n    return self.read(nbytes, buffer)\n  File "/usr/lib/python3.4/ssl.py", line 618, in read\n    v = self._sslobj.read(len, buffer)\nConnectionResetError: [Errno 104] Connection reset by peer\n')
('2015-03-21 10:39:20.051169', 'Traceback (most recent call last):\n  File "/river/fd/fd_worker/fd_channel.py", line 204, in create_channel\n    handle.connect()\n  File "/usr/lib/python3.4/http/client.py", line 1205, in connect\n    server_hostname=server_hostname)\n  File "/usr/lib/python3.4/ssl.py", line 364, in wrap_socket\n    _context=self)\n  File "/usr/lib/python3.4/ssl.py", line 578, in __init__\n    self.do_handshake()\n  File "/usr/lib/python3.4/ssl.py", line 805, in do_handshake\n    self._sslobj.do_handshake()\nConnectionResetError: [Errno 104] Connection reset by peer\n')
('2015-03-21 10:39:21.586994', 'Traceback (most recent call last):\n  File "/river/fd/fd_worker/fd_channel.py", line 144, in pyget\n    ack  = handle.getresponse()\n  File "/usr/lib/python3.4/http/client.py", line 1147, in getresponse\n    response.begin()\n  File "/usr/lib/python3.4/http/client.py", line 351, in begin\n    version, status, reason = self._read_status()\n  File "/usr/lib/python3.4/http/client.py", line 313, in _read_status\n    line = str(self.fp.readline(_MAXLINE + 1), "iso-8859-1")\n  File "/usr/lib/python3.4/socket.py", line 371, in readinto\n    return self._sock.recv_into(b)\n  File "/usr/lib/python3.4/ssl.py", line 746, in recv_into\n    return self.read(nbytes, buffer)\n  File "/usr/lib/python3.4/ssl.py", line 618, in read\n    v = self._sslobj.read(len, buffer)\nConnectionResetError: [Errno 104] Connection reset by peer\n')
('2015-03-21 10:39:41.554259', 'Traceback (most recent call last):\n  File "/river/fd/fd_worker/fd_channel.py", line 144, in pyget\n    ack  = handle.getresponse()\n  File "/usr/lib/python3.4/http/client.py", line 1147, in getresponse\n    response.begin()\n  File "/usr/lib/python3.4/http/client.py", line 351, in begin\n    version, status, reason = self._read_status()\n  File "/usr/lib/python3.4/http/client.py", line 313, in _read_status\n    line = str(self.fp.readline(_MAXLINE + 1), "iso-8859-1")\n  File "/usr/lib/python3.4/socket.py", line 371, in readinto\n    return self._sock.recv_into(b)\n  File "/usr/lib/python3.4/ssl.py", line 746, in recv_into\n    return self.read(nbytes, buffer)\n  File "/usr/lib/python3.4/ssl.py", line 618, in read\n    v = self._sslobj.read(len, buffer)\nConnectionResetError: [Errno 104] Connection reset by peer\n')
('2015-03-21 10:39:44.626327', 'Traceback (most recent call last):\n  File "/river/fd/fd_worker/fd_channel.py", line 144, in pyget\n    ack  = handle.getresponse()\n  File "/usr/lib/python3.4/http/client.py", line 1147, in getresponse\n    response.begin()\n  File "/usr/lib/python3.4/http/client.py", line 351, in begin\n    version, status, reason = self._read_status()\n  File "/usr/lib/python3.4/http/client.py", line 313, in _read_status\n    line = str(self.fp.readline(_MAXLINE + 1), "iso-8859-1")\n  File "/usr/lib/python3.4/socket.py", line 371, in readinto\n    return self._sock.recv_into(b)\n  File "/usr/lib/python3.4/ssl.py", line 746, in recv_into\n    return self.read(nbytes, buffer)\n  File "/usr/lib/python3.4/ssl.py", line 618, in read\n    v = self._sslobj.read(len, buffer)\nConnectionResetError: [Errno 104] Connection reset by peer\n')
('2015-03-21 10:39:46.675356', 'Traceback (most recent call last):\n  File "/river/fd/fd_worker/fd_channel.py", line 144, in pyget\n    ack  = handle.getresponse()\n  File "/usr/lib/python3.4/http/client.py", line 1147, in getresponse\n    response.begin()\n  File "/usr/lib/python3.4/http/client.py", line 351, in begin\n    version, status, reason = self._read_status()\n  File "/usr/lib/python3.4/http/client.py", line 313, in _read_status\n    line = str(self.fp.readline(_MAXLINE + 1), "iso-8859-1")\n  File "/usr/lib/python3.4/socket.py", line 371, in readinto\n    return self._sock.recv_into(b)\n  File "/usr/lib/python3.4/ssl.py", line 746, in recv_into\n    return self.read(nbytes, buffer)\n  File "/usr/lib/python3.4/ssl.py", line 618, in read\n    v = self._sslobj.read(len, buffer)\nConnectionResetError: [Errno 104] Connection reset by peer\n')
('2015-03-21 10:39:48.210748', 'Traceback (most recent call last):\n  File "/river/fd/fd_worker/fd_channel.py", line 144, in pyget\n    ack  = handle.getresponse()\n  File "/usr/lib/python3.4/http/client.py", line 1147, in getresponse\n    response.begin()\n  File "/usr/lib/python3.4/http/client.py", line 351, in begin\n    version, status, reason = self._read_status()\n  File "/usr/lib/python3.4/http/client.py", line 313, in _read_status\n    line = str(self.fp.readline(_MAXLINE + 1), "iso-8859-1")\n  File "/usr/lib/python3.4/socket.py", line 371, in readinto\n    return self._sock.recv_into(b)\n  File "/usr/lib/python3.4/ssl.py", line 746, in recv_into\n    return self.read(nbytes, buffer)\n  File "/usr/lib/python3.4/ssl.py", line 618, in read\n    v = self._sslobj.read(len, buffer)\nConnectionResetError: [Errno 104] Connection reset by peer\n')
('2015-03-21 10:39:48.723334', 'Traceback (most recent call last):\n  File "/river/fd/fd_worker/fd_channel.py", line 144, in pyget\n    ack  = handle.getresponse()\n  File "/usr/lib/python3.4/http/client.py", line 1147, in getresponse\n    response.begin()\n  File "/usr/lib/python3.4/http/client.py", line 351, in begin\n    version, status, reason = self._read_status()\n  File "/usr/lib/python3.4/http/client.py", line 313, in _read_status\n    line = str(self.fp.readline(_MAXLINE + 1), "iso-8859-1")\n  File "/usr/lib/python3.4/socket.py", line 371, in readinto\n    return self._sock.recv_into(b)\n  File "/usr/lib/python3.4/ssl.py", line 746, in recv_into\n    return self.read(nbytes, buffer)\n  File "/usr/lib/python3.4/ssl.py", line 618, in read\n    v = self._sslobj.read(len, buffer)\nConnectionResetError: [Errno 104] Connection reset by peer\n')
('2015-03-21 10:39:50.258459', 'Traceback (most recent call last):\n  File "/river/fd/fd_worker/fd_channel.py", line 144, in pyget\n    ack  = handle.getresponse()\n  File "/usr/lib/python3.4/http/client.py", line 1147, in getresponse\n    response.begin()\n  File "/usr/lib/python3.4/http/client.py", line 351, in begin\n    version, status, reason = self._read_status()\n  File "/usr/lib/python3.4/http/client.py", line 313, in _read_status\n    line = str(self.fp.readline(_MAXLINE + 1), "iso-8859-1")\n  File "/usr/lib/python3.4/socket.py", line 371, in readinto\n    return self._sock.recv_into(b)\n  File "/usr/lib/python3.4/ssl.py", line 746, in recv_into\n    return self.read(nbytes, buffer)\n  File "/usr/lib/python3.4/ssl.py", line 618, in read\n    v = self._sslobj.read(len, buffer)\nConnectionResetError: [Errno 104] Connection reset by peer\n')
('2015-03-21 10:41:18.834891', 'Traceback (most recent call last):\n  File "/river/fd/fd_worker/fd_channel.py", line 204, in create_channel\n    handle.connect()\n  File "/usr/lib/python3.4/http/client.py", line 1205, in connect\n    server_hostname=server_hostname)\n  File "/usr/lib/python3.4/ssl.py", line 364, in wrap_socket\n    _context=self)\n  File "/usr/lib/python3.4/ssl.py", line 578, in __init__\n    self.do_handshake()\n  File "/usr/lib/python3.4/ssl.py", line 805, in do_handshake\n    self._sslobj.do_handshake()\nConnectionResetError: [Errno 104] Connection reset by peer\n')
('2015-03-21 11:29:25.494658', 'Traceback (most recent call last):\n  File "/river/fd/fd_worker/fd_channel.py", line 204, in create_channel\n    handle.connect()\n  File "/usr/lib/python3.4/http/client.py", line 1205, in connect\n    server_hostname=server_hostname)\n  File "/usr/lib/python3.4/ssl.py", line 364, in wrap_socket\n    _context=self)\n  File "/usr/lib/python3.4/ssl.py", line 578, in __init__\n    self.do_handshake()\n  File "/usr/lib/python3.4/ssl.py", line 805, in do_handshake\n    self._sslobj.do_handshake()\nConnectionResetError: [Errno 104] Connection reset by peer\n')
('2015-03-21 11:29:28.635333', 'Traceback (most recent call last):\n  File "/river/fd/fd_worker/fd_channel.py", line 204, in create_channel\n    handle.connect()\n  File "/usr/lib/python3.4/http/client.py", line 1205, in connect\n    server_hostname=server_hostname)\n  File "/usr/lib/python3.4/ssl.py", line 364, in wrap_socket\n    _context=self)\n  File "/usr/lib/python3.4/ssl.py", line 578, in __init__\n    self.do_handshake()\n  File "/usr/lib/python3.4/ssl.py", line 805, in do_handshake\n    self._sslobj.do_handshake()\nConnectionResetError: [Errno 104] Connection reset by peer\n')
('2015-03-21 11:29:31.495415', 'Traceback (most recent call last):\n  File "/river/fd/fd_worker/fd_channel.py", line 204, in create_channel\n    handle.connect()\n  File "/usr/lib/python3.4/http/client.py", line 1205, in connect\n    server_hostname=server_hostname)\n  File "/usr/lib/python3.4/ssl.py", line 364, in wrap_socket\n    _context=self)\n  File "/usr/lib/python3.4/ssl.py", line 578, in __init__\n    self.do_handshake()\n  File "/usr/lib/python3.4/ssl.py", line 805, in do_handshake\n    self._sslobj.do_handshake()\nConnectionResetError: [Errno 104] Connection reset by peer\n')
('2015-03-21 11:29:33.847166', 'Traceback (most recent call last):\n  File "/river/fd/fd_worker/fd_channel.py", line 204, in create_channel\n    handle.connect()\n  File "/usr/lib/python3.4/http/client.py", line 1205, in connect\n    server_hostname=server_hostname)\n  File "/usr/lib/python3.4/ssl.py", line 364, in wrap_socket\n    _context=self)\n  File "/usr/lib/python3.4/ssl.py", line 578, in __init__\n    self.do_handshake()\n  File "/usr/lib/python3.4/ssl.py", line 805, in do_handshake\n    self._sslobj.do_handshake()\nConnectionResetError: [Errno 104] Connection reset by peer\n')
('2015-03-21 11:29:34.027276', 'Traceback (most recent call last):\n  File "/river/fd/fd_worker/fd_channel.py", line 204, in create_channel\n    handle.connect()\n  File "/usr/lib/python3.4/http/client.py", line 1205, in connect\n    server_hostname=server_hostname)\n  File "/usr/lib/python3.4/ssl.py", line 364, in wrap_socket\n    _context=self)\n  File "/usr/lib/python3.4/ssl.py", line 578, in __init__\n    self.do_handshake()\n  File "/usr/lib/python3.4/ssl.py", line 805, in do_handshake\n    self._sslobj.do_handshake()\nConnectionResetError: [Errno 104] Connection reset by peer\n')
('2015-03-21 11:29:36.847175', 'Traceback (most recent call last):\n  File "/river/fd/fd_worker/fd_channel.py", line 204, in create_channel\n    handle.connect()\n  File "/usr/lib/python3.4/http/client.py", line 1205, in connect\n    server_hostname=server_hostname)\n  File "/usr/lib/python3.4/ssl.py", line 364, in wrap_socket\n    _context=self)\n  File "/usr/lib/python3.4/ssl.py", line 578, in __init__\n    self.do_handshake()\n  File "/usr/lib/python3.4/ssl.py", line 805, in do_handshake\n    self._sslobj.do_handshake()\nConnectionResetError: [Errno 104] Connection reset by peer\n')
('2015-03-21 11:29:37.495333', 'Traceback (most recent call last):\n  File "/river/fd/fd_worker/fd_channel.py", line 204, in create_channel\n    handle.connect()\n  File "/usr/lib/python3.4/http/client.py", line 1205, in connect\n    server_hostname=server_hostname)\n  File "/usr/lib/python3.4/ssl.py", line 364, in wrap_socket\n    _context=self)\n  File "/usr/lib/python3.4/ssl.py", line 578, in __init__\n    self.do_handshake()\n  File "/usr/lib/python3.4/ssl.py", line 805, in do_handshake\n    self._sslobj.do_handshake()\nConnectionResetError: [Errno 104] Connection reset by peer\n')
('2015-03-21 11:29:40.026353', 'Traceback (most recent call last):\n  File "/river/fd/fd_worker/fd_channel.py", line 204, in create_channel\n    handle.connect()\n  File "/usr/lib/python3.4/http/client.py", line 1205, in connect\n    server_hostname=server_hostname)\n  File "/usr/lib/python3.4/ssl.py", line 364, in wrap_socket\n    _context=self)\n  File "/usr/lib/python3.4/ssl.py", line 578, in __init__\n    self.do_handshake()\n  File "/usr/lib/python3.4/ssl.py", line 805, in do_handshake\n    self._sslobj.do_handshake()\nConnectionResetError: [Errno 104] Connection reset by peer\n')
('2015-03-21 11:29:43.474990', 'Traceback (most recent call last):\n  File "/river/fd/fd_worker/fd_channel.py", line 204, in create_channel\n    handle.connect()\n  File "/usr/lib/python3.4/http/client.py", line 1205, in connect\n    server_hostname=server_hostname)\n  File "/usr/lib/python3.4/ssl.py", line 364, in wrap_socket\n    _context=self)\n  File "/usr/lib/python3.4/ssl.py", line 578, in __init__\n    self.do_handshake()\n  File "/usr/lib/python3.4/ssl.py", line 805, in do_handshake\n    self._sslobj.do_handshake()\nConnectionResetError: [Errno 104] Connection reset by peer\n')
('2015-03-21 11:29:45.846794', 'Traceback (most recent call last):\n  File "/river/fd/fd_worker/fd_channel.py", line 204, in create_channel\n    handle.connect()\n  File "/usr/lib/python3.4/http/client.py", line 1205, in connect\n    server_hostname=server_hostname)\n  File "/usr/lib/python3.4/ssl.py", line 364, in wrap_socket\n    _context=self)\n  File "/usr/lib/python3.4/ssl.py", line 578, in __init__\n    self.do_handshake()\n  File "/usr/lib/python3.4/ssl.py", line 805, in do_handshake\n    self._sslobj.do_handshake()\nConnectionResetError: [Errno 104] Connection reset by peer\n')
('2015-03-21 11:29:47.467327', 'Traceback (most recent call last):\n  File "/river/fd/fd_worker/fd_channel.py", line 204, in create_channel\n    handle.connect()\n  File "/usr/lib/python3.4/http/client.py", line 1205, in connect\n    server_hostname=server_hostname)\n  File "/usr/lib/python3.4/ssl.py", line 364, in wrap_socket\n    _context=self)\n  File "/usr/lib/python3.4/ssl.py", line 578, in __init__\n    self.do_handshake()\n  File "/usr/lib/python3.4/ssl.py", line 805, in do_handshake\n    self._sslobj.do_handshake()\nConnectionResetError: [Errno 104] Connection reset by peer\n')
('2015-03-21 11:29:47.570932', 'Traceback (most recent call last):\n  File "/river/fd/fd_worker/fd_channel.py", line 204, in create_channel\n    handle.connect()\n  File "/usr/lib/python3.4/http/client.py", line 1205, in connect\n    server_hostname=server_hostname)\n  File "/usr/lib/python3.4/ssl.py", line 364, in wrap_socket\n    _context=self)\n  File "/usr/lib/python3.4/ssl.py", line 578, in __init__\n    self.do_handshake()\n  File "/usr/lib/python3.4/ssl.py", line 805, in do_handshake\n    self._sslobj.do_handshake()\nConnectionResetError: [Errno 104] Connection reset by peer\n')
('2015-03-21 11:29:49.545872', 'Traceback (most recent call last):\n  File "/river/fd/fd_worker/fd_channel.py", line 204, in create_channel\n    handle.connect()\n  File "/usr/lib/python3.4/http/client.py", line 1205, in connect\n    server_hostname=server_hostname)\n  File "/usr/lib/python3.4/ssl.py", line 364, in wrap_socket\n    _context=self)\n  File "/usr/lib/python3.4/ssl.py", line 578, in __init__\n    self.do_handshake()\n  File "/usr/lib/python3.4/ssl.py", line 805, in do_handshake\n    self._sslobj.do_handshake()\nConnectionResetError: [Errno 104] Connection reset by peer\n')
('2015-03-21 11:29:53.466412', 'Traceback (most recent call last):\n  File "/river/fd/fd_worker/fd_channel.py", line 204, in create_channel\n    handle.connect()\n  File "/usr/lib/python3.4/http/client.py", line 1205, in connect\n    server_hostname=server_hostname)\n  File "/usr/lib/python3.4/ssl.py", line 364, in wrap_socket\n    _context=self)\n  File "/usr/lib/python3.4/ssl.py", line 578, in __init__\n    self.do_handshake()\n  File "/usr/lib/python3.4/ssl.py", line 805, in do_handshake\n    self._sslobj.do_handshake()\nConnectionResetError: [Errno 104] Connection reset by peer\n')
('2015-03-21 11:29:54.847316', 'Traceback (most recent call last):\n  File "/river/fd/fd_worker/fd_channel.py", line 204, in create_channel\n    handle.connect()\n  File "/usr/lib/python3.4/http/client.py", line 1205, in connect\n    server_hostname=server_hostname)\n  File "/usr/lib/python3.4/ssl.py", line 364, in wrap_socket\n    _context=self)\n  File "/usr/lib/python3.4/ssl.py", line 578, in __init__\n    self.do_handshake()\n  File "/usr/lib/python3.4/ssl.py", line 805, in do_handshake\n    self._sslobj.do_handshake()\nConnectionResetError: [Errno 104] Connection reset by peer\n')
('2015-03-21 11:29:57.016288', 'Traceback (most recent call last):\n  File "/river/fd/fd_worker/fd_channel.py", line 204, in create_channel\n    handle.connect()\n  File "/usr/lib/python3.4/http/client.py", line 1205, in connect\n    server_hostname=server_hostname)\n  File "/usr/lib/python3.4/ssl.py", line 364, in wrap_socket\n    _context=self)\n  File "/usr/lib/python3.4/ssl.py", line 578, in __init__\n    self.do_handshake()\n  File "/usr/lib/python3.4/ssl.py", line 805, in do_handshake\n    self._sslobj.do_handshake()\nConnectionResetError: [Errno 104] Connection reset by peer\n')
('2015-03-21 11:29:58.067306', 'Traceback (most recent call last):\n  File "/river/fd/fd_worker/fd_channel.py", line 204, in create_channel\n    handle.connect()\n  File "/usr/lib/python3.4/http/client.py", line 1205, in connect\n    server_hostname=server_hostname)\n  File "/usr/lib/python3.4/ssl.py", line 364, in wrap_socket\n    _context=self)\n  File "/usr/lib/python3.4/ssl.py", line 578, in __init__\n    self.do_handshake()\n  File "/usr/lib/python3.4/ssl.py", line 805, in do_handshake\n    self._sslobj.do_handshake()\nConnectionResetError: [Errno 104] Connection reset by peer\n')
('2015-03-21 11:29:58.546779', 'Traceback (most recent call last):\n  File "/river/fd/fd_worker/fd_channel.py", line 204, in create_channel\n    handle.connect()\n  File "/usr/lib/python3.4/http/client.py", line 1205, in connect\n    server_hostname=server_hostname)\n  File "/usr/lib/python3.4/ssl.py", line 364, in wrap_socket\n    _context=self)\n  File "/usr/lib/python3.4/ssl.py", line 578, in __init__\n    self.do_handshake()\n  File "/usr/lib/python3.4/ssl.py", line 805, in do_handshake\n    self._sslobj.do_handshake()\nConnectionResetError: [Errno 104] Connection reset by peer\n')
('2015-03-21 11:30:10.283454', 'Traceback (most recent call last):\n  File "/river/fd/fd_worker/fd_channel.py", line 204, in create_channel\n    handle.connect()\n  File "/usr/lib/python3.4/http/client.py", line 1197, in connect\n    self.timeout, self.source_address)\n  File "/usr/lib/python3.4/socket.py", line 509, in create_connection\n    raise err\n  File "/usr/lib/python3.4/socket.py", line 500, in create_connection\n    sock.connect(sa)\nTimeoutError: [Errno 110] Connection timed out\n')
('2015-03-21 11:30:11.571270', 'Traceback (most recent call last):\n  File "/river/fd/fd_worker/fd_channel.py", line 204, in create_channel\n    handle.connect()\n  File "/usr/lib/python3.4/http/client.py", line 1205, in connect\n    server_hostname=server_hostname)\n  File "/usr/lib/python3.4/ssl.py", line 364, in wrap_socket\n    _context=self)\n  File "/usr/lib/python3.4/ssl.py", line 578, in __init__\n    self.do_handshake()\n  File "/usr/lib/python3.4/ssl.py", line 805, in do_handshake\n    self._sslobj.do_handshake()\nConnectionResetError: [Errno 104] Connection reset by peer\n')
('2015-03-21 11:30:19.190189', 'Traceback (most recent call last):\n  File "/river/fd/fd_worker/fd_channel.py", line 204, in create_channel\n    handle.connect()\n  File "/usr/lib/python3.4/http/client.py", line 1205, in connect\n    server_hostname=server_hostname)\n  File "/usr/lib/python3.4/ssl.py", line 364, in wrap_socket\n    _context=self)\n  File "/usr/lib/python3.4/ssl.py", line 578, in __init__\n    self.do_handshake()\n  File "/usr/lib/python3.4/ssl.py", line 805, in do_handshake\n    self._sslobj.do_handshake()\nConnectionResetError: [Errno 104] Connection reset by peer\n')
('2015-03-21 11:30:31.275521', 'Traceback (most recent call last):\n  File "/river/fd/fd_worker/fd_channel.py", line 204, in create_channel\n    handle.connect()\n  File "/usr/lib/python3.4/http/client.py", line 1197, in connect\n    self.timeout, self.source_address)\n  File "/usr/lib/python3.4/socket.py", line 509, in create_connection\n    raise err\n  File "/usr/lib/python3.4/socket.py", line 500, in create_connection\n    sock.connect(sa)\nTimeoutError: [Errno 110] Connection timed out\n')
('2015-03-21 11:30:37.291585', 'Traceback (most recent call last):\n  File "/river/fd/fd_worker/fd_channel.py", line 204, in create_channel\n    handle.connect()\n  File "/usr/lib/python3.4/http/client.py", line 1197, in connect\n    self.timeout, self.source_address)\n  File "/usr/lib/python3.4/socket.py", line 509, in create_connection\n    raise err\n  File "/usr/lib/python3.4/socket.py", line 500, in create_connection\n    sock.connect(sa)\nTimeoutError: [Errno 110] Connection timed out\n')
('2015-03-21 11:30:38.699539', 'Traceback (most recent call last):\n  File "/river/fd/fd_worker/fd_channel.py", line 204, in create_channel\n    handle.connect()\n  File "/usr/lib/python3.4/http/client.py", line 1197, in connect\n    self.timeout, self.source_address)\n  File "/usr/lib/python3.4/socket.py", line 509, in create_connection\n    raise err\n  File "/usr/lib/python3.4/socket.py", line 500, in create_connection\n    sock.connect(sa)\nTimeoutError: [Errno 110] Connection timed out\n')
('2015-03-21 11:30:43.307540', 'Traceback (most recent call last):\n  File "/river/fd/fd_worker/fd_channel.py", line 204, in create_channel\n    handle.connect()\n  File "/usr/lib/python3.4/http/client.py", line 1197, in connect\n    self.timeout, self.source_address)\n  File "/usr/lib/python3.4/socket.py", line 509, in create_connection\n    raise err\n  File "/usr/lib/python3.4/socket.py", line 500, in create_connection\n    sock.connect(sa)\nTimeoutError: [Errno 110] Connection timed out\n')
('2015-03-21 11:30:47.787447', 'Traceback (most recent call last):\n  File "/river/fd/fd_worker/fd_channel.py", line 204, in create_channel\n    handle.connect()\n  File "/usr/lib/python3.4/http/client.py", line 1197, in connect\n    self.timeout, self.source_address)\n  File "/usr/lib/python3.4/socket.py", line 509, in create_connection\n    raise err\n  File "/usr/lib/python3.4/socket.py", line 500, in create_connection\n    sock.connect(sa)\nTimeoutError: [Errno 110] Connection timed out\n')
('2015-03-21 11:30:55.211537', 'Traceback (most recent call last):\n  File "/river/fd/fd_worker/fd_channel.py", line 204, in create_channel\n    handle.connect()\n  File "/usr/lib/python3.4/http/client.py", line 1197, in connect\n    self.timeout, self.source_address)\n  File "/usr/lib/python3.4/socket.py", line 509, in create_connection\n    raise err\n  File "/usr/lib/python3.4/socket.py", line 500, in create_connection\n    sock.connect(sa)\nTimeoutError: [Errno 110] Connection timed out\n')
('2015-03-21 11:31:01.227486', 'Traceback (most recent call last):\n  File "/river/fd/fd_worker/fd_channel.py", line 204, in create_channel\n    handle.connect()\n  File "/usr/lib/python3.4/http/client.py", line 1197, in connect\n    self.timeout, self.source_address)\n  File "/usr/lib/python3.4/socket.py", line 509, in create_connection\n    raise err\n  File "/usr/lib/python3.4/socket.py", line 500, in create_connection\n    sock.connect(sa)\nTimeoutError: [Errno 110] Connection timed out\n')
