('2015-03-21 10:33:33.088980', 'Traceback (most recent call last):\n  File "/river/fd/fd_worker/fd_channel.py", line 204, in create_channel\n    handle.connect()\n  File "/usr/lib/python3.4/http/client.py", line 1205, in connect\n    server_hostname=server_hostname)\n  File "/usr/lib/python3.4/ssl.py", line 364, in wrap_socket\n    _context=self)\n  File "/usr/lib/python3.4/ssl.py", line 578, in __init__\n    self.do_handshake()\n  File "/usr/lib/python3.4/ssl.py", line 805, in do_handshake\n    self._sslobj.do_handshake()\nConnectionResetError: [Errno 104] Connection reset by peer\n')
('2015-03-21 10:33:33.270618', 'Traceback (most recent call last):\n  File "/river/fd/fd_worker/fd_channel.py", line 204, in create_channel\n    handle.connect()\n  File "/usr/lib/python3.4/http/client.py", line 1205, in connect\n    server_hostname=server_hostname)\n  File "/usr/lib/python3.4/ssl.py", line 364, in wrap_socket\n    _context=self)\n  File "/usr/lib/python3.4/ssl.py", line 578, in __init__\n    self.do_handshake()\n  File "/usr/lib/python3.4/ssl.py", line 805, in do_handshake\n    self._sslobj.do_handshake()\nConnectionResetError: [Errno 104] Connection reset by peer\n')
('2015-03-21 10:33:38.166025', 'Traceback (most recent call last):\n  File "/river/fd/fd_worker/fd_channel.py", line 204, in create_channel\n    handle.connect()\n  File "/usr/lib/python3.4/http/client.py", line 1205, in connect\n    server_hostname=server_hostname)\n  File "/usr/lib/python3.4/ssl.py", line 364, in wrap_socket\n    _context=self)\n  File "/usr/lib/python3.4/ssl.py", line 578, in __init__\n    self.do_handshake()\n  File "/usr/lib/python3.4/ssl.py", line 805, in do_handshake\n    self._sslobj.do_handshake()\nConnectionResetError: [Errno 104] Connection reset by peer\n')
('2015-03-21 10:34:09.134945', 'Traceback (most recent call last):\n  File "/river/fd/fd_worker/fd_channel.py", line 204, in create_channel\n    handle.connect()\n  File "/usr/lib/python3.4/http/client.py", line 1205, in connect\n    server_hostname=server_hostname)\n  File "/usr/lib/python3.4/ssl.py", line 364, in wrap_socket\n    _context=self)\n  File "/usr/lib/python3.4/ssl.py", line 578, in __init__\n    self.do_handshake()\n  File "/usr/lib/python3.4/ssl.py", line 805, in do_handshake\n    self._sslobj.do_handshake()\nConnectionResetError: [Errno 104] Connection reset by peer\n')
('2015-03-21 10:34:09.269922', 'Traceback (most recent call last):\n  File "/river/fd/fd_worker/fd_channel.py", line 204, in create_channel\n    handle.connect()\n  File "/usr/lib/python3.4/http/client.py", line 1205, in connect\n    server_hostname=server_hostname)\n  File "/usr/lib/python3.4/ssl.py", line 364, in wrap_socket\n    _context=self)\n  File "/usr/lib/python3.4/ssl.py", line 578, in __init__\n    self.do_handshake()\n  File "/usr/lib/python3.4/ssl.py", line 805, in do_handshake\n    self._sslobj.do_handshake()\nConnectionResetError: [Errno 104] Connection reset by peer\n')
('2015-03-21 10:34:11.590225', 'Traceback (most recent call last):\n  File "/river/fd/fd_worker/fd_channel.py", line 204, in create_channel\n    handle.connect()\n  File "/usr/lib/python3.4/http/client.py", line 1205, in connect\n    server_hostname=server_hostname)\n  File "/usr/lib/python3.4/ssl.py", line 364, in wrap_socket\n    _context=self)\n  File "/usr/lib/python3.4/ssl.py", line 578, in __init__\n    self.do_handshake()\n  File "/usr/lib/python3.4/ssl.py", line 805, in do_handshake\n    self._sslobj.do_handshake()\nConnectionResetError: [Errno 104] Connection reset by peer\n')
('2015-03-21 10:34:13.030618', 'Traceback (most recent call last):\n  File "/river/fd/fd_worker/fd_channel.py", line 204, in create_channel\n    handle.connect()\n  File "/usr/lib/python3.4/http/client.py", line 1205, in connect\n    server_hostname=server_hostname)\n  File "/usr/lib/python3.4/ssl.py", line 364, in wrap_socket\n    _context=self)\n  File "/usr/lib/python3.4/ssl.py", line 578, in __init__\n    self.do_handshake()\n  File "/usr/lib/python3.4/ssl.py", line 805, in do_handshake\n    self._sslobj.do_handshake()\nConnectionResetError: [Errno 104] Connection reset by peer\n')
('2015-03-21 10:34:13.078531', 'Traceback (most recent call last):\n  File "/river/fd/fd_worker/fd_channel.py", line 204, in create_channel\n    handle.connect()\n  File "/usr/lib/python3.4/http/client.py", line 1205, in connect\n    server_hostname=server_hostname)\n  File "/usr/lib/python3.4/ssl.py", line 364, in wrap_socket\n    _context=self)\n  File "/usr/lib/python3.4/ssl.py", line 578, in __init__\n    self.do_handshake()\n  File "/usr/lib/python3.4/ssl.py", line 805, in do_handshake\n    self._sslobj.do_handshake()\nConnectionResetError: [Errno 104] Connection reset by peer\n')
('2015-03-21 10:34:14.166562', 'Traceback (most recent call last):\n  File "/river/fd/fd_worker/fd_channel.py", line 204, in create_channel\n    handle.connect()\n  File "/usr/lib/python3.4/http/client.py", line 1205, in connect\n    server_hostname=server_hostname)\n  File "/usr/lib/python3.4/ssl.py", line 364, in wrap_socket\n    _context=self)\n  File "/usr/lib/python3.4/ssl.py", line 578, in __init__\n    self.do_handshake()\n  File "/usr/lib/python3.4/ssl.py", line 805, in do_handshake\n    self._sslobj.do_handshake()\nConnectionResetError: [Errno 104] Connection reset by peer\n')
('2015-03-21 10:34:14.582108', 'Traceback (most recent call last):\n  File "/river/fd/fd_worker/fd_channel.py", line 204, in create_channel\n    handle.connect()\n  File "/usr/lib/python3.4/http/client.py", line 1205, in connect\n    server_hostname=server_hostname)\n  File "/usr/lib/python3.4/ssl.py", line 364, in wrap_socket\n    _context=self)\n  File "/usr/lib/python3.4/ssl.py", line 578, in __init__\n    self.do_handshake()\n  File "/usr/lib/python3.4/ssl.py", line 805, in do_handshake\n    self._sslobj.do_handshake()\nConnectionResetError: [Errno 104] Connection reset by peer\n')
('2015-03-21 10:34:17.175428', 'Traceback (most recent call last):\n  File "/river/fd/fd_worker/fd_channel.py", line 204, in create_channel\n    handle.connect()\n  File "/usr/lib/python3.4/http/client.py", line 1205, in connect\n    server_hostname=server_hostname)\n  File "/usr/lib/python3.4/ssl.py", line 364, in wrap_socket\n    _context=self)\n  File "/usr/lib/python3.4/ssl.py", line 578, in __init__\n    self.do_handshake()\n  File "/usr/lib/python3.4/ssl.py", line 805, in do_handshake\n    self._sslobj.do_handshake()\nConnectionResetError: [Errno 104] Connection reset by peer\n')
('2015-03-21 10:34:17.558632', 'Traceback (most recent call last):\n  File "/river/fd/fd_worker/fd_channel.py", line 204, in create_channel\n    handle.connect()\n  File "/usr/lib/python3.4/http/client.py", line 1205, in connect\n    server_hostname=server_hostname)\n  File "/usr/lib/python3.4/ssl.py", line 364, in wrap_socket\n    _context=self)\n  File "/usr/lib/python3.4/ssl.py", line 578, in __init__\n    self.do_handshake()\n  File "/usr/lib/python3.4/ssl.py", line 805, in do_handshake\n    self._sslobj.do_handshake()\nConnectionResetError: [Errno 104] Connection reset by peer\n')
('2015-03-21 10:34:18.678886', 'Traceback (most recent call last):\n  File "/river/fd/fd_worker/fd_channel.py", line 204, in create_channel\n    handle.connect()\n  File "/usr/lib/python3.4/http/client.py", line 1205, in connect\n    server_hostname=server_hostname)\n  File "/usr/lib/python3.4/ssl.py", line 364, in wrap_socket\n    _context=self)\n  File "/usr/lib/python3.4/ssl.py", line 578, in __init__\n    self.do_handshake()\n  File "/usr/lib/python3.4/ssl.py", line 805, in do_handshake\n    self._sslobj.do_handshake()\nConnectionResetError: [Errno 104] Connection reset by peer\n')
('2015-03-21 10:34:20.182026', 'Traceback (most recent call last):\n  File "/river/fd/fd_worker/fd_channel.py", line 204, in create_channel\n    handle.connect()\n  File "/usr/lib/python3.4/http/client.py", line 1205, in connect\n    server_hostname=server_hostname)\n  File "/usr/lib/python3.4/ssl.py", line 364, in wrap_socket\n    _context=self)\n  File "/usr/lib/python3.4/ssl.py", line 578, in __init__\n    self.do_handshake()\n  File "/usr/lib/python3.4/ssl.py", line 805, in do_handshake\n    self._sslobj.do_handshake()\nConnectionResetError: [Errno 104] Connection reset by peer\n')
('2015-03-21 10:34:52.534015', 'Traceback (most recent call last):\n  File "/river/fd/fd_worker/fd_channel.py", line 204, in create_channel\n    handle.connect()\n  File "/usr/lib/python3.4/http/client.py", line 1205, in connect\n    server_hostname=server_hostname)\n  File "/usr/lib/python3.4/ssl.py", line 364, in wrap_socket\n    _context=self)\n  File "/usr/lib/python3.4/ssl.py", line 578, in __init__\n    self.do_handshake()\n  File "/usr/lib/python3.4/ssl.py", line 805, in do_handshake\n    self._sslobj.do_handshake()\nConnectionResetError: [Errno 104] Connection reset by peer\n')
('2015-03-21 10:34:52.706418', 'Traceback (most recent call last):\n  File "/river/fd/fd_worker/fd_channel.py", line 204, in create_channel\n    handle.connect()\n  File "/usr/lib/python3.4/http/client.py", line 1205, in connect\n    server_hostname=server_hostname)\n  File "/usr/lib/python3.4/ssl.py", line 364, in wrap_socket\n    _context=self)\n  File "/usr/lib/python3.4/ssl.py", line 578, in __init__\n    self.do_handshake()\n  File "/usr/lib/python3.4/ssl.py", line 805, in do_handshake\n    self._sslobj.do_handshake()\nConnectionResetError: [Errno 104] Connection reset by peer\n')
('2015-03-21 10:34:52.770526', 'Traceback (most recent call last):\n  File "/river/fd/fd_worker/fd_channel.py", line 204, in create_channel\n    handle.connect()\n  File "/usr/lib/python3.4/http/client.py", line 1205, in connect\n    server_hostname=server_hostname)\n  File "/usr/lib/python3.4/ssl.py", line 364, in wrap_socket\n    _context=self)\n  File "/usr/lib/python3.4/ssl.py", line 578, in __init__\n    self.do_handshake()\n  File "/usr/lib/python3.4/ssl.py", line 805, in do_handshake\n    self._sslobj.do_handshake()\nConnectionResetError: [Errno 104] Connection reset by peer\n')
('2015-03-21 10:34:53.046506', 'Traceback (most recent call last):\n  File "/river/fd/fd_worker/fd_channel.py", line 204, in create_channel\n    handle.connect()\n  File "/usr/lib/python3.4/http/client.py", line 1205, in connect\n    server_hostname=server_hostname)\n  File "/usr/lib/python3.4/ssl.py", line 364, in wrap_socket\n    _context=self)\n  File "/usr/lib/python3.4/ssl.py", line 578, in __init__\n    self.do_handshake()\n  File "/usr/lib/python3.4/ssl.py", line 805, in do_handshake\n    self._sslobj.do_handshake()\nConnectionResetError: [Errno 104] Connection reset by peer\n')
('2015-03-21 10:34:53.174715', 'Traceback (most recent call last):\n  File "/river/fd/fd_worker/fd_channel.py", line 204, in create_channel\n    handle.connect()\n  File "/usr/lib/python3.4/http/client.py", line 1205, in connect\n    server_hostname=server_hostname)\n  File "/usr/lib/python3.4/ssl.py", line 364, in wrap_socket\n    _context=self)\n  File "/usr/lib/python3.4/ssl.py", line 578, in __init__\n    self.do_handshake()\n  File "/usr/lib/python3.4/ssl.py", line 805, in do_handshake\n    self._sslobj.do_handshake()\nConnectionResetError: [Errno 104] Connection reset by peer\n')
('2015-03-21 10:34:53.590559', 'Traceback (most recent call last):\n  File "/river/fd/fd_worker/fd_channel.py", line 204, in create_channel\n    handle.connect()\n  File "/usr/lib/python3.4/http/client.py", line 1205, in connect\n    server_hostname=server_hostname)\n  File "/usr/lib/python3.4/ssl.py", line 364, in wrap_socket\n    _context=self)\n  File "/usr/lib/python3.4/ssl.py", line 578, in __init__\n    self.do_handshake()\n  File "/usr/lib/python3.4/ssl.py", line 805, in do_handshake\n    self._sslobj.do_handshake()\nConnectionResetError: [Errno 104] Connection reset by peer\n')
('2015-03-21 10:34:54.464811', 'Traceback (most recent call last):\n  File "/river/fd/fd_worker/fd_channel.py", line 144, in pyget\n    ack  = handle.getresponse()\n  File "/usr/lib/python3.4/http/client.py", line 1147, in getresponse\n    response.begin()\n  File "/usr/lib/python3.4/http/client.py", line 351, in begin\n    version, status, reason = self._read_status()\n  File "/usr/lib/python3.4/http/client.py", line 313, in _read_status\n    line = str(self.fp.readline(_MAXLINE + 1), "iso-8859-1")\n  File "/usr/lib/python3.4/socket.py", line 371, in readinto\n    return self._sock.recv_into(b)\n  File "/usr/lib/python3.4/ssl.py", line 746, in recv_into\n    return self.read(nbytes, buffer)\n  File "/usr/lib/python3.4/ssl.py", line 618, in read\n    v = self._sslobj.read(len, buffer)\nConnectionResetError: [Errno 104] Connection reset by peer\n')
('2015-03-21 10:34:54.542606', 'Traceback (most recent call last):\n  File "/river/fd/fd_worker/fd_channel.py", line 204, in create_channel\n    handle.connect()\n  File "/usr/lib/python3.4/http/client.py", line 1205, in connect\n    server_hostname=server_hostname)\n  File "/usr/lib/python3.4/ssl.py", line 364, in wrap_socket\n    _context=self)\n  File "/usr/lib/python3.4/ssl.py", line 578, in __init__\n    self.do_handshake()\n  File "/usr/lib/python3.4/ssl.py", line 805, in do_handshake\n    self._sslobj.do_handshake()\nConnectionResetError: [Errno 104] Connection reset by peer\n')
('2015-03-21 10:34:54.678170', 'Traceback (most recent call last):\n  File "/river/fd/fd_worker/fd_channel.py", line 204, in create_channel\n    handle.connect()\n  File "/usr/lib/python3.4/http/client.py", line 1205, in connect\n    server_hostname=server_hostname)\n  File "/usr/lib/python3.4/ssl.py", line 364, in wrap_socket\n    _context=self)\n  File "/usr/lib/python3.4/ssl.py", line 578, in __init__\n    self.do_handshake()\n  File "/usr/lib/python3.4/ssl.py", line 805, in do_handshake\n    self._sslobj.do_handshake()\nConnectionResetError: [Errno 104] Connection reset by peer\n')
('2015-03-21 10:34:55.022551', 'Traceback (most recent call last):\n  File "/river/fd/fd_worker/fd_channel.py", line 204, in create_channel\n    handle.connect()\n  File "/usr/lib/python3.4/http/client.py", line 1205, in connect\n    server_hostname=server_hostname)\n  File "/usr/lib/python3.4/ssl.py", line 364, in wrap_socket\n    _context=self)\n  File "/usr/lib/python3.4/ssl.py", line 578, in __init__\n    self.do_handshake()\n  File "/usr/lib/python3.4/ssl.py", line 805, in do_handshake\n    self._sslobj.do_handshake()\nConnectionResetError: [Errno 104] Connection reset by peer\n')
('2015-03-21 10:34:55.100595', 'Traceback (most recent call last):\n  File "/river/fd/fd_worker/fd_channel.py", line 204, in create_channel\n    handle.connect()\n  File "/usr/lib/python3.4/http/client.py", line 1205, in connect\n    server_hostname=server_hostname)\n  File "/usr/lib/python3.4/ssl.py", line 364, in wrap_socket\n    _context=self)\n  File "/usr/lib/python3.4/ssl.py", line 578, in __init__\n    self.do_handshake()\n  File "/usr/lib/python3.4/ssl.py", line 805, in do_handshake\n    self._sslobj.do_handshake()\nConnectionResetError: [Errno 104] Connection reset by peer\n')
('2015-03-21 10:34:56.182715', 'Traceback (most recent call last):\n  File "/river/fd/fd_worker/fd_channel.py", line 204, in create_channel\n    handle.connect()\n  File "/usr/lib/python3.4/http/client.py", line 1205, in connect\n    server_hostname=server_hostname)\n  File "/usr/lib/python3.4/ssl.py", line 364, in wrap_socket\n    _context=self)\n  File "/usr/lib/python3.4/ssl.py", line 578, in __init__\n    self.do_handshake()\n  File "/usr/lib/python3.4/ssl.py", line 805, in do_handshake\n    self._sslobj.do_handshake()\nConnectionResetError: [Errno 104] Connection reset by peer\n')
('2015-03-21 10:34:56.582504', 'Traceback (most recent call last):\n  File "/river/fd/fd_worker/fd_channel.py", line 204, in create_channel\n    handle.connect()\n  File "/usr/lib/python3.4/http/client.py", line 1205, in connect\n    server_hostname=server_hostname)\n  File "/usr/lib/python3.4/ssl.py", line 364, in wrap_socket\n    _context=self)\n  File "/usr/lib/python3.4/ssl.py", line 578, in __init__\n    self.do_handshake()\n  File "/usr/lib/python3.4/ssl.py", line 805, in do_handshake\n    self._sslobj.do_handshake()\nConnectionResetError: [Errno 104] Connection reset by peer\n')
('2015-03-21 10:34:57.046100', 'Traceback (most recent call last):\n  File "/river/fd/fd_worker/fd_channel.py", line 204, in create_channel\n    handle.connect()\n  File "/usr/lib/python3.4/http/client.py", line 1205, in connect\n    server_hostname=server_hostname)\n  File "/usr/lib/python3.4/ssl.py", line 364, in wrap_socket\n    _context=self)\n  File "/usr/lib/python3.4/ssl.py", line 578, in __init__\n    self.do_handshake()\n  File "/usr/lib/python3.4/ssl.py", line 805, in do_handshake\n    self._sslobj.do_handshake()\nConnectionResetError: [Errno 104] Connection reset by peer\n')
('2015-03-21 10:34:59.573997', 'Traceback (most recent call last):\n  File "/river/fd/fd_worker/fd_channel.py", line 204, in create_channel\n    handle.connect()\n  File "/usr/lib/python3.4/http/client.py", line 1205, in connect\n    server_hostname=server_hostname)\n  File "/usr/lib/python3.4/ssl.py", line 364, in wrap_socket\n    _context=self)\n  File "/usr/lib/python3.4/ssl.py", line 578, in __init__\n    self.do_handshake()\n  File "/usr/lib/python3.4/ssl.py", line 805, in do_handshake\n    self._sslobj.do_handshake()\nConnectionResetError: [Errno 104] Connection reset by peer\n')
('2015-03-21 10:35:01.589876', 'Traceback (most recent call last):\n  File "/river/fd/fd_worker/fd_channel.py", line 204, in create_channel\n    handle.connect()\n  File "/usr/lib/python3.4/http/client.py", line 1205, in connect\n    server_hostname=server_hostname)\n  File "/usr/lib/python3.4/ssl.py", line 364, in wrap_socket\n    _context=self)\n  File "/usr/lib/python3.4/ssl.py", line 578, in __init__\n    self.do_handshake()\n  File "/usr/lib/python3.4/ssl.py", line 805, in do_handshake\n    self._sslobj.do_handshake()\nConnectionResetError: [Errno 104] Connection reset by peer\n')
('2015-03-21 10:35:03.061972', 'Traceback (most recent call last):\n  File "/river/fd/fd_worker/fd_channel.py", line 204, in create_channel\n    handle.connect()\n  File "/usr/lib/python3.4/http/client.py", line 1205, in connect\n    server_hostname=server_hostname)\n  File "/usr/lib/python3.4/ssl.py", line 364, in wrap_socket\n    _context=self)\n  File "/usr/lib/python3.4/ssl.py", line 578, in __init__\n    self.do_handshake()\n  File "/usr/lib/python3.4/ssl.py", line 805, in do_handshake\n    self._sslobj.do_handshake()\nConnectionResetError: [Errno 104] Connection reset by peer\n')
('2015-03-21 10:35:03.670656', 'Traceback (most recent call last):\n  File "/river/fd/fd_worker/fd_channel.py", line 204, in create_channel\n    handle.connect()\n  File "/usr/lib/python3.4/http/client.py", line 1205, in connect\n    server_hostname=server_hostname)\n  File "/usr/lib/python3.4/ssl.py", line 364, in wrap_socket\n    _context=self)\n  File "/usr/lib/python3.4/ssl.py", line 578, in __init__\n    self.do_handshake()\n  File "/usr/lib/python3.4/ssl.py", line 805, in do_handshake\n    self._sslobj.do_handshake()\nConnectionResetError: [Errno 104] Connection reset by peer\n')
('2015-03-21 10:35:10.838541', 'Traceback (most recent call last):\n  File "/river/fd/fd_worker/fd_channel.py", line 144, in pyget\n    ack  = handle.getresponse()\n  File "/usr/lib/python3.4/http/client.py", line 1147, in getresponse\n    response.begin()\n  File "/usr/lib/python3.4/http/client.py", line 351, in begin\n    version, status, reason = self._read_status()\n  File "/usr/lib/python3.4/http/client.py", line 313, in _read_status\n    line = str(self.fp.readline(_MAXLINE + 1), "iso-8859-1")\n  File "/usr/lib/python3.4/socket.py", line 371, in readinto\n    return self._sock.recv_into(b)\n  File "/usr/lib/python3.4/ssl.py", line 746, in recv_into\n    return self.read(nbytes, buffer)\n  File "/usr/lib/python3.4/ssl.py", line 618, in read\n    v = self._sslobj.read(len, buffer)\nConnectionResetError: [Errno 104] Connection reset by peer\n')
('2015-03-21 10:35:28.277198', 'Traceback (most recent call last):\n  File "/river/fd/fd_worker/fd_channel.py", line 204, in create_channel\n    handle.connect()\n  File "/usr/lib/python3.4/http/client.py", line 1197, in connect\n    self.timeout, self.source_address)\n  File "/usr/lib/python3.4/socket.py", line 509, in create_connection\n    raise err\n  File "/usr/lib/python3.4/socket.py", line 500, in create_connection\n    sock.connect(sa)\nTimeoutError: [Errno 110] Connection timed out\n')
('2015-03-21 10:35:44.789018', 'Traceback (most recent call last):\n  File "/river/fd/fd_worker/fd_channel.py", line 204, in create_channel\n    handle.connect()\n  File "/usr/lib/python3.4/http/client.py", line 1197, in connect\n    self.timeout, self.source_address)\n  File "/usr/lib/python3.4/socket.py", line 509, in create_connection\n    raise err\n  File "/usr/lib/python3.4/socket.py", line 500, in create_connection\n    sock.connect(sa)\nTimeoutError: [Errno 110] Connection timed out\n')
('2015-03-21 10:35:58.229169', 'Traceback (most recent call last):\n  File "/river/fd/fd_worker/fd_channel.py", line 204, in create_channel\n    handle.connect()\n  File "/usr/lib/python3.4/http/client.py", line 1197, in connect\n    self.timeout, self.source_address)\n  File "/usr/lib/python3.4/socket.py", line 509, in create_connection\n    raise err\n  File "/usr/lib/python3.4/socket.py", line 500, in create_connection\n    sock.connect(sa)\nTimeoutError: [Errno 110] Connection timed out\n')
('2015-03-21 10:35:59.765114', 'Traceback (most recent call last):\n  File "/river/fd/fd_worker/fd_channel.py", line 204, in create_channel\n    handle.connect()\n  File "/usr/lib/python3.4/http/client.py", line 1197, in connect\n    self.timeout, self.source_address)\n  File "/usr/lib/python3.4/socket.py", line 509, in create_connection\n    raise err\n  File "/usr/lib/python3.4/socket.py", line 500, in create_connection\n    sock.connect(sa)\nTimeoutError: [Errno 110] Connection timed out\n')
('2015-03-21 10:36:04.246374', 'Traceback (most recent call last):\n  File "/river/fd/fd_worker/fd_channel.py", line 204, in create_channel\n    handle.connect()\n  File "/usr/lib/python3.4/http/client.py", line 1205, in connect\n    server_hostname=server_hostname)\n  File "/usr/lib/python3.4/ssl.py", line 364, in wrap_socket\n    _context=self)\n  File "/usr/lib/python3.4/ssl.py", line 578, in __init__\n    self.do_handshake()\n  File "/usr/lib/python3.4/ssl.py", line 805, in do_handshake\n    self._sslobj.do_handshake()\nConnectionResetError: [Errno 104] Connection reset by peer\n')
('2015-03-21 10:36:05.781422', 'Traceback (most recent call last):\n  File "/river/fd/fd_worker/fd_channel.py", line 204, in create_channel\n    handle.connect()\n  File "/usr/lib/python3.4/http/client.py", line 1197, in connect\n    self.timeout, self.source_address)\n  File "/usr/lib/python3.4/socket.py", line 509, in create_connection\n    raise err\n  File "/usr/lib/python3.4/socket.py", line 500, in create_connection\n    sock.connect(sa)\nTimeoutError: [Errno 110] Connection timed out\n')
('2015-03-21 10:36:07.190218', 'Traceback (most recent call last):\n  File "/river/fd/fd_worker/fd_channel.py", line 204, in create_channel\n    handle.connect()\n  File "/usr/lib/python3.4/http/client.py", line 1205, in connect\n    server_hostname=server_hostname)\n  File "/usr/lib/python3.4/ssl.py", line 364, in wrap_socket\n    _context=self)\n  File "/usr/lib/python3.4/ssl.py", line 578, in __init__\n    self.do_handshake()\n  File "/usr/lib/python3.4/ssl.py", line 805, in do_handshake\n    self._sslobj.do_handshake()\nConnectionResetError: [Errno 104] Connection reset by peer\n')
('2015-03-21 10:36:07.317097', 'Traceback (most recent call last):\n  File "/river/fd/fd_worker/fd_channel.py", line 204, in create_channel\n    handle.connect()\n  File "/usr/lib/python3.4/http/client.py", line 1197, in connect\n    self.timeout, self.source_address)\n  File "/usr/lib/python3.4/socket.py", line 509, in create_connection\n    raise err\n  File "/usr/lib/python3.4/socket.py", line 500, in create_connection\n    sock.connect(sa)\nTimeoutError: [Errno 110] Connection timed out\n')
('2015-03-21 10:36:08.725091', 'Traceback (most recent call last):\n  File "/river/fd/fd_worker/fd_channel.py", line 204, in create_channel\n    handle.connect()\n  File "/usr/lib/python3.4/http/client.py", line 1197, in connect\n    self.timeout, self.source_address)\n  File "/usr/lib/python3.4/socket.py", line 509, in create_connection\n    raise err\n  File "/usr/lib/python3.4/socket.py", line 500, in create_connection\n    sock.connect(sa)\nTimeoutError: [Errno 110] Connection timed out\n')
('2015-03-21 10:36:22.293178', 'Traceback (most recent call last):\n  File "/river/fd/fd_worker/fd_channel.py", line 204, in create_channel\n    handle.connect()\n  File "/usr/lib/python3.4/http/client.py", line 1197, in connect\n    self.timeout, self.source_address)\n  File "/usr/lib/python3.4/socket.py", line 509, in create_connection\n    raise err\n  File "/usr/lib/python3.4/socket.py", line 500, in create_connection\n    sock.connect(sa)\nTimeoutError: [Errno 110] Connection timed out\n')
('2015-03-21 10:36:23.701121', 'Traceback (most recent call last):\n  File "/river/fd/fd_worker/fd_channel.py", line 204, in create_channel\n    handle.connect()\n  File "/usr/lib/python3.4/http/client.py", line 1197, in connect\n    self.timeout, self.source_address)\n  File "/usr/lib/python3.4/socket.py", line 509, in create_connection\n    raise err\n  File "/usr/lib/python3.4/socket.py", line 500, in create_connection\n    sock.connect(sa)\nTimeoutError: [Errno 110] Connection timed out\n')
('2015-03-21 10:36:27.142381', 'Traceback (most recent call last):\n  File "/river/fd/fd_worker/fd_channel.py", line 144, in pyget\n    ack  = handle.getresponse()\n  File "/usr/lib/python3.4/http/client.py", line 1147, in getresponse\n    response.begin()\n  File "/usr/lib/python3.4/http/client.py", line 351, in begin\n    version, status, reason = self._read_status()\n  File "/usr/lib/python3.4/http/client.py", line 321, in _read_status\n    raise BadStatusLine(line)\nhttp.client.BadStatusLine: \'\'\n')
('2015-03-21 10:36:29.717070', 'Traceback (most recent call last):\n  File "/river/fd/fd_worker/fd_channel.py", line 204, in create_channel\n    handle.connect()\n  File "/usr/lib/python3.4/http/client.py", line 1197, in connect\n    self.timeout, self.source_address)\n  File "/usr/lib/python3.4/socket.py", line 509, in create_connection\n    raise err\n  File "/usr/lib/python3.4/socket.py", line 500, in create_connection\n    sock.connect(sa)\nTimeoutError: [Errno 110] Connection timed out\n')
('2015-03-21 10:36:31.253089', 'Traceback (most recent call last):\n  File "/river/fd/fd_worker/fd_channel.py", line 204, in create_channel\n    handle.connect()\n  File "/usr/lib/python3.4/http/client.py", line 1197, in connect\n    self.timeout, self.source_address)\n  File "/usr/lib/python3.4/socket.py", line 509, in create_connection\n    raise err\n  File "/usr/lib/python3.4/socket.py", line 500, in create_connection\n    sock.connect(sa)\nTimeoutError: [Errno 110] Connection timed out\n')
('2015-03-21 10:36:32.789106', 'Traceback (most recent call last):\n  File "/river/fd/fd_worker/fd_channel.py", line 204, in create_channel\n    handle.connect()\n  File "/usr/lib/python3.4/http/client.py", line 1197, in connect\n    self.timeout, self.source_address)\n  File "/usr/lib/python3.4/socket.py", line 509, in create_connection\n    raise err\n  File "/usr/lib/python3.4/socket.py", line 500, in create_connection\n    sock.connect(sa)\nTimeoutError: [Errno 110] Connection timed out\n')
('2015-03-21 10:36:50.837077', 'Traceback (most recent call last):\n  File "/river/fd/fd_worker/fd_channel.py", line 204, in create_channel\n    handle.connect()\n  File "/usr/lib/python3.4/http/client.py", line 1197, in connect\n    self.timeout, self.source_address)\n  File "/usr/lib/python3.4/socket.py", line 509, in create_connection\n    raise err\n  File "/usr/lib/python3.4/socket.py", line 500, in create_connection\n    sock.connect(sa)\nTimeoutError: [Errno 110] Connection timed out\n')
('2015-03-21 10:36:52.245133', 'Traceback (most recent call last):\n  File "/river/fd/fd_worker/fd_channel.py", line 204, in create_channel\n    handle.connect()\n  File "/usr/lib/python3.4/http/client.py", line 1197, in connect\n    self.timeout, self.source_address)\n  File "/usr/lib/python3.4/socket.py", line 509, in create_connection\n    raise err\n  File "/usr/lib/python3.4/socket.py", line 500, in create_connection\n    sock.connect(sa)\nTimeoutError: [Errno 110] Connection timed out\n')
('2015-03-21 10:36:53.781095', 'Traceback (most recent call last):\n  File "/river/fd/fd_worker/fd_channel.py", line 204, in create_channel\n    handle.connect()\n  File "/usr/lib/python3.4/http/client.py", line 1197, in connect\n    self.timeout, self.source_address)\n  File "/usr/lib/python3.4/socket.py", line 509, in create_connection\n    raise err\n  File "/usr/lib/python3.4/socket.py", line 500, in create_connection\n    sock.connect(sa)\nTimeoutError: [Errno 110] Connection timed out\n')
('2015-03-21 10:36:55.189452', 'Traceback (most recent call last):\n  File "/river/fd/fd_worker/fd_channel.py", line 204, in create_channel\n    handle.connect()\n  File "/usr/lib/python3.4/http/client.py", line 1197, in connect\n    self.timeout, self.source_address)\n  File "/usr/lib/python3.4/socket.py", line 509, in create_connection\n    raise err\n  File "/usr/lib/python3.4/socket.py", line 500, in create_connection\n    sock.connect(sa)\nTimeoutError: [Errno 110] Connection timed out\n')
('2015-03-21 10:36:56.725112', 'Traceback (most recent call last):\n  File "/river/fd/fd_worker/fd_channel.py", line 204, in create_channel\n    handle.connect()\n  File "/usr/lib/python3.4/http/client.py", line 1197, in connect\n    self.timeout, self.source_address)\n  File "/usr/lib/python3.4/socket.py", line 509, in create_connection\n    raise err\n  File "/usr/lib/python3.4/socket.py", line 500, in create_connection\n    sock.connect(sa)\nTimeoutError: [Errno 110] Connection timed out\n')
('2015-03-21 10:36:58.261116', 'Traceback (most recent call last):\n  File "/river/fd/fd_worker/fd_channel.py", line 204, in create_channel\n    handle.connect()\n  File "/usr/lib/python3.4/http/client.py", line 1197, in connect\n    self.timeout, self.source_address)\n  File "/usr/lib/python3.4/socket.py", line 509, in create_connection\n    raise err\n  File "/usr/lib/python3.4/socket.py", line 500, in create_connection\n    sock.connect(sa)\nTimeoutError: [Errno 110] Connection timed out\n')
('2015-03-21 10:36:59.797350', 'Traceback (most recent call last):\n  File "/river/fd/fd_worker/fd_channel.py", line 204, in create_channel\n    handle.connect()\n  File "/usr/lib/python3.4/http/client.py", line 1197, in connect\n    self.timeout, self.source_address)\n  File "/usr/lib/python3.4/socket.py", line 509, in create_connection\n    raise err\n  File "/usr/lib/python3.4/socket.py", line 500, in create_connection\n    sock.connect(sa)\nTimeoutError: [Errno 110] Connection timed out\n')
('2015-03-21 10:37:01.333153', 'Traceback (most recent call last):\n  File "/river/fd/fd_worker/fd_channel.py", line 204, in create_channel\n    handle.connect()\n  File "/usr/lib/python3.4/http/client.py", line 1197, in connect\n    self.timeout, self.source_address)\n  File "/usr/lib/python3.4/socket.py", line 509, in create_connection\n    raise err\n  File "/usr/lib/python3.4/socket.py", line 500, in create_connection\n    sock.connect(sa)\nTimeoutError: [Errno 110] Connection timed out\n')
('2015-03-21 10:37:05.685220', 'Traceback (most recent call last):\n  File "/river/fd/fd_worker/fd_channel.py", line 204, in create_channel\n    handle.connect()\n  File "/usr/lib/python3.4/http/client.py", line 1197, in connect\n    self.timeout, self.source_address)\n  File "/usr/lib/python3.4/socket.py", line 509, in create_connection\n    raise err\n  File "/usr/lib/python3.4/socket.py", line 500, in create_connection\n    sock.connect(sa)\nTimeoutError: [Errno 110] Connection timed out\n')
('2015-03-21 10:37:07.221124', 'Traceback (most recent call last):\n  File "/river/fd/fd_worker/fd_channel.py", line 204, in create_channel\n    handle.connect()\n  File "/usr/lib/python3.4/http/client.py", line 1197, in connect\n    self.timeout, self.source_address)\n  File "/usr/lib/python3.4/socket.py", line 509, in create_connection\n    raise err\n  File "/usr/lib/python3.4/socket.py", line 500, in create_connection\n    sock.connect(sa)\nTimeoutError: [Errno 110] Connection timed out\n')
('2015-03-21 10:37:08.757098', 'Traceback (most recent call last):\n  File "/river/fd/fd_worker/fd_channel.py", line 204, in create_channel\n    handle.connect()\n  File "/usr/lib/python3.4/http/client.py", line 1197, in connect\n    self.timeout, self.source_address)\n  File "/usr/lib/python3.4/socket.py", line 509, in create_connection\n    raise err\n  File "/usr/lib/python3.4/socket.py", line 500, in create_connection\n    sock.connect(sa)\nTimeoutError: [Errno 110] Connection timed out\n')
('2015-03-21 10:37:13.237139', 'Traceback (most recent call last):\n  File "/river/fd/fd_worker/fd_channel.py", line 204, in create_channel\n    handle.connect()\n  File "/usr/lib/python3.4/http/client.py", line 1197, in connect\n    self.timeout, self.source_address)\n  File "/usr/lib/python3.4/socket.py", line 509, in create_connection\n    raise err\n  File "/usr/lib/python3.4/socket.py", line 500, in create_connection\n    sock.connect(sa)\nTimeoutError: [Errno 110] Connection timed out\n')
('2015-03-21 10:37:16.438227', 'Traceback (most recent call last):\n  File "/river/fd/fd_worker/fd_channel.py", line 144, in pyget\n    ack  = handle.getresponse()\n  File "/usr/lib/python3.4/http/client.py", line 1147, in getresponse\n    response.begin()\n  File "/usr/lib/python3.4/http/client.py", line 351, in begin\n    version, status, reason = self._read_status()\n  File "/usr/lib/python3.4/http/client.py", line 313, in _read_status\n    line = str(self.fp.readline(_MAXLINE + 1), "iso-8859-1")\n  File "/usr/lib/python3.4/socket.py", line 371, in readinto\n    return self._sock.recv_into(b)\n  File "/usr/lib/python3.4/ssl.py", line 746, in recv_into\n    return self.read(nbytes, buffer)\n  File "/usr/lib/python3.4/ssl.py", line 618, in read\n    v = self._sslobj.read(len, buffer)\nConnectionResetError: [Errno 104] Connection reset by peer\n')
('2015-03-21 10:37:23.733180', 'Traceback (most recent call last):\n  File "/river/fd/fd_worker/fd_channel.py", line 204, in create_channel\n    handle.connect()\n  File "/usr/lib/python3.4/http/client.py", line 1197, in connect\n    self.timeout, self.source_address)\n  File "/usr/lib/python3.4/socket.py", line 509, in create_connection\n    raise err\n  File "/usr/lib/python3.4/socket.py", line 500, in create_connection\n    sock.connect(sa)\nTimeoutError: [Errno 110] Connection timed out\n')
('2015-03-21 10:37:25.269189', 'Traceback (most recent call last):\n  File "/river/fd/fd_worker/fd_channel.py", line 204, in create_channel\n    handle.connect()\n  File "/usr/lib/python3.4/http/client.py", line 1197, in connect\n    self.timeout, self.source_address)\n  File "/usr/lib/python3.4/socket.py", line 509, in create_connection\n    raise err\n  File "/usr/lib/python3.4/socket.py", line 500, in create_connection\n    sock.connect(sa)\nTimeoutError: [Errno 110] Connection timed out\n')
('2015-03-21 10:37:26.677108', 'Traceback (most recent call last):\n  File "/river/fd/fd_worker/fd_channel.py", line 204, in create_channel\n    handle.connect()\n  File "/usr/lib/python3.4/http/client.py", line 1197, in connect\n    self.timeout, self.source_address)\n  File "/usr/lib/python3.4/socket.py", line 509, in create_connection\n    raise err\n  File "/usr/lib/python3.4/socket.py", line 500, in create_connection\n    sock.connect(sa)\nTimeoutError: [Errno 110] Connection timed out\n')
('2015-03-21 10:37:28.213105', 'Traceback (most recent call last):\n  File "/river/fd/fd_worker/fd_channel.py", line 204, in create_channel\n    handle.connect()\n  File "/usr/lib/python3.4/http/client.py", line 1197, in connect\n    self.timeout, self.source_address)\n  File "/usr/lib/python3.4/socket.py", line 509, in create_connection\n    raise err\n  File "/usr/lib/python3.4/socket.py", line 500, in create_connection\n    sock.connect(sa)\nTimeoutError: [Errno 110] Connection timed out\n')
('2015-03-21 10:37:29.749115', 'Traceback (most recent call last):\n  File "/river/fd/fd_worker/fd_channel.py", line 204, in create_channel\n    handle.connect()\n  File "/usr/lib/python3.4/http/client.py", line 1197, in connect\n    self.timeout, self.source_address)\n  File "/usr/lib/python3.4/socket.py", line 509, in create_connection\n    raise err\n  File "/usr/lib/python3.4/socket.py", line 500, in create_connection\n    sock.connect(sa)\nTimeoutError: [Errno 110] Connection timed out\n')
('2015-03-21 10:37:31.285379', 'Traceback (most recent call last):\n  File "/river/fd/fd_worker/fd_channel.py", line 204, in create_channel\n    handle.connect()\n  File "/usr/lib/python3.4/http/client.py", line 1197, in connect\n    self.timeout, self.source_address)\n  File "/usr/lib/python3.4/socket.py", line 509, in create_connection\n    raise err\n  File "/usr/lib/python3.4/socket.py", line 500, in create_connection\n    sock.connect(sa)\nTimeoutError: [Errno 110] Connection timed out\n')
('2015-03-21 10:37:38.709005', 'Traceback (most recent call last):\n  File "/river/fd/fd_worker/fd_channel.py", line 204, in create_channel\n    handle.connect()\n  File "/usr/lib/python3.4/http/client.py", line 1197, in connect\n    self.timeout, self.source_address)\n  File "/usr/lib/python3.4/socket.py", line 509, in create_connection\n    raise err\n  File "/usr/lib/python3.4/socket.py", line 500, in create_connection\n    sock.connect(sa)\nTimeoutError: [Errno 110] Connection timed out\n')
('2015-03-21 10:37:44.725111', 'Traceback (most recent call last):\n  File "/river/fd/fd_worker/fd_channel.py", line 204, in create_channel\n    handle.connect()\n  File "/usr/lib/python3.4/http/client.py", line 1197, in connect\n    self.timeout, self.source_address)\n  File "/usr/lib/python3.4/socket.py", line 509, in create_connection\n    raise err\n  File "/usr/lib/python3.4/socket.py", line 500, in create_connection\n    sock.connect(sa)\nTimeoutError: [Errno 110] Connection timed out\n')
('2015-03-21 10:37:46.261100', 'Traceback (most recent call last):\n  File "/river/fd/fd_worker/fd_channel.py", line 204, in create_channel\n    handle.connect()\n  File "/usr/lib/python3.4/http/client.py", line 1197, in connect\n    self.timeout, self.source_address)\n  File "/usr/lib/python3.4/socket.py", line 509, in create_connection\n    raise err\n  File "/usr/lib/python3.4/socket.py", line 500, in create_connection\n    sock.connect(sa)\nTimeoutError: [Errno 110] Connection timed out\n')
('2015-03-21 10:37:47.669058', 'Traceback (most recent call last):\n  File "/river/fd/fd_worker/fd_channel.py", line 204, in create_channel\n    handle.connect()\n  File "/usr/lib/python3.4/http/client.py", line 1197, in connect\n    self.timeout, self.source_address)\n  File "/usr/lib/python3.4/socket.py", line 509, in create_connection\n    raise err\n  File "/usr/lib/python3.4/socket.py", line 500, in create_connection\n    sock.connect(sa)\nTimeoutError: [Errno 110] Connection timed out\n')
('2015-03-21 10:37:49.205099', 'Traceback (most recent call last):\n  File "/river/fd/fd_worker/fd_channel.py", line 204, in create_channel\n    handle.connect()\n  File "/usr/lib/python3.4/http/client.py", line 1197, in connect\n    self.timeout, self.source_address)\n  File "/usr/lib/python3.4/socket.py", line 509, in create_connection\n    raise err\n  File "/usr/lib/python3.4/socket.py", line 500, in create_connection\n    sock.connect(sa)\nTimeoutError: [Errno 110] Connection timed out\n')
('2015-03-21 10:37:50.741306', 'Traceback (most recent call last):\n  File "/river/fd/fd_worker/fd_channel.py", line 204, in create_channel\n    handle.connect()\n  File "/usr/lib/python3.4/http/client.py", line 1197, in connect\n    self.timeout, self.source_address)\n  File "/usr/lib/python3.4/socket.py", line 509, in create_connection\n    raise err\n  File "/usr/lib/python3.4/socket.py", line 500, in create_connection\n    sock.connect(sa)\nTimeoutError: [Errno 110] Connection timed out\n')
('2015-03-21 10:37:52.277256', 'Traceback (most recent call last):\n  File "/river/fd/fd_worker/fd_channel.py", line 204, in create_channel\n    handle.connect()\n  File "/usr/lib/python3.4/http/client.py", line 1197, in connect\n    self.timeout, self.source_address)\n  File "/usr/lib/python3.4/socket.py", line 509, in create_connection\n    raise err\n  File "/usr/lib/python3.4/socket.py", line 500, in create_connection\n    sock.connect(sa)\nTimeoutError: [Errno 110] Connection timed out\n')
('2015-03-21 10:37:53.813075', 'Traceback (most recent call last):\n  File "/river/fd/fd_worker/fd_channel.py", line 204, in create_channel\n    handle.connect()\n  File "/usr/lib/python3.4/http/client.py", line 1197, in connect\n    self.timeout, self.source_address)\n  File "/usr/lib/python3.4/socket.py", line 509, in create_connection\n    raise err\n  File "/usr/lib/python3.4/socket.py", line 500, in create_connection\n    sock.connect(sa)\nTimeoutError: [Errno 110] Connection timed out\n')
('2015-03-21 10:37:59.701065', 'Traceback (most recent call last):\n  File "/river/fd/fd_worker/fd_channel.py", line 204, in create_channel\n    handle.connect()\n  File "/usr/lib/python3.4/http/client.py", line 1197, in connect\n    self.timeout, self.source_address)\n  File "/usr/lib/python3.4/socket.py", line 509, in create_connection\n    raise err\n  File "/usr/lib/python3.4/socket.py", line 500, in create_connection\n    sock.connect(sa)\nTimeoutError: [Errno 110] Connection timed out\n')
('2015-03-21 10:38:01.237330', 'Traceback (most recent call last):\n  File "/river/fd/fd_worker/fd_channel.py", line 204, in create_channel\n    handle.connect()\n  File "/usr/lib/python3.4/http/client.py", line 1197, in connect\n    self.timeout, self.source_address)\n  File "/usr/lib/python3.4/socket.py", line 509, in create_connection\n    raise err\n  File "/usr/lib/python3.4/socket.py", line 500, in create_connection\n    sock.connect(sa)\nTimeoutError: [Errno 110] Connection timed out\n')
('2015-03-21 10:38:01.237858', 'Traceback (most recent call last):\n  File "/river/fd/fd_worker/fd_channel.py", line 204, in create_channel\n    handle.connect()\n  File "/usr/lib/python3.4/http/client.py", line 1197, in connect\n    self.timeout, self.source_address)\n  File "/usr/lib/python3.4/socket.py", line 509, in create_connection\n    raise err\n  File "/usr/lib/python3.4/socket.py", line 500, in create_connection\n    sock.connect(sa)\nTimeoutError: [Errno 110] Connection timed out\n')
('2015-03-21 10:38:01.238321', 'Traceback (most recent call last):\n  File "/river/fd/fd_worker/fd_channel.py", line 144, in pyget\n    ack  = handle.getresponse()\n  File "/usr/lib/python3.4/http/client.py", line 1147, in getresponse\n    response.begin()\n  File "/usr/lib/python3.4/http/client.py", line 351, in begin\n    version, status, reason = self._read_status()\n  File "/usr/lib/python3.4/http/client.py", line 313, in _read_status\n    line = str(self.fp.readline(_MAXLINE + 1), "iso-8859-1")\n  File "/usr/lib/python3.4/socket.py", line 371, in readinto\n    return self._sock.recv_into(b)\n  File "/usr/lib/python3.4/ssl.py", line 746, in recv_into\n    return self.read(nbytes, buffer)\n  File "/usr/lib/python3.4/ssl.py", line 618, in read\n    v = self._sslobj.read(len, buffer)\nConnectionResetError: [Errno 104] Connection reset by peer\n')
('2015-03-21 10:38:01.238882', 'Traceback (most recent call last):\n  File "/river/fd/fd_worker/fd_channel.py", line 144, in pyget\n    ack  = handle.getresponse()\n  File "/usr/lib/python3.4/http/client.py", line 1147, in getresponse\n    response.begin()\n  File "/usr/lib/python3.4/http/client.py", line 351, in begin\n    version, status, reason = self._read_status()\n  File "/usr/lib/python3.4/http/client.py", line 313, in _read_status\n    line = str(self.fp.readline(_MAXLINE + 1), "iso-8859-1")\n  File "/usr/lib/python3.4/socket.py", line 371, in readinto\n    return self._sock.recv_into(b)\n  File "/usr/lib/python3.4/ssl.py", line 746, in recv_into\n    return self.read(nbytes, buffer)\n  File "/usr/lib/python3.4/ssl.py", line 618, in read\n    v = self._sslobj.read(len, buffer)\nConnectionResetError: [Errno 104] Connection reset by peer\n')
('2015-03-21 10:38:02.773085', 'Traceback (most recent call last):\n  File "/river/fd/fd_worker/fd_channel.py", line 204, in create_channel\n    handle.connect()\n  File "/usr/lib/python3.4/http/client.py", line 1197, in connect\n    self.timeout, self.source_address)\n  File "/usr/lib/python3.4/socket.py", line 509, in create_connection\n    raise err\n  File "/usr/lib/python3.4/socket.py", line 500, in create_connection\n    sock.connect(sa)\nTimeoutError: [Errno 110] Connection timed out\n')
('2015-03-21 10:38:04.309081', 'Traceback (most recent call last):\n  File "/river/fd/fd_worker/fd_channel.py", line 204, in create_channel\n    handle.connect()\n  File "/usr/lib/python3.4/http/client.py", line 1197, in connect\n    self.timeout, self.source_address)\n  File "/usr/lib/python3.4/socket.py", line 509, in create_connection\n    raise err\n  File "/usr/lib/python3.4/socket.py", line 500, in create_connection\n    sock.connect(sa)\nTimeoutError: [Errno 110] Connection timed out\n')
('2015-03-21 10:38:05.717042', 'Traceback (most recent call last):\n  File "/river/fd/fd_worker/fd_channel.py", line 204, in create_channel\n    handle.connect()\n  File "/usr/lib/python3.4/http/client.py", line 1197, in connect\n    self.timeout, self.source_address)\n  File "/usr/lib/python3.4/socket.py", line 509, in create_connection\n    raise err\n  File "/usr/lib/python3.4/socket.py", line 500, in create_connection\n    sock.connect(sa)\nTimeoutError: [Errno 110] Connection timed out\n')
('2015-03-21 10:38:12.807170', 'Traceback (most recent call last):\n  File "/river/fd/fd_worker/fd_channel.py", line 204, in create_channel\n    handle.connect()\n  File "/usr/lib/python3.4/http/client.py", line 1205, in connect\n    server_hostname=server_hostname)\n  File "/usr/lib/python3.4/ssl.py", line 364, in wrap_socket\n    _context=self)\n  File "/usr/lib/python3.4/ssl.py", line 578, in __init__\n    self.do_handshake()\n  File "/usr/lib/python3.4/ssl.py", line 805, in do_handshake\n    self._sslobj.do_handshake()\nConnectionResetError: [Errno 104] Connection reset by peer\n')
('2015-03-21 10:38:13.269403', 'Traceback (most recent call last):\n  File "/river/fd/fd_worker/fd_channel.py", line 204, in create_channel\n    handle.connect()\n  File "/usr/lib/python3.4/http/client.py", line 1197, in connect\n    self.timeout, self.source_address)\n  File "/usr/lib/python3.4/socket.py", line 509, in create_connection\n    raise err\n  File "/usr/lib/python3.4/socket.py", line 500, in create_connection\n    sock.connect(sa)\nTimeoutError: [Errno 110] Connection timed out\n')
('2015-03-21 10:38:14.037836', 'Traceback (most recent call last):\n  File "/river/fd/fd_worker/fd_channel.py", line 144, in pyget\n    ack  = handle.getresponse()\n  File "/usr/lib/python3.4/http/client.py", line 1147, in getresponse\n    response.begin()\n  File "/usr/lib/python3.4/http/client.py", line 351, in begin\n    version, status, reason = self._read_status()\n  File "/usr/lib/python3.4/http/client.py", line 313, in _read_status\n    line = str(self.fp.readline(_MAXLINE + 1), "iso-8859-1")\n  File "/usr/lib/python3.4/socket.py", line 371, in readinto\n    return self._sock.recv_into(b)\n  File "/usr/lib/python3.4/ssl.py", line 746, in recv_into\n    return self.read(nbytes, buffer)\n  File "/usr/lib/python3.4/ssl.py", line 618, in read\n    v = self._sslobj.read(len, buffer)\nConnectionResetError: [Errno 104] Connection reset by peer\n')
('2015-03-21 10:38:14.038608', 'Traceback (most recent call last):\n  File "/river/fd/fd_worker/fd_channel.py", line 144, in pyget\n    ack  = handle.getresponse()\n  File "/usr/lib/python3.4/http/client.py", line 1147, in getresponse\n    response.begin()\n  File "/usr/lib/python3.4/http/client.py", line 351, in begin\n    version, status, reason = self._read_status()\n  File "/usr/lib/python3.4/http/client.py", line 313, in _read_status\n    line = str(self.fp.readline(_MAXLINE + 1), "iso-8859-1")\n  File "/usr/lib/python3.4/socket.py", line 371, in readinto\n    return self._sock.recv_into(b)\n  File "/usr/lib/python3.4/ssl.py", line 746, in recv_into\n    return self.read(nbytes, buffer)\n  File "/usr/lib/python3.4/ssl.py", line 618, in read\n    v = self._sslobj.read(len, buffer)\nConnectionResetError: [Errno 104] Connection reset by peer\n')
('2015-03-21 10:38:14.805235', 'Traceback (most recent call last):\n  File "/river/fd/fd_worker/fd_channel.py", line 204, in create_channel\n    handle.connect()\n  File "/usr/lib/python3.4/http/client.py", line 1197, in connect\n    self.timeout, self.source_address)\n  File "/usr/lib/python3.4/socket.py", line 509, in create_connection\n    raise err\n  File "/usr/lib/python3.4/socket.py", line 500, in create_connection\n    sock.connect(sa)\nTimeoutError: [Errno 110] Connection timed out\n')
('2015-03-21 10:38:16.085932', 'Traceback (most recent call last):\n  File "/river/fd/fd_worker/fd_channel.py", line 144, in pyget\n    ack  = handle.getresponse()\n  File "/usr/lib/python3.4/http/client.py", line 1147, in getresponse\n    response.begin()\n  File "/usr/lib/python3.4/http/client.py", line 351, in begin\n    version, status, reason = self._read_status()\n  File "/usr/lib/python3.4/http/client.py", line 313, in _read_status\n    line = str(self.fp.readline(_MAXLINE + 1), "iso-8859-1")\n  File "/usr/lib/python3.4/socket.py", line 371, in readinto\n    return self._sock.recv_into(b)\n  File "/usr/lib/python3.4/ssl.py", line 746, in recv_into\n    return self.read(nbytes, buffer)\n  File "/usr/lib/python3.4/ssl.py", line 618, in read\n    v = self._sslobj.read(len, buffer)\nConnectionResetError: [Errno 104] Connection reset by peer\n')
('2015-03-21 10:38:16.086548', 'Traceback (most recent call last):\n  File "/river/fd/fd_worker/fd_channel.py", line 144, in pyget\n    ack  = handle.getresponse()\n  File "/usr/lib/python3.4/http/client.py", line 1147, in getresponse\n    response.begin()\n  File "/usr/lib/python3.4/http/client.py", line 351, in begin\n    version, status, reason = self._read_status()\n  File "/usr/lib/python3.4/http/client.py", line 313, in _read_status\n    line = str(self.fp.readline(_MAXLINE + 1), "iso-8859-1")\n  File "/usr/lib/python3.4/socket.py", line 371, in readinto\n    return self._sock.recv_into(b)\n  File "/usr/lib/python3.4/ssl.py", line 746, in recv_into\n    return self.read(nbytes, buffer)\n  File "/usr/lib/python3.4/ssl.py", line 618, in read\n    v = self._sslobj.read(len, buffer)\nConnectionResetError: [Errno 104] Connection reset by peer\n')
('2015-03-21 10:38:20.693164', 'Traceback (most recent call last):\n  File "/river/fd/fd_worker/fd_channel.py", line 204, in create_channel\n    handle.connect()\n  File "/usr/lib/python3.4/http/client.py", line 1197, in connect\n    self.timeout, self.source_address)\n  File "/usr/lib/python3.4/socket.py", line 509, in create_connection\n    raise err\n  File "/usr/lib/python3.4/socket.py", line 500, in create_connection\n    sock.connect(sa)\nTimeoutError: [Errno 110] Connection timed out\n')
('2015-03-21 10:38:22.229165', 'Traceback (most recent call last):\n  File "/river/fd/fd_worker/fd_channel.py", line 204, in create_channel\n    handle.connect()\n  File "/usr/lib/python3.4/http/client.py", line 1197, in connect\n    self.timeout, self.source_address)\n  File "/usr/lib/python3.4/socket.py", line 509, in create_connection\n    raise err\n  File "/usr/lib/python3.4/socket.py", line 500, in create_connection\n    sock.connect(sa)\nTimeoutError: [Errno 110] Connection timed out\n')
('2015-03-21 10:38:23.765112', 'Traceback (most recent call last):\n  File "/river/fd/fd_worker/fd_channel.py", line 204, in create_channel\n    handle.connect()\n  File "/usr/lib/python3.4/http/client.py", line 1197, in connect\n    self.timeout, self.source_address)\n  File "/usr/lib/python3.4/socket.py", line 509, in create_connection\n    raise err\n  File "/usr/lib/python3.4/socket.py", line 500, in create_connection\n    sock.connect(sa)\nTimeoutError: [Errno 110] Connection timed out\n')
('2015-03-21 10:38:25.301436', 'Traceback (most recent call last):\n  File "/river/fd/fd_worker/fd_channel.py", line 204, in create_channel\n    handle.connect()\n  File "/usr/lib/python3.4/http/client.py", line 1197, in connect\n    self.timeout, self.source_address)\n  File "/usr/lib/python3.4/socket.py", line 509, in create_connection\n    raise err\n  File "/usr/lib/python3.4/socket.py", line 500, in create_connection\n    sock.connect(sa)\nTimeoutError: [Errno 110] Connection timed out\n')
('2015-03-21 10:38:31.190126', 'Traceback (most recent call last):\n  File "/river/fd/fd_worker/fd_channel.py", line 144, in pyget\n    ack  = handle.getresponse()\n  File "/usr/lib/python3.4/http/client.py", line 1147, in getresponse\n    response.begin()\n  File "/usr/lib/python3.4/http/client.py", line 351, in begin\n    version, status, reason = self._read_status()\n  File "/usr/lib/python3.4/http/client.py", line 313, in _read_status\n    line = str(self.fp.readline(_MAXLINE + 1), "iso-8859-1")\n  File "/usr/lib/python3.4/socket.py", line 371, in readinto\n    return self._sock.recv_into(b)\n  File "/usr/lib/python3.4/ssl.py", line 746, in recv_into\n    return self.read(nbytes, buffer)\n  File "/usr/lib/python3.4/ssl.py", line 618, in read\n    v = self._sslobj.read(len, buffer)\nConnectionResetError: [Errno 104] Connection reset by peer\n')
('2015-03-21 10:38:31.190671', 'Traceback (most recent call last):\n  File "/river/fd/fd_worker/fd_channel.py", line 144, in pyget\n    ack  = handle.getresponse()\n  File "/usr/lib/python3.4/http/client.py", line 1147, in getresponse\n    response.begin()\n  File "/usr/lib/python3.4/http/client.py", line 351, in begin\n    version, status, reason = self._read_status()\n  File "/usr/lib/python3.4/http/client.py", line 313, in _read_status\n    line = str(self.fp.readline(_MAXLINE + 1), "iso-8859-1")\n  File "/usr/lib/python3.4/socket.py", line 371, in readinto\n    return self._sock.recv_into(b)\n  File "/usr/lib/python3.4/ssl.py", line 746, in recv_into\n    return self.read(nbytes, buffer)\n  File "/usr/lib/python3.4/ssl.py", line 618, in read\n    v = self._sslobj.read(len, buffer)\nConnectionResetError: [Errno 104] Connection reset by peer\n')
('2015-03-21 10:38:34.774527', 'Traceback (most recent call last):\n  File "/river/fd/fd_worker/fd_channel.py", line 144, in pyget\n    ack  = handle.getresponse()\n  File "/usr/lib/python3.4/http/client.py", line 1147, in getresponse\n    response.begin()\n  File "/usr/lib/python3.4/http/client.py", line 351, in begin\n    version, status, reason = self._read_status()\n  File "/usr/lib/python3.4/http/client.py", line 313, in _read_status\n    line = str(self.fp.readline(_MAXLINE + 1), "iso-8859-1")\n  File "/usr/lib/python3.4/socket.py", line 371, in readinto\n    return self._sock.recv_into(b)\n  File "/usr/lib/python3.4/ssl.py", line 746, in recv_into\n    return self.read(nbytes, buffer)\n  File "/usr/lib/python3.4/ssl.py", line 618, in read\n    v = self._sslobj.read(len, buffer)\nConnectionResetError: [Errno 104] Connection reset by peer\n')
('2015-03-21 10:39:01.142477', 'Traceback (most recent call last):\n  File "/river/fd/fd_worker/fd_channel.py", line 144, in pyget\n    ack  = handle.getresponse()\n  File "/usr/lib/python3.4/http/client.py", line 1147, in getresponse\n    response.begin()\n  File "/usr/lib/python3.4/http/client.py", line 351, in begin\n    version, status, reason = self._read_status()\n  File "/usr/lib/python3.4/http/client.py", line 313, in _read_status\n    line = str(self.fp.readline(_MAXLINE + 1), "iso-8859-1")\n  File "/usr/lib/python3.4/socket.py", line 371, in readinto\n    return self._sock.recv_into(b)\n  File "/usr/lib/python3.4/ssl.py", line 746, in recv_into\n    return self.read(nbytes, buffer)\n  File "/usr/lib/python3.4/ssl.py", line 618, in read\n    v = self._sslobj.read(len, buffer)\nConnectionResetError: [Errno 104] Connection reset by peer\n')
('2015-03-21 10:39:31.094264', 'Traceback (most recent call last):\n  File "/river/fd/fd_worker/fd_channel.py", line 144, in pyget\n    ack  = handle.getresponse()\n  File "/usr/lib/python3.4/http/client.py", line 1147, in getresponse\n    response.begin()\n  File "/usr/lib/python3.4/http/client.py", line 351, in begin\n    version, status, reason = self._read_status()\n  File "/usr/lib/python3.4/http/client.py", line 313, in _read_status\n    line = str(self.fp.readline(_MAXLINE + 1), "iso-8859-1")\n  File "/usr/lib/python3.4/socket.py", line 371, in readinto\n    return self._sock.recv_into(b)\n  File "/usr/lib/python3.4/ssl.py", line 746, in recv_into\n    return self.read(nbytes, buffer)\n  File "/usr/lib/python3.4/ssl.py", line 618, in read\n    v = self._sslobj.read(len, buffer)\nConnectionResetError: [Errno 104] Connection reset by peer\n')
('2015-03-21 10:39:31.605867', 'Traceback (most recent call last):\n  File "/river/fd/fd_worker/fd_channel.py", line 144, in pyget\n    ack  = handle.getresponse()\n  File "/usr/lib/python3.4/http/client.py", line 1147, in getresponse\n    response.begin()\n  File "/usr/lib/python3.4/http/client.py", line 351, in begin\n    version, status, reason = self._read_status()\n  File "/usr/lib/python3.4/http/client.py", line 313, in _read_status\n    line = str(self.fp.readline(_MAXLINE + 1), "iso-8859-1")\n  File "/usr/lib/python3.4/socket.py", line 371, in readinto\n    return self._sock.recv_into(b)\n  File "/usr/lib/python3.4/ssl.py", line 746, in recv_into\n    return self.read(nbytes, buffer)\n  File "/usr/lib/python3.4/ssl.py", line 618, in read\n    v = self._sslobj.read(len, buffer)\nConnectionResetError: [Errno 104] Connection reset by peer\n')
('2015-03-21 10:39:31.606481', 'Traceback (most recent call last):\n  File "/river/fd/fd_worker/fd_channel.py", line 144, in pyget\n    ack  = handle.getresponse()\n  File "/usr/lib/python3.4/http/client.py", line 1147, in getresponse\n    response.begin()\n  File "/usr/lib/python3.4/http/client.py", line 351, in begin\n    version, status, reason = self._read_status()\n  File "/usr/lib/python3.4/http/client.py", line 313, in _read_status\n    line = str(self.fp.readline(_MAXLINE + 1), "iso-8859-1")\n  File "/usr/lib/python3.4/socket.py", line 371, in readinto\n    return self._sock.recv_into(b)\n  File "/usr/lib/python3.4/ssl.py", line 746, in recv_into\n    return self.read(nbytes, buffer)\n  File "/usr/lib/python3.4/ssl.py", line 618, in read\n    v = self._sslobj.read(len, buffer)\nConnectionResetError: [Errno 104] Connection reset by peer\n')
('2015-03-21 10:39:31.606861', 'Traceback (most recent call last):\n  File "/river/fd/fd_worker/fd_channel.py", line 144, in pyget\n    ack  = handle.getresponse()\n  File "/usr/lib/python3.4/http/client.py", line 1147, in getresponse\n    response.begin()\n  File "/usr/lib/python3.4/http/client.py", line 351, in begin\n    version, status, reason = self._read_status()\n  File "/usr/lib/python3.4/http/client.py", line 313, in _read_status\n    line = str(self.fp.readline(_MAXLINE + 1), "iso-8859-1")\n  File "/usr/lib/python3.4/socket.py", line 371, in readinto\n    return self._sock.recv_into(b)\n  File "/usr/lib/python3.4/ssl.py", line 746, in recv_into\n    return self.read(nbytes, buffer)\n  File "/usr/lib/python3.4/ssl.py", line 618, in read\n    v = self._sslobj.read(len, buffer)\nConnectionResetError: [Errno 104] Connection reset by peer\n')
('2015-03-21 11:29:31.634102', 'Traceback (most recent call last):\n  File "/river/fd/fd_worker/fd_channel.py", line 204, in create_channel\n    handle.connect()\n  File "/usr/lib/python3.4/http/client.py", line 1205, in connect\n    server_hostname=server_hostname)\n  File "/usr/lib/python3.4/ssl.py", line 364, in wrap_socket\n    _context=self)\n  File "/usr/lib/python3.4/ssl.py", line 578, in __init__\n    self.do_handshake()\n  File "/usr/lib/python3.4/ssl.py", line 805, in do_handshake\n    self._sslobj.do_handshake()\nConnectionResetError: [Errno 104] Connection reset by peer\n')
('2015-03-21 11:29:31.914905', 'Traceback (most recent call last):\n  File "/river/fd/fd_worker/fd_channel.py", line 204, in create_channel\n    handle.connect()\n  File "/usr/lib/python3.4/http/client.py", line 1205, in connect\n    server_hostname=server_hostname)\n  File "/usr/lib/python3.4/ssl.py", line 364, in wrap_socket\n    _context=self)\n  File "/usr/lib/python3.4/ssl.py", line 578, in __init__\n    self.do_handshake()\n  File "/usr/lib/python3.4/ssl.py", line 805, in do_handshake\n    self._sslobj.do_handshake()\nConnectionResetError: [Errno 104] Connection reset by peer\n')
('2015-03-21 11:29:33.102713', 'Traceback (most recent call last):\n  File "/river/fd/fd_worker/fd_channel.py", line 204, in create_channel\n    handle.connect()\n  File "/usr/lib/python3.4/http/client.py", line 1205, in connect\n    server_hostname=server_hostname)\n  File "/usr/lib/python3.4/ssl.py", line 364, in wrap_socket\n    _context=self)\n  File "/usr/lib/python3.4/ssl.py", line 578, in __init__\n    self.do_handshake()\n  File "/usr/lib/python3.4/ssl.py", line 805, in do_handshake\n    self._sslobj.do_handshake()\nConnectionResetError: [Errno 104] Connection reset by peer\n')
('2015-03-21 11:29:34.274183', 'Traceback (most recent call last):\n  File "/river/fd/fd_worker/fd_channel.py", line 204, in create_channel\n    handle.connect()\n  File "/usr/lib/python3.4/http/client.py", line 1205, in connect\n    server_hostname=server_hostname)\n  File "/usr/lib/python3.4/ssl.py", line 364, in wrap_socket\n    _context=self)\n  File "/usr/lib/python3.4/ssl.py", line 578, in __init__\n    self.do_handshake()\n  File "/usr/lib/python3.4/ssl.py", line 805, in do_handshake\n    self._sslobj.do_handshake()\nConnectionResetError: [Errno 104] Connection reset by peer\n')
('2015-03-21 11:29:34.915212', 'Traceback (most recent call last):\n  File "/river/fd/fd_worker/fd_channel.py", line 204, in create_channel\n    handle.connect()\n  File "/usr/lib/python3.4/http/client.py", line 1205, in connect\n    server_hostname=server_hostname)\n  File "/usr/lib/python3.4/ssl.py", line 364, in wrap_socket\n    _context=self)\n  File "/usr/lib/python3.4/ssl.py", line 578, in __init__\n    self.do_handshake()\n  File "/usr/lib/python3.4/ssl.py", line 805, in do_handshake\n    self._sslobj.do_handshake()\nConnectionResetError: [Errno 104] Connection reset by peer\n')
('2015-03-21 11:29:36.270770', 'Traceback (most recent call last):\n  File "/river/fd/fd_worker/fd_channel.py", line 204, in create_channel\n    handle.connect()\n  File "/usr/lib/python3.4/http/client.py", line 1205, in connect\n    server_hostname=server_hostname)\n  File "/usr/lib/python3.4/ssl.py", line 364, in wrap_socket\n    _context=self)\n  File "/usr/lib/python3.4/ssl.py", line 578, in __init__\n    self.do_handshake()\n  File "/usr/lib/python3.4/ssl.py", line 805, in do_handshake\n    self._sslobj.do_handshake()\nConnectionResetError: [Errno 104] Connection reset by peer\n')
('2015-03-21 11:29:40.614203', 'Traceback (most recent call last):\n  File "/river/fd/fd_worker/fd_channel.py", line 204, in create_channel\n    handle.connect()\n  File "/usr/lib/python3.4/http/client.py", line 1205, in connect\n    server_hostname=server_hostname)\n  File "/usr/lib/python3.4/ssl.py", line 364, in wrap_socket\n    _context=self)\n  File "/usr/lib/python3.4/ssl.py", line 578, in __init__\n    self.do_handshake()\n  File "/usr/lib/python3.4/ssl.py", line 805, in do_handshake\n    self._sslobj.do_handshake()\nConnectionResetError: [Errno 104] Connection reset by peer\n')
('2015-03-21 11:29:42.414803', 'Traceback (most recent call last):\n  File "/river/fd/fd_worker/fd_channel.py", line 204, in create_channel\n    handle.connect()\n  File "/usr/lib/python3.4/http/client.py", line 1205, in connect\n    server_hostname=server_hostname)\n  File "/usr/lib/python3.4/ssl.py", line 364, in wrap_socket\n    _context=self)\n  File "/usr/lib/python3.4/ssl.py", line 578, in __init__\n    self.do_handshake()\n  File "/usr/lib/python3.4/ssl.py", line 805, in do_handshake\n    self._sslobj.do_handshake()\nConnectionResetError: [Errno 104] Connection reset by peer\n')
('2015-03-21 11:29:44.504250', 'Traceback (most recent call last):\n  File "/river/fd/fd_worker/fd_channel.py", line 204, in create_channel\n    handle.connect()\n  File "/usr/lib/python3.4/http/client.py", line 1205, in connect\n    server_hostname=server_hostname)\n  File "/usr/lib/python3.4/ssl.py", line 364, in wrap_socket\n    _context=self)\n  File "/usr/lib/python3.4/ssl.py", line 578, in __init__\n    self.do_handshake()\n  File "/usr/lib/python3.4/ssl.py", line 805, in do_handshake\n    self._sslobj.do_handshake()\nConnectionResetError: [Errno 104] Connection reset by peer\n')
('2015-03-21 11:29:45.175190', 'Traceback (most recent call last):\n  File "/river/fd/fd_worker/fd_channel.py", line 204, in create_channel\n    handle.connect()\n  File "/usr/lib/python3.4/http/client.py", line 1205, in connect\n    server_hostname=server_hostname)\n  File "/usr/lib/python3.4/ssl.py", line 364, in wrap_socket\n    _context=self)\n  File "/usr/lib/python3.4/ssl.py", line 578, in __init__\n    self.do_handshake()\n  File "/usr/lib/python3.4/ssl.py", line 805, in do_handshake\n    self._sslobj.do_handshake()\nConnectionResetError: [Errno 104] Connection reset by peer\n')
('2015-03-21 11:29:45.415215', 'Traceback (most recent call last):\n  File "/river/fd/fd_worker/fd_channel.py", line 204, in create_channel\n    handle.connect()\n  File "/usr/lib/python3.4/http/client.py", line 1205, in connect\n    server_hostname=server_hostname)\n  File "/usr/lib/python3.4/ssl.py", line 364, in wrap_socket\n    _context=self)\n  File "/usr/lib/python3.4/ssl.py", line 578, in __init__\n    self.do_handshake()\n  File "/usr/lib/python3.4/ssl.py", line 805, in do_handshake\n    self._sslobj.do_handshake()\nConnectionResetError: [Errno 104] Connection reset by peer\n')
('2015-03-21 11:29:46.614521', 'Traceback (most recent call last):\n  File "/river/fd/fd_worker/fd_channel.py", line 204, in create_channel\n    handle.connect()\n  File "/usr/lib/python3.4/http/client.py", line 1205, in connect\n    server_hostname=server_hostname)\n  File "/usr/lib/python3.4/ssl.py", line 364, in wrap_socket\n    _context=self)\n  File "/usr/lib/python3.4/ssl.py", line 578, in __init__\n    self.do_handshake()\n  File "/usr/lib/python3.4/ssl.py", line 805, in do_handshake\n    self._sslobj.do_handshake()\nConnectionResetError: [Errno 104] Connection reset by peer\n')
('2015-03-21 11:29:50.741126', 'Traceback (most recent call last):\n  File "/river/fd/fd_worker/fd_channel.py", line 204, in create_channel\n    handle.connect()\n  File "/usr/lib/python3.4/http/client.py", line 1197, in connect\n    self.timeout, self.source_address)\n  File "/usr/lib/python3.4/socket.py", line 509, in create_connection\n    raise err\n  File "/usr/lib/python3.4/socket.py", line 500, in create_connection\n    sock.connect(sa)\nTimeoutError: [Errno 110] Connection timed out\n')
('2015-03-21 11:29:52.006663', 'Traceback (most recent call last):\n  File "/river/fd/fd_worker/fd_channel.py", line 204, in create_channel\n    handle.connect()\n  File "/usr/lib/python3.4/http/client.py", line 1205, in connect\n    server_hostname=server_hostname)\n  File "/usr/lib/python3.4/ssl.py", line 364, in wrap_socket\n    _context=self)\n  File "/usr/lib/python3.4/ssl.py", line 578, in __init__\n    self.do_handshake()\n  File "/usr/lib/python3.4/ssl.py", line 805, in do_handshake\n    self._sslobj.do_handshake()\nConnectionResetError: [Errno 104] Connection reset by peer\n')
('2015-03-21 11:29:52.206127', 'Traceback (most recent call last):\n  File "/river/fd/fd_worker/fd_channel.py", line 204, in create_channel\n    handle.connect()\n  File "/usr/lib/python3.4/http/client.py", line 1205, in connect\n    server_hostname=server_hostname)\n  File "/usr/lib/python3.4/ssl.py", line 364, in wrap_socket\n    _context=self)\n  File "/usr/lib/python3.4/ssl.py", line 578, in __init__\n    self.do_handshake()\n  File "/usr/lib/python3.4/ssl.py", line 805, in do_handshake\n    self._sslobj.do_handshake()\nConnectionResetError: [Errno 104] Connection reset by peer\n')
('2015-03-21 11:29:54.454746', 'Traceback (most recent call last):\n  File "/river/fd/fd_worker/fd_channel.py", line 204, in create_channel\n    handle.connect()\n  File "/usr/lib/python3.4/http/client.py", line 1205, in connect\n    server_hostname=server_hostname)\n  File "/usr/lib/python3.4/ssl.py", line 364, in wrap_socket\n    _context=self)\n  File "/usr/lib/python3.4/ssl.py", line 578, in __init__\n    self.do_handshake()\n  File "/usr/lib/python3.4/ssl.py", line 805, in do_handshake\n    self._sslobj.do_handshake()\nConnectionResetError: [Errno 104] Connection reset by peer\n')
('2015-03-21 11:29:57.206717', 'Traceback (most recent call last):\n  File "/river/fd/fd_worker/fd_channel.py", line 204, in create_channel\n    handle.connect()\n  File "/usr/lib/python3.4/http/client.py", line 1205, in connect\n    server_hostname=server_hostname)\n  File "/usr/lib/python3.4/ssl.py", line 364, in wrap_socket\n    _context=self)\n  File "/usr/lib/python3.4/ssl.py", line 578, in __init__\n    self.do_handshake()\n  File "/usr/lib/python3.4/ssl.py", line 805, in do_handshake\n    self._sslobj.do_handshake()\nConnectionResetError: [Errno 104] Connection reset by peer\n')
('2015-03-21 11:29:58.614696', 'Traceback (most recent call last):\n  File "/river/fd/fd_worker/fd_channel.py", line 204, in create_channel\n    handle.connect()\n  File "/usr/lib/python3.4/http/client.py", line 1205, in connect\n    server_hostname=server_hostname)\n  File "/usr/lib/python3.4/ssl.py", line 364, in wrap_socket\n    _context=self)\n  File "/usr/lib/python3.4/ssl.py", line 578, in __init__\n    self.do_handshake()\n  File "/usr/lib/python3.4/ssl.py", line 805, in do_handshake\n    self._sslobj.do_handshake()\nConnectionResetError: [Errno 104] Connection reset by peer\n')
('2015-03-21 11:30:02.518745', 'Traceback (most recent call last):\n  File "/river/fd/fd_worker/fd_channel.py", line 204, in create_channel\n    handle.connect()\n  File "/usr/lib/python3.4/http/client.py", line 1205, in connect\n    server_hostname=server_hostname)\n  File "/usr/lib/python3.4/ssl.py", line 364, in wrap_socket\n    _context=self)\n  File "/usr/lib/python3.4/ssl.py", line 578, in __init__\n    self.do_handshake()\n  File "/usr/lib/python3.4/ssl.py", line 805, in do_handshake\n    self._sslobj.do_handshake()\nConnectionResetError: [Errno 104] Connection reset by peer\n')
('2015-03-21 11:30:04.066596', 'Traceback (most recent call last):\n  File "/river/fd/fd_worker/fd_channel.py", line 204, in create_channel\n    handle.connect()\n  File "/usr/lib/python3.4/http/client.py", line 1205, in connect\n    server_hostname=server_hostname)\n  File "/usr/lib/python3.4/ssl.py", line 364, in wrap_socket\n    _context=self)\n  File "/usr/lib/python3.4/ssl.py", line 578, in __init__\n    self.do_handshake()\n  File "/usr/lib/python3.4/ssl.py", line 805, in do_handshake\n    self._sslobj.do_handshake()\nConnectionResetError: [Errno 104] Connection reset by peer\n')
('2015-03-21 11:30:04.181090', 'Traceback (most recent call last):\n  File "/river/fd/fd_worker/fd_channel.py", line 204, in create_channel\n    handle.connect()\n  File "/usr/lib/python3.4/http/client.py", line 1197, in connect\n    self.timeout, self.source_address)\n  File "/usr/lib/python3.4/socket.py", line 509, in create_connection\n    raise err\n  File "/usr/lib/python3.4/socket.py", line 500, in create_connection\n    sock.connect(sa)\nTimeoutError: [Errno 110] Connection timed out\n')
('2015-03-21 11:30:10.325115', 'Traceback (most recent call last):\n  File "/river/fd/fd_worker/fd_channel.py", line 204, in create_channel\n    handle.connect()\n  File "/usr/lib/python3.4/http/client.py", line 1197, in connect\n    self.timeout, self.source_address)\n  File "/usr/lib/python3.4/socket.py", line 509, in create_connection\n    raise err\n  File "/usr/lib/python3.4/socket.py", line 500, in create_connection\n    sock.connect(sa)\nTimeoutError: [Errno 110] Connection timed out\n')
('2015-03-21 11:30:10.325442', 'Traceback (most recent call last):\n  File "/river/fd/fd_worker/fd_channel.py", line 204, in create_channel\n    handle.connect()\n  File "/usr/lib/python3.4/http/client.py", line 1197, in connect\n    self.timeout, self.source_address)\n  File "/usr/lib/python3.4/socket.py", line 509, in create_connection\n    raise err\n  File "/usr/lib/python3.4/socket.py", line 500, in create_connection\n    sock.connect(sa)\nTimeoutError: [Errno 110] Connection timed out\n')
('2015-03-21 11:30:13.269078', 'Traceback (most recent call last):\n  File "/river/fd/fd_worker/fd_channel.py", line 204, in create_channel\n    handle.connect()\n  File "/usr/lib/python3.4/http/client.py", line 1197, in connect\n    self.timeout, self.source_address)\n  File "/usr/lib/python3.4/socket.py", line 509, in create_connection\n    raise err\n  File "/usr/lib/python3.4/socket.py", line 500, in create_connection\n    sock.connect(sa)\nTimeoutError: [Errno 110] Connection timed out\n')
('2015-03-21 11:30:16.213078', 'Traceback (most recent call last):\n  File "/river/fd/fd_worker/fd_channel.py", line 204, in create_channel\n    handle.connect()\n  File "/usr/lib/python3.4/http/client.py", line 1197, in connect\n    self.timeout, self.source_address)\n  File "/usr/lib/python3.4/socket.py", line 509, in create_connection\n    raise err\n  File "/usr/lib/python3.4/socket.py", line 500, in create_connection\n    sock.connect(sa)\nTimeoutError: [Errno 110] Connection timed out\n')
('2015-03-21 11:30:19.285160', 'Traceback (most recent call last):\n  File "/river/fd/fd_worker/fd_channel.py", line 204, in create_channel\n    handle.connect()\n  File "/usr/lib/python3.4/http/client.py", line 1197, in connect\n    self.timeout, self.source_address)\n  File "/usr/lib/python3.4/socket.py", line 509, in create_connection\n    raise err\n  File "/usr/lib/python3.4/socket.py", line 500, in create_connection\n    sock.connect(sa)\nTimeoutError: [Errno 110] Connection timed out\n')
('2015-03-21 11:30:19.285573', 'Traceback (most recent call last):\n  File "/river/fd/fd_worker/fd_channel.py", line 204, in create_channel\n    handle.connect()\n  File "/usr/lib/python3.4/http/client.py", line 1197, in connect\n    self.timeout, self.source_address)\n  File "/usr/lib/python3.4/socket.py", line 509, in create_connection\n    raise err\n  File "/usr/lib/python3.4/socket.py", line 500, in create_connection\n    sock.connect(sa)\nTimeoutError: [Errno 110] Connection timed out\n')
('2015-03-21 11:30:20.821136', 'Traceback (most recent call last):\n  File "/river/fd/fd_worker/fd_channel.py", line 204, in create_channel\n    handle.connect()\n  File "/usr/lib/python3.4/http/client.py", line 1197, in connect\n    self.timeout, self.source_address)\n  File "/usr/lib/python3.4/socket.py", line 509, in create_connection\n    raise err\n  File "/usr/lib/python3.4/socket.py", line 500, in create_connection\n    sock.connect(sa)\nTimeoutError: [Errno 110] Connection timed out\n')
('2015-03-21 11:30:20.824157', 'Traceback (most recent call last):\n  File "/river/fd/fd_worker/fd_channel.py", line 204, in create_channel\n    handle.connect()\n  File "/usr/lib/python3.4/http/client.py", line 1205, in connect\n    server_hostname=server_hostname)\n  File "/usr/lib/python3.4/ssl.py", line 364, in wrap_socket\n    _context=self)\n  File "/usr/lib/python3.4/ssl.py", line 578, in __init__\n    self.do_handshake()\n  File "/usr/lib/python3.4/ssl.py", line 805, in do_handshake\n    self._sslobj.do_handshake()\nConnectionResetError: [Errno 104] Connection reset by peer\n')
('2015-03-21 11:30:22.229093', 'Traceback (most recent call last):\n  File "/river/fd/fd_worker/fd_channel.py", line 204, in create_channel\n    handle.connect()\n  File "/usr/lib/python3.4/http/client.py", line 1197, in connect\n    self.timeout, self.source_address)\n  File "/usr/lib/python3.4/socket.py", line 509, in create_connection\n    raise err\n  File "/usr/lib/python3.4/socket.py", line 500, in create_connection\n    sock.connect(sa)\nTimeoutError: [Errno 110] Connection timed out\n')
('2015-03-21 11:30:22.229442', 'Traceback (most recent call last):\n  File "/river/fd/fd_worker/fd_channel.py", line 204, in create_channel\n    handle.connect()\n  File "/usr/lib/python3.4/http/client.py", line 1197, in connect\n    self.timeout, self.source_address)\n  File "/usr/lib/python3.4/socket.py", line 509, in create_connection\n    raise err\n  File "/usr/lib/python3.4/socket.py", line 500, in create_connection\n    sock.connect(sa)\nTimeoutError: [Errno 110] Connection timed out\n')
('2015-03-21 11:30:23.765101', 'Traceback (most recent call last):\n  File "/river/fd/fd_worker/fd_channel.py", line 204, in create_channel\n    handle.connect()\n  File "/usr/lib/python3.4/http/client.py", line 1197, in connect\n    self.timeout, self.source_address)\n  File "/usr/lib/python3.4/socket.py", line 509, in create_connection\n    raise err\n  File "/usr/lib/python3.4/socket.py", line 500, in create_connection\n    sock.connect(sa)\nTimeoutError: [Errno 110] Connection timed out\n')
('2015-03-21 11:30:25.173068', 'Traceback (most recent call last):\n  File "/river/fd/fd_worker/fd_channel.py", line 204, in create_channel\n    handle.connect()\n  File "/usr/lib/python3.4/http/client.py", line 1197, in connect\n    self.timeout, self.source_address)\n  File "/usr/lib/python3.4/socket.py", line 509, in create_connection\n    raise err\n  File "/usr/lib/python3.4/socket.py", line 500, in create_connection\n    sock.connect(sa)\nTimeoutError: [Errno 110] Connection timed out\n')
('2015-03-21 11:30:28.245309', 'Traceback (most recent call last):\n  File "/river/fd/fd_worker/fd_channel.py", line 204, in create_channel\n    handle.connect()\n  File "/usr/lib/python3.4/http/client.py", line 1197, in connect\n    self.timeout, self.source_address)\n  File "/usr/lib/python3.4/socket.py", line 509, in create_connection\n    raise err\n  File "/usr/lib/python3.4/socket.py", line 500, in create_connection\n    sock.connect(sa)\nTimeoutError: [Errno 110] Connection timed out\n')
('2015-03-21 11:30:32.725176', 'Traceback (most recent call last):\n  File "/river/fd/fd_worker/fd_channel.py", line 204, in create_channel\n    handle.connect()\n  File "/usr/lib/python3.4/http/client.py", line 1197, in connect\n    self.timeout, self.source_address)\n  File "/usr/lib/python3.4/socket.py", line 509, in create_connection\n    raise err\n  File "/usr/lib/python3.4/socket.py", line 500, in create_connection\n    sock.connect(sa)\nTimeoutError: [Errno 110] Connection timed out\n')
('2015-03-21 11:30:34.261095', 'Traceback (most recent call last):\n  File "/river/fd/fd_worker/fd_channel.py", line 204, in create_channel\n    handle.connect()\n  File "/usr/lib/python3.4/http/client.py", line 1197, in connect\n    self.timeout, self.source_address)\n  File "/usr/lib/python3.4/socket.py", line 509, in create_connection\n    raise err\n  File "/usr/lib/python3.4/socket.py", line 500, in create_connection\n    sock.connect(sa)\nTimeoutError: [Errno 110] Connection timed out\n')
('2015-03-21 11:30:35.669101', 'Traceback (most recent call last):\n  File "/river/fd/fd_worker/fd_channel.py", line 204, in create_channel\n    handle.connect()\n  File "/usr/lib/python3.4/http/client.py", line 1197, in connect\n    self.timeout, self.source_address)\n  File "/usr/lib/python3.4/socket.py", line 509, in create_connection\n    raise err\n  File "/usr/lib/python3.4/socket.py", line 500, in create_connection\n    sock.connect(sa)\nTimeoutError: [Errno 110] Connection timed out\n')
('2015-03-21 11:30:37.205075', 'Traceback (most recent call last):\n  File "/river/fd/fd_worker/fd_channel.py", line 204, in create_channel\n    handle.connect()\n  File "/usr/lib/python3.4/http/client.py", line 1197, in connect\n    self.timeout, self.source_address)\n  File "/usr/lib/python3.4/socket.py", line 509, in create_connection\n    raise err\n  File "/usr/lib/python3.4/socket.py", line 500, in create_connection\n    sock.connect(sa)\nTimeoutError: [Errno 110] Connection timed out\n')
('2015-03-21 11:30:41.813097', 'Traceback (most recent call last):\n  File "/river/fd/fd_worker/fd_channel.py", line 204, in create_channel\n    handle.connect()\n  File "/usr/lib/python3.4/http/client.py", line 1197, in connect\n    self.timeout, self.source_address)\n  File "/usr/lib/python3.4/socket.py", line 509, in create_connection\n    raise err\n  File "/usr/lib/python3.4/socket.py", line 500, in create_connection\n    sock.connect(sa)\nTimeoutError: [Errno 110] Connection timed out\n')
('2015-03-21 11:30:43.221176', 'Traceback (most recent call last):\n  File "/river/fd/fd_worker/fd_channel.py", line 204, in create_channel\n    handle.connect()\n  File "/usr/lib/python3.4/http/client.py", line 1197, in connect\n    self.timeout, self.source_address)\n  File "/usr/lib/python3.4/socket.py", line 509, in create_connection\n    raise err\n  File "/usr/lib/python3.4/socket.py", line 500, in create_connection\n    sock.connect(sa)\nTimeoutError: [Errno 110] Connection timed out\n')
('2015-03-21 11:30:43.221641', 'Traceback (most recent call last):\n  File "/river/fd/fd_worker/fd_channel.py", line 204, in create_channel\n    handle.connect()\n  File "/usr/lib/python3.4/http/client.py", line 1197, in connect\n    self.timeout, self.source_address)\n  File "/usr/lib/python3.4/socket.py", line 509, in create_connection\n    raise err\n  File "/usr/lib/python3.4/socket.py", line 500, in create_connection\n    sock.connect(sa)\nTimeoutError: [Errno 110] Connection timed out\n')
('2015-03-21 11:30:44.757079', 'Traceback (most recent call last):\n  File "/river/fd/fd_worker/fd_channel.py", line 204, in create_channel\n    handle.connect()\n  File "/usr/lib/python3.4/http/client.py", line 1197, in connect\n    self.timeout, self.source_address)\n  File "/usr/lib/python3.4/socket.py", line 509, in create_connection\n    raise err\n  File "/usr/lib/python3.4/socket.py", line 500, in create_connection\n    sock.connect(sa)\nTimeoutError: [Errno 110] Connection timed out\n')
('2015-03-21 11:30:46.293088', 'Traceback (most recent call last):\n  File "/river/fd/fd_worker/fd_channel.py", line 204, in create_channel\n    handle.connect()\n  File "/usr/lib/python3.4/http/client.py", line 1197, in connect\n    self.timeout, self.source_address)\n  File "/usr/lib/python3.4/socket.py", line 509, in create_connection\n    raise err\n  File "/usr/lib/python3.4/socket.py", line 500, in create_connection\n    sock.connect(sa)\nTimeoutError: [Errno 110] Connection timed out\n')
('2015-03-21 11:30:49.237085', 'Traceback (most recent call last):\n  File "/river/fd/fd_worker/fd_channel.py", line 204, in create_channel\n    handle.connect()\n  File "/usr/lib/python3.4/http/client.py", line 1197, in connect\n    self.timeout, self.source_address)\n  File "/usr/lib/python3.4/socket.py", line 509, in create_connection\n    raise err\n  File "/usr/lib/python3.4/socket.py", line 500, in create_connection\n    sock.connect(sa)\nTimeoutError: [Errno 110] Connection timed out\n')
('2015-03-21 11:30:53.717060', 'Traceback (most recent call last):\n  File "/river/fd/fd_worker/fd_channel.py", line 204, in create_channel\n    handle.connect()\n  File "/usr/lib/python3.4/http/client.py", line 1197, in connect\n    self.timeout, self.source_address)\n  File "/usr/lib/python3.4/socket.py", line 509, in create_connection\n    raise err\n  File "/usr/lib/python3.4/socket.py", line 500, in create_connection\n    sock.connect(sa)\nTimeoutError: [Errno 110] Connection timed out\n')
('2015-03-21 11:30:53.717572', 'Traceback (most recent call last):\n  File "/river/fd/fd_worker/fd_channel.py", line 204, in create_channel\n    handle.connect()\n  File "/usr/lib/python3.4/http/client.py", line 1197, in connect\n    self.timeout, self.source_address)\n  File "/usr/lib/python3.4/socket.py", line 509, in create_connection\n    raise err\n  File "/usr/lib/python3.4/socket.py", line 500, in create_connection\n    sock.connect(sa)\nTimeoutError: [Errno 110] Connection timed out\n')
('2015-03-21 11:30:55.253136', 'Traceback (most recent call last):\n  File "/river/fd/fd_worker/fd_channel.py", line 204, in create_channel\n    handle.connect()\n  File "/usr/lib/python3.4/http/client.py", line 1197, in connect\n    self.timeout, self.source_address)\n  File "/usr/lib/python3.4/socket.py", line 509, in create_connection\n    raise err\n  File "/usr/lib/python3.4/socket.py", line 500, in create_connection\n    sock.connect(sa)\nTimeoutError: [Errno 110] Connection timed out\n')
('2015-03-21 11:30:56.789070', 'Traceback (most recent call last):\n  File "/river/fd/fd_worker/fd_channel.py", line 204, in create_channel\n    handle.connect()\n  File "/usr/lib/python3.4/http/client.py", line 1197, in connect\n    self.timeout, self.source_address)\n  File "/usr/lib/python3.4/socket.py", line 509, in create_connection\n    raise err\n  File "/usr/lib/python3.4/socket.py", line 500, in create_connection\n    sock.connect(sa)\nTimeoutError: [Errno 110] Connection timed out\n')
('2015-03-21 11:30:58.197024', 'Traceback (most recent call last):\n  File "/river/fd/fd_worker/fd_channel.py", line 204, in create_channel\n    handle.connect()\n  File "/usr/lib/python3.4/http/client.py", line 1197, in connect\n    self.timeout, self.source_address)\n  File "/usr/lib/python3.4/socket.py", line 509, in create_connection\n    raise err\n  File "/usr/lib/python3.4/socket.py", line 500, in create_connection\n    sock.connect(sa)\nTimeoutError: [Errno 110] Connection timed out\n')
