('2015-02-07 10:33:27.071424', 'Traceback (most recent call last):\n  File "/river/fd/fd_worker/fd_channel.py", line 204, in create_channel\n    handle.connect()\n  File "/usr/lib/python3.4/http/client.py", line 1205, in connect\n    server_hostname=server_hostname)\n  File "/usr/lib/python3.4/ssl.py", line 364, in wrap_socket\n    _context=self)\n  File "/usr/lib/python3.4/ssl.py", line 578, in __init__\n    self.do_handshake()\n  File "/usr/lib/python3.4/ssl.py", line 805, in do_handshake\n    self._sslobj.do_handshake()\nConnectionResetError: [Errno 104] Connection reset by peer\n')
('2015-02-07 10:33:27.676003', 'Traceback (most recent call last):\n  File "/river/fd/fd_worker/fd_channel.py", line 204, in create_channel\n    handle.connect()\n  File "/usr/lib/python3.4/http/client.py", line 1205, in connect\n    server_hostname=server_hostname)\n  File "/usr/lib/python3.4/ssl.py", line 364, in wrap_socket\n    _context=self)\n  File "/usr/lib/python3.4/ssl.py", line 578, in __init__\n    self.do_handshake()\n  File "/usr/lib/python3.4/ssl.py", line 805, in do_handshake\n    self._sslobj.do_handshake()\nConnectionResetError: [Errno 104] Connection reset by peer\n')
('2015-02-07 10:33:29.180852', 'Traceback (most recent call last):\n  File "/river/fd/fd_worker/fd_channel.py", line 204, in create_channel\n    handle.connect()\n  File "/usr/lib/python3.4/http/client.py", line 1205, in connect\n    server_hostname=server_hostname)\n  File "/usr/lib/python3.4/ssl.py", line 364, in wrap_socket\n    _context=self)\n  File "/usr/lib/python3.4/ssl.py", line 578, in __init__\n    self.do_handshake()\n  File "/usr/lib/python3.4/ssl.py", line 805, in do_handshake\n    self._sslobj.do_handshake()\nConnectionResetError: [Errno 104] Connection reset by peer\n')
('2015-02-07 10:33:30.684218', 'Traceback (most recent call last):\n  File "/river/fd/fd_worker/fd_channel.py", line 204, in create_channel\n    handle.connect()\n  File "/usr/lib/python3.4/http/client.py", line 1205, in connect\n    server_hostname=server_hostname)\n  File "/usr/lib/python3.4/ssl.py", line 364, in wrap_socket\n    _context=self)\n  File "/usr/lib/python3.4/ssl.py", line 578, in __init__\n    self.do_handshake()\n  File "/usr/lib/python3.4/ssl.py", line 805, in do_handshake\n    self._sslobj.do_handshake()\nConnectionResetError: [Errno 104] Connection reset by peer\n')
('2015-02-07 10:33:31.084557', 'Traceback (most recent call last):\n  File "/river/fd/fd_worker/fd_channel.py", line 204, in create_channel\n    handle.connect()\n  File "/usr/lib/python3.4/http/client.py", line 1205, in connect\n    server_hostname=server_hostname)\n  File "/usr/lib/python3.4/ssl.py", line 364, in wrap_socket\n    _context=self)\n  File "/usr/lib/python3.4/ssl.py", line 578, in __init__\n    self.do_handshake()\n  File "/usr/lib/python3.4/ssl.py", line 805, in do_handshake\n    self._sslobj.do_handshake()\nConnectionResetError: [Errno 104] Connection reset by peer\n')
('2015-02-07 10:33:31.548729', 'Traceback (most recent call last):\n  File "/river/fd/fd_worker/fd_channel.py", line 204, in create_channel\n    handle.connect()\n  File "/usr/lib/python3.4/http/client.py", line 1205, in connect\n    server_hostname=server_hostname)\n  File "/usr/lib/python3.4/ssl.py", line 364, in wrap_socket\n    _context=self)\n  File "/usr/lib/python3.4/ssl.py", line 578, in __init__\n    self.do_handshake()\n  File "/usr/lib/python3.4/ssl.py", line 805, in do_handshake\n    self._sslobj.do_handshake()\nConnectionResetError: [Errno 104] Connection reset by peer\n')
('2015-02-07 10:33:32.156611', 'Traceback (most recent call last):\n  File "/river/fd/fd_worker/fd_channel.py", line 204, in create_channel\n    handle.connect()\n  File "/usr/lib/python3.4/http/client.py", line 1205, in connect\n    server_hostname=server_hostname)\n  File "/usr/lib/python3.4/ssl.py", line 364, in wrap_socket\n    _context=self)\n  File "/usr/lib/python3.4/ssl.py", line 578, in __init__\n    self.do_handshake()\n  File "/usr/lib/python3.4/ssl.py", line 805, in do_handshake\n    self._sslobj.do_handshake()\nConnectionResetError: [Errno 104] Connection reset by peer\n')
('2015-02-07 10:33:32.540634', 'Traceback (most recent call last):\n  File "/river/fd/fd_worker/fd_channel.py", line 204, in create_channel\n    handle.connect()\n  File "/usr/lib/python3.4/http/client.py", line 1205, in connect\n    server_hostname=server_hostname)\n  File "/usr/lib/python3.4/ssl.py", line 364, in wrap_socket\n    _context=self)\n  File "/usr/lib/python3.4/ssl.py", line 578, in __init__\n    self.do_handshake()\n  File "/usr/lib/python3.4/ssl.py", line 805, in do_handshake\n    self._sslobj.do_handshake()\nConnectionResetError: [Errno 104] Connection reset by peer\n')
('2015-02-07 10:33:35.164326', 'Traceback (most recent call last):\n  File "/river/fd/fd_worker/fd_channel.py", line 204, in create_channel\n    handle.connect()\n  File "/usr/lib/python3.4/http/client.py", line 1205, in connect\n    server_hostname=server_hostname)\n  File "/usr/lib/python3.4/ssl.py", line 364, in wrap_socket\n    _context=self)\n  File "/usr/lib/python3.4/ssl.py", line 578, in __init__\n    self.do_handshake()\n  File "/usr/lib/python3.4/ssl.py", line 805, in do_handshake\n    self._sslobj.do_handshake()\nConnectionResetError: [Errno 104] Connection reset by peer\n')
('2015-02-07 10:33:49.373040', 'Traceback (most recent call last):\n  File "/river/fd/fd_worker/fd_channel.py", line 204, in create_channel\n    handle.connect()\n  File "/usr/lib/python3.4/http/client.py", line 1205, in connect\n    server_hostname=server_hostname)\n  File "/usr/lib/python3.4/ssl.py", line 364, in wrap_socket\n    _context=self)\n  File "/usr/lib/python3.4/ssl.py", line 578, in __init__\n    self.do_handshake()\n  File "/usr/lib/python3.4/ssl.py", line 805, in do_handshake\n    self._sslobj.do_handshake()\nConnectionResetError: [Errno 104] Connection reset by peer\n')
('2015-02-07 10:33:50.844533', 'Traceback (most recent call last):\n  File "/river/fd/fd_worker/fd_channel.py", line 204, in create_channel\n    handle.connect()\n  File "/usr/lib/python3.4/http/client.py", line 1205, in connect\n    server_hostname=server_hostname)\n  File "/usr/lib/python3.4/ssl.py", line 364, in wrap_socket\n    _context=self)\n  File "/usr/lib/python3.4/ssl.py", line 578, in __init__\n    self.do_handshake()\n  File "/usr/lib/python3.4/ssl.py", line 805, in do_handshake\n    self._sslobj.do_handshake()\nConnectionResetError: [Errno 104] Connection reset by peer\n')
('2015-02-07 10:33:52.317058', 'Traceback (most recent call last):\n  File "/river/fd/fd_worker/fd_channel.py", line 204, in create_channel\n    handle.connect()\n  File "/usr/lib/python3.4/http/client.py", line 1205, in connect\n    server_hostname=server_hostname)\n  File "/usr/lib/python3.4/ssl.py", line 364, in wrap_socket\n    _context=self)\n  File "/usr/lib/python3.4/ssl.py", line 578, in __init__\n    self.do_handshake()\n  File "/usr/lib/python3.4/ssl.py", line 805, in do_handshake\n    self._sslobj.do_handshake()\nConnectionResetError: [Errno 104] Connection reset by peer\n')
('2015-02-07 10:34:29.180853', 'Traceback (most recent call last):\n  File "/river/fd/fd_worker/fd_channel.py", line 204, in create_channel\n    handle.connect()\n  File "/usr/lib/python3.4/http/client.py", line 1205, in connect\n    server_hostname=server_hostname)\n  File "/usr/lib/python3.4/ssl.py", line 364, in wrap_socket\n    _context=self)\n  File "/usr/lib/python3.4/ssl.py", line 578, in __init__\n    self.do_handshake()\n  File "/usr/lib/python3.4/ssl.py", line 805, in do_handshake\n    self._sslobj.do_handshake()\nConnectionResetError: [Errno 104] Connection reset by peer\n')
('2015-02-07 10:34:30.684888', 'Traceback (most recent call last):\n  File "/river/fd/fd_worker/fd_channel.py", line 204, in create_channel\n    handle.connect()\n  File "/usr/lib/python3.4/http/client.py", line 1205, in connect\n    server_hostname=server_hostname)\n  File "/usr/lib/python3.4/ssl.py", line 364, in wrap_socket\n    _context=self)\n  File "/usr/lib/python3.4/ssl.py", line 578, in __init__\n    self.do_handshake()\n  File "/usr/lib/python3.4/ssl.py", line 805, in do_handshake\n    self._sslobj.do_handshake()\nConnectionResetError: [Errno 104] Connection reset by peer\n')
('2015-02-07 10:34:32.188916', 'Traceback (most recent call last):\n  File "/river/fd/fd_worker/fd_channel.py", line 204, in create_channel\n    handle.connect()\n  File "/usr/lib/python3.4/http/client.py", line 1205, in connect\n    server_hostname=server_hostname)\n  File "/usr/lib/python3.4/ssl.py", line 364, in wrap_socket\n    _context=self)\n  File "/usr/lib/python3.4/ssl.py", line 578, in __init__\n    self.do_handshake()\n  File "/usr/lib/python3.4/ssl.py", line 805, in do_handshake\n    self._sslobj.do_handshake()\nConnectionResetError: [Errno 104] Connection reset by peer\n')
('2015-02-07 10:34:33.659961', 'Traceback (most recent call last):\n  File "/river/fd/fd_worker/fd_channel.py", line 204, in create_channel\n    handle.connect()\n  File "/usr/lib/python3.4/http/client.py", line 1205, in connect\n    server_hostname=server_hostname)\n  File "/usr/lib/python3.4/ssl.py", line 364, in wrap_socket\n    _context=self)\n  File "/usr/lib/python3.4/ssl.py", line 578, in __init__\n    self.do_handshake()\n  File "/usr/lib/python3.4/ssl.py", line 805, in do_handshake\n    self._sslobj.do_handshake()\nConnectionResetError: [Errno 104] Connection reset by peer\n')
('2015-02-07 10:34:48.124080', 'Traceback (most recent call last):\n  File "/river/fd/fd_worker/fd_channel.py", line 204, in create_channel\n    handle.connect()\n  File "/usr/lib/python3.4/http/client.py", line 1205, in connect\n    server_hostname=server_hostname)\n  File "/usr/lib/python3.4/ssl.py", line 364, in wrap_socket\n    _context=self)\n  File "/usr/lib/python3.4/ssl.py", line 578, in __init__\n    self.do_handshake()\n  File "/usr/lib/python3.4/ssl.py", line 805, in do_handshake\n    self._sslobj.do_handshake()\nConnectionResetError: [Errno 104] Connection reset by peer\n')
('2015-02-07 10:34:49.596580', 'Traceback (most recent call last):\n  File "/river/fd/fd_worker/fd_channel.py", line 204, in create_channel\n    handle.connect()\n  File "/usr/lib/python3.4/http/client.py", line 1205, in connect\n    server_hostname=server_hostname)\n  File "/usr/lib/python3.4/ssl.py", line 364, in wrap_socket\n    _context=self)\n  File "/usr/lib/python3.4/ssl.py", line 578, in __init__\n    self.do_handshake()\n  File "/usr/lib/python3.4/ssl.py", line 805, in do_handshake\n    self._sslobj.do_handshake()\nConnectionResetError: [Errno 104] Connection reset by peer\n')
('2015-02-07 10:35:11.816166', 'Traceback (most recent call last):\n  File "/river/fd/fd_worker/fd_channel.py", line 204, in create_channel\n    handle.connect()\n  File "/usr/lib/python3.4/http/client.py", line 1197, in connect\n    self.timeout, self.source_address)\n  File "/usr/lib/python3.4/socket.py", line 509, in create_connection\n    raise err\n  File "/usr/lib/python3.4/socket.py", line 500, in create_connection\n    sock.connect(sa)\nTimeoutError: [Errno 110] Connection timed out\n')
('2015-02-07 10:35:13.211083', 'Traceback (most recent call last):\n  File "/river/fd/fd_worker/fd_channel.py", line 204, in create_channel\n    handle.connect()\n  File "/usr/lib/python3.4/http/client.py", line 1197, in connect\n    self.timeout, self.source_address)\n  File "/usr/lib/python3.4/socket.py", line 509, in create_connection\n    raise err\n  File "/usr/lib/python3.4/socket.py", line 500, in create_connection\n    sock.connect(sa)\nTimeoutError: [Errno 110] Connection timed out\n')
('2015-02-07 10:35:14.747224', 'Traceback (most recent call last):\n  File "/river/fd/fd_worker/fd_channel.py", line 204, in create_channel\n    handle.connect()\n  File "/usr/lib/python3.4/http/client.py", line 1197, in connect\n    self.timeout, self.source_address)\n  File "/usr/lib/python3.4/socket.py", line 509, in create_connection\n    raise err\n  File "/usr/lib/python3.4/socket.py", line 500, in create_connection\n    sock.connect(sa)\nTimeoutError: [Errno 110] Connection timed out\n')
('2015-02-07 10:35:38.683139', 'Traceback (most recent call last):\n  File "/river/fd/fd_worker/fd_channel.py", line 204, in create_channel\n    handle.connect()\n  File "/usr/lib/python3.4/http/client.py", line 1197, in connect\n    self.timeout, self.source_address)\n  File "/usr/lib/python3.4/socket.py", line 509, in create_connection\n    raise err\n  File "/usr/lib/python3.4/socket.py", line 500, in create_connection\n    sock.connect(sa)\nTimeoutError: [Errno 110] Connection timed out\n')
('2015-02-07 10:35:46.492017', 'Traceback (most recent call last):\n  File "/river/fd/fd_worker/fd_channel.py", line 144, in pyget\n    ack  = handle.getresponse()\n  File "/usr/lib/python3.4/http/client.py", line 1147, in getresponse\n    response.begin()\n  File "/usr/lib/python3.4/http/client.py", line 351, in begin\n    version, status, reason = self._read_status()\n  File "/usr/lib/python3.4/http/client.py", line 313, in _read_status\n    line = str(self.fp.readline(_MAXLINE + 1), "iso-8859-1")\n  File "/usr/lib/python3.4/socket.py", line 371, in readinto\n    return self._sock.recv_into(b)\n  File "/usr/lib/python3.4/ssl.py", line 746, in recv_into\n    return self.read(nbytes, buffer)\n  File "/usr/lib/python3.4/ssl.py", line 618, in read\n    v = self._sslobj.read(len, buffer)\nConnectionResetError: [Errno 104] Connection reset by peer\n')
('2015-02-07 10:35:59.675212', 'Traceback (most recent call last):\n  File "/river/fd/fd_worker/fd_channel.py", line 204, in create_channel\n    handle.connect()\n  File "/usr/lib/python3.4/http/client.py", line 1197, in connect\n    self.timeout, self.source_address)\n  File "/usr/lib/python3.4/socket.py", line 509, in create_connection\n    raise err\n  File "/usr/lib/python3.4/socket.py", line 500, in create_connection\n    sock.connect(sa)\nTimeoutError: [Errno 110] Connection timed out\n')
('2015-02-07 10:36:02.747316', 'Traceback (most recent call last):\n  File "/river/fd/fd_worker/fd_channel.py", line 204, in create_channel\n    handle.connect()\n  File "/usr/lib/python3.4/http/client.py", line 1197, in connect\n    self.timeout, self.source_address)\n  File "/usr/lib/python3.4/socket.py", line 509, in create_connection\n    raise err\n  File "/usr/lib/python3.4/socket.py", line 500, in create_connection\n    sock.connect(sa)\nTimeoutError: [Errno 110] Connection timed out\n')
('2015-02-07 10:36:04.283251', 'Traceback (most recent call last):\n  File "/river/fd/fd_worker/fd_channel.py", line 204, in create_channel\n    handle.connect()\n  File "/usr/lib/python3.4/http/client.py", line 1197, in connect\n    self.timeout, self.source_address)\n  File "/usr/lib/python3.4/socket.py", line 509, in create_connection\n    raise err\n  File "/usr/lib/python3.4/socket.py", line 500, in create_connection\n    sock.connect(sa)\nTimeoutError: [Errno 110] Connection timed out\n')
('2015-02-07 10:36:05.819166', 'Traceback (most recent call last):\n  File "/river/fd/fd_worker/fd_channel.py", line 204, in create_channel\n    handle.connect()\n  File "/usr/lib/python3.4/http/client.py", line 1197, in connect\n    self.timeout, self.source_address)\n  File "/usr/lib/python3.4/socket.py", line 509, in create_connection\n    raise err\n  File "/usr/lib/python3.4/socket.py", line 500, in create_connection\n    sock.connect(sa)\nTimeoutError: [Errno 110] Connection timed out\n')
('2015-02-07 10:36:29.755181', 'Traceback (most recent call last):\n  File "/river/fd/fd_worker/fd_channel.py", line 204, in create_channel\n    handle.connect()\n  File "/usr/lib/python3.4/http/client.py", line 1197, in connect\n    self.timeout, self.source_address)\n  File "/usr/lib/python3.4/socket.py", line 509, in create_connection\n    raise err\n  File "/usr/lib/python3.4/socket.py", line 500, in create_connection\n    sock.connect(sa)\nTimeoutError: [Errno 110] Connection timed out\n')
('2015-02-07 10:36:31.291320', 'Traceback (most recent call last):\n  File "/river/fd/fd_worker/fd_channel.py", line 204, in create_channel\n    handle.connect()\n  File "/usr/lib/python3.4/http/client.py", line 1197, in connect\n    self.timeout, self.source_address)\n  File "/usr/lib/python3.4/socket.py", line 509, in create_connection\n    raise err\n  File "/usr/lib/python3.4/socket.py", line 500, in create_connection\n    sock.connect(sa)\nTimeoutError: [Errno 110] Connection timed out\n')
('2015-02-07 10:36:32.699209', 'Traceback (most recent call last):\n  File "/river/fd/fd_worker/fd_channel.py", line 204, in create_channel\n    handle.connect()\n  File "/usr/lib/python3.4/http/client.py", line 1197, in connect\n    self.timeout, self.source_address)\n  File "/usr/lib/python3.4/socket.py", line 509, in create_connection\n    raise err\n  File "/usr/lib/python3.4/socket.py", line 500, in create_connection\n    sock.connect(sa)\nTimeoutError: [Errno 110] Connection timed out\n')
('2015-02-07 10:36:34.235602', 'Traceback (most recent call last):\n  File "/river/fd/fd_worker/fd_channel.py", line 204, in create_channel\n    handle.connect()\n  File "/usr/lib/python3.4/http/client.py", line 1197, in connect\n    self.timeout, self.source_address)\n  File "/usr/lib/python3.4/socket.py", line 509, in create_connection\n    raise err\n  File "/usr/lib/python3.4/socket.py", line 500, in create_connection\n    sock.connect(sa)\nTimeoutError: [Errno 110] Connection timed out\n')
('2015-02-07 10:36:35.771423', 'Traceback (most recent call last):\n  File "/river/fd/fd_worker/fd_channel.py", line 204, in create_channel\n    handle.connect()\n  File "/usr/lib/python3.4/http/client.py", line 1197, in connect\n    self.timeout, self.source_address)\n  File "/usr/lib/python3.4/socket.py", line 509, in create_connection\n    raise err\n  File "/usr/lib/python3.4/socket.py", line 500, in create_connection\n    sock.connect(sa)\nTimeoutError: [Errno 110] Connection timed out\n')
('2015-02-07 10:36:37.307368', 'Traceback (most recent call last):\n  File "/river/fd/fd_worker/fd_channel.py", line 204, in create_channel\n    handle.connect()\n  File "/usr/lib/python3.4/http/client.py", line 1197, in connect\n    self.timeout, self.source_address)\n  File "/usr/lib/python3.4/socket.py", line 509, in create_connection\n    raise err\n  File "/usr/lib/python3.4/socket.py", line 500, in create_connection\n    sock.connect(sa)\nTimeoutError: [Errno 110] Connection timed out\n')
('2015-02-07 10:36:38.715167', 'Traceback (most recent call last):\n  File "/river/fd/fd_worker/fd_channel.py", line 204, in create_channel\n    handle.connect()\n  File "/usr/lib/python3.4/http/client.py", line 1197, in connect\n    self.timeout, self.source_address)\n  File "/usr/lib/python3.4/socket.py", line 509, in create_connection\n    raise err\n  File "/usr/lib/python3.4/socket.py", line 500, in create_connection\n    sock.connect(sa)\nTimeoutError: [Errno 110] Connection timed out\n')
('2015-02-07 10:37:01.243623', 'Traceback (most recent call last):\n  File "/river/fd/fd_worker/fd_channel.py", line 204, in create_channel\n    handle.connect()\n  File "/usr/lib/python3.4/http/client.py", line 1197, in connect\n    self.timeout, self.source_address)\n  File "/usr/lib/python3.4/socket.py", line 509, in create_connection\n    raise err\n  File "/usr/lib/python3.4/socket.py", line 500, in create_connection\n    sock.connect(sa)\nTimeoutError: [Errno 110] Connection timed out\n')
('2015-02-07 10:37:01.244239', 'Traceback (most recent call last):\n  File "/river/fd/fd_worker/fd_channel.py", line 204, in create_channel\n    handle.connect()\n  File "/usr/lib/python3.4/http/client.py", line 1197, in connect\n    self.timeout, self.source_address)\n  File "/usr/lib/python3.4/socket.py", line 509, in create_connection\n    raise err\n  File "/usr/lib/python3.4/socket.py", line 500, in create_connection\n    sock.connect(sa)\nTimeoutError: [Errno 110] Connection timed out\n')
('2015-02-07 10:37:02.779185', 'Traceback (most recent call last):\n  File "/river/fd/fd_worker/fd_channel.py", line 204, in create_channel\n    handle.connect()\n  File "/usr/lib/python3.4/http/client.py", line 1197, in connect\n    self.timeout, self.source_address)\n  File "/usr/lib/python3.4/socket.py", line 509, in create_connection\n    raise err\n  File "/usr/lib/python3.4/socket.py", line 500, in create_connection\n    sock.connect(sa)\nTimeoutError: [Errno 110] Connection timed out\n')
('2015-02-07 10:37:02.779481', 'Traceback (most recent call last):\n  File "/river/fd/fd_worker/fd_channel.py", line 204, in create_channel\n    handle.connect()\n  File "/usr/lib/python3.4/http/client.py", line 1197, in connect\n    self.timeout, self.source_address)\n  File "/usr/lib/python3.4/socket.py", line 509, in create_connection\n    raise err\n  File "/usr/lib/python3.4/socket.py", line 500, in create_connection\n    sock.connect(sa)\nTimeoutError: [Errno 110] Connection timed out\n')
('2015-02-07 10:37:04.187213', 'Traceback (most recent call last):\n  File "/river/fd/fd_worker/fd_channel.py", line 204, in create_channel\n    handle.connect()\n  File "/usr/lib/python3.4/http/client.py", line 1197, in connect\n    self.timeout, self.source_address)\n  File "/usr/lib/python3.4/socket.py", line 509, in create_connection\n    raise err\n  File "/usr/lib/python3.4/socket.py", line 500, in create_connection\n    sock.connect(sa)\nTimeoutError: [Errno 110] Connection timed out\n')
('2015-02-07 10:37:05.723123', 'Traceback (most recent call last):\n  File "/river/fd/fd_worker/fd_channel.py", line 204, in create_channel\n    handle.connect()\n  File "/usr/lib/python3.4/http/client.py", line 1197, in connect\n    self.timeout, self.source_address)\n  File "/usr/lib/python3.4/socket.py", line 509, in create_connection\n    raise err\n  File "/usr/lib/python3.4/socket.py", line 500, in create_connection\n    sock.connect(sa)\nTimeoutError: [Errno 110] Connection timed out\n')
('2015-02-07 10:37:07.259122', 'Traceback (most recent call last):\n  File "/river/fd/fd_worker/fd_channel.py", line 204, in create_channel\n    handle.connect()\n  File "/usr/lib/python3.4/http/client.py", line 1197, in connect\n    self.timeout, self.source_address)\n  File "/usr/lib/python3.4/socket.py", line 509, in create_connection\n    raise err\n  File "/usr/lib/python3.4/socket.py", line 500, in create_connection\n    sock.connect(sa)\nTimeoutError: [Errno 110] Connection timed out\n')
('2015-02-07 10:37:08.407980', 'Traceback (most recent call last):\n  File "/river/fd/fd_worker/fd_channel.py", line 144, in pyget\n    ack  = handle.getresponse()\n  File "/usr/lib/python3.4/http/client.py", line 1147, in getresponse\n    response.begin()\n  File "/usr/lib/python3.4/http/client.py", line 351, in begin\n    version, status, reason = self._read_status()\n  File "/usr/lib/python3.4/http/client.py", line 321, in _read_status\n    raise BadStatusLine(line)\nhttp.client.BadStatusLine: \'\'\n')
('2015-02-07 10:37:08.795189', 'Traceback (most recent call last):\n  File "/river/fd/fd_worker/fd_channel.py", line 204, in create_channel\n    handle.connect()\n  File "/usr/lib/python3.4/http/client.py", line 1197, in connect\n    self.timeout, self.source_address)\n  File "/usr/lib/python3.4/socket.py", line 509, in create_connection\n    raise err\n  File "/usr/lib/python3.4/socket.py", line 500, in create_connection\n    sock.connect(sa)\nTimeoutError: [Errno 110] Connection timed out\n')
('2015-02-07 10:37:08.795811', 'Traceback (most recent call last):\n  File "/river/fd/fd_worker/fd_channel.py", line 204, in create_channel\n    handle.connect()\n  File "/usr/lib/python3.4/http/client.py", line 1197, in connect\n    self.timeout, self.source_address)\n  File "/usr/lib/python3.4/socket.py", line 509, in create_connection\n    raise err\n  File "/usr/lib/python3.4/socket.py", line 500, in create_connection\n    sock.connect(sa)\nTimeoutError: [Errno 110] Connection timed out\n')
('2015-02-07 10:37:12.254657', 'Traceback (most recent call last):\n  File "/river/fd/fd_worker/fd_channel.py", line 144, in pyget\n    ack  = handle.getresponse()\n  File "/usr/lib/python3.4/http/client.py", line 1147, in getresponse\n    response.begin()\n  File "/usr/lib/python3.4/http/client.py", line 351, in begin\n    version, status, reason = self._read_status()\n  File "/usr/lib/python3.4/http/client.py", line 321, in _read_status\n    raise BadStatusLine(line)\nhttp.client.BadStatusLine: \'\'\n')
('2015-02-07 10:37:22.761225', 'Traceback (most recent call last):\n  File "/river/fd/fd_worker/fd_channel.py", line 144, in pyget\n    ack  = handle.getresponse()\n  File "/usr/lib/python3.4/http/client.py", line 1147, in getresponse\n    response.begin()\n  File "/usr/lib/python3.4/http/client.py", line 351, in begin\n    version, status, reason = self._read_status()\n  File "/usr/lib/python3.4/http/client.py", line 321, in _read_status\n    raise BadStatusLine(line)\nhttp.client.BadStatusLine: \'\'\n')
('2015-02-07 10:37:22.842156', 'Traceback (most recent call last):\n  File "/river/fd/fd_worker/fd_channel.py", line 144, in pyget\n    ack  = handle.getresponse()\n  File "/usr/lib/python3.4/http/client.py", line 1147, in getresponse\n    response.begin()\n  File "/usr/lib/python3.4/http/client.py", line 351, in begin\n    version, status, reason = self._read_status()\n  File "/usr/lib/python3.4/http/client.py", line 321, in _read_status\n    raise BadStatusLine(line)\nhttp.client.BadStatusLine: \'\'\n')
('2015-02-07 10:37:23.771150', 'Traceback (most recent call last):\n  File "/river/fd/fd_worker/fd_channel.py", line 204, in create_channel\n    handle.connect()\n  File "/usr/lib/python3.4/http/client.py", line 1197, in connect\n    self.timeout, self.source_address)\n  File "/usr/lib/python3.4/socket.py", line 509, in create_connection\n    raise err\n  File "/usr/lib/python3.4/socket.py", line 500, in create_connection\n    sock.connect(sa)\nTimeoutError: [Errno 110] Connection timed out\n')
('2015-02-07 10:37:25.179404', 'Traceback (most recent call last):\n  File "/river/fd/fd_worker/fd_channel.py", line 204, in create_channel\n    handle.connect()\n  File "/usr/lib/python3.4/http/client.py", line 1197, in connect\n    self.timeout, self.source_address)\n  File "/usr/lib/python3.4/socket.py", line 509, in create_connection\n    raise err\n  File "/usr/lib/python3.4/socket.py", line 500, in create_connection\n    sock.connect(sa)\nTimeoutError: [Errno 110] Connection timed out\n')
('2015-02-07 10:37:25.400604', 'Traceback (most recent call last):\n  File "/river/fd/fd_worker/fd_channel.py", line 144, in pyget\n    ack  = handle.getresponse()\n  File "/usr/lib/python3.4/http/client.py", line 1147, in getresponse\n    response.begin()\n  File "/usr/lib/python3.4/http/client.py", line 351, in begin\n    version, status, reason = self._read_status()\n  File "/usr/lib/python3.4/http/client.py", line 321, in _read_status\n    raise BadStatusLine(line)\nhttp.client.BadStatusLine: \'\'\n')
('2015-02-07 10:37:26.715127', 'Traceback (most recent call last):\n  File "/river/fd/fd_worker/fd_channel.py", line 204, in create_channel\n    handle.connect()\n  File "/usr/lib/python3.4/http/client.py", line 1197, in connect\n    self.timeout, self.source_address)\n  File "/usr/lib/python3.4/socket.py", line 509, in create_connection\n    raise err\n  File "/usr/lib/python3.4/socket.py", line 500, in create_connection\n    sock.connect(sa)\nTimeoutError: [Errno 110] Connection timed out\n')
('2015-02-07 10:37:28.251229', 'Traceback (most recent call last):\n  File "/river/fd/fd_worker/fd_channel.py", line 204, in create_channel\n    handle.connect()\n  File "/usr/lib/python3.4/http/client.py", line 1197, in connect\n    self.timeout, self.source_address)\n  File "/usr/lib/python3.4/socket.py", line 509, in create_connection\n    raise err\n  File "/usr/lib/python3.4/socket.py", line 500, in create_connection\n    sock.connect(sa)\nTimeoutError: [Errno 110] Connection timed out\n')
('2015-02-07 10:37:29.787132', 'Traceback (most recent call last):\n  File "/river/fd/fd_worker/fd_channel.py", line 204, in create_channel\n    handle.connect()\n  File "/usr/lib/python3.4/http/client.py", line 1197, in connect\n    self.timeout, self.source_address)\n  File "/usr/lib/python3.4/socket.py", line 509, in create_connection\n    raise err\n  File "/usr/lib/python3.4/socket.py", line 500, in create_connection\n    sock.connect(sa)\nTimeoutError: [Errno 110] Connection timed out\n')
('2015-02-07 10:37:30.490616', 'Traceback (most recent call last):\n  File "/river/fd/fd_worker/fd_channel.py", line 144, in pyget\n    ack  = handle.getresponse()\n  File "/usr/lib/python3.4/http/client.py", line 1147, in getresponse\n    response.begin()\n  File "/usr/lib/python3.4/http/client.py", line 351, in begin\n    version, status, reason = self._read_status()\n  File "/usr/lib/python3.4/http/client.py", line 321, in _read_status\n    raise BadStatusLine(line)\nhttp.client.BadStatusLine: \'\'\n')
('2015-02-07 10:37:31.323150', 'Traceback (most recent call last):\n  File "/river/fd/fd_worker/fd_channel.py", line 204, in create_channel\n    handle.connect()\n  File "/usr/lib/python3.4/http/client.py", line 1197, in connect\n    self.timeout, self.source_address)\n  File "/usr/lib/python3.4/socket.py", line 509, in create_connection\n    raise err\n  File "/usr/lib/python3.4/socket.py", line 500, in create_connection\n    sock.connect(sa)\nTimeoutError: [Errno 110] Connection timed out\n')
('2015-02-07 10:37:32.731188', 'Traceback (most recent call last):\n  File "/river/fd/fd_worker/fd_channel.py", line 204, in create_channel\n    handle.connect()\n  File "/usr/lib/python3.4/http/client.py", line 1197, in connect\n    self.timeout, self.source_address)\n  File "/usr/lib/python3.4/socket.py", line 509, in create_connection\n    raise err\n  File "/usr/lib/python3.4/socket.py", line 500, in create_connection\n    sock.connect(sa)\nTimeoutError: [Errno 110] Connection timed out\n')
('2015-02-07 10:37:34.267383', 'Traceback (most recent call last):\n  File "/river/fd/fd_worker/fd_channel.py", line 204, in create_channel\n    handle.connect()\n  File "/usr/lib/python3.4/http/client.py", line 1197, in connect\n    self.timeout, self.source_address)\n  File "/usr/lib/python3.4/socket.py", line 509, in create_connection\n    raise err\n  File "/usr/lib/python3.4/socket.py", line 500, in create_connection\n    sock.connect(sa)\nTimeoutError: [Errno 110] Connection timed out\n')
('2015-02-07 10:37:35.675127', 'Traceback (most recent call last):\n  File "/river/fd/fd_worker/fd_channel.py", line 204, in create_channel\n    handle.connect()\n  File "/usr/lib/python3.4/http/client.py", line 1197, in connect\n    self.timeout, self.source_address)\n  File "/usr/lib/python3.4/socket.py", line 509, in create_connection\n    raise err\n  File "/usr/lib/python3.4/socket.py", line 500, in create_connection\n    sock.connect(sa)\nTimeoutError: [Errno 110] Connection timed out\n')
('2015-02-07 10:37:37.211350', 'Traceback (most recent call last):\n  File "/river/fd/fd_worker/fd_channel.py", line 204, in create_channel\n    handle.connect()\n  File "/usr/lib/python3.4/http/client.py", line 1197, in connect\n    self.timeout, self.source_address)\n  File "/usr/lib/python3.4/socket.py", line 509, in create_connection\n    raise err\n  File "/usr/lib/python3.4/socket.py", line 500, in create_connection\n    sock.connect(sa)\nTimeoutError: [Errno 110] Connection timed out\n')
('2015-02-07 10:37:38.747252', 'Traceback (most recent call last):\n  File "/river/fd/fd_worker/fd_channel.py", line 204, in create_channel\n    handle.connect()\n  File "/usr/lib/python3.4/http/client.py", line 1197, in connect\n    self.timeout, self.source_address)\n  File "/usr/lib/python3.4/socket.py", line 509, in create_connection\n    raise err\n  File "/usr/lib/python3.4/socket.py", line 500, in create_connection\n    sock.connect(sa)\nTimeoutError: [Errno 110] Connection timed out\n')
('2015-02-07 10:37:40.283194', 'Traceback (most recent call last):\n  File "/river/fd/fd_worker/fd_channel.py", line 204, in create_channel\n    handle.connect()\n  File "/usr/lib/python3.4/http/client.py", line 1197, in connect\n    self.timeout, self.source_address)\n  File "/usr/lib/python3.4/socket.py", line 509, in create_connection\n    raise err\n  File "/usr/lib/python3.4/socket.py", line 500, in create_connection\n    sock.connect(sa)\nTimeoutError: [Errno 110] Connection timed out\n')
('2015-02-07 10:37:41.819167', 'Traceback (most recent call last):\n  File "/river/fd/fd_worker/fd_channel.py", line 204, in create_channel\n    handle.connect()\n  File "/usr/lib/python3.4/http/client.py", line 1197, in connect\n    self.timeout, self.source_address)\n  File "/usr/lib/python3.4/socket.py", line 509, in create_connection\n    raise err\n  File "/usr/lib/python3.4/socket.py", line 500, in create_connection\n    sock.connect(sa)\nTimeoutError: [Errno 110] Connection timed out\n')
('2015-02-07 10:37:49.243337', 'Traceback (most recent call last):\n  File "/river/fd/fd_worker/fd_channel.py", line 204, in create_channel\n    handle.connect()\n  File "/usr/lib/python3.4/http/client.py", line 1197, in connect\n    self.timeout, self.source_address)\n  File "/usr/lib/python3.4/socket.py", line 509, in create_connection\n    raise err\n  File "/usr/lib/python3.4/socket.py", line 500, in create_connection\n    sock.connect(sa)\nTimeoutError: [Errno 110] Connection timed out\n')
('2015-02-07 10:37:50.779214', 'Traceback (most recent call last):\n  File "/river/fd/fd_worker/fd_channel.py", line 204, in create_channel\n    handle.connect()\n  File "/usr/lib/python3.4/http/client.py", line 1197, in connect\n    self.timeout, self.source_address)\n  File "/usr/lib/python3.4/socket.py", line 509, in create_connection\n    raise err\n  File "/usr/lib/python3.4/socket.py", line 500, in create_connection\n    sock.connect(sa)\nTimeoutError: [Errno 110] Connection timed out\n')
('2015-02-07 10:37:52.315501', 'Traceback (most recent call last):\n  File "/river/fd/fd_worker/fd_channel.py", line 204, in create_channel\n    handle.connect()\n  File "/usr/lib/python3.4/http/client.py", line 1197, in connect\n    self.timeout, self.source_address)\n  File "/usr/lib/python3.4/socket.py", line 509, in create_connection\n    raise err\n  File "/usr/lib/python3.4/socket.py", line 500, in create_connection\n    sock.connect(sa)\nTimeoutError: [Errno 110] Connection timed out\n')
('2015-02-07 10:37:53.723383', 'Traceback (most recent call last):\n  File "/river/fd/fd_worker/fd_channel.py", line 204, in create_channel\n    handle.connect()\n  File "/usr/lib/python3.4/http/client.py", line 1197, in connect\n    self.timeout, self.source_address)\n  File "/usr/lib/python3.4/socket.py", line 509, in create_connection\n    raise err\n  File "/usr/lib/python3.4/socket.py", line 500, in create_connection\n    sock.connect(sa)\nTimeoutError: [Errno 110] Connection timed out\n')
('2015-02-07 10:37:55.259239', 'Traceback (most recent call last):\n  File "/river/fd/fd_worker/fd_channel.py", line 204, in create_channel\n    handle.connect()\n  File "/usr/lib/python3.4/http/client.py", line 1197, in connect\n    self.timeout, self.source_address)\n  File "/usr/lib/python3.4/socket.py", line 509, in create_connection\n    raise err\n  File "/usr/lib/python3.4/socket.py", line 500, in create_connection\n    sock.connect(sa)\nTimeoutError: [Errno 110] Connection timed out\n')
('2015-02-07 10:37:55.259792', 'Traceback (most recent call last):\n  File "/river/fd/fd_worker/fd_channel.py", line 204, in create_channel\n    handle.connect()\n  File "/usr/lib/python3.4/http/client.py", line 1197, in connect\n    self.timeout, self.source_address)\n  File "/usr/lib/python3.4/socket.py", line 509, in create_connection\n    raise err\n  File "/usr/lib/python3.4/socket.py", line 500, in create_connection\n    sock.connect(sa)\nTimeoutError: [Errno 110] Connection timed out\n')
('2015-02-07 10:37:56.667230', 'Traceback (most recent call last):\n  File "/river/fd/fd_worker/fd_channel.py", line 204, in create_channel\n    handle.connect()\n  File "/usr/lib/python3.4/http/client.py", line 1197, in connect\n    self.timeout, self.source_address)\n  File "/usr/lib/python3.4/socket.py", line 509, in create_connection\n    raise err\n  File "/usr/lib/python3.4/socket.py", line 500, in create_connection\n    sock.connect(sa)\nTimeoutError: [Errno 110] Connection timed out\n')
('2015-02-07 10:37:56.667699', 'Traceback (most recent call last):\n  File "/river/fd/fd_worker/fd_channel.py", line 204, in create_channel\n    handle.connect()\n  File "/usr/lib/python3.4/http/client.py", line 1197, in connect\n    self.timeout, self.source_address)\n  File "/usr/lib/python3.4/socket.py", line 509, in create_connection\n    raise err\n  File "/usr/lib/python3.4/socket.py", line 500, in create_connection\n    sock.connect(sa)\nTimeoutError: [Errno 110] Connection timed out\n')
('2015-02-07 10:37:58.203550', 'Traceback (most recent call last):\n  File "/river/fd/fd_worker/fd_channel.py", line 204, in create_channel\n    handle.connect()\n  File "/usr/lib/python3.4/http/client.py", line 1197, in connect\n    self.timeout, self.source_address)\n  File "/usr/lib/python3.4/socket.py", line 509, in create_connection\n    raise err\n  File "/usr/lib/python3.4/socket.py", line 500, in create_connection\n    sock.connect(sa)\nTimeoutError: [Errno 110] Connection timed out\n')
('2015-02-07 10:37:59.739221', 'Traceback (most recent call last):\n  File "/river/fd/fd_worker/fd_channel.py", line 204, in create_channel\n    handle.connect()\n  File "/usr/lib/python3.4/http/client.py", line 1197, in connect\n    self.timeout, self.source_address)\n  File "/usr/lib/python3.4/socket.py", line 509, in create_connection\n    raise err\n  File "/usr/lib/python3.4/socket.py", line 500, in create_connection\n    sock.connect(sa)\nTimeoutError: [Errno 110] Connection timed out\n')
('2015-02-07 10:38:01.275392', 'Traceback (most recent call last):\n  File "/river/fd/fd_worker/fd_channel.py", line 204, in create_channel\n    handle.connect()\n  File "/usr/lib/python3.4/http/client.py", line 1197, in connect\n    self.timeout, self.source_address)\n  File "/usr/lib/python3.4/socket.py", line 509, in create_connection\n    raise err\n  File "/usr/lib/python3.4/socket.py", line 500, in create_connection\n    sock.connect(sa)\nTimeoutError: [Errno 110] Connection timed out\n')
('2015-02-07 10:38:01.276167', 'Traceback (most recent call last):\n  File "/river/fd/fd_worker/fd_channel.py", line 144, in pyget\n    ack  = handle.getresponse()\n  File "/usr/lib/python3.4/http/client.py", line 1147, in getresponse\n    response.begin()\n  File "/usr/lib/python3.4/http/client.py", line 351, in begin\n    version, status, reason = self._read_status()\n  File "/usr/lib/python3.4/http/client.py", line 313, in _read_status\n    line = str(self.fp.readline(_MAXLINE + 1), "iso-8859-1")\n  File "/usr/lib/python3.4/socket.py", line 371, in readinto\n    return self._sock.recv_into(b)\n  File "/usr/lib/python3.4/ssl.py", line 746, in recv_into\n    return self.read(nbytes, buffer)\n  File "/usr/lib/python3.4/ssl.py", line 618, in read\n    v = self._sslobj.read(len, buffer)\nConnectionResetError: [Errno 104] Connection reset by peer\n')
('2015-02-07 10:38:02.811382', 'Traceback (most recent call last):\n  File "/river/fd/fd_worker/fd_channel.py", line 204, in create_channel\n    handle.connect()\n  File "/usr/lib/python3.4/http/client.py", line 1197, in connect\n    self.timeout, self.source_address)\n  File "/usr/lib/python3.4/socket.py", line 509, in create_connection\n    raise err\n  File "/usr/lib/python3.4/socket.py", line 500, in create_connection\n    sock.connect(sa)\nTimeoutError: [Errno 110] Connection timed out\n')
('2015-02-07 10:38:03.068392', 'Traceback (most recent call last):\n  File "/river/fd/fd_worker/fd_channel.py", line 144, in pyget\n    ack  = handle.getresponse()\n  File "/usr/lib/python3.4/http/client.py", line 1147, in getresponse\n    response.begin()\n  File "/usr/lib/python3.4/http/client.py", line 351, in begin\n    version, status, reason = self._read_status()\n  File "/usr/lib/python3.4/http/client.py", line 313, in _read_status\n    line = str(self.fp.readline(_MAXLINE + 1), "iso-8859-1")\n  File "/usr/lib/python3.4/socket.py", line 371, in readinto\n    return self._sock.recv_into(b)\n  File "/usr/lib/python3.4/ssl.py", line 746, in recv_into\n    return self.read(nbytes, buffer)\n  File "/usr/lib/python3.4/ssl.py", line 618, in read\n    v = self._sslobj.read(len, buffer)\nConnectionResetError: [Errno 104] Connection reset by peer\n')
('2015-02-07 10:38:04.219135', 'Traceback (most recent call last):\n  File "/river/fd/fd_worker/fd_channel.py", line 204, in create_channel\n    handle.connect()\n  File "/usr/lib/python3.4/http/client.py", line 1197, in connect\n    self.timeout, self.source_address)\n  File "/usr/lib/python3.4/socket.py", line 509, in create_connection\n    raise err\n  File "/usr/lib/python3.4/socket.py", line 500, in create_connection\n    sock.connect(sa)\nTimeoutError: [Errno 110] Connection timed out\n')
('2015-02-07 10:38:04.219428', 'Traceback (most recent call last):\n  File "/river/fd/fd_worker/fd_channel.py", line 204, in create_channel\n    handle.connect()\n  File "/usr/lib/python3.4/http/client.py", line 1197, in connect\n    self.timeout, self.source_address)\n  File "/usr/lib/python3.4/socket.py", line 509, in create_connection\n    raise err\n  File "/usr/lib/python3.4/socket.py", line 500, in create_connection\n    sock.connect(sa)\nTimeoutError: [Errno 110] Connection timed out\n')
('2015-02-07 10:38:05.755246', 'Traceback (most recent call last):\n  File "/river/fd/fd_worker/fd_channel.py", line 204, in create_channel\n    handle.connect()\n  File "/usr/lib/python3.4/http/client.py", line 1197, in connect\n    self.timeout, self.source_address)\n  File "/usr/lib/python3.4/socket.py", line 509, in create_connection\n    raise err\n  File "/usr/lib/python3.4/socket.py", line 500, in create_connection\n    sock.connect(sa)\nTimeoutError: [Errno 110] Connection timed out\n')
('2015-02-07 10:38:10.235128', 'Traceback (most recent call last):\n  File "/river/fd/fd_worker/fd_channel.py", line 204, in create_channel\n    handle.connect()\n  File "/usr/lib/python3.4/http/client.py", line 1197, in connect\n    self.timeout, self.source_address)\n  File "/usr/lib/python3.4/socket.py", line 509, in create_connection\n    raise err\n  File "/usr/lib/python3.4/socket.py", line 500, in create_connection\n    sock.connect(sa)\nTimeoutError: [Errno 110] Connection timed out\n')
('2015-02-07 10:38:19.195282', 'Traceback (most recent call last):\n  File "/river/fd/fd_worker/fd_channel.py", line 204, in create_channel\n    handle.connect()\n  File "/usr/lib/python3.4/http/client.py", line 1197, in connect\n    self.timeout, self.source_address)\n  File "/usr/lib/python3.4/socket.py", line 509, in create_connection\n    raise err\n  File "/usr/lib/python3.4/socket.py", line 500, in create_connection\n    sock.connect(sa)\nTimeoutError: [Errno 110] Connection timed out\n')
('2015-02-07 10:38:19.195951', 'Traceback (most recent call last):\n  File "/river/fd/fd_worker/fd_channel.py", line 204, in create_channel\n    handle.connect()\n  File "/usr/lib/python3.4/http/client.py", line 1197, in connect\n    self.timeout, self.source_address)\n  File "/usr/lib/python3.4/socket.py", line 509, in create_connection\n    raise err\n  File "/usr/lib/python3.4/socket.py", line 500, in create_connection\n    sock.connect(sa)\nTimeoutError: [Errno 110] Connection timed out\n')
('2015-02-07 10:38:20.731338', 'Traceback (most recent call last):\n  File "/river/fd/fd_worker/fd_channel.py", line 204, in create_channel\n    handle.connect()\n  File "/usr/lib/python3.4/http/client.py", line 1197, in connect\n    self.timeout, self.source_address)\n  File "/usr/lib/python3.4/socket.py", line 509, in create_connection\n    raise err\n  File "/usr/lib/python3.4/socket.py", line 500, in create_connection\n    sock.connect(sa)\nTimeoutError: [Errno 110] Connection timed out\n')
('2015-02-07 10:38:20.732045', 'Traceback (most recent call last):\n  File "/river/fd/fd_worker/fd_channel.py", line 204, in create_channel\n    handle.connect()\n  File "/usr/lib/python3.4/http/client.py", line 1197, in connect\n    self.timeout, self.source_address)\n  File "/usr/lib/python3.4/socket.py", line 509, in create_connection\n    raise err\n  File "/usr/lib/python3.4/socket.py", line 500, in create_connection\n    sock.connect(sa)\nTimeoutError: [Errno 110] Connection timed out\n')
('2015-02-07 10:38:22.267523', 'Traceback (most recent call last):\n  File "/river/fd/fd_worker/fd_channel.py", line 204, in create_channel\n    handle.connect()\n  File "/usr/lib/python3.4/http/client.py", line 1197, in connect\n    self.timeout, self.source_address)\n  File "/usr/lib/python3.4/socket.py", line 509, in create_connection\n    raise err\n  File "/usr/lib/python3.4/socket.py", line 500, in create_connection\n    sock.connect(sa)\nTimeoutError: [Errno 110] Connection timed out\n')
('2015-02-07 10:38:22.268004', 'Traceback (most recent call last):\n  File "/river/fd/fd_worker/fd_channel.py", line 204, in create_channel\n    handle.connect()\n  File "/usr/lib/python3.4/http/client.py", line 1197, in connect\n    self.timeout, self.source_address)\n  File "/usr/lib/python3.4/socket.py", line 509, in create_connection\n    raise err\n  File "/usr/lib/python3.4/socket.py", line 500, in create_connection\n    sock.connect(sa)\nTimeoutError: [Errno 110] Connection timed out\n')
('2015-02-07 10:38:23.803222', 'Traceback (most recent call last):\n  File "/river/fd/fd_worker/fd_channel.py", line 204, in create_channel\n    handle.connect()\n  File "/usr/lib/python3.4/http/client.py", line 1197, in connect\n    self.timeout, self.source_address)\n  File "/usr/lib/python3.4/socket.py", line 509, in create_connection\n    raise err\n  File "/usr/lib/python3.4/socket.py", line 500, in create_connection\n    sock.connect(sa)\nTimeoutError: [Errno 110] Connection timed out\n')
('2015-02-07 10:38:23.803700', 'Traceback (most recent call last):\n  File "/river/fd/fd_worker/fd_channel.py", line 204, in create_channel\n    handle.connect()\n  File "/usr/lib/python3.4/http/client.py", line 1197, in connect\n    self.timeout, self.source_address)\n  File "/usr/lib/python3.4/socket.py", line 509, in create_connection\n    raise err\n  File "/usr/lib/python3.4/socket.py", line 500, in create_connection\n    sock.connect(sa)\nTimeoutError: [Errno 110] Connection timed out\n')
('2015-02-07 10:38:25.211160', 'Traceback (most recent call last):\n  File "/river/fd/fd_worker/fd_channel.py", line 204, in create_channel\n    handle.connect()\n  File "/usr/lib/python3.4/http/client.py", line 1197, in connect\n    self.timeout, self.source_address)\n  File "/usr/lib/python3.4/socket.py", line 509, in create_connection\n    raise err\n  File "/usr/lib/python3.4/socket.py", line 500, in create_connection\n    sock.connect(sa)\nTimeoutError: [Errno 110] Connection timed out\n')
('2015-02-07 10:38:25.339154', 'Traceback (most recent call last):\n  File "/river/fd/fd_worker/fd_channel.py", line 204, in create_channel\n    handle.connect()\n  File "/usr/lib/python3.4/http/client.py", line 1197, in connect\n    self.timeout, self.source_address)\n  File "/usr/lib/python3.4/socket.py", line 509, in create_connection\n    raise err\n  File "/usr/lib/python3.4/socket.py", line 500, in create_connection\n    sock.connect(sa)\nTimeoutError: [Errno 110] Connection timed out\n')
('2015-02-07 10:38:26.747156', 'Traceback (most recent call last):\n  File "/river/fd/fd_worker/fd_channel.py", line 204, in create_channel\n    handle.connect()\n  File "/usr/lib/python3.4/http/client.py", line 1197, in connect\n    self.timeout, self.source_address)\n  File "/usr/lib/python3.4/socket.py", line 509, in create_connection\n    raise err\n  File "/usr/lib/python3.4/socket.py", line 500, in create_connection\n    sock.connect(sa)\nTimeoutError: [Errno 110] Connection timed out\n')
('2015-02-07 10:38:26.747646', 'Traceback (most recent call last):\n  File "/river/fd/fd_worker/fd_channel.py", line 204, in create_channel\n    handle.connect()\n  File "/usr/lib/python3.4/http/client.py", line 1197, in connect\n    self.timeout, self.source_address)\n  File "/usr/lib/python3.4/socket.py", line 509, in create_connection\n    raise err\n  File "/usr/lib/python3.4/socket.py", line 500, in create_connection\n    sock.connect(sa)\nTimeoutError: [Errno 110] Connection timed out\n')
('2015-02-07 10:38:28.283599', 'Traceback (most recent call last):\n  File "/river/fd/fd_worker/fd_channel.py", line 204, in create_channel\n    handle.connect()\n  File "/usr/lib/python3.4/http/client.py", line 1197, in connect\n    self.timeout, self.source_address)\n  File "/usr/lib/python3.4/socket.py", line 509, in create_connection\n    raise err\n  File "/usr/lib/python3.4/socket.py", line 500, in create_connection\n    sock.connect(sa)\nTimeoutError: [Errno 110] Connection timed out\n')
('2015-02-07 10:38:29.691146', 'Traceback (most recent call last):\n  File "/river/fd/fd_worker/fd_channel.py", line 204, in create_channel\n    handle.connect()\n  File "/usr/lib/python3.4/http/client.py", line 1197, in connect\n    self.timeout, self.source_address)\n  File "/usr/lib/python3.4/socket.py", line 509, in create_connection\n    raise err\n  File "/usr/lib/python3.4/socket.py", line 500, in create_connection\n    sock.connect(sa)\nTimeoutError: [Errno 110] Connection timed out\n')
('2015-02-07 10:38:31.227131', 'Traceback (most recent call last):\n  File "/river/fd/fd_worker/fd_channel.py", line 204, in create_channel\n    handle.connect()\n  File "/usr/lib/python3.4/http/client.py", line 1197, in connect\n    self.timeout, self.source_address)\n  File "/usr/lib/python3.4/socket.py", line 509, in create_connection\n    raise err\n  File "/usr/lib/python3.4/socket.py", line 500, in create_connection\n    sock.connect(sa)\nTimeoutError: [Errno 110] Connection timed out\n')
('2015-02-07 10:38:32.763280', 'Traceback (most recent call last):\n  File "/river/fd/fd_worker/fd_channel.py", line 204, in create_channel\n    handle.connect()\n  File "/usr/lib/python3.4/http/client.py", line 1197, in connect\n    self.timeout, self.source_address)\n  File "/usr/lib/python3.4/socket.py", line 509, in create_connection\n    raise err\n  File "/usr/lib/python3.4/socket.py", line 500, in create_connection\n    sock.connect(sa)\nTimeoutError: [Errno 110] Connection timed out\n')
('2015-02-07 10:38:34.299184', 'Traceback (most recent call last):\n  File "/river/fd/fd_worker/fd_channel.py", line 204, in create_channel\n    handle.connect()\n  File "/usr/lib/python3.4/http/client.py", line 1197, in connect\n    self.timeout, self.source_address)\n  File "/usr/lib/python3.4/socket.py", line 509, in create_connection\n    raise err\n  File "/usr/lib/python3.4/socket.py", line 500, in create_connection\n    sock.connect(sa)\nTimeoutError: [Errno 110] Connection timed out\n')
('2015-02-07 10:38:35.835274', 'Traceback (most recent call last):\n  File "/river/fd/fd_worker/fd_channel.py", line 204, in create_channel\n    handle.connect()\n  File "/usr/lib/python3.4/http/client.py", line 1197, in connect\n    self.timeout, self.source_address)\n  File "/usr/lib/python3.4/socket.py", line 509, in create_connection\n    raise err\n  File "/usr/lib/python3.4/socket.py", line 500, in create_connection\n    sock.connect(sa)\nTimeoutError: [Errno 110] Connection timed out\n')
('2015-02-07 10:38:37.243521', 'Traceback (most recent call last):\n  File "/river/fd/fd_worker/fd_channel.py", line 204, in create_channel\n    handle.connect()\n  File "/usr/lib/python3.4/http/client.py", line 1197, in connect\n    self.timeout, self.source_address)\n  File "/usr/lib/python3.4/socket.py", line 509, in create_connection\n    raise err\n  File "/usr/lib/python3.4/socket.py", line 500, in create_connection\n    sock.connect(sa)\nTimeoutError: [Errno 110] Connection timed out\n')
('2015-02-07 10:39:01.180625', 'Traceback (most recent call last):\n  File "/river/fd/fd_worker/fd_channel.py", line 144, in pyget\n    ack  = handle.getresponse()\n  File "/usr/lib/python3.4/http/client.py", line 1147, in getresponse\n    response.begin()\n  File "/usr/lib/python3.4/http/client.py", line 351, in begin\n    version, status, reason = self._read_status()\n  File "/usr/lib/python3.4/http/client.py", line 313, in _read_status\n    line = str(self.fp.readline(_MAXLINE + 1), "iso-8859-1")\n  File "/usr/lib/python3.4/socket.py", line 371, in readinto\n    return self._sock.recv_into(b)\n  File "/usr/lib/python3.4/ssl.py", line 746, in recv_into\n    return self.read(nbytes, buffer)\n  File "/usr/lib/python3.4/ssl.py", line 618, in read\n    v = self._sslobj.read(len, buffer)\nConnectionResetError: [Errno 104] Connection reset by peer\n')
('2015-02-07 10:39:31.388616', 'Traceback (most recent call last):\n  File "/river/fd/fd_worker/fd_channel.py", line 144, in pyget\n    ack  = handle.getresponse()\n  File "/usr/lib/python3.4/http/client.py", line 1147, in getresponse\n    response.begin()\n  File "/usr/lib/python3.4/http/client.py", line 351, in begin\n    version, status, reason = self._read_status()\n  File "/usr/lib/python3.4/http/client.py", line 313, in _read_status\n    line = str(self.fp.readline(_MAXLINE + 1), "iso-8859-1")\n  File "/usr/lib/python3.4/socket.py", line 371, in readinto\n    return self._sock.recv_into(b)\n  File "/usr/lib/python3.4/ssl.py", line 746, in recv_into\n    return self.read(nbytes, buffer)\n  File "/usr/lib/python3.4/ssl.py", line 618, in read\n    v = self._sslobj.read(len, buffer)\nConnectionResetError: [Errno 104] Connection reset by peer\n')
('2015-02-07 10:40:01.596558', 'Traceback (most recent call last):\n  File "/river/fd/fd_worker/fd_channel.py", line 144, in pyget\n    ack  = handle.getresponse()\n  File "/usr/lib/python3.4/http/client.py", line 1147, in getresponse\n    response.begin()\n  File "/usr/lib/python3.4/http/client.py", line 351, in begin\n    version, status, reason = self._read_status()\n  File "/usr/lib/python3.4/http/client.py", line 313, in _read_status\n    line = str(self.fp.readline(_MAXLINE + 1), "iso-8859-1")\n  File "/usr/lib/python3.4/socket.py", line 371, in readinto\n    return self._sock.recv_into(b)\n  File "/usr/lib/python3.4/ssl.py", line 746, in recv_into\n    return self.read(nbytes, buffer)\n  File "/usr/lib/python3.4/ssl.py", line 618, in read\n    v = self._sslobj.read(len, buffer)\nConnectionResetError: [Errno 104] Connection reset by peer\n')
('2015-02-07 10:40:07.741148', 'Traceback (most recent call last):\n  File "/river/fd/fd_worker/fd_channel.py", line 144, in pyget\n    ack  = handle.getresponse()\n  File "/usr/lib/python3.4/http/client.py", line 1147, in getresponse\n    response.begin()\n  File "/usr/lib/python3.4/http/client.py", line 351, in begin\n    version, status, reason = self._read_status()\n  File "/usr/lib/python3.4/http/client.py", line 313, in _read_status\n    line = str(self.fp.readline(_MAXLINE + 1), "iso-8859-1")\n  File "/usr/lib/python3.4/socket.py", line 371, in readinto\n    return self._sock.recv_into(b)\n  File "/usr/lib/python3.4/ssl.py", line 746, in recv_into\n    return self.read(nbytes, buffer)\n  File "/usr/lib/python3.4/ssl.py", line 618, in read\n    v = self._sslobj.read(len, buffer)\nConnectionResetError: [Errno 104] Connection reset by peer\n')
('2015-02-07 11:29:21.076892', 'Traceback (most recent call last):\n  File "/river/fd/fd_worker/fd_channel.py", line 204, in create_channel\n    handle.connect()\n  File "/usr/lib/python3.4/http/client.py", line 1205, in connect\n    server_hostname=server_hostname)\n  File "/usr/lib/python3.4/ssl.py", line 364, in wrap_socket\n    _context=self)\n  File "/usr/lib/python3.4/ssl.py", line 578, in __init__\n    self.do_handshake()\n  File "/usr/lib/python3.4/ssl.py", line 805, in do_handshake\n    self._sslobj.do_handshake()\nConnectionResetError: [Errno 104] Connection reset by peer\n')
('2015-02-07 11:29:25.736738', 'Traceback (most recent call last):\n  File "/river/fd/fd_worker/fd_channel.py", line 204, in create_channel\n    handle.connect()\n  File "/usr/lib/python3.4/http/client.py", line 1205, in connect\n    server_hostname=server_hostname)\n  File "/usr/lib/python3.4/ssl.py", line 364, in wrap_socket\n    _context=self)\n  File "/usr/lib/python3.4/ssl.py", line 578, in __init__\n    self.do_handshake()\n  File "/usr/lib/python3.4/ssl.py", line 805, in do_handshake\n    self._sslobj.do_handshake()\nConnectionResetError: [Errno 104] Connection reset by peer\n')
('2015-02-07 11:29:29.769751', 'Traceback (most recent call last):\n  File "/river/fd/fd_worker/fd_channel.py", line 204, in create_channel\n    handle.connect()\n  File "/usr/lib/python3.4/http/client.py", line 1205, in connect\n    server_hostname=server_hostname)\n  File "/usr/lib/python3.4/ssl.py", line 364, in wrap_socket\n    _context=self)\n  File "/usr/lib/python3.4/ssl.py", line 578, in __init__\n    self.do_handshake()\n  File "/usr/lib/python3.4/ssl.py", line 805, in do_handshake\n    self._sslobj.do_handshake()\nConnectionResetError: [Errno 104] Connection reset by peer\n')
('2015-02-07 11:29:30.365347', 'Traceback (most recent call last):\n  File "/river/fd/fd_worker/fd_channel.py", line 204, in create_channel\n    handle.connect()\n  File "/usr/lib/python3.4/http/client.py", line 1205, in connect\n    server_hostname=server_hostname)\n  File "/usr/lib/python3.4/ssl.py", line 364, in wrap_socket\n    _context=self)\n  File "/usr/lib/python3.4/ssl.py", line 578, in __init__\n    self.do_handshake()\n  File "/usr/lib/python3.4/ssl.py", line 805, in do_handshake\n    self._sslobj.do_handshake()\nConnectionResetError: [Errno 104] Connection reset by peer\n')
('2015-02-07 11:29:31.209263', 'Traceback (most recent call last):\n  File "/river/fd/fd_worker/fd_channel.py", line 204, in create_channel\n    handle.connect()\n  File "/usr/lib/python3.4/http/client.py", line 1205, in connect\n    server_hostname=server_hostname)\n  File "/usr/lib/python3.4/ssl.py", line 364, in wrap_socket\n    _context=self)\n  File "/usr/lib/python3.4/ssl.py", line 578, in __init__\n    self.do_handshake()\n  File "/usr/lib/python3.4/ssl.py", line 805, in do_handshake\n    self._sslobj.do_handshake()\nConnectionResetError: [Errno 104] Connection reset by peer\n')
('2015-02-07 11:29:31.224579', 'Traceback (most recent call last):\n  File "/river/fd/fd_worker/fd_channel.py", line 204, in create_channel\n    handle.connect()\n  File "/usr/lib/python3.4/http/client.py", line 1205, in connect\n    server_hostname=server_hostname)\n  File "/usr/lib/python3.4/ssl.py", line 364, in wrap_socket\n    _context=self)\n  File "/usr/lib/python3.4/ssl.py", line 578, in __init__\n    self.do_handshake()\n  File "/usr/lib/python3.4/ssl.py", line 805, in do_handshake\n    self._sslobj.do_handshake()\nConnectionResetError: [Errno 104] Connection reset by peer\n')
('2015-02-07 11:29:31.272046', 'Traceback (most recent call last):\n  File "/river/fd/fd_worker/fd_channel.py", line 204, in create_channel\n    handle.connect()\n  File "/usr/lib/python3.4/http/client.py", line 1205, in connect\n    server_hostname=server_hostname)\n  File "/usr/lib/python3.4/ssl.py", line 364, in wrap_socket\n    _context=self)\n  File "/usr/lib/python3.4/ssl.py", line 578, in __init__\n    self.do_handshake()\n  File "/usr/lib/python3.4/ssl.py", line 805, in do_handshake\n    self._sslobj.do_handshake()\nConnectionResetError: [Errno 104] Connection reset by peer\n')
('2015-02-07 11:29:37.836787', 'Traceback (most recent call last):\n  File "/river/fd/fd_worker/fd_channel.py", line 204, in create_channel\n    handle.connect()\n  File "/usr/lib/python3.4/http/client.py", line 1205, in connect\n    server_hostname=server_hostname)\n  File "/usr/lib/python3.4/ssl.py", line 364, in wrap_socket\n    _context=self)\n  File "/usr/lib/python3.4/ssl.py", line 578, in __init__\n    self.do_handshake()\n  File "/usr/lib/python3.4/ssl.py", line 805, in do_handshake\n    self._sslobj.do_handshake()\nConnectionResetError: [Errno 104] Connection reset by peer\n')
('2015-02-07 11:29:39.453328', 'Traceback (most recent call last):\n  File "/river/fd/fd_worker/fd_channel.py", line 204, in create_channel\n    handle.connect()\n  File "/usr/lib/python3.4/http/client.py", line 1205, in connect\n    server_hostname=server_hostname)\n  File "/usr/lib/python3.4/ssl.py", line 364, in wrap_socket\n    _context=self)\n  File "/usr/lib/python3.4/ssl.py", line 578, in __init__\n    self.do_handshake()\n  File "/usr/lib/python3.4/ssl.py", line 805, in do_handshake\n    self._sslobj.do_handshake()\nConnectionResetError: [Errno 104] Connection reset by peer\n')
('2015-02-07 11:29:39.745390', 'Traceback (most recent call last):\n  File "/river/fd/fd_worker/fd_channel.py", line 204, in create_channel\n    handle.connect()\n  File "/usr/lib/python3.4/http/client.py", line 1205, in connect\n    server_hostname=server_hostname)\n  File "/usr/lib/python3.4/ssl.py", line 364, in wrap_socket\n    _context=self)\n  File "/usr/lib/python3.4/ssl.py", line 578, in __init__\n    self.do_handshake()\n  File "/usr/lib/python3.4/ssl.py", line 805, in do_handshake\n    self._sslobj.do_handshake()\nConnectionResetError: [Errno 104] Connection reset by peer\n')
('2015-02-07 11:29:39.937774', 'Traceback (most recent call last):\n  File "/river/fd/fd_worker/fd_channel.py", line 204, in create_channel\n    handle.connect()\n  File "/usr/lib/python3.4/http/client.py", line 1205, in connect\n    server_hostname=server_hostname)\n  File "/usr/lib/python3.4/ssl.py", line 364, in wrap_socket\n    _context=self)\n  File "/usr/lib/python3.4/ssl.py", line 578, in __init__\n    self.do_handshake()\n  File "/usr/lib/python3.4/ssl.py", line 805, in do_handshake\n    self._sslobj.do_handshake()\nConnectionResetError: [Errno 104] Connection reset by peer\n')
('2015-02-07 11:29:41.044754', 'Traceback (most recent call last):\n  File "/river/fd/fd_worker/fd_channel.py", line 204, in create_channel\n    handle.connect()\n  File "/usr/lib/python3.4/http/client.py", line 1205, in connect\n    server_hostname=server_hostname)\n  File "/usr/lib/python3.4/ssl.py", line 364, in wrap_socket\n    _context=self)\n  File "/usr/lib/python3.4/ssl.py", line 578, in __init__\n    self.do_handshake()\n  File "/usr/lib/python3.4/ssl.py", line 805, in do_handshake\n    self._sslobj.do_handshake()\nConnectionResetError: [Errno 104] Connection reset by peer\n')
('2015-02-07 11:29:45.760199', 'Traceback (most recent call last):\n  File "/river/fd/fd_worker/fd_channel.py", line 204, in create_channel\n    handle.connect()\n  File "/usr/lib/python3.4/http/client.py", line 1205, in connect\n    server_hostname=server_hostname)\n  File "/usr/lib/python3.4/ssl.py", line 364, in wrap_socket\n    _context=self)\n  File "/usr/lib/python3.4/ssl.py", line 578, in __init__\n    self.do_handshake()\n  File "/usr/lib/python3.4/ssl.py", line 805, in do_handshake\n    self._sslobj.do_handshake()\nConnectionResetError: [Errno 104] Connection reset by peer\n')
('2015-02-07 11:29:46.436887', 'Traceback (most recent call last):\n  File "/river/fd/fd_worker/fd_channel.py", line 204, in create_channel\n    handle.connect()\n  File "/usr/lib/python3.4/http/client.py", line 1205, in connect\n    server_hostname=server_hostname)\n  File "/usr/lib/python3.4/ssl.py", line 364, in wrap_socket\n    _context=self)\n  File "/usr/lib/python3.4/ssl.py", line 578, in __init__\n    self.do_handshake()\n  File "/usr/lib/python3.4/ssl.py", line 805, in do_handshake\n    self._sslobj.do_handshake()\nConnectionResetError: [Errno 104] Connection reset by peer\n')
('2015-02-07 11:29:47.721098', 'Traceback (most recent call last):\n  File "/river/fd/fd_worker/fd_channel.py", line 204, in create_channel\n    handle.connect()\n  File "/usr/lib/python3.4/http/client.py", line 1205, in connect\n    server_hostname=server_hostname)\n  File "/usr/lib/python3.4/ssl.py", line 364, in wrap_socket\n    _context=self)\n  File "/usr/lib/python3.4/ssl.py", line 578, in __init__\n    self.do_handshake()\n  File "/usr/lib/python3.4/ssl.py", line 805, in do_handshake\n    self._sslobj.do_handshake()\nConnectionResetError: [Errno 104] Connection reset by peer\n')
('2015-02-07 11:29:49.404453', 'Traceback (most recent call last):\n  File "/river/fd/fd_worker/fd_channel.py", line 204, in create_channel\n    handle.connect()\n  File "/usr/lib/python3.4/http/client.py", line 1205, in connect\n    server_hostname=server_hostname)\n  File "/usr/lib/python3.4/ssl.py", line 364, in wrap_socket\n    _context=self)\n  File "/usr/lib/python3.4/ssl.py", line 578, in __init__\n    self.do_handshake()\n  File "/usr/lib/python3.4/ssl.py", line 805, in do_handshake\n    self._sslobj.do_handshake()\nConnectionResetError: [Errno 104] Connection reset by peer\n')
('2015-02-07 11:29:50.320846', 'Traceback (most recent call last):\n  File "/river/fd/fd_worker/fd_channel.py", line 204, in create_channel\n    handle.connect()\n  File "/usr/lib/python3.4/http/client.py", line 1205, in connect\n    server_hostname=server_hostname)\n  File "/usr/lib/python3.4/ssl.py", line 364, in wrap_socket\n    _context=self)\n  File "/usr/lib/python3.4/ssl.py", line 578, in __init__\n    self.do_handshake()\n  File "/usr/lib/python3.4/ssl.py", line 805, in do_handshake\n    self._sslobj.do_handshake()\nConnectionResetError: [Errno 104] Connection reset by peer\n')
('2015-02-07 11:29:51.437239', 'Traceback (most recent call last):\n  File "/river/fd/fd_worker/fd_channel.py", line 204, in create_channel\n    handle.connect()\n  File "/usr/lib/python3.4/http/client.py", line 1205, in connect\n    server_hostname=server_hostname)\n  File "/usr/lib/python3.4/ssl.py", line 364, in wrap_socket\n    _context=self)\n  File "/usr/lib/python3.4/ssl.py", line 578, in __init__\n    self.do_handshake()\n  File "/usr/lib/python3.4/ssl.py", line 805, in do_handshake\n    self._sslobj.do_handshake()\nConnectionResetError: [Errno 104] Connection reset by peer\n')
('2015-02-07 11:29:51.776943', 'Traceback (most recent call last):\n  File "/river/fd/fd_worker/fd_channel.py", line 204, in create_channel\n    handle.connect()\n  File "/usr/lib/python3.4/http/client.py", line 1205, in connect\n    server_hostname=server_hostname)\n  File "/usr/lib/python3.4/ssl.py", line 364, in wrap_socket\n    _context=self)\n  File "/usr/lib/python3.4/ssl.py", line 578, in __init__\n    self.do_handshake()\n  File "/usr/lib/python3.4/ssl.py", line 805, in do_handshake\n    self._sslobj.do_handshake()\nConnectionResetError: [Errno 104] Connection reset by peer\n')
('2015-02-07 11:29:58.331150', 'Traceback (most recent call last):\n  File "/river/fd/fd_worker/fd_channel.py", line 204, in create_channel\n    handle.connect()\n  File "/usr/lib/python3.4/http/client.py", line 1197, in connect\n    self.timeout, self.source_address)\n  File "/usr/lib/python3.4/socket.py", line 509, in create_connection\n    raise err\n  File "/usr/lib/python3.4/socket.py", line 500, in create_connection\n    sock.connect(sa)\nTimeoutError: [Errno 110] Connection timed out\n')
('2015-02-07 11:29:59.739120', 'Traceback (most recent call last):\n  File "/river/fd/fd_worker/fd_channel.py", line 204, in create_channel\n    handle.connect()\n  File "/usr/lib/python3.4/http/client.py", line 1197, in connect\n    self.timeout, self.source_address)\n  File "/usr/lib/python3.4/socket.py", line 509, in create_connection\n    raise err\n  File "/usr/lib/python3.4/socket.py", line 500, in create_connection\n    sock.connect(sa)\nTimeoutError: [Errno 110] Connection timed out\n')
('2015-02-07 11:30:01.275328', 'Traceback (most recent call last):\n  File "/river/fd/fd_worker/fd_channel.py", line 204, in create_channel\n    handle.connect()\n  File "/usr/lib/python3.4/http/client.py", line 1197, in connect\n    self.timeout, self.source_address)\n  File "/usr/lib/python3.4/socket.py", line 509, in create_connection\n    raise err\n  File "/usr/lib/python3.4/socket.py", line 500, in create_connection\n    sock.connect(sa)\nTimeoutError: [Errno 110] Connection timed out\n')
('2015-02-07 11:30:21.728155', 'Traceback (most recent call last):\n  File "/river/fd/fd_worker/fd_channel.py", line 204, in create_channel\n    handle.connect()\n  File "/usr/lib/python3.4/http/client.py", line 1205, in connect\n    server_hostname=server_hostname)\n  File "/usr/lib/python3.4/ssl.py", line 364, in wrap_socket\n    _context=self)\n  File "/usr/lib/python3.4/ssl.py", line 578, in __init__\n    self.do_handshake()\n  File "/usr/lib/python3.4/ssl.py", line 805, in do_handshake\n    self._sslobj.do_handshake()\nConnectionResetError: [Errno 104] Connection reset by peer\n')
('2015-02-07 11:30:22.140868', 'Traceback (most recent call last):\n  File "/river/fd/fd_worker/fd_channel.py", line 204, in create_channel\n    handle.connect()\n  File "/usr/lib/python3.4/http/client.py", line 1205, in connect\n    server_hostname=server_hostname)\n  File "/usr/lib/python3.4/ssl.py", line 364, in wrap_socket\n    _context=self)\n  File "/usr/lib/python3.4/ssl.py", line 578, in __init__\n    self.do_handshake()\n  File "/usr/lib/python3.4/ssl.py", line 805, in do_handshake\n    self._sslobj.do_handshake()\nConnectionResetError: [Errno 104] Connection reset by peer\n')
('2015-02-07 11:30:25.211138', 'Traceback (most recent call last):\n  File "/river/fd/fd_worker/fd_channel.py", line 204, in create_channel\n    handle.connect()\n  File "/usr/lib/python3.4/http/client.py", line 1197, in connect\n    self.timeout, self.source_address)\n  File "/usr/lib/python3.4/socket.py", line 509, in create_connection\n    raise err\n  File "/usr/lib/python3.4/socket.py", line 500, in create_connection\n    sock.connect(sa)\nTimeoutError: [Errno 110] Connection timed out\n')
('2015-02-07 11:30:29.821351', 'Traceback (most recent call last):\n  File "/river/fd/fd_worker/fd_channel.py", line 204, in create_channel\n    handle.connect()\n  File "/usr/lib/python3.4/http/client.py", line 1205, in connect\n    server_hostname=server_hostname)\n  File "/usr/lib/python3.4/ssl.py", line 364, in wrap_socket\n    _context=self)\n  File "/usr/lib/python3.4/ssl.py", line 578, in __init__\n    self.do_handshake()\n  File "/usr/lib/python3.4/ssl.py", line 805, in do_handshake\n    self._sslobj.do_handshake()\nConnectionResetError: [Errno 104] Connection reset by peer\n')
('2015-02-07 11:30:34.171211', 'Traceback (most recent call last):\n  File "/river/fd/fd_worker/fd_channel.py", line 204, in create_channel\n    handle.connect()\n  File "/usr/lib/python3.4/http/client.py", line 1197, in connect\n    self.timeout, self.source_address)\n  File "/usr/lib/python3.4/socket.py", line 509, in create_connection\n    raise err\n  File "/usr/lib/python3.4/socket.py", line 500, in create_connection\n    sock.connect(sa)\nTimeoutError: [Errno 110] Connection timed out\n')
('2015-02-07 11:30:41.723157', 'Traceback (most recent call last):\n  File "/river/fd/fd_worker/fd_channel.py", line 204, in create_channel\n    handle.connect()\n  File "/usr/lib/python3.4/http/client.py", line 1197, in connect\n    self.timeout, self.source_address)\n  File "/usr/lib/python3.4/socket.py", line 509, in create_connection\n    raise err\n  File "/usr/lib/python3.4/socket.py", line 500, in create_connection\n    sock.connect(sa)\nTimeoutError: [Errno 110] Connection timed out\n')
('2015-02-07 11:30:43.259129', 'Traceback (most recent call last):\n  File "/river/fd/fd_worker/fd_channel.py", line 204, in create_channel\n    handle.connect()\n  File "/usr/lib/python3.4/http/client.py", line 1197, in connect\n    self.timeout, self.source_address)\n  File "/usr/lib/python3.4/socket.py", line 509, in create_connection\n    raise err\n  File "/usr/lib/python3.4/socket.py", line 500, in create_connection\n    sock.connect(sa)\nTimeoutError: [Errno 110] Connection timed out\n')
('2015-02-07 11:30:44.667177', 'Traceback (most recent call last):\n  File "/river/fd/fd_worker/fd_channel.py", line 204, in create_channel\n    handle.connect()\n  File "/usr/lib/python3.4/http/client.py", line 1197, in connect\n    self.timeout, self.source_address)\n  File "/usr/lib/python3.4/socket.py", line 509, in create_connection\n    raise err\n  File "/usr/lib/python3.4/socket.py", line 500, in create_connection\n    sock.connect(sa)\nTimeoutError: [Errno 110] Connection timed out\n')
('2015-02-07 11:30:46.203335', 'Traceback (most recent call last):\n  File "/river/fd/fd_worker/fd_channel.py", line 204, in create_channel\n    handle.connect()\n  File "/usr/lib/python3.4/http/client.py", line 1197, in connect\n    self.timeout, self.source_address)\n  File "/usr/lib/python3.4/socket.py", line 509, in create_connection\n    raise err\n  File "/usr/lib/python3.4/socket.py", line 500, in create_connection\n    sock.connect(sa)\nTimeoutError: [Errno 110] Connection timed out\n')
('2015-02-07 11:30:56.699174', 'Traceback (most recent call last):\n  File "/river/fd/fd_worker/fd_channel.py", line 204, in create_channel\n    handle.connect()\n  File "/usr/lib/python3.4/http/client.py", line 1197, in connect\n    self.timeout, self.source_address)\n  File "/usr/lib/python3.4/socket.py", line 509, in create_connection\n    raise err\n  File "/usr/lib/python3.4/socket.py", line 500, in create_connection\n    sock.connect(sa)\nTimeoutError: [Errno 110] Connection timed out\n')
('2015-02-07 11:30:58.235680', 'Traceback (most recent call last):\n  File "/river/fd/fd_worker/fd_channel.py", line 204, in create_channel\n    handle.connect()\n  File "/usr/lib/python3.4/http/client.py", line 1197, in connect\n    self.timeout, self.source_address)\n  File "/usr/lib/python3.4/socket.py", line 509, in create_connection\n    raise err\n  File "/usr/lib/python3.4/socket.py", line 500, in create_connection\n    sock.connect(sa)\nTimeoutError: [Errno 110] Connection timed out\n')
('2015-02-07 11:30:59.771156', 'Traceback (most recent call last):\n  File "/river/fd/fd_worker/fd_channel.py", line 204, in create_channel\n    handle.connect()\n  File "/usr/lib/python3.4/http/client.py", line 1197, in connect\n    self.timeout, self.source_address)\n  File "/usr/lib/python3.4/socket.py", line 509, in create_connection\n    raise err\n  File "/usr/lib/python3.4/socket.py", line 500, in create_connection\n    sock.connect(sa)\nTimeoutError: [Errno 110] Connection timed out\n')
